Workbook
Name g_: 'DCF Commodities'!$F$18
Name NExp: 'DCF Commodities'!$F$19
Name TVx: 'DCF Commodities'!$F$20

Sheet DCF Commodities
B1: Commodities - FCFE with zero real growth, the analysts' logic on the box consensus (end-2027)
B2: Consensus 2026-28 summed from the members (Box Consensus); the projection is done for the box: ROE held, growth to g by the last explicit year, cash to shareholders = net income - the increase in book value; Gordon perpetuity.
B3: Legend: | C3: input | D3: assumption | E3: formula
B5: 1. Inputs
B6: Item | C6: Value | P6: Source / note
B7: Commodities, index points today | C7: ='Box Consensus'!C22 -> 65411.174 | P7: Members' weight x Ibovespa close of Oct-5-2026 (Box Consensus; Box Shares!C10 of the main model).
B8: Long-term IPCA | C8: 0.04 | P8: House (Target!B63) and the analysts' Macro sheets.
B9: Long-term real growth of the box | C9: 0 | P9: Caio, Oct-8-2026: zero, as the analysts' commodity models (perpetuity g = inflation, or finite lives).
B10: Share of the risk free kept after tax | C10: 0.85 | P10: As the analysts: risk free = (NTN-B + IPCA) x 0.85.
B11: Equity risk premium, the same for every box | C11: 0.055 | P11: Unified (Caio, Oct-8-2026).
B12: Earnings elasticity to commodity prices | C12: 1.262 | P12: Box Earnings!J10 of the main model: 12-month change of the box 12m fwd EPS vs. the DJP commodity ETN, Oct-07 to Sep-26.
B13: Box ROE after 2028 (blank = consensus FY28 of the box) | P13: Typed value replaces the FY28 box ROE after 2028.
B15: 2. House vs. analysts, variable by variable (choice: 1 = house, 2 = analysts)
B16: Variable | C16: House | D16: Analysts | E16: Choice | F16: Used | P16: House / analysts
B17: Beta | C17: 0.872 | D17: 1 | E17: 1 | F17: =IF(E17=1,C17,D17) -> 0.872 | P17: House: the box beta, weekly 5 years vs. the Ibovespa from the local box index (Box Betas). Analysts: 1.0 (Vale, Suzano).
B18: Perpetuity growth (g) | C18: 0.047 | D18: =(1+C8)*(1+C9)-1 -> 0.04 | E18: 2 | F18: =IF(E18=1,C18,D18) -> 0.04 | P18: House: 4.7% (Target!B54). Analysts (commodities): inflation x (1 + real growth), real growth 0%.
B19: Explicit years after the value date | C19: 4 | D19: 8 | E19: 1 | F19: =IF(E19=1,C19,D19) -> 4 | P19: House: 2028-31. Analysts: to 2035 (Vale, Suzano). Growth reaches g by the last explicit year.
B20: Extra periods in the discount of the terminal value | C20: 1 | D20: 0 | E20: 2 | F20: =IF(E20=1,C20,D20) -> 0 | P20: House: the TV is discounted one period more than the last flow. Analysts: the last year's factor.
B22: 3. Cost of equity by scenario
B23: Item | C23: Bear | D23: Base | E23: Bull | P23: How it is calculated
B24: 5-year real rate (NTN-B) | C24: 0.085 | D24: 0.0676 | E24: 0.055 | P24: Same scenarios as the other boxes.
B25: Risk free, nominal = (NTN-B + long-term IPCA) x share kept after tax | C25: =(C24+$C$8)*$C$10 -> 0.10625 | D25: =(D24+$C$8)*$C$10 -> 0.09146 | E25: =(E24+$C$8)*$C$10 -> 0.08075 | P25: Nominal, because the flows are nominal.
B26: Ke = risk free + beta x ERP | C26: =C25+$F$17*$C$11 -> 0.15421 | D26: =D25+$F$17*$C$11 -> 0.13942 | E26: =E25+$F$17*$C$11 -> 0.12871
B27: Ke - g | C27: =(C26-g_)*100 -> 11.421 | D27: =(D26-g_)*100 -> 9.942 | E27: =(E26-g_)*100 -> 8.871
B29: 4. Box projection (index points): consensus 2026-28, box-level projection after 2028
B30: Line | C30: 2026 | D30: 2027 | E30: 2028 | F30: 2029 | G30: 2030 | H30: 2031 | I30: 2032 | J30: 2033 | K30: 2034 | L30: 2035 | M30: 2036 | N30: 2037 | P30: How it is calculated / source
B31: Years after end-2027 (grey = after the explicit years, not used) | E31: =2028-2027 -> 1 | F31: =2029-2027 -> 2 | G31: =2030-2027 -> 3 | H31: =2031-2027 -> 4 | I31: =2032-2027 -> 5 | J31: =2033-2027 -> 6 | K31: =2034-2027 -> 7 | L31: =2035-2027 -> 8 | M31: =2036-2027 -> 9 | N31: =2037-2027 -> 10
B32: Net income: 2026-28 consensus (sum of the members); then previous x (1 + growth) | C32: ='Box Consensus'!L22 -> 10671.973 | D32: ='Box Consensus'!M22 -> 9633.4894 | E32: ='Box Consensus'!N22 -> 9460.6727 | F32: =E32*(1+F33) -> 9473.6707 | G32: =F32*(1+G33) -> 9669.652 | H32: =G32*(1+H33) -> 10056.438 | I32: =H32*(1+I33) -> 10458.696 | J32: =I32*(1+J33) -> 10877.043 | K32: =J32*(1+K33) -> 11312.125 | L32: =K32*(1+L33) -> 11764.61 | M32: =L32*(1+M33) -> 12235.195 | N32: =M32*(1+N33) -> 12724.602 | P32: Box Consensus.
B33: Net income growth: 2027-28 consensus; then linear from the 2028 growth to g in the last explicit year | D33: =D32/C32-1 -> -0.097309389 | E33: =E32/D32-1 -> -0.017939157 | F33: =IF(F31>=NExp,g_,$E$33+(g_-$E$33)*(F31-1)/(NExp-1)) -> 0.0013738955 | G33: =IF(G31>=NExp,g_,$E$33+(g_-$E$33)*(G31-1)/(NExp-1)) -> 0.020686948 | H33: =IF(H31>=NExp,g_,$E$33+(g_-$E$33)*(H31-1)/(NExp-1)) -> 0.04 | I33: =IF(I31>=NExp,g_,$E$33+(g_-$E$33)*(I31-1)/(NExp-1)) -> 0.04 | J33: =IF(J31>=NExp,g_,$E$33+(g_-$E$33)*(J31-1)/(NExp-1)) -> 0.04 | K33: =IF(K31>=NExp,g_,$E$33+(g_-$E$33)*(K31-1)/(NExp-1)) -> 0.04 | L33: =IF(L31>=NExp,g_,$E$33+(g_-$E$33)*(L31-1)/(NExp-1)) -> 0.04 | M33: =IF(M31>=NExp,g_,$E$33+(g_-$E$33)*(M31-1)/(NExp-1)) -> 0.04 | N33: =IF(N31>=NExp,g_,$E$33+(g_-$E$33)*(N31-1)/(NExp-1)) -> 0.04 | P33: The consensus already brings prices toward the long term (net income falls 2026-28); after that, nominal growth = inflation.
B34: ROE: 2026-28 consensus of the box; then held at FY28 | C34: ='Box Consensus'!I22 -> 0.23604498 | D34: ='Box Consensus'!J22 -> 0.18933914 | E34: ='Box Consensus'!K22 -> 0.17110432 | F34: =IF(ISNUMBER($C$13),$C$13,$E$34) -> 0.17110432 | G34: =IF(ISNUMBER($C$13),$C$13,$E$34) -> 0.17110432 | H34: =IF(ISNUMBER($C$13),$C$13,$E$34) -> 0.17110432 | I34: =IF(ISNUMBER($C$13),$C$13,$E$34) -> 0.17110432 | J34: =IF(ISNUMBER($C$13),$C$13,$E$34) -> 0.17110432 | K34: =IF(ISNUMBER($C$13),$C$13,$E$34) -> 0.17110432 | L34: =IF(ISNUMBER($C$13),$C$13,$E$34) -> 0.17110432 | M34: =IF(ISNUMBER($C$13),$C$13,$E$34) -> 0.17110432 | N34: =IF(ISNUMBER($C$13),$C$13,$E$34) -> 0.17110432 | P34: FY28 consensus ROE of the box vs. its 12m fwd history: 10y average 18.5%, ex-2021-22 boom ~15%.
B35: Book value: 2026-28 consensus (net income / ROE, summed); then net income / ROE | C35: ='Box Consensus'!O22 -> 45211.606 | D35: ='Box Consensus'!P22 -> 50879.545 | E35: ='Box Consensus'!Q22 -> 55291.84 | F35: =F32/F34 -> 55367.805 | G35: =G32/G34 -> 56513.196 | H35: =H32/H34 -> 58773.724 | I35: =I32/I34 -> 61124.673 | J35: =J32/J34 -> 63569.66 | K35: =K32/K34 -> 66112.446 | L35: =L32/L34 -> 68756.944 | M35: =M32/M34 -> 71507.222 | N35: =N32/N34 -> 74367.511
B36: Cash to shareholders = net income - increase in book value (dividends + buybacks) | D36: =D32-(D35-C35) -> 3965.5501 | E36: =E32-(E35-D35) -> 5048.3779 | F36: =F32-(F35-E35) -> 9397.7055 | G36: =G32-(G35-F35) -> 8524.2612 | H36: =H32-(H35-G35) -> 7795.9103 | I36: =I32-(I35-H35) -> 8107.7467 | J36: =J32-(J35-I35) -> 8432.0566 | K36: =K32-(K35-J35) -> 8769.3388 | ... N36: =N32-(N35-M35) -> 9864.3136 | P36: FCFE at constant leverage: the equity part of the reinvestment is retained, the rest is paid out.
B37: Payout | D37: =D36/D32 -> 0.41164213 | E37: =E36/E32 -> 0.53361722 | F37: =F36/F32 -> 0.99198144 | G37: =G36/G32 -> 0.88154787 | H37: =H36/H32 -> 0.77521586 | I37: =I36/I32 -> 0.77521586 | J37: =J36/J32 -> 0.77521586 | K37: =K36/K32 -> 0.77521586 | ... N37: =N36/N32 -> 0.77521586 | P37: Converges to about 1 - g / ROE.
B39: 5. Valuation at the end of 2027
B40: Item | C40: Bear | D40: Base | E40: Bull | P40: How it is calculated
B41: Ke | C41: =C26 -> 0.15421 | D41: =D26 -> 0.13942 | E41: =E26 -> 0.12871
B42: Commodity price shock | C42: -0.2 | D42: 0 | E42: 0.2 | P42: Symmetric +/-20%, as Assumptions row 62 of the main model.
B43: Earnings shock of Commodities = elasticity x price shock | C43: =$C$12*C42 -> -0.2524 | D43: =$C$12*D42 -> 0 | E43: =$C$12*E42 -> 0.2524 | P43: Moves the cash to shareholders of every year.
B44: PV of the explicit flows = (1 + shock) x sum of flow / (1 + Ke) ^ t | C44: =(1+C43)*SUMPRODUCT($E$36:$N$36,--($E$31:$N$31<=NExp),1/(1+C41)^$E$31:$N$31) -> 15972.133 | D44: =(1+D43)*SUMPRODUCT($E$36:$N$36,--($E$31:$N$31<=NExp),1/(1+D41)^$E$31:$N$31) -> 22056.883 | E44: =(1+E43)*SUMPRODUCT($E$36:$N$36,--($E$31:$N$31<=NExp),1/(1+E41)^$E$31:$N$31) -> 28279.95 | P44: t = 1 for 2028 (value at end-2027); only the explicit years.
B45: Terminal value = last explicit flow x (1 + shock) x (1 + g) / (Ke - g) | C45: =INDEX($E$36:$N$36,NExp)*(1+C43)*(1+g_)/(C41-g_) -> 53071.985 | D45: =INDEX($E$36:$N$36,NExp)*(1+D43)*(1+g_)/(D41-g_) -> 81550.46 | E45: =INDEX($E$36:$N$36,NExp)*(1+E43)*(1+g_)/(E41-g_) -> 114464.46 | P45: Gordon on the last explicit flow, nominal growth = inflation (zero real).
...

Sheet Box Consensus
B1: Commodities - consensus 2026-28 of the members, summed into the box (index points)
B2: Bloomberg BEST consensus (Oct-7-2026): net income (BEST_NET_INCOME, Members sheet of the main model) and ROE (BEST_ROE, dcf_members.parquet). Book value = net income / ROE. Index points = R$ mn x points / market cap. Only the actuals and consensus years are built from the members; the projection is done for the box.
B3: Legend: | C3: input | D3: assumption | E3: formula
B6: Member | C6: Index points | D6: Market cap (R$ mn) | E6: Points / market cap | F6: Net income 2026 (R$ mn) | G6: Net income 2027 (R$ mn) | H6: Net income 2028 (R$ mn) | I6: ROE 2026 | J6: ROE 2027 | K6: ROE 2028 | L6: Net income 2026 (pts) | M6: Net income 2027 (pts) | N6: Net income 2028 (pts) | O6: Book value 2026 (pts) | P6: Book value 2027 (pts) | Q6: Book value 2028 (pts)
B7: Vale (VALE3) | C7: 18861.588 | D7: 292583.69 | E7: =C7/D7 -> 0.064465618 | F7: 37349.381 | G7: 38936.048 | H7: 39670.895 | I7: 0.18961 | J7: 0.18174 | K7: 0.16601 | L7: =F7*$E7 -> 2407.7509 | M7: =G7*$E7 -> 2510.0364 | N7: =H7*$E7 -> 2557.4087 | O7: =L7/I7 -> 12698.438 | P7: =M7/J7 -> 13811.139 | Q7: =N7/K7 -> 15405.149
B8: Petrobras (PETR4 + PETR3) | C8: 28130.207 | D8: 742814.41 | E8: =C8/D8 -> 0.037869764 | F8: 159783.86 | G8: 134066.29 | H8: 123997.15 | I8: 0.31741 | J8: 0.22129 | K8: 0.18461 | L8: =F8*$E8 -> 6050.977 | M8: =G8*$E8 -> 5077.0587 | N8: =H8*$E8 -> 4695.743 | O8: =L8/I8 -> 19063.599 | P8: =M8/J8 -> 22943.01 | Q8: =N8/K8 -> 25436.017
B9: PRIO (PRIO3) | C9: 3466.2927 | D9: 54626.928 | E9: =C9/D9 -> 0.063453919 | F9: 7814.3 | G9: 7794.364 | H9: 7817.455 | I9: 0.28075 | J9: 0.25385 | K9: 0.27792 | L9: =F9*$E9 -> 495.84796 | M9: =G9*$E9 -> 494.58294 | N9: =H9*$E9 -> 496.04816 | O9: =L9/I9 -> 1766.1548 | P9: =M9/J9 -> 1948.3275 | Q9: =N9/K9 -> 1784.8595
B10: Vibra Energia (VBBR3) | C10: 3300.0683 | D10: 45006.061 | E10: =C10/D10 -> 0.073324975 | F10: 6856.071 | G10: 4105.071 | H10: 4567.308 | I10: 0.30051 | J10: 0.1693 | K10: 0.17703 | L10: =F10*$E10 -> 502.72123 | M10: =G10*$E10 -> 301.00423 | N10: =H10*$E10 -> 334.89774 | O10: =L10/I10 -> 1672.8935 | P10: =M10/J10 -> 1777.934 | Q10: =N10/K10 -> 1891.757
B11: Ultrapar (UGPA3) | C11: 2985.2772 | D11: 43216.866 | E11: =C11/D11 -> 0.069076671 | F11: 5020.273 | G11: 3493.364 | H11: 3939.2 | I11: 0.28287 | J11: 0.18903 | K11: 0.19763 | L11: =F11*$E11 -> 346.78374 | M11: =G11*$E11 -> 241.30995 | N11: =H11*$E11 -> 272.10682 | O11: =L11/I11 -> 1225.9474 | P11: =M11/J11 -> 1276.5696 | Q11: =N11/K11 -> 1376.8498
B12: Gerdau (GGBR4) | C12: 2308.3046 | D12: 47327.83 | E12: =C12/D12 -> 0.04877267 | F12: 5373.077 | G12: 5819.538 | H12: 5690.7 | I12: 0.09788 | J12: 0.10334 | K12: 0.09883 | L12: =F12*$E12 -> 262.05931 | M12: =G12*$E12 -> 283.8344 | N12: =H12*$E12 -> 277.55063 | O12: =L12/I12 -> 2677.353 | P12: =M12/J12 -> 2746.6074 | Q12: =N12/K12 -> 2808.3642
B13: Suzano (SUZB3) | C13: 1834.4478 | D13: 53320.481 | E13: =C13/D13 -> 0.034404186 | F13: 9407.214 | G13: 6888.4 | H13: 7008 | I13: 0.17596 | J13: 0.11924 | K13: 0.10178 | L13: =F13*$E13 -> 323.64754 | M13: =G13*$E13 -> 236.9898 | N13: =H13*$E13 -> 241.10454 | O13: =L13/I13 -> 1839.3245 | P13: =M13/J13 -> 1987.5025 | Q13: =N13/K13 -> 2368.8793
B14: Klabin (KLBN11) | C14: 1042.0522 | D14: 23199.922 | E14: =C14/D14 -> 0.044916193 | F14: 1009.727 | G14: 1680.583 | H14: 1980.545 | I14: 0.17711 | J14: 0.19678 | K14: 0.30387 | L14: =F14*$E14 -> 45.353093 | M14: =G14*$E14 -> 75.48539 | N14: =H14*$E14 -> 88.958541 | O14: =L14/I14 -> 256.07302 | P14: =M14/J14 -> 383.60296 | Q14: =N14/K14 -> 292.75197
B15: Cosan (CSAN3) | C15: 838.67827 | D15: 20031.183 | E15: =C15/D15 -> 0.041868634 | F15: -856.55 | G15: 2196.857 | H15: 3607.167 | I15: -0.1221 | J15: 0.1846 | K15: 0.21347 | L15: =F15*$E15 -> -35.862578 | M15: =G15*$E15 -> 91.979401 | N15: =H15*$E15 -> 151.02715 | O15: =L15/I15 -> 293.71481 | P15: =M15/J15 -> 498.26328 | Q15: =N15/K15 -> 707.48655
B16: Met. Gerdau (GOAU4) | C16: 699.89539 | D16: 14527.916 | E16: =C16/D16 -> 0.048175898 | F16: 1932 | G16: 1686 | H16: 1648.6739 | I16: 0.0989 | J16: 0.10334 | K16: 0.09883 | L16: =F16*$E16 -> 93.075835 | M16: =G16*$E16 -> 81.224564 | N16: =H16*$E16 -> 79.426344 | O16: =L16/I16 -> 941.11057 | P16: =M16/J16 -> 785.99346 | Q16: =N16/K16 -> 803.66634
B17: CSN Mineração (CMIN3) | C17: 569.56628 | D17: 26997.261 | E17: =C17/D17 -> 0.021097187 | F17: 1535.091 | G17: 1364.7 | H17: 1844 | I17: 0.18611 | J17: 0.19104 | K17: 0.3377 | L17: =F17*$E17 -> 32.386103 | M17: =G17*$E17 -> 28.791332 | N17: =H17*$E17 -> 38.903214 | O17: =L17/I17 -> 174.01592 | P17: =M17/J17 -> 150.70839 | Q17: =N17/K17 -> 115.20051
B18: Brava Energia (BRAV3) | C18: 381.39676 | D18: 9240.0441 | E18: =C18/D18 -> 0.041276509 | F18: 911 | G18: 1804.545 | H18: 1734.778 | I18: 0.0587 | J18: 0.10544 | K18: 0.10748 | L18: =F18*$E18 -> 37.6029 | M18: =G18*$E18 -> 74.485318 | N18: =H18*$E18 -> 71.60558 | O18: =L18/I18 -> 640.59454 | P18: =M18/J18 -> 706.42373 | Q18: =N18/K18 -> 666.22236
... B21: Usiminas (USIM5) | C21: 277.31932 | D21: 8789.3845 | E21: =C21/D21 -> 0.03155162 | F21: 1592.909 | G21: 1416.182 | H21: 1598.667 | I21: 0.08031 | J21: 0.05898 | K21: 0.06654 | L21: =F21*$E21 -> 50.25886 | M21: =G21*$E21 -> 44.682836 | N21: =H21*$E21 -> 50.440534 | O21: =L21/I21 -> 625.81073 | P21: =M21/J21 -> 757.59302 | Q21: =N21/K21 -> 758.0483
B22: Commodities box | C22: =SUM(C7:C21) -> 65411.174 | I22: =L22/O22 -> 0.23604498 | J22: =M22/P22 -> 0.18933914 | K22: =N22/Q22 -> 0.17110432 | L22: =SUM(L7:L21) -> 10671.973 | M22: =SUM(M7:M21) -> 9633.4894 | N22: =SUM(N7:N21) -> 9460.6727 | O22: =SUM(O7:O21) -> 45211.606 | P22: =SUM(P7:P21) -> 50879.545 | Q22: =SUM(Q7:Q21) -> 55291.84
B23: Check: net income vs. Box Shares!M10:O10 of the main model | L23: =L22-10671.9725499485 -> 0 | M23: =M22-9633.48941904183 -> 0 | N23: =N22-9381.24639794184 -> 79.426344
B25: Box ROE = sum of net income / sum of book value (row total).
B26: Metalurgica Gerdau (holding of Gerdau): no consensus for 2028 net income and 2027-28 ROE; Gerdau's path (pink, editable). The main model had 0 for its 2028 net income, hence the check difference in 2028.
B27: Petrobras: PETR4 and PETR3 points added (same company figures).
B28: Cosan and CSN have negative 2026 consensus net income and ROE: book value = net income / ROE stays positive.

Sheet Analyst Models
B1: Commodities - how the XP commodity analysts treat the long term (memo)
B2: Files in inputs/analyst_models/Commodities (DCF & Sensitivity, Valuation, Control Panel sheets), read on Oct-8-2026.
B3: Legend: | C3: input | D3: assumption | E3: formula
B5: Model | C5: Currency | D5: Method | E5: Value date | F5: Explicit to | G5: Perpetuity g | H5: Risk free | I5: Beta x ERP | J5: Ke / WACC | K5: Long-term price
B6: Vale (VALE3) | C6: USD | D6: FCFF - net debt, SOTP | E6: End-2027 | F6: 2035 | G6: 2.4% (US CPI, real 0%) | H6: (real 70% BR 7.8% + 30% US 2.55%, + US CPI) x 0.85 = 7.5% | I6: 1.0 x 5.5% | J6: 13.0% / 11.3% | K6: Iron ore US$100 (26YE) > 97.5 > 93.75 > 90/t from 2029; copper 14k > 15k (2030)
B7: Petrobras (PETR4) | C7: USD | D7: FCFF - net debt, by business | E7: (older vintage) | F7: 2031 (EBITDA to 2060) | G7: 2.4% on an adjusted 2031 FCFF | H7: Treasury 4.0% + CDS 2.1% | I7: 1.53 (levered) x 5.0% | J7: 13.7% / 12.1% | K7: Brent US$63/bbl; EBITDA falls with reserves: -6% a year real 2028-35
B8: Suzano (SUZB3) | C8: BRL | D8: FCFE (FCFF check) | E8: End-2027 | F8: 2035 | G8: 4.0% (IPCA, real 0%) | H8: (real 90% BR 7.5% + 10% US, + IPCA) x 0.85 = 9.6% | I8: 1.0 x 5.5% | J8: 15.1% / 11.2% | K8: BHKP real US$590 > 570 > 560/t from 2028
B9: Aura (AURA33) | C9: USD | D9: FCFF, SOTP by mine | E9: End-2026 | F9: Mine lives (to ~2047) | G9: None (finite reserves) | H9: Same rule, USD = 8.5% | I9: 0.5 x 5.5% | J9: 11.2% / 10.5% | K9: Gold US$4,500 (26-27) > 3,500 by 2035; copper 14k
B11: Real growth after 2028 in the analysts' models (a year, 2028-35)
B12: Model | C12: Line | D12: Nominal | E12: Real | F12: Note
B13: Vale | C13: NOPLAT, USD | D13: 0.063 | E13: 0.038 | F13: Copper and nickel growth; 28.8% of the box
B14: Petrobras | C14: EBITDA, USD | D14: -0.038 | E14: -0.061 | F14: Reserve depletion; 43.0% of the box
B15: Suzano | C15: NOPLAT, BRL | D15: 0.047 | E15: 0.007 | F15: Real pulp price flat from 2028; 2.8% of the box
B17: Weighted by the box points, the three give about -2% a year real: zero real growth for the box is neutral to slightly generous.
