Workbook
Name g_: 'DCF Commodities'!$F$18
Name NExp: 'DCF Commodities'!$F$19
Name PETRFX: 'Box Consensus'!$C$5
Name TVx: 'DCF Commodities'!$F$20

Sheet DCF Commodities
B1: Commodities - FCFE with zero real growth, the analysts' logic on the box consensus (end-2027)
B2: Cash to shareholders = net income + D&A + capex - lease principal + change in working capital (net debt constant). Consensus 2026-28 summed from the members; projection for the box; Gordon perpetuity with zero real growth.
B3: Legend: | C3: input | D3: assumption | E3: formula
B5: 1. Inputs
B6: Item | C6: Value | P6: Source / note
B7: Commodities, index points today | C7: ='Box Consensus'!C43 -> 65411.174 | P7: Members' weight x Ibovespa close of Oct-5-2026 (Box Shares!C10 of the main model).
B8: Long-term IPCA | C8: 0.04 | P8: House (Target!B63) and the analysts' Macro sheets.
B9: Long-term real growth of the box | C9: 0 | P9: Caio, Oct-8-2026: zero, as the analysts' commodity perpetuities (g = inflation) or finite lives.
B10: Share of the risk free kept after tax | C10: 0.85 | P10: As the analysts: risk free = (NTN-B + IPCA) x 0.85.
B11: Equity risk premium, the same for every box | C11: 0.055 | P11: Unified (Caio, Oct-8-2026).
B12: Earnings elasticity to commodity prices | C12: 1.262 | P12: Box Earnings!J10 of the main model: 12-month change of the box 12m fwd EPS vs. the DJP commodity ETN, Oct-07 to Sep-26.
B13: Working capital, % of sales | C13: 0.04 | P13: House assumption (Assumptions!C15 of the main model).
B15: 2. House vs. analysts, variable by variable (choice: 1 = house, 2 = analysts)
B16: Variable | C16: House | D16: Analysts | E16: Choice | F16: Used | P16: House / analysts
B17: Beta | C17: 0.872 | D17: 1 | E17: 1 | F17: =IF(E17=1,C17,D17) -> 0.872 | P17: House: the box beta, weekly 5 years vs. the Ibovespa from the local box index (Box Betas). Analysts: 1.0 (Vale, Suzano).
B18: Perpetuity growth (g) | C18: 0.047 | D18: =(1+C8)*(1+C9)-1 -> 0.04 | E18: 2 | F18: =IF(E18=1,C18,D18) -> 0.04 | P18: House: 4.7% (Target!B54). Analysts (commodities): inflation x (1 + real growth), real growth 0%.
B19: Explicit years after the value date | C19: 4 | D19: 8 | E19: 1 | F19: =IF(E19=1,C19,D19) -> 4 | P19: House: 2028-31. Analysts: to 2035 (Vale, Suzano). Growth reaches g by the last explicit year.
B20: Extra periods in the discount of the terminal value | C20: 1 | D20: 0 | E20: 2 | F20: =IF(E20=1,C20,D20) -> 0 | P20: House: the TV is discounted one period more than the last flow. Analysts: the last year's factor.
B22: 3. Cost of equity by scenario
B23: Item | C23: Bear | D23: Base | E23: Bull | P23: How it is calculated
B24: 5-year real rate (NTN-B) | C24: 0.085 | D24: 0.0676 | E24: 0.055 | P24: Same scenarios as the other boxes.
B25: Risk free, nominal = (NTN-B + long-term IPCA) x share kept after tax | C25: =(C24+$C$8)*$C$10 -> 0.10625 | D25: =(D24+$C$8)*$C$10 -> 0.09146 | E25: =(E24+$C$8)*$C$10 -> 0.08075 | P25: Nominal, because the flows are nominal.
B26: Ke = risk free + beta x ERP | C26: =C25+$F$17*$C$11 -> 0.15421 | D26: =D25+$F$17*$C$11 -> 0.13942 | E26: =E25+$F$17*$C$11 -> 0.12871
B27: Ke - g | C27: =(C26-g_)*100 -> 11.421 | D27: =(D26-g_)*100 -> 9.942 | E27: =(E26-g_)*100 -> 8.871
B29: 4. Box projection (index points): consensus 2026-28, box-level projection after 2028
B30: Line | C30: 2026 | D30: 2027 | E30: 2028 | F30: 2029 | G30: 2030 | H30: 2031 | I30: 2032 | J30: 2033 | K30: 2034 | L30: 2035 | M30: 2036 | N30: 2037 | P30: How it is calculated / source
B31: Years after end-2027 (grey = after the explicit years, not used) | E31: =2028-2027 -> 1 | F31: =2029-2027 -> 2 | G31: =2030-2027 -> 3 | H31: =2031-2027 -> 4 | I31: =2032-2027 -> 5 | J31: =2033-2027 -> 6 | K31: =2034-2027 -> 7 | L31: =2035-2027 -> 8 | M31: =2036-2027 -> 9 | N31: =2037-2027 -> 10
B32: Growth: 2027-28 net income consensus; then linear from the 2028 growth to g in the last explicit year | D32: =D34/C34-1 -> -0.097309389 | E32: =E34/D34-1 -> -0.017939157 | F32: =IF(F31>=NExp,g_,$E$32+(g_-$E$32)*(F31-1)/(NExp-1)) -> 0.0013738955 | G32: =IF(G31>=NExp,g_,$E$32+(g_-$E$32)*(G31-1)/(NExp-1)) -> 0.020686948 | H32: =IF(H31>=NExp,g_,$E$32+(g_-$E$32)*(H31-1)/(NExp-1)) -> 0.04 | I32: =IF(I31>=NExp,g_,$E$32+(g_-$E$32)*(I31-1)/(NExp-1)) -> 0.04 | J32: =IF(J31>=NExp,g_,$E$32+(g_-$E$32)*(J31-1)/(NExp-1)) -> 0.04 | K32: =IF(K31>=NExp,g_,$E$32+(g_-$E$32)*(K31-1)/(NExp-1)) -> 0.04 | L32: =IF(L31>=NExp,g_,$E$32+(g_-$E$32)*(L31-1)/(NExp-1)) -> 0.04 | M32: =IF(M31>=NExp,g_,$E$32+(g_-$E$32)*(M31-1)/(NExp-1)) -> 0.04 | N32: =IF(N31>=NExp,g_,$E$32+(g_-$E$32)*(N31-1)/(NExp-1)) -> 0.04 | P32: Every line grows at this rate after 2028: prices at their long-term level, volumes flat in real terms.
B33: Sales | C33: ='Box Consensus'!F43 -> 78679.535 | D33: ='Box Consensus'!G43 -> 77625.17 | E33: ='Box Consensus'!H43 -> 78048.395 | F33: =E33*(1+F32) -> 78155.625 | G33: =F33*(1+G32) -> 79772.427 | H33: =G33*(1+H32) -> 82963.324 | I33: =H33*(1+I32) -> 86281.857 | J33: =I33*(1+J32) -> 89733.131 | K33: =J33*(1+K32) -> 93322.456 | L33: =K33*(1+L32) -> 97055.354 | M33: =L33*(1+M32) -> 100937.57 | N33: =M33*(1+N32) -> 104975.07 | P33: Box Consensus; used only for the working capital.
B34: Net income | C34: ='Box Consensus'!O43 -> 10671.973 | D34: ='Box Consensus'!P43 -> 9633.4894 | E34: ='Box Consensus'!Q43 -> 9460.6727 | F34: =E34*(1+F32) -> 9473.6707 | G34: =F34*(1+G32) -> 9669.652 | H34: =G34*(1+H32) -> 10056.438 | I34: =H34*(1+I32) -> 10458.696 | J34: =I34*(1+J32) -> 10877.043 | K34: =J34*(1+K32) -> 11312.125 | L34: =K34*(1+L32) -> 11764.61 | M34: =L34*(1+M32) -> 12235.195 | N34: =M34*(1+N32) -> 12724.602 | P34: Box Consensus (sum of the members).
B35: (+) D&A = EBITDA - EBIT | C35: ='Box Consensus'!I43-'Box Consensus'!L43 -> 7703.2768 | D35: ='Box Consensus'!J43-'Box Consensus'!M43 -> 7928.4256 | E35: ='Box Consensus'!K43-'Box Consensus'!N43 -> 8046.0095 | F35: =E35*(1+F32) -> 8057.0639 | G35: =F35*(1+G32) -> 8223.74 | H35: =G35*(1+H32) -> 8552.6896 | I35: =H35*(1+I32) -> 8894.7971 | J35: =I35*(1+J32) -> 9250.589 | K35: =J35*(1+K32) -> 9620.6126 | L35: =K35*(1+L32) -> 10005.437 | M35: =L35*(1+M32) -> 10405.655 | N35: =M35*(1+N32) -> 10821.881 | P35: Includes the depreciation of leased assets (IFRS 16), hence the lease line below.
B36: (-) Capex | C36: ='Box Consensus'!R43 -> -8024.7999 | D36: ='Box Consensus'!S43 -> -7975.8577 | E36: ='Box Consensus'!T43 -> -8197.8556 | F36: =E36*(1+F32) -> -8209.1186 | G36: =F36*(1+G32) -> -8378.9402 | H36: =G36*(1+H32) -> -8714.0978 | I36: =H36*(1+I32) -> -9062.6617 | J36: =I36*(1+J32) -> -9425.1682 | K36: =J36*(1+K32) -> -9802.1749 | L36: =K36*(1+L32) -> -10194.262 | M36: =L36*(1+M32) -> -10602.032 | N36: =M36*(1+N32) -> -11026.114 | P36: Consensus 2026-28 (about 1.1x D&A in 2028: maintenance level); then with inflation.
B37: (-) Lease principal | C37: ='Box Consensus'!U43 -> -1476.018 | D37: ='Box Consensus'!V43 -> -1489.2379 | E37: ='Box Consensus'!W43 -> -1558.2829 | F37: =E37*(1+F32) -> -1560.4238 | G37: =F37*(1+G32) -> -1592.7042 | H37: =G37*(1+H32) -> -1656.4124 | I37: =H37*(1+I32) -> -1722.6689 | J37: =I37*(1+J32) -> -1791.5756 | K37: =J37*(1+K32) -> -1863.2386 | L37: =K37*(1+L32) -> -1937.7682 | M37: =L37*(1+M32) -> -2015.2789 | N37: =M37*(1+N32) -> -2095.8901 | P37: Petrobras and Suzano (analysts' models); others pending. The lease interest is already in net income.
B38: (+/-) Change in working capital = -NWC % x change in sales | D38: =-$C$13*(D33-C33) -> 42.174588 | E38: =-$C$13*(E33-D33) -> -16.928987 | F38: =-$C$13*(F33-E33) -> -4.2892135 | G38: =-$C$13*(G33-F33) -> -64.672053 | H38: =-$C$13*(H33-G33) -> -127.63588 | I38: =-$C$13*(I33-H33) -> -132.74132 | J38: =-$C$13*(J33-I33) -> -138.05097 | K38: =-$C$13*(K33-J33) -> -143.57301 | ... N38: =-$C$13*(N33-M33) -> -161.50011
B39: Cash to shareholders (FCFE, net debt constant) | D39: =D34+D35+D36+D37+D38 -> 8138.9941 | E39: =E34+E35+E36+E37+E38 -> 7733.6148 | F39: =F34+F35+F36+F37+F38 -> 7756.903 | G39: =G34+G35+G36+G37+G38 -> 7857.0756 | H39: =H34+H35+H36+H37+H38 -> 8110.9816 | I39: =I34+I35+I36+I37+I38 -> 8435.4209 | J39: =J34+J35+J36+J37+J38 -> 8772.8377 | K39: =K34+K35+K36+K37+K38 -> 9123.7513 | ... N39: =N34+N35+N36+N37+N38 -> 10262.979 | P39: As the analysts' bridges (NOPAT + D&A - capex - NWC - leases), at the equity level with constant net debt.
B40: FCFE / net income | D40: =D39/D34 -> 0.84486459 | E40: =E39/E34 -> 0.81744872 | F40: =F39/F34 -> 0.81878538 | G40: =G39/G34 -> 0.81254998 | H40: =H39/H34 -> 0.80654617 | I40: =I39/I34 -> 0.80654617 | J40: =J39/J34 -> 0.80654617 | K40: =K39/K34 -> 0.80654617 | ... N40: =N39/N34 -> 0.80654617
B41: Memo: capex / D&A | C41: =-C36/C35 -> 1.0417385 | D41: =-D36/D35 -> 1.0059825 | E41: =-E36/E35 -> 1.0188722 | F41: =-F36/F35 -> 1.0188722 | G41: =-G36/G35 -> 1.0188722 | H41: =-H36/H35 -> 1.0188722 | I41: =-I36/I35 -> 1.0188722 | J41: =-J36/J35 -> 1.0188722 | ... N41: =-N36/N35 -> 1.0188722
B43: 5. Valuation at the end of 2027
B44: Item | C44: Bear | D44: Base | E44: Bull | P44: How it is calculated
B45: Ke | C45: =C26 -> 0.15421 | D45: =D26 -> 0.13942 | E45: =E26 -> 0.12871
...

Sheet Box Consensus
B1: Commodities - consensus 2026-28 of the members, summed into the box
B2: Bloomberg BEST consensus (Oct-7-2026, company totals in R$ mn; Members sheet of the main model). Lease principal: the analysts' models. Index points = R$ mn x points / market cap. Only 2026-28 are built from the members.
B3: Legend: | C3: input | D3: assumption | E3: formula
B5: FX for Petrobras' lease (R$ / US$) | C5: 5.15 | D5: Analysts' 2027 average (Vale, Suzano Macro sheets).
B7: 1. Consensus by member (R$ mn)
B8: Member | C8: Index points | D8: Market cap (R$ mn) | E8: Points / market cap | F8: Sales 2026 | G8: Sales 2027 | H8: Sales 2028 | I8: EBITDA 2026 | J8: EBITDA 2027 | K8: EBITDA 2028 | L8: EBIT 2026 | M8: EBIT 2027 | N8: EBIT 2028 | O8: Net income 2026 | P8: Net income 2027 | Q8: Net income 2028 | R8: Capex 2026 | S8: Capex 2027 | T8: Capex 2028 | U8: Lease principal 2026 | V8: Lease principal 2027 | W8: Lease principal 2028
B9: Vale (VALE3) | C9: 18861.588 | D9: 292583.69 | E9: =C9/D9 -> 0.064465618 | F9: 210241.45 | G9: 211218.5 | H9: 216317.9 | I9: 80791.273 | J9: 82896.955 | K9: 85768.381 | L9: 53667.864 | M9: 58140.091 | N9: 61076.905 | O9: 37349.381 | P9: 38936.048 | Q9: 39670.895 | R9: -28356.611 | S9: -29763 | T9: -29912.556 | U9: 0 | V9: 0 | W9: 0
B10: Petrobras (PETR4 + PETR3) | C10: 28130.207 | D10: 742814.41 | E10: =C10/D10 -> 0.037869764 | F10: 603798.14 | G10: 576794.64 | H10: 560041.46 | I10: 324852.5 | J10: 306271.14 | K10: 292163 | L10: 226311.33 | M10: 197993.5 | N10: 181539.64 | O10: 159783.86 | P10: 134066.29 | Q10: 123997.15 | R10: -96257.714 | S10: -102580.71 | T10: -103080.71 | U10: =PETRFX*-7323 -> -37713.45 | V10: =PETRFX*-7403 -> -38125.45 | W10: =PETRFX*-7766 -> -39994.9
B11: PRIO (PRIO3) | C11: 3466.2927 | D11: 54626.928 | E11: =C11/D11 -> 0.063453919 | F11: 26514.1 | G11: 27631.8 | H11: 27316.444 | I11: 17826.167 | J11: 20450.6 | K11: 20080.667 | L11: 10905 | M11: 13060.1 | N11: 13365.222 | O11: 7814.3 | P11: 7794.364 | Q11: 7817.455 | R11: -5500 | S11: -3260 | T11: -5061 | U11: 0 | V11: 0 | W11: 0
B12: Vibra Energia (VBBR3) | C12: 3300.0683 | D12: 45006.061 | E12: =C12/D12 -> 0.073324975 | F12: 221191.64 | G12: 215452.57 | H12: 216420.46 | I12: 13223 | J12: 8845.3333 | K12: 9329.75 | L12: 11578.778 | M12: 7133.1111 | N12: 7570.7778 | O12: 6856.071 | P12: 4105.071 | Q12: 4567.308 | R12: -1588.6667 | S12: -1503 | T12: -1594 | U12: 0 | V12: 0 | W12: 0
B13: Ultrapar (UGPA3) | C13: 2985.2772 | D13: 43216.866 | E13: =C13/D13 -> 0.069076671 | F13: 163149.23 | G13: 160150.46 | H13: 161947.27 | I13: 11213.727 | J13: 8694.5455 | K13: 9270.4 | L13: 8992.8 | M13: 6362.1 | N13: 6883.3333 | O13: 5020.273 | P13: 3493.364 | Q13: 3939.2 | R13: -2424.5714 | S13: -2483.2857 | T13: -2376.7143 | U13: 0 | V13: 0 | W13: 0
B14: Gerdau (GGBR4) | C14: 2308.3046 | D14: 47327.83 | E14: =C14/D14 -> 0.04877267 | F14: 71120.538 | G14: 73508.308 | H14: 75563.4 | I14: 12889 | J14: 13312.308 | K14: 13170 | L14: 8593.75 | M14: 8796.4167 | N14: 8362.1818 | O14: 5373.077 | P14: 5819.538 | Q14: 5690.7 | R14: -4696.2 | S14: -4223.2857 | T14: -4169.1667 | U14: 0 | V14: 0 | W14: 0
B15: Suzano (SUZB3) | C15: 1834.4478 | D15: 53320.481 | E15: =C15/D15 -> 0.034404186 | F15: 54433.533 | G15: 62460.067 | H15: 63804.154 | I15: 22602.875 | J15: 25683.625 | K15: 26069.571 | L15: 11374.938 | M15: 13838.625 | N15: 14174.067 | O15: 9407.214 | P15: 6888.4 | Q15: 7008 | R15: -14489.727 | S15: -10735.909 | T15: -10806.4 | U15: -1389.9044 | V15: -1320.6551 | W15: -1269.7707
B16: Klabin (KLBN11) | C16: 1042.0522 | D16: 23199.922 | E16: =C16/D16 -> 0.044916193 | F16: 21123.929 | G16: 22132.786 | H16: 22840.75 | I16: 7594.3571 | J16: 8069.0714 | K16: 8357 | L16: 3463.6364 | M16: 4265.6364 | N16: 4616.4545 | O16: 1009.727 | P16: 1680.583 | Q16: 1980.545 | R16: -3249.5 | S16: -2873 | T16: -2698.4286 | U16: 0 | V16: 0 | W16: 0
B17: Cosan (CSAN3) | C17: 838.67827 | D17: 20031.183 | E17: =C17/D17 -> 0.041868634 | F17: 39894.2 | G17: 46724 | H17: 52061.25 | I17: 17435.857 | J17: 17310.556 | K17: 20075.667 | L17: 12235.4 | M17: 13142.6 | N17: 14606 | O17: -856.55 | P17: 2196.857 | Q17: 3607.167 | R17: -11294.667 | S17: -10044 | T17: -11243.333 | U17: 0 | V17: 0 | W17: 0
B18: Met. Gerdau (GOAU4) | C18: 699.89539 | D18: 14527.916 | E18: =C18/D18 -> 0.048175898 | F18: 25572.848 | G18: 21296.365 | H18: 21891.754 | I18: 4634.5042 | J18: 3856.7582 | K18: 3815.5297 | L18: 3090.059 | M18: 2548.4426 | N18: 2422.6388 | O18: 1932 | P18: 1686 | Q18: 1648.6739 | R18: -1688.615 | S18: -1223.5438 | T18: -1207.8648 | U18: 0 | V18: 0 | W18: 0
B19: CSN Mineração (CMIN3) | C19: 569.56628 | D19: 26997.261 | E19: =C19/D19 -> 0.021097187 | F19: 14636.2 | G19: 14279.4 | H19: 16155.25 | I19: 4729.8182 | J19: 4618.2727 | K19: 5805.1111 | L19: 3309 | M19: 3156.2 | N19: 4810.7778 | O19: 1535.091 | P19: 1364.7 | Q19: 1844 | R19: -2891.2857 | S19: -3586.1429 | T19: -4009.5 | U19: 0 | V19: 0 | W19: 0
B20: Brava Energia (BRAV3) | C20: 381.39676 | D20: 9240.0441 | E20: =C20/D20 -> 0.041276509 | F20: 13491.1 | G20: 13712.182 | H20: 13075.333 | I20: 6799.4 | J20: 7196.7273 | K20: 6561.8889 | L20: 4110.3 | M20: 4262.2727 | N20: 3471.8 | O20: 911 | P20: 1804.545 | Q20: 1734.778 | R20: -3101.1667 | S20: -2098 | T20: -2040.6667 | U20: 0 | V20: 0 | W20: 0
B21: Bradespar (BRAP4) | C21: 380.24257 | D21: 7940.7481 | E21: =C21/D21 -> 0.047884981 | F21: 9344.2195 | G21: 9024.079 | H21: 8359.1597 | I21: 3590.7827 | J21: 3541.6816 | K21: 3314.3424 | L21: 2385.2779 | M21: 2483.9717 | N21: 2360.1911 | O21: 1660 | P21: 1663.5 | Q21: 1533 | R21: -1260.3147 | S21: -1271.5916 | T21: -1155.9091 | U21: 0 | V21: 0 | W21: 0
B22: CSN (CSNA3) | C22: 335.83783 | D22: 8420.6966 | E22: =C22/D22 -> 0.039882428 | F22: 45041.333 | G22: 43164.8 | H22: 45946.5 | I22: 10237.6 | J22: 11015.2 | K22: 12622.625 | L22: 5127.1111 | M22: 5876.8889 | N22: 7499.25 | O22: -504.444 | P22: 310.1 | Q22: 803.463 | R22: -5019 | S22: -5630 | T22: -6095.75 | U22: 0 | V22: 0 | W22: 0
B23: Usiminas (USIM5) | C23: 277.31932 | D23: 8789.3845 | E23: =C23/D23 -> 0.03155162 | F23: 24954.182 | G23: 26001 | H23: 26984.778 | I23: 2644 | J23: 3020.4 | K23: 3319.5556 | L23: 1569.75 | M23: 1984 | N23: 2097 | O23: 1592.909 | P23: 1416.182 | Q23: 1598.667 | R23: -1308.1667 | S23: -1658 | T23: -2254.6667 | U23: 0 | V23: 0 | W23: 0
B26: 2. In index points (= R$ mn x points / market cap) and the box total
B27: Member | C27: Index points | D27: Market cap (R$ mn) | E27: Points / market cap | F27: Sales 2026 | G27: Sales 2027 | H27: Sales 2028 | I27: EBITDA 2026 | J27: EBITDA 2027 | K27: EBITDA 2028 | L27: EBIT 2026 | M27: EBIT 2027 | N27: EBIT 2028 | O27: Net income 2026 | P27: Net income 2027 | Q27: Net income 2028 | R27: Capex 2026 | S27: Capex 2027 | T27: Capex 2028 | U27: Lease principal 2026 | V27: Lease principal 2027 | W27: Lease principal 2028
B28: Vale (VALE3) | C28: =C9 -> 18861.588 | F28: =F9*$E$9 -> 13553.345 | G28: =G9*$E$9 -> 13616.331 | H28: =H9*$E$9 -> 13945.067 | I28: =I9*$E$9 -> 5208.2593 | J28: =J9*$E$9 -> 5344.0034 | K28: =K9*$E$9 -> 5529.1116 | L28: =L9*$E$9 -> 3459.732 | M28: =M9*$E$9 -> 3748.0369 | ... W28: =W9*$E$9 -> 0
B29: Petrobras (PETR4 + PETR3) | C29: =C10 -> 28130.207 | F29: =F10*$E$10 -> 22865.693 | G29: =G10*$E$10 -> 21843.077 | H29: =H10*$E$10 -> 21208.638 | I29: =I10*$E$10 -> 12302.088 | J29: =J10*$E$10 -> 11598.416 | K29: =K10*$E$10 -> 11064.144 | L29: =L10*$E$10 -> 8570.3569 | M29: =M10*$E$10 -> 7497.9672 | ... W29: =W10*$E$10 -> -1514.5974
B30: PRIO (PRIO3) | C30: =C11 -> 3466.2927 | F30: =F11*$E$11 -> 1682.4236 | G30: =G11*$E$11 -> 1753.346 | H30: =H11*$E$11 -> 1733.3355 | I30: =I11*$E$11 -> 1131.1401 | J30: =J11*$E$11 -> 1297.6707 | K30: =K11*$E$11 -> 1274.197 | L30: =L11*$E$11 -> 691.96499 | M30: =M11*$E$11 -> 828.71453 | ... W30: =W11*$E$11 -> 0
B31: Vibra Energia (VBBR3) | C31: =C12 -> 3300.0683 | F31: =F12*$E$12 -> 16218.872 | G31: =G12*$E$12 -> 15798.054 | H31: =H12*$E$12 -> 15869.025 | I31: =I12*$E$12 -> 969.57614 | J31: =J12*$E$12 -> 648.58384 | K31: =K12*$E$12 -> 684.10368 | L31: =L12*$E$12 -> 849.01359 | M31: =M12*$E$12 -> 523.03519 | ... W31: =W12*$E$12 -> 0
B32: Ultrapar (UGPA3) | C32: =C13 -> 2985.2772 | F32: =F13*$E$13 -> 11269.806 | G32: =G13*$E$13 -> 11062.661 | H32: =H13*$E$13 -> 11186.778 | I32: =I13*$E$13 -> 774.60695 | J32: =J13*$E$13 -> 600.59025 | K32: =K13*$E$13 -> 640.36837 | L32: =L13*$E$13 -> 621.19268 | M32: =M13*$E$13 -> 439.47269 | ... W32: =W13*$E$13 -> 0
B33: Gerdau (GGBR4) | C33: =C14 -> 2308.3046 | F33: =F14*$E$14 -> 3468.7385 | G33: =G14*$E$14 -> 3585.1964 | H33: =H14*$E$14 -> 3685.4287 | I33: =I14*$E$14 -> 628.63094 | J33: =J14*$E$14 -> 649.27679 | K33: =K14*$E$14 -> 642.33606 | L33: =L14*$E$14 -> 419.14013 | M33: =M14*$E$14 -> 429.02472 | ... W33: =W14*$E$14 -> 0
B34: Suzano (SUZB3) | C34: =C15 -> 1834.4478 | F34: =F15*$E$15 -> 1872.7414 | G34: =G15*$E$15 -> 2148.8878 | H34: =H15*$E$15 -> 2195.13 | I34: =I15*$E$15 -> 777.63352 | J34: =J15*$E$15 -> 883.62422 | K34: =K15*$E$15 -> 896.90239 | L34: =L15*$E$15 -> 391.34547 | M34: =M15*$E$15 -> 476.10663 | ... W34: =W15*$E$15 -> -43.685429
B35: Klabin (KLBN11) | C35: =C16 -> 1042.0522 | F35: =F16*$E$16 -> 948.80645 | G35: =G16*$E$16 -> 994.12047 | H35: =H16*$E$16 -> 1025.9195 | I35: =I16*$E$16 -> 341.10961 | J35: =J16*$E$16 -> 362.43197 | K35: =K16*$E$16 -> 375.36462 | L35: =L16*$E$16 -> 155.57336 | M35: =M16*$E$16 -> 191.59615 | ... W35: =W16*$E$16 -> 0
B36: Cosan (CSAN3) | C36: =C17 -> 838.67827 | F36: =F17*$E$17 -> 1670.3156 | G36: =G17*$E$17 -> 1956.27 | H36: =H17*$E$17 -> 2179.7334 | I36: =I17*$E$17 -> 730.01552 | J36: =J17*$E$17 -> 724.76931 | K36: =K17*$E$17 -> 840.54074 | L36: =L17*$E$17 -> 512.27948 | M36: =M17*$E$17 -> 550.26271 | ... W36: =W17*$E$17 -> 0
B37: Met. Gerdau (GOAU4) | C37: =C18 -> 699.89539 | F37: =F18*$E$18 -> 1231.9949 | G37: =G18*$E$18 -> 1025.9715 | H37: =H18*$E$18 -> 1054.6549 | I37: =I18*$E$18 -> 223.2714 | J37: =J18*$E$18 -> 185.80279 | K37: =K18*$E$18 -> 183.81657 | L37: =L18*$E$18 -> 148.86637 | M37: =M18*$E$18 -> 122.77351 | ... W37: =W18*$E$18 -> 0
B38: CSN Mineração (CMIN3) | C38: =C19 -> 569.56628 | F38: =F19*$E$19 -> 308.78265 | G38: =G19*$E$19 -> 301.25518 | H38: =H19*$E$19 -> 340.83034 | I38: =I19*$E$19 -> 99.785861 | J38: =J19*$E$19 -> 97.432565 | K38: =K19*$E$19 -> 122.47152 | L38: =L19*$E$19 -> 69.810593 | M38: =M19*$E$19 -> 66.586943 | ... W38: =W19*$E$19 -> 0
B39: Brava Energia (BRAV3) | C39: =C20 -> 381.39676 | F39: =F20*$E$20 -> 556.86551 | G39: =G20*$E$20 -> 565.991 | H39: =H20*$E$20 -> 539.70411 | I39: =I20*$E$20 -> 280.6555 | J39: =J20*$E$20 -> 297.05578 | K39: =K20*$E$20 -> 270.85187 | L39: =L20*$E$20 -> 169.65884 | M39: =M20*$E$20 -> 175.93174 | ... W39: =W20*$E$20 -> 0
B40: Bradespar (BRAP4) | C40: =C21 -> 380.24257 | F40: =F21*$E$21 -> 447.44777 | G40: =G21*$E$21 -> 432.11785 | H40: =H21*$E$21 -> 400.2782 | I40: =I21*$E$21 -> 171.94456 | J40: =J21*$E$21 -> 169.59335 | K40: =K21*$E$21 -> 158.70722 | L40: =L21*$E$21 -> 114.21899 | M40: =M21*$E$21 -> 118.94494 | ... W40: =W21*$E$21 -> 0
B41: CSN (CSNA3) | C41: =C22 -> 335.83783 | F41: =F22*$E$22 -> 1796.3577 | G41: =G22*$E$22 -> 1721.517 | H41: =H22*$E$22 -> 1832.458 | I41: =I22*$E$22 -> 408.30035 | J41: =J22*$E$22 -> 439.31292 | K41: =K22*$E$22 -> 503.42093 | L41: =L22*$E$22 -> 204.48164 | M41: =M22*$E$22 -> 234.3846 | ... W41: =W22*$E$22 -> 0
B42: Usiminas (USIM5) | C42: =C23 -> 277.31932 | F42: =F23*$E$23 -> 787.34486 | G42: =G23*$E$23 -> 820.37367 | H42: =H23*$E$23 -> 851.41346 | I42: =I23*$E$23 -> 83.422484 | J42: =J23*$E$23 -> 95.298513 | K42: =K23*$E$23 -> 104.73736 | L42: =L23*$E$23 -> 49.528156 | M42: =M23*$E$23 -> 62.598414 | ... W42: =W23*$E$23 -> 0
B43: Commodities box | C43: =SUM(C28:C42) -> 65411.174 | F43: =SUM(F28:F42) -> 78679.535 | G43: =SUM(G28:G42) -> 77625.17 | H43: =SUM(H28:H42) -> 78048.395 | I43: =SUM(I28:I42) -> 24130.44 | J43: =SUM(J28:J42) -> 23393.862 | K43: =SUM(K28:K42) -> 23291.074 | L43: =SUM(L28:L42) -> 16427.163 | M43: =SUM(M28:M42) -> 15465.437 | ... W43: =SUM(W28:W42) -> -1558.2829
B44: Check: net income vs. Box Shares!M10:O10 | O44: =O43-10671.9725499485 -> 0 | P44: =P43-9633.48941904183 -> 0 | Q44: =Q43-9381.24639794184 -> 79.426344
...

Sheet Analyst Models
B1: Commodities - how the XP commodity analysts treat the long term (memo)
B2: Files in inputs/analyst_models/Commodities (DCF & Sensitivity, Valuation, Control Panel sheets), read on Oct-8-2026.
B3: Legend: | C3: input | D3: assumption | E3: formula
B5: Model | C5: Currency | D5: Method | E5: Value date | F5: Explicit to | G5: Perpetuity g | H5: Risk free | I5: Beta x ERP | J5: Ke / WACC | K5: Long-term price
B6: Vale (VALE3) | C6: USD | D6: FCFF - net debt, SOTP | E6: End-2027 | F6: 2035 | G6: 2.4% (US CPI, real 0%) | H6: (real 70% BR 7.8% + 30% US 2.55%, + US CPI) x 0.85 = 7.5% | I6: 1.0 x 5.5% | J6: 13.0% / 11.3% | K6: Iron ore US$100 (26YE) > 97.5 > 93.75 > 90/t from 2029; copper 14k > 15k (2030)
B7: Petrobras (PETR4) | C7: USD | D7: FCFF - net debt, by business | E7: (older vintage) | F7: 2031 (EBITDA to 2060) | G7: 2.4% on an adjusted 2031 FCFF | H7: Treasury 4.0% + CDS 2.1% | I7: 1.53 (levered) x 5.0% | J7: 13.7% / 12.1% | K7: Brent US$63/bbl; EBITDA falls with reserves: -6% a year real 2028-35
B8: Suzano (SUZB3) | C8: BRL | D8: FCFE (FCFF check) | E8: End-2027 | F8: 2035 | G8: 4.0% (IPCA, real 0%) | H8: (real 90% BR 7.5% + 10% US, + IPCA) x 0.85 = 9.6% | I8: 1.0 x 5.5% | J8: 15.1% / 11.2% | K8: BHKP real US$590 > 570 > 560/t from 2028
B9: Aura (AURA33) | C9: USD | D9: FCFF, SOTP by mine | E9: End-2026 | F9: Mine lives (to ~2047) | G9: None (finite reserves) | H9: Same rule, USD = 8.5% | I9: 0.5 x 5.5% | J9: 11.2% / 10.5% | K9: Gold US$4,500 (26-27) > 3,500 by 2035; copper 14k
B11: Real growth after 2028 in the analysts' models (a year, 2028-35)
B12: Model | C12: Line | D12: Nominal | E12: Real | F12: Note
B13: Vale | C13: NOPLAT, USD | D13: 0.063 | E13: 0.038 | F13: Copper and nickel growth; 28.8% of the box
B14: Petrobras | C14: EBITDA, USD | D14: -0.038 | E14: -0.061 | F14: Reserve depletion; 43.0% of the box
B15: Suzano | C15: NOPLAT, BRL | D15: 0.047 | E15: 0.007 | F15: Real pulp price flat from 2028; 2.8% of the box
B17: Weighted by the box points, the three give about -2% a year real: zero real growth for the box is neutral to slightly generous.
