Workbook
Name ERP: 'DCF Cyclicals'!$C$12
Name gLT: 'DCF Cyclicals'!$C$11

Sheet DCF Cyclicals
B1: Cyclicals - simplified DCF (FCFE)
B2: Value = earnings x (1 - g / ROE) / (Ke - g): the cash left to shareholders after the reinvestment that funds growth g, discounted at the box's cost of equity. No net debt (equity flows).
B3: Legend: | C3: input | D3: assumption | E3: formula
B5: 1. Assumptions
B6: Item | C6: Value | F6: Source / note
B7: Pricing date | C7: 46300 | F7: Close of Oct-5-2026, as in the multiples model.
B8: Target date | C8: 46752 | F8: End-2027, as the house target model rolled to 2027.
B9: Years from pricing to target | C9: =(C8-C7)/365 -> 1.2383562
B10: Cyclicals, index points today | C10: 26271.075 | F10: Members' weight x Ibovespa close 208,432 (Box Shares sheet of Ibov_house_2027_by_box_XP.xlsx).
B11: Long-term nominal growth (g) | C11: 0.047 | F11: House perpetuity growth (DCF Ibov 2026_Out.xlsx, Target!B54).
B12: Equity risk premium (ERP) | C12: 0.06 | F12: House ERP (Target!B57).
B13: Share of the gap to the 10-year median spread closed by the target | C13: 0.5 | F13: 0% = Cyclicals keep today's spread to the Ibovespa; 100% = back to the 10-year median.
B14: Earnings level shock, Ibovespa ex-Commodities (bull +, bear -) | C14: 0.2 | F14: Symmetric, as agreed (house bottom-up uses +/-20%).
B15: Earnings beta of Cyclicals to the Ibovespa ex-Commodities | C15: 1.4907 | F15: 12-month log change of the 12m fwd EPS index, Oct-07 to Sep-26 (Box Earnings sheet).
B16: Normalization factor of the domestic earnings betas | C16: 1.1869 | F16: Makes the weighted average beta of Financials, Defensives and Cyclicals = 1 (Box Earnings!I16).
B17: Change in target price per 100 bp of Ke (analysts' models) | C17: 0.174 | F17: XP analysts' models, Ke -100 bp, Cyclicals box (Ke_sensitivity_by_box_2026-10-06.xlsx).
B19: 2. Cost of equity the market implies today (12m fwd consensus, last month of History)
B20: Item | C20: Cyclicals | D20: Ibovespa | F20: Note
B21: P/E, 12m fwd | C21: =History!C126 -> 11.449812 | D21: =History!E126 -> 8.6012907 | F21: History, Sep-26.
B22: ROE, 12m fwd | C22: =History!D126 -> 0.15552646 | D22: =History!F126 -> 0.17214752
B23: Implied Ke = g + (1 - g / ROE) / (P/E) | C23: =gLT+(1-gLT/C22)/C21 -> 0.10794428 | D23: =gLT+(1-gLT/D22)/D21 -> 0.13151968 | F23: The discount rate at which the value-driver formula gives today's price.
B24: Spread to the Ibovespa today (pp) | C24: =(C23-D23)*100 -> -2.3575398
B25: Spread to the Ibovespa, 10-year median (pp) | C25: =MEDIAN(History!I7:I126) -> -3.9232759 | F25: Median, not average: the Cyclicals series is noisy when ROE is close to g.
B26: Spread used = today + share closed x (median - today) (pp) | C26: =C24+C13*(C25-C24) -> -3.1404079
B28: 3. Scenarios
B29: Item | C29: Bear | D29: Base | E29: Bull | F29: Note
B30: 5-year real rate (NTN-B) | C30: 0.085 | D30: 0.0676 | E30: 0.055 | F30: Bear 8.5% as the house; base = today's 5y real rate; bull 5.5%.
B31: Fair Ke of Cyclicals = real rate + ERP + spread used | C31: =C30+ERP+$C$26/100 -> 0.11359592 | D31: =D30+ERP+$C$26/100 -> 0.096195921 | E31: =E30+ERP+$C$26/100 -> 0.083595921
B32: Change in the real rate vs the base (pp) | C32: =(C30-$D$30)*100 -> 1.74 | D32: =(D30-$D$30)*100 -> 0 | E32: =(E30-$D$30)*100 -> -1.26
B33: Base valuation factor = (implied Ke - g) / (fair Ke base - g) | C33: =($C$23-gLT)/($D$31-gLT) -> 1.2388077 | D33: =($C$23-gLT)/($D$31-gLT) -> 1.2388077 | E33: =($C$23-gLT)/($D$31-gLT) -> 1.2388077 | F33: Same in every scenario: how far today's price is from the base fair value.
B34: Effective Ke - g from the analysts' sensitivity = 1% / sensitivity (pp) | C34: =1/$C$17 -> 5.7471264 | D34: =1/$C$17 -> 5.7471264 | E34: =1/$C$17 -> 5.7471264 | F34: Gordon form that reproduces the analysts' change per 100 bp of Ke.
B35: Rate factor = (Ke - g) / (Ke - g + change in the real rate) | C35: =C34/(C34+C32) -> 0.76760109 | D35: =D34/(D34+D32) -> 1 | E35: =E34/(E34+E32) -> 1.2808033
B36: Earnings shock, Ibovespa ex-Commodities | C36: =-$C$14 -> -0.2 | D36: =0 -> 0 | E36: =$C$14 -> 0.2
B37: Earnings shock of Cyclicals = beta x normalization x shock | C37: =$C$15*$C$16*C36 -> -0.35386237 | D37: =$C$15*$C$16*D36 -> 0 | E37: =$C$15*$C$16*E36 -> 0.35386237 | F37: Moves the level of earnings and of the value one to one.
B38: Fair value today (index pts) | C38: =$C$10*C33*C35*(1+C37) -> 16141.442 | D38: =$C$10*D33*D35*(1+D37) -> 32544.808 | E38: =$C$10*E33*E35*(1+E37) -> 56433.72 | F38: Points x base factor x rate factor x (1 + earnings shock).
B39: Fair value at the target date (index pts) = today x (1 + g) ^ years | C39: =C38*(1+gLT)^$C$9 -> 17086.119 | D39: =D38*(1+gLT)^$C$9 -> 34449.491 | E39: =E38*(1+gLT)^$C$9 -> 59736.5 | F39: In the Gordon model the value grows at g once the dividends are paid.
B40: Upside vs today | C40: =C39/$C$10-1 -> -0.34962237 | D40: =D39/$C$10-1 -> 0.3113088 | E40: =E39/$C$10-1 -> 1.2738507
B42: 4. Base upside: share of the gap closed (rows) x 5-year real rate (columns)
B43: Share closed \ real rate | C43: 0.085 | D43: 0.0676 | E43: 0.055
B44: 0 | C44: =($C$23-gLT)/($D$30+ERP+($C$24+$B44*($C$25-$C$24))/100-gLT)*(1/$C$17)/(1/$C$17+(C$43-$D$30)*100)*(1+gLT)^$C$9-1 -> -0.13162483 | D44: =($C$23-gLT)/($D$30+ERP+($C$24+$B44*($C$25-$C$24))/100-gLT)*(1/$C$17)/(1/$C$17+(D$43-$D$30)*100)*(1+gLT)^$C$9-1 -> 0.13128444 | E44: =($C$23-gLT)/($D$30+ERP+($C$24+$B44*($C$25-$C$24))/100-gLT)*(1/$C$17)/(1/$C$17+(E$43-$D$30)*100)*(1+gLT)^$C$9-1 -> 0.44895286
...

Sheet History
B1: Cyclicals - implied cost of equity, 10 years
B2: Monthly 12m fwd consensus of the Ibovespa members (Bloomberg BEST_PE_RATIO / BEST_ROE), aggregated by box: P/E = sum of weights / sum of earnings; ROE = sum of earnings / sum of book value.
B3: Legend: | C3: input | D3: assumption | E3: formula
B5: Implied Ke = g + (1 - g / ROE) / (P/E) (Gordon in value-driver form, g from DCF Cyclicals)
B6: Month-end | C6: Cyclicals P/E | D6: Cyclicals ROE | E6: Ibovespa P/E | F6: Ibovespa ROE | G6: Cyclicals implied Ke | H6: Ibovespa implied Ke | I6: Spread, Cyclicals - Ibovespa
B7: 42674 | C7: 16.387868 | D7: 0.12969841 | E7: 14.194437 | F7: 0.098549836 | G7: =gLT+(1-gLT/D7)/C7 -> 0.085908104 | H7: =gLT+(1-gLT/F7)/E7 -> 0.083851334 | I7: =(G7-H7)*100 -> 0.20567695
B8: 42704 | C8: 14.519825 | D8: 0.12334295 | E8: 13.286745 | F8: 0.096239989 | G8: =gLT+(1-gLT/D8)/C8 -> 0.089627832 | H8: =gLT+(1-gLT/F8)/E8 -> 0.085507364 | I8: =(G8-H8)*100 -> 0.41204674
B9: 42735 | C9: 14.432757 | D9: 0.12998149 | E9: 12.327159 | F9: 0.10890768 | G9: =gLT+(1-gLT/D9)/C9 -> 0.091233409 | H9: =gLT+(1-gLT/F9)/E9 -> 0.093112962 | I9: =(G9-H9)*100 -> -0.18795534
B10: 42766 | C10: 14.867785 | D10: 0.13186068 | E10: 12.622489 | F10: 0.12246586 | G10: =gLT+(1-gLT/D10)/C10 -> 0.090285748 | H10: =gLT+(1-gLT/F10)/E10 -> 0.095819182 | I10: =(G10-H10)*100 -> -0.55334335
B11: 42794 | C11: 15.53076 | D11: 0.13527687 | E11: 12.495554 | F11: 0.12268623 | G11: =gLT+(1-gLT/D11)/C11 -> 0.089017544 | H11: =gLT+(1-gLT/F11)/E11 -> 0.096370274 | I11: =(G11-H11)*100 -> -0.73527301
B12: 42825 | C12: 15.552675 | D12: 0.13949976 | E12: 11.679569 | F12: 0.12466013 | G12: =gLT+(1-gLT/D12)/C12 -> 0.089634586 | H12: =gLT+(1-gLT/F12)/E12 -> 0.10033886 | I12: =(G12-H12)*100 -> -1.0704275
B13: 42855 | C13: 15.985985 | D13: 0.12926377 | E13: 11.839827 | F13: 0.11956178 | G13: =gLT+(1-gLT/D13)/C13 -> 0.086810021 | H13: =gLT+(1-gLT/F13)/E13 -> 0.098259007 | I13: =(G13-H13)*100 -> -1.1448986
B14: 42886 | C14: 15.363662 | D14: 0.12867474 | E14: 11.139799 | F14: 0.12322419 | G14: =gLT+(1-gLT/D14)/C14 -> 0.088314235 | H14: =gLT+(1-gLT/F14)/E14 -> 0.10252895 | I14: =(G14-H14)*100 -> -1.4214719
B15: 42916 | C15: 15.349971 | D15: 0.13495076 | E15: 10.876661 | F15: 0.081225867 | G15: =gLT+(1-gLT/D15)/C15 -> 0.089457724 | H15: =gLT+(1-gLT/F15)/E15 -> 0.085740438 | I15: =(G15-H15)*100 -> 0.37172862
B16: 42947 | C16: 16.329288 | D16: 0.13807289 | E16: 11.487868 | F16: 0.12261242 | G16: =gLT+(1-gLT/D16)/C16 -> 0.087393682 | H16: =gLT+(1-gLT/F16)/E16 -> 0.10068083 | I16: =(G16-H16)*100 -> -1.3287151
B17: 42978 | C17: 16.972938 | D17: 0.13642481 | E17: 12.333127 | F17: 0.12070712 | G17: =gLT+(1-gLT/D17)/C17 -> 0.08561959 | H17: =gLT+(1-gLT/F17)/E17 -> 0.096511189 | I17: =(G17-H17)*100 -> -1.0891599
B18: 43008 | C18: 18.268507 | D18: 0.13379353 | E18: 12.79982 | F18: 0.12129485 | G18: =gLT+(1-gLT/D18)/C18 -> 0.082509879 | H18: =gLT+(1-gLT/F18)/E18 -> 0.094853365 | I18: =(G18-H18)*100 -> -1.2343486
... B126: 46295 | C126: 11.449812 | D126: 0.15552646 | E126: 8.6012907 | F126: 0.17214752 | G126: =gLT+(1-gLT/D126)/C126 -> 0.10794428 | H126: =gLT+(1-gLT/F126)/E126 -> 0.13151968 | I126: =(G126-H126)*100 -> -2.3575398
