Workbook
Name FleetRatio: 'Box Consensus'!$D$4
Name NExp: 'DCF Cyclicals'!$H$23
Name TVx: 'DCF Cyclicals'!$H$24

Sheet DCF Cyclicals
B1: Cyclicals - DCF by sub-box with the analysts' cash-flow method (end-2027)
B2: 2026-28: net income + D&A - capex (+ fleet sales) +/- NWC from the consensus; from 2029: growth paid at the sub-box ROE. Two sub-boxes, summed. Ke unified with the other boxes.
B3: Legend: | C3: input | D3: assumption | E3: formula
B5: 1. Inputs
B6: Item | C6: W&E | D6: Ex | P6: Source / note
B7: Index points today | C7: ='Box Consensus'!D61 -> 0 | D7: ='Box Consensus'!D62 -> 0 | P7: W&E = WEG & Embraer; Ex = Cyclicals ex-WEG & Embraer (Box Consensus).
B8: Long-term IPCA | C8: 0.04 | P8: House and the analysts' Macro sheets.
B9: Share of the risk free kept after tax | C9: 0.85 | P9: As the analysts: risk free = (NTN-B + IPCA) x 0.85.
B10: Equity risk premium, the same for every box | C10: 0.055 | P10: Unified (Caio, Oct-8-2026).
B11: Earnings shock per 1% of the Ibovespa ex-Commodities shock (beta x normalization) | C11: 0.15085806 | D11: 1.7925093 | P11: Box Earnings!I13:I14 x I16 of the main model (WEG & Embraer 0.13, ex 1.51, normalized by 1.19).
B12: Working capital, % of sales | C12: 0.04 | P12: House assumption.
B13: ROE for the growth from 2029 (blank = FY28 consensus of the sub-box) | P13: Typed value replaces the sub-box ROE.
B14: Growth paid from 2029: 1 = all the growth of the year; 2 = only the long-term growth g (the excess comes from margins) | C14: 1 | P14: 1: cash = net income x (1 - growth / ROE). 2: cash = net income x (1 - g / ROE): the consensus growth above g is a recovery of margins (the 2026-28 consensus already shows cash at ~75-80% of net income while net income grows ~20% a year).
B15: Growth after 2028 starts from: 1 = the 2028 book value growth (consensus-consistent); 2 = the 2028 net income growth | C15: 1 | P15: 1: with ROE held at FY28, net income grows as the book value; the consensus 2026-28 net income growth comes mostly from ROE rising (ex-WEG & Embraer: ROE 13% > 17%, book value +3% in 2028), which cannot be extrapolated at a constant ROE.
B16: Cash to shareholders 2027-28: 1 = net income - increase in book value (consensus); 2 = analysts' bridge (NI + D&A + capex + NWC) | C16: 1 | P16: 1 uses only consensus net income and ROE (book value = net income / ROE), as Financials. 2 uses consensus D&A, capex and sales (gross fleet capex for Localiza and Vamos).
B17: WEG & Embraer (global part): Brazil share of the real risk free | C17: 0.27917606 | P17: Analysts' weights by revenue geography: WEG 35% Brazil (DCF & Sensitivity C55), Embraer 20% (C66); weighted by index points.
B18: US real risk free | C18: 0.021 | P18: Analysts: WEG 2.08% (F56), Embraer 2.51% (F69).
B19: 2. House vs. analysts, variable by variable (choice: 1 = house, 2 = analysts)
B20: Variable | C20: House W&E | D20: House Ex | E20: Analysts W&E | F20: Analysts Ex | G20: Choice | H20: Used W&E | I20: Used Ex | P20: House / analysts
B21: Beta | C21: 0.7214 | D21: 1.324 | E21: 0.89 | F21: 1.02 | G21: 1 | H21: =IF($G21=1,C21,E21) -> 0 | I21: =IF($G21=1,D21,F21) -> 0 | P21: House: sub-box betas, weekly 5 years from the local indices (Box Betas). Analysts: WEG 0.8 / Embraer 1.0; ex: Localiza 0.95, Rumo 1.0, Motiva 0.92, Renner 0.95, Totvs 0.8, Cyrela 1.46.
B22: Long-term real growth (g = (1 + IPCA) x (1 + real) - 1) | C22: 0.0067 | D22: 0.0067 | E22: 0.018 | F22: 0.007 | G22: 2 | H22: =IF($G22=1,C22,E22) -> 0 | I22: =IF($G22=1,D22,F22) -> 0 | P22: Long-term real growth. House: g 4.7% = about 0.7% real over a 4% IPCA. Analysts, weighted: WEG 3.4% and Embraer 0% -> 1.8%; Localiza ~2%, the rest 0% -> 0.7%.
B23: Explicit years after the value date | C23: 4 | D23: 4 | E23: 8 | F23: 8 | G23: 2 | H23: =IF($G23=1,C23,E23) -> 0 | I23: =IF($G23=1,D23,F23) -> 0 | P23: Explicit years after end-2027. House: 2028-31. Analysts: to 2035.
B24: Extra periods in the discount of the terminal value | C24: 1 | D24: 1 | E24: 0 | F24: 0 | G24: 2 | H24: =IF($G24=1,C24,E24) -> 0 | I24: =IF($G24=1,D24,F24) -> 0 | P24: Extra periods in the discount of the terminal value. House: one more than the last flow. Analysts: none.
B25: g used = (1 + IPCA) x (1 + real growth) - 1 | H25: =(1+$C$8)*(1+H22)-1 -> 0 | I25: =(1+$C$8)*(1+I22)-1 -> 0
B27: 3. Cost of equity by scenario
B28: Item | C28: Bear | D28: Base | E28: Bull | P28: How it is calculated
B29: 5-year real rate (NTN-B) | C29: 0.085 | D29: 0.0676 | E29: 0.055 | P29: Same scenarios as the other boxes.
B30: Risk free, Brazil = (NTN-B + IPCA) x share kept after tax | C30: =(C29+$C$8)*$C$9 -> 0 | D30: =(D29+$C$8)*$C$9 -> 0 | E30: =(E29+$C$8)*$C$9 -> 0 | P30: The rest of the index (unified).
B31: Risk free, global (WEG & Embraer) = (Brazil share x NTN-B + US share x US real + IPCA) x share kept | C31: =($C$17*C29+(1-$C$17)*$C$18+$C$8)*$C$9 -> 0 | D31: =($C$17*D29+(1-$C$17)*$C$18+$C$8)*$C$9 -> 0 | E31: =($C$17*E29+(1-$C$17)*$C$18+$C$8)*$C$9 -> 0 | P31: As the WEG and Embraer analysts: real risk free weighted by revenue geography; nominal in R$ with the IPCA.
B32: Ke, WEG & Embraer = global risk free + beta x ERP | C32: =C31+$H$21*$C$10 -> 0 | D32: =D31+$H$21*$C$10 -> 0 | E32: =E31+$H$21*$C$10 -> 0
B33: Ke, Cyclicals ex-WEG & Embraer = Brazil risk free + beta x ERP | C33: =C30+$I$21*$C$10 -> 0 | D33: =D30+$I$21*$C$10 -> 0 | E33: =E30+$I$21*$C$10 -> 0
B35: 4a. WEG & Embraer: projection (index points)
B36: Line | C36: 2026 | D36: 2027 | E36: 2028 | F36: 2029 | G36: 2030 | H36: 2031 | I36: 2032 | J36: 2033 | K36: 2034 | L36: 2035 | M36: 2036 | N36: 2037 | P36: How it is calculated / source
B37: Years after end-2027 (grey = after the explicit years) | E37: =2028-2027 -> 0 | F37: =2029-2027 -> 0 | G37: =2030-2027 -> 0 | H37: =2031-2027 -> 0 | I37: =2032-2027 -> 0 | J37: =2033-2027 -> 0 | K37: =2034-2027 -> 0 | L37: =2035-2027 -> 0 | M37: =2036-2027 -> 0 | N37: =2037-2027 -> 0
B38: Net income growth: 2027-28 consensus; then from the 2028 book value growth (switch C15) linearly to g in the last explicit year | D38: =D39/C39-1 -> 0 | E38: =E39/D39-1 -> 0 | F38: =IF(F37>=NExp,$H$25,IF($C$15=1,$E$41/$D$41-1,$E$38)+($H$25-IF($C$15=1,$E$41/$D$41-1,$E$38))*(F37-1)/(NExp-1)) -> 0 | G38: =IF(G37>=NExp,$H$25,IF($C$15=1,$E$41/$D$41-1,$E$38)+($H$25-IF($C$15=1,$E$41/$D$41-1,$E$38))*(G37-1)/(NExp-1)) -> 0 | H38: =IF(H37>=NExp,$H$25,IF($C$15=1,$E$41/$D$41-1,$E$38)+($H$25-IF($C$15=1,$E$41/$D$41-1,$E$38))*(H37-1)/(NExp-1)) -> 0 | I38: =IF(I37>=NExp,$H$25,IF($C$15=1,$E$41/$D$41-1,$E$38)+($H$25-IF($C$15=1,$E$41/$D$41-1,$E$38))*(I37-1)/(NExp-1)) -> 0 | J38: =IF(J37>=NExp,$H$25,IF($C$15=1,$E$41/$D$41-1,$E$38)+($H$25-IF($C$15=1,$E$41/$D$41-1,$E$38))*(J37-1)/(NExp-1)) -> 0 | K38: =IF(K37>=NExp,$H$25,IF($C$15=1,$E$41/$D$41-1,$E$38)+($H$25-IF($C$15=1,$E$41/$D$41-1,$E$38))*(K37-1)/(NExp-1)) -> 0 | L38: =IF(L37>=NExp,$H$25,IF($C$15=1,$E$41/$D$41-1,$E$38)+($H$25-IF($C$15=1,$E$41/$D$41-1,$E$38))*(L37-1)/(NExp-1)) -> 0 | M38: =IF(M37>=NExp,$H$25,IF($C$15=1,$E$41/$D$41-1,$E$38)+($H$25-IF($C$15=1,$E$41/$D$41-1,$E$38))*(M37-1)/(NExp-1)) -> 0 | N38: =IF(N37>=NExp,$H$25,IF($C$15=1,$E$41/$D$41-1,$E$38)+($H$25-IF($C$15=1,$E$41/$D$41-1,$E$38))*(N37-1)/(NExp-1)) -> 0
B39: Net income | C39: ='Box Consensus'!O61 -> 0 | D39: ='Box Consensus'!P61 -> 0 | E39: ='Box Consensus'!Q61 -> 0 | F39: =E39*(1+F38) -> 0 | G39: =F39*(1+G38) -> 0 | H39: =G39*(1+H38) -> 0 | I39: =H39*(1+I38) -> 0 | J39: =I39*(1+J38) -> 0 | K39: =J39*(1+K38) -> 0 | L39: =K39*(1+L38) -> 0 | M39: =L39*(1+M38) -> 0 | N39: =M39*(1+N38) -> 0 | P39: Box Consensus (sum of the members).
B40: ROE (consensus; held at FY28): the return on the reinvestment that funds growth | C40: ='Box Consensus'!O61/'Box Consensus'!X61 -> 0 | D40: ='Box Consensus'!P61/'Box Consensus'!Y61 -> 0 | E40: ='Box Consensus'!Q61/'Box Consensus'!Z61 -> 0 | F40: =IF(ISNUMBER($C$13),$C$13,$E$40) -> 0 | G40: =IF(ISNUMBER($C$13),$C$13,$E$40) -> 0 | H40: =IF(ISNUMBER($C$13),$C$13,$E$40) -> 0 | I40: =IF(ISNUMBER($C$13),$C$13,$E$40) -> 0 | J40: =IF(ISNUMBER($C$13),$C$13,$E$40) -> 0 | K40: =IF(ISNUMBER($C$13),$C$13,$E$40) -> 0 | L40: =IF(ISNUMBER($C$13),$C$13,$E$40) -> 0 | M40: =IF(ISNUMBER($C$13),$C$13,$E$40) -> 0 | N40: =IF(ISNUMBER($C$13),$C$13,$E$40) -> 0 | P40: Sum of net income / sum of book value (net income / BEST_ROE) of the sub-box members.
B41: Book value: 2026-28 consensus (net income / ROE, summed); then net income / ROE | C41: ='Box Consensus'!X61 -> 0 | D41: ='Box Consensus'!Y61 -> 0 | E41: ='Box Consensus'!Z61 -> 0 | F41: =F39/F40 -> 0 | G41: =G39/G40 -> 0 | H41: =H39/H40 -> 0 | I41: =I39/I40 -> 0 | J41: =J39/J40 -> 0 | K41: =K39/K40 -> 0 | L41: =L39/L40 -> 0 | M41: =M39/M40 -> 0 | N41: =N39/N40 -> 0
B42: Sales (consensus) | C42: ='Box Consensus'!F61 -> 0 | D42: ='Box Consensus'!G61 -> 0 | E42: ='Box Consensus'!H61 -> 0
B43: (+) D&A = EBITDA - EBIT (consensus) | C43: ='Box Consensus'!I61-'Box Consensus'!L61 -> 0 | D43: ='Box Consensus'!J61-'Box Consensus'!M61 -> 0 | E43: ='Box Consensus'!K61-'Box Consensus'!N61 -> 0
...

Sheet Box Consensus
B1: Cyclicals - consensus 2026-28 of the members, summed into the two sub-boxes
B2: Bloomberg BEST consensus (Oct-7-2026, company totals in R$ mn; Members sheet of the main model; ROE from dcf_members.parquet). Index points = R$ mn x points / market cap. Only 2026-28 are built from the members.
B3: Legend: | C3: input | D3: assumption | E3: formula
B4: Fleet sales / gross capex (Localiza model, 2028) | D4: 0 | E4: 0 = consensus only (Caio, Oct-8-2026: no company-specific adjustments). Memo: in the Localiza model the book value of cars sold is 73% of gross capex (2028); typing it here nets Localiza and Vamos.
B7: 1. Consensus by member (R$ mn; ROE in %)
B8: Member | C8: Sub-box | D8: Index points | E8: Points / market cap | F8: Sales 2026 | G8: Sales 2027 | H8: Sales 2028 | I8: EBITDA 2026 | J8: EBITDA 2027 | K8: EBITDA 2028 | L8: EBIT 2026 | M8: EBIT 2027 | N8: EBIT 2028 | O8: Net income 2026 | P8: Net income 2027 | Q8: Net income 2028 | R8: Capex 2026 | S8: Capex 2027 | T8: Capex 2028 | U8: Fleet sales 2026 | V8: Fleet sales 2027 | W8: Fleet sales 2028 | X8: ROE 2026 | Y8: ROE 2027 | Z8: ROE 2028
B9: Weg (WEGE3) | C9: WEG & Embraer | D9: 5386.7222 | E9: =D9/215196.49375746 -> 0 | F9: 41713.188 | G9: 48520.5 | H9: 56448.214 | I9: 9170.4667 | J9: 10852.267 | K9: 12863.5 | L9: 8084.6 | M9: 9588.0667 | N9: 11394.533 | O9: 6440.25 | P9: 7619.5 | Q9: 8928.143 | R9: -3553 | S9: -3328 | T9: -3328.1111 | U9: 0 | V9: 0 | W9: 0 | X9: 0.3417 | Y9: 0.32072 | Z9: 0.31405
B10: Embraer (EMBJ3) | C10: WEG & Embraer | D10: 4817.8329 | E10: =D10/66153.14703096 -> 0 | F10: 44422.538 | G10: 49697.917 | H10: 55109.091 | I10: 5802.5833 | J10: 6596.0833 | K10: 7501.4545 | L10: 4537.6667 | M10: 5299.75 | N10: 6049.2727 | O10: 2943.462 | P10: 3584.455 | Q10: 4315.4 | R10: -1794.6667 | S10: -1916.3333 | T10: -2050.8333 | U10: 0 | V10: 0 | W10: 0 | X10: 0.15725 | Y10: 0.1695 | Z10: 0.17658
B11: Localiza (RENT3) | C11: Cyclicals ex-WEG & Embraer | D11: 3528.9277 | E11: =D11/56927.4969252 -> 0 | F11: 50013.25 | G11: 53487.75 | H11: 57020.167 | I11: 15815.75 | J11: 17033.5 | K11: 18414.667 | L11: 10127 | M11: 10959.091 | N11: 12195.636 | O11: 4288.833 | P11: 4771.273 | Q11: 5818.455 | R11: -23848 | S11: -26666.8 | T11: -26482.5 | U11: =-R11*FleetRatio -> 0 | V11: =-S11*FleetRatio -> 0 | W11: =-T11*FleetRatio -> 0 | X11: 0.15723 | Y11: 0.16306 | Z11: 0.18642
B12: Rumo (RAIL3) | C12: Cyclicals ex-WEG & Embraer | D12: 1897.6387 | E12: =D12/34406.91770067 -> 0 | F12: 14779.917 | G12: 15642.182 | H12: 16416.5 | I12: 8140.1818 | J12: 8991.9 | K12: 9504.7778 | L12: 5803.1 | M12: 6618 | N12: 6974.8 | O12: 1917.727 | P12: 2669.7 | Q12: 3229.4 | R12: -5817.6667 | S12: -4786.5 | T12: -4930.8333 | U12: 0 | V12: 0 | W12: 0 | X12: 0.12653 | Y12: 0.15813 | Z12: 0.16495
B13: Motiva (MOTV3) | C13: Cyclicals ex-WEG & Embraer | D13: 1406.9784 | E13: =D13/39895 -> 0 | F13: 18179.286 | G13: 19255 | H13: 21238.667 | I13: 10278.111 | J13: 11125.222 | K13: 12640.571 | L13: 7972.1111 | M13: 8459.8889 | N13: 9510.75 | O13: 2759.5 | P13: 2858.556 | Q13: 3504.429 | R13: -9351 | S13: -7625 | T13: -8095 | U13: 0 | V13: 0 | W13: 0 | X13: 0.14718 | Y13: 0.14652 | Z13: 0.17485
B14: TOTVS (TOTS3) | C14: Cyclicals ex-WEG & Embraer | D14: 1378.3571 | E14: =D14/23568.47016492 -> 0 | F14: 7675.8462 | G14: 8856.5 | H14: 9997.75 | I14: 2001.9091 | J14: 2357.0833 | K14: 2763.7143 | L14: 1487.2 | M14: 1881.8182 | N14: 2259.5 | O14: 1078 | P14: 1223.182 | Q14: 1570.5 | R14: -393.33333 | S14: -432.33333 | T14: -473.66667 | U14: 0 | V14: 0 | W14: 0 | X14: 0.21023 | Y14: 0.18546 | Z14: 0.22057
B15: Allos (ALOS3) | C15: Cyclicals ex-WEG & Embraer | D15: 1141.4957 | E15: =D15/17374.42003362 -> 0 | F15: 2994.875 | G15: 3153 | H15: 3296 | I15: 2219.4 | J15: 2344.6 | K15: 2453.25 | L15: 1619.25 | M15: 1754.75 | N15: 1841.8571 | O15: 916.222 | P15: 960 | Q15: 1078.714 | R15: -331 | S15: -436 | T15: -257 | U15: 0 | V15: 0 | W15: 0 | X15: 0.07269 | Y15: 0.07893 | Z15: 0.0939
B16: Lojas Renner (LREN3) | C16: Cyclicals ex-WEG & Embraer | D16: 951.12139 | E16: =D16/13521.92962585 -> 0 | F16: 16650.077 | G16: 17782.571 | H16: 19255.385 | I16: 3261.3 | J16: 3505.9 | K16: 3808.4 | L16: 1955.4667 | M16: 2136.3333 | N16: 2373.0667 | O16: 1553.2 | P16: 1645 | Q16: 1797.143 | R16: -968.44444 | S16: -1016.3333 | T16: -1078 | U16: 0 | V16: 0 | W16: 0 | X16: 0.14433 | Y16: 0.14791 | Z16: 0.15145
B17: Multiplan (MULT3) | C17: Cyclicals ex-WEG & Embraer | D17: 831.74581 | E17: =D17/18807.44964165 -> 0 | F17: 2912.3636 | G17: 2769.5455 | H17: 2903.2727 | I17: 2158.1667 | J17: 2094.1667 | K17: 2243.9091 | L17: 2057.0909 | M17: 1940.2727 | N17: 2066.7273 | O17: 1249.909 | P17: 1304.182 | Q17: 1490 | R17: -358.25 | S17: -317.50125 | T17: -320.6875 | U17: 0 | V17: 0 | W17: 0 | X17: 0.18429 | Y17: 0.1665 | Z17: 0.18486
B18: Smart Fit (SMFT3) | C18: Cyclicals ex-WEG & Embraer | D18: 831.72715 | E18: =D18/13764.34071496 -> 0 | F18: 8963.3636 | G18: 10786.364 | H18: 12481.2 | I18: 2917.8 | J18: 3546.7 | K18: 4144.4444 | L18: 1845.6364 | M18: 2303 | N18: 2748 | O18: 945.636 | P18: 1245.455 | Q18: 1540 | R18: -2710.5 | S18: -2494.5 | T18: -2363.75 | U18: 0 | V18: 0 | W18: 0 | X18: 0.14806 | Y18: 0.17758 | Z18: 0.20321
B19: Cyrela (CYRE3) | C19: Cyclicals ex-WEG & Embraer | D19: 614.64098 | E19: =D19/14967.384 -> 0 | F19: 10125 | G19: 11799.8 | H19: 12516.778 | I19: 2474.125 | J19: 2797.3333 | K19: 3031.625 | L19: 2099.3333 | M19: 2576.1111 | N19: 2830.5556 | O19: 1949.111 | P19: 2310.5 | Q19: 2554.111 | R19: -162 | S19: -229 | T19: -235 | U19: 0 | V19: 0 | W19: 0 | X19: 0.18201 | Y19: 0.18853 | Z19: 0.18666
B20: Iguatemi (IGTI11) | C20: Cyclicals ex-WEG & Embraer | D20: 488.82398 | E20: =D20/9053.50892735 -> 0 | F20: 1645.5 | G20: 1822.75 | H20: 2047.5 | I20: 1242.5 | J20: 1361.5 | K20: 1524 | L20: 1048.3333 | M20: 1132.3333 | N20: 1345 | O20: 576.857 | P20: 672.143 | Q20: 778.6 | R20: -512.5 | S20: -343 | T20: -255 | U20: 0 | V20: 0 | W20: 0 | X20: 0.11978 | Y20: 0.126 | Z20: 0.1411
B21: Cogna (COGN3) | C21: Cyclicals ex-WEG & Embraer | D21: 373.09241 | E21: =D21/6048.30181483 -> 0 | F21: 7984.7273 | G21: 8404 | H21: 8772.2222 | I21: 2465.1818 | J21: 2553.5455 | K21: 2652.3333 | L21: 1460.6 | M21: 1530.4 | N21: 1659 | O21: 724.909 | P21: 877.182 | Q21: 978.778 | R21: -580 | S21: -597.16667 | T21: -580.4 | U21: 0 | V21: 0 | W21: 0 | X21: 0.05468 | Y21: 0.0553 | Z21: 0.10336
B22: Cury (CURY3) | C22: Cyclicals ex-WEG & Embraer | D22: 351.67065 | E22: =D22/9940.69585838 -> 0 | F22: 6833.8182 | G22: 7942.0909 | H22: 8683.8 | I22: 1644.2 | J22: 1920.1 | K22: 2066.5556 | L22: 1626.1 | M22: 1893.3 | N22: 2037.2 | O22: 1230.182 | P22: 1453.909 | Q22: 1584.5 | R22: -54.666667 | S22: -89.466667 | T22: -94.4 | U22: 0 | V22: 0 | W22: 0 | X22: 0.79447 | Y22: 0.76168 | Z22: 0.71634
B23: Direcional (DIRR3) | C23: Cyclicals ex-WEG & Embraer | D23: 268.23831 | E23: =D23/6063.825 -> 0 | F23: 5291.1818 | G23: 6236.3636 | H23: 6622.8 | I23: 1398.9 | J23: 1624.6 | K23: 1709.3333 | L23: 1275.3 | M23: 1497.1 | N23: 1584.9 | O23: 919.818 | P23: 1113.364 | Q23: 1200 | R23: -115.8 | S23: -122.5 | T23: -128.75 | U23: 0 | V23: 0 | W23: 0 | X23: 0.40789 | Y23: 0.39338 | Z23: 0.36248
B24: Magazine Luiza (MGLU3) | C24: Cyclicals ex-WEG & Embraer | D24: 262.49334 | E24: =D24/7911.148704000002 -> 0 | F24: 39297.833 | G24: 41804.846 | H24: 43576.545 | I24: 2989.7778 | J24: 3277.3333 | K24: 3455 | L24: 1760.5 | M24: 1983.75 | N24: 2157.3333 | O24: 151.825 | P24: 437.5 | Q24: 651.273 | R24: -914.85714 | S24: -975 | T24: -1019.4286 | U24: 0 | V24: 0 | W24: 0 | X24: 0.00926 | Y24: 0.03424 | Z24: 0.04905
B25: Tenda (TEND3) | C25: Cyclicals ex-WEG & Embraer | D25: 251.0846 | E25: =D25/3709.21487952 -> 0 | F25: 5199.75 | G25: 6120.75 | H25: 6827 | I25: 910.14286 | J25: 1107.5714 | K25: 1252.1667 | L25: 835.42857 | M25: 1018.2857 | N25: 1164.1429 | O25: 665.125 | P25: 839 | Q25: 978.857 | R25: -96.4 | S25: -93.066667 | T25: -104.26667 | U25: 0 | V25: 0 | W25: 0 | X25: 0.45619 | Y25: 0.40308 | Z25: 0.38014
B26: Marcopolo (POMO4) | C26: Cyclicals ex-WEG & Embraer | D26: 246.63344 | E26: =D26/5792.715650009999 -> 0 | F26: 8959.125 | G26: 9651.75 | H26: 10269.875 | I26: 1432.875 | J26: 1585.625 | K26: 1695.625 | L26: 1239.125 | M26: 1366.625 | N26: 1460 | O26: 1081.5 | P26: 1122.5 | Q26: 1198.625 | R26: -307.85714 | S26: -327.57143 | T26: -352.42857 | U26: 0 | V26: 0 | W26: 0 | X26: 0.26397 | Y26: 0.24368 | Z26: 0.23972
B27: Vivara (VIVA3) | C27: Cyclicals ex-WEG & Embraer | D27: 246.62879 | E27: =D27/6632.433353519999 -> 0 | F27: 3356.4286 | G27: 3771.1429 | H27: 4169.2308 | I27: 904.07692 | J27: 1020.3846 | K27: 1169.5 | L27: 788.07692 | M27: 895.07692 | N27: 1003.8462 | O27: 623.143 | P27: 735.143 | Q27: 843.923 | R27: -128.3 | S27: -142 | T27: -141.9 | U27: 0 | V27: 0 | W27: 0 | X27: 0.19397 | Y27: 0.19895 | Z27: 0.20181
B28: YDUQS (YDUQ3) | C28: Cyclicals ex-WEG & Embraer | D28: 219.64421 | E28: =D28/3626.19549873 -> 0 | F28: 5699.0769 | G28: 5999.2308 | H28: 6283.5 | I28: 1850.4615 | J28: 1932.1538 | K28: 2008.1667 | L28: 1008.4 | M28: 1148.8182 | N28: 1231.8182 | O28: 354.222 | P28: 515.273 | Q28: 637.364 | R28: -427.4 | S28: -429.8 | T28: -441.8 | U28: 0 | V28: 0 | W28: 0 | X28: 0.10645 | Y28: 0.14985 | Z28: 0.16766
B29: Vamos (VAMO3) | C29: Cyclicals ex-WEG & Embraer | D29: 218.86239 | E29: =D29/7404.270801899999 -> 0 | F29: 6636.1 | G29: 7336.2 | H29: 7785.1111 | I29: 3936.9 | J29: 4261.8 | K29: 4599.5556 | L29: 2732.7778 | M29: 2898.1111 | N29: 3023.2222 | O29: 473.2 | P29: 731.9 | Q29: 1081.333 | R29: -2967.8333 | S29: -3416.5 | T29: -3910.8333 | U29: =-R29*FleetRatio -> 0 | V29: =-S29*FleetRatio -> 0 | W29: =-T29*FleetRatio -> 0 | X29: 0.15723 | Y29: 0.2093 | Z29: 0.26423
B30: Azzas 2154 (AZZA3) | C30: Cyclicals ex-WEG & Embraer | D30: 208.33727 | E30: =D30/4846.315911109999 -> 0 | F30: 11464 | G30: 12169.778 | H30: 12871.625 | I30: 1614.4286 | J30: 1817.2857 | K30: 1959.5 | L30: 1049.3333 | M30: 1218.375 | N30: 1417.375 | O30: 399.1 | P30: 575.9 | Q30: 710.556 | R30: -375.5 | S30: -375 | T30: -407 | U30: 0 | V30: 0 | W30: 0 | X30: 0.05738 | Y30: 0.0753 | Z30: 0.09116
B31: C&A Modas (CEAB3) | C31: Cyclicals ex-WEG & Embraer | D31: 180.49236 | E31: =D31/3868.4756034 -> 0 | F31: 8396.75 | G31: 9055.75 | H31: 9749.5 | I31: 1651.2222 | J31: 1699.5455 | K31: 1842.0909 | L31: 955.1 | M31: 1021.7 | N31: 1110.6 | O31: 517.636 | P31: 547.6 | Q31: 586.1 | R31: -632.14286 | S31: -701.25 | T31: -751.125 | U31: 0 | V31: 0 | W31: 0 | X31: 0.13163 | Y31: 0.12885 | Z31: 0.12423
B32: MRV (MRVE3) | C32: Cyclicals ex-WEG & Embraer | D32: 167.88482 | E32: =D32/3574.00714585 -> 0 | F32: 11757.5 | G32: 11928.286 | H32: 12097.714 | I32: 1198.8571 | J32: 2156.3333 | K32: 2112.3333 | L32: 819.33333 | M32: 1769 | N32: 1803.5 | O32: -394.6 | P32: 649.286 | Q32: 870.286 | R32: -146.7 | S32: -229.55 | T32: -270.05 | U32: 0 | V32: 0 | W32: 0 | X32: -0.0802 | Y32: 0.1406 | Z32: 0.14758
B35: 2. In index points (= R$ mn x points / market cap); book value = net income / ROE
B36: Member | C36: Sub-box | D36: Index points | E36: Points / market cap | F36: Sales 2026 | G36: Sales 2027 | H36: Sales 2028 | I36: EBITDA 2026 | J36: EBITDA 2027 | K36: EBITDA 2028 | L36: EBIT 2026 | M36: EBIT 2027 | N36: EBIT 2028 | O36: Net income 2026 | P36: Net income 2027 | Q36: Net income 2028 | R36: Capex 2026 | S36: Capex 2027 | T36: Capex 2028 | U36: Fleet sales 2026 | V36: Fleet sales 2027 | W36: Fleet sales 2028 | X36: Book value 2026 | Y36: Book value 2027 | Z36: Book value 2028
B37: Weg (WEGE3) | C37: =C9 -> 0 | D37: =D9 -> 0 | F37: =F9*$E$9 -> 0 | G37: =G9*$E$9 -> 0 | H37: =H9*$E$9 -> 0 | I37: =I9*$E$9 -> 0 | J37: =J9*$E$9 -> 0 | K37: =K9*$E$9 -> 0 | L37: =L9*$E$9 -> 0 | M37: =M9*$E$9 -> 0 | ... W37: =W9*$E$9 -> 0 | X37: =IF(ISNUMBER(X9),O9*$E$9/X9,0) -> 0 | Y37: =IF(ISNUMBER(Y9),P9*$E$9/Y9,0) -> 0 | Z37: =IF(ISNUMBER(Z9),Q9*$E$9/Z9,0) -> 0
B38: Embraer (EMBJ3) | C38: =C10 -> 0 | D38: =D10 -> 0 | F38: =F10*$E$10 -> 0 | G38: =G10*$E$10 -> 0 | H38: =H10*$E$10 -> 0 | I38: =I10*$E$10 -> 0 | J38: =J10*$E$10 -> 0 | K38: =K10*$E$10 -> 0 | L38: =L10*$E$10 -> 0 | M38: =M10*$E$10 -> 0 | ... W38: =W10*$E$10 -> 0 | X38: =IF(ISNUMBER(X10),O10*$E$10/X10,0) -> 0 | Y38: =IF(ISNUMBER(Y10),P10*$E$10/Y10,0) -> 0 | Z38: =IF(ISNUMBER(Z10),Q10*$E$10/Z10,0) -> 0
B39: Localiza (RENT3) | C39: =C11 -> 0 | D39: =D11 -> 0 | F39: =F11*$E$11 -> 0 | G39: =G11*$E$11 -> 0 | H39: =H11*$E$11 -> 0 | I39: =I11*$E$11 -> 0 | J39: =J11*$E$11 -> 0 | K39: =K11*$E$11 -> 0 | L39: =L11*$E$11 -> 0 | M39: =M11*$E$11 -> 0 | ... W39: =W11*$E$11 -> 0 | X39: =IF(ISNUMBER(X11),O11*$E$11/X11,0) -> 0 | Y39: =IF(ISNUMBER(Y11),P11*$E$11/Y11,0) -> 0 | Z39: =IF(ISNUMBER(Z11),Q11*$E$11/Z11,0) -> 0
B40: Rumo (RAIL3) | C40: =C12 -> 0 | D40: =D12 -> 0 | F40: =F12*$E$12 -> 0 | G40: =G12*$E$12 -> 0 | H40: =H12*$E$12 -> 0 | I40: =I12*$E$12 -> 0 | J40: =J12*$E$12 -> 0 | K40: =K12*$E$12 -> 0 | L40: =L12*$E$12 -> 0 | M40: =M12*$E$12 -> 0 | ... W40: =W12*$E$12 -> 0 | X40: =IF(ISNUMBER(X12),O12*$E$12/X12,0) -> 0 | Y40: =IF(ISNUMBER(Y12),P12*$E$12/Y12,0) -> 0 | Z40: =IF(ISNUMBER(Z12),Q12*$E$12/Z12,0) -> 0
B41: Motiva (MOTV3) | C41: =C13 -> 0 | D41: =D13 -> 0 | F41: =F13*$E$13 -> 0 | G41: =G13*$E$13 -> 0 | H41: =H13*$E$13 -> 0 | I41: =I13*$E$13 -> 0 | J41: =J13*$E$13 -> 0 | K41: =K13*$E$13 -> 0 | L41: =L13*$E$13 -> 0 | M41: =M13*$E$13 -> 0 | ... W41: =W13*$E$13 -> 0 | X41: =IF(ISNUMBER(X13),O13*$E$13/X13,0) -> 0 | Y41: =IF(ISNUMBER(Y13),P13*$E$13/Y13,0) -> 0 | Z41: =IF(ISNUMBER(Z13),Q13*$E$13/Z13,0) -> 0
B42: TOTVS (TOTS3) | C42: =C14 -> 0 | D42: =D14 -> 0 | F42: =F14*$E$14 -> 0 | G42: =G14*$E$14 -> 0 | H42: =H14*$E$14 -> 0 | I42: =I14*$E$14 -> 0 | J42: =J14*$E$14 -> 0 | K42: =K14*$E$14 -> 0 | L42: =L14*$E$14 -> 0 | M42: =M14*$E$14 -> 0 | ... W42: =W14*$E$14 -> 0 | X42: =IF(ISNUMBER(X14),O14*$E$14/X14,0) -> 0 | Y42: =IF(ISNUMBER(Y14),P14*$E$14/Y14,0) -> 0 | Z42: =IF(ISNUMBER(Z14),Q14*$E$14/Z14,0) -> 0
B43: Allos (ALOS3) | C43: =C15 -> 0 | D43: =D15 -> 0 | F43: =F15*$E$15 -> 0 | G43: =G15*$E$15 -> 0 | H43: =H15*$E$15 -> 0 | I43: =I15*$E$15 -> 0 | J43: =J15*$E$15 -> 0 | K43: =K15*$E$15 -> 0 | L43: =L15*$E$15 -> 0 | M43: =M15*$E$15 -> 0 | ... W43: =W15*$E$15 -> 0 | X43: =IF(ISNUMBER(X15),O15*$E$15/X15,0) -> 0 | Y43: =IF(ISNUMBER(Y15),P15*$E$15/Y15,0) -> 0 | Z43: =IF(ISNUMBER(Z15),Q15*$E$15/Z15,0) -> 0
B44: Lojas Renner (LREN3) | C44: =C16 -> 0 | D44: =D16 -> 0 | F44: =F16*$E$16 -> 0 | G44: =G16*$E$16 -> 0 | H44: =H16*$E$16 -> 0 | I44: =I16*$E$16 -> 0 | J44: =J16*$E$16 -> 0 | K44: =K16*$E$16 -> 0 | L44: =L16*$E$16 -> 0 | M44: =M16*$E$16 -> 0 | ... W44: =W16*$E$16 -> 0 | X44: =IF(ISNUMBER(X16),O16*$E$16/X16,0) -> 0 | Y44: =IF(ISNUMBER(Y16),P16*$E$16/Y16,0) -> 0 | Z44: =IF(ISNUMBER(Z16),Q16*$E$16/Z16,0) -> 0
...

Sheet Analyst Models
B1: Cyclicals - how the XP Cyclicals analysts value their companies (memo)
B2: Files in inputs/analyst_models/Cyclicals (DCF & Sensitivity / Valuation sheets), read on Oct-8-2026.
B3: Legend: | C3: input | D3: assumption | E3: formula
B5: Model (weight in the box) | C5: Currency / method | D5: Explicit to | E5: Perpetuity g | F5: Ke (beta) | G5: WACC | H5: Cash flow | I5: Note
B6: WEG (20.5%) | C6: BRL; FCFF - net debt | D6: 2035 | E6: 7.6% (about 3.4% real) | F6: 11.4% (0.8) | G6: 11.2% | H6: NOPAT + D&A - capex +/- NWC | I6: Permanent real growth
B7: Embraer (18.3%) | C7: USD; FCFF - net debt | D7: ~2035 | E7: 2.4% (real 0%) | F7: 10.6% (1.0) | G7: 9.8% | H7: NOPAT + D&A - capex +/- NWC | I7: Exporter
B8: Localiza (13.4%) | C8: BRL; FCFF / FCFE | D8: 2035 | E8: 6.1% (about 2% real, GDP-linked) | F8: 15.2% (0.95) | G8: 12.3% | H8: NOPAT + D&A - capex + BV of cars sold +/- NWC | I8: Fleet net of used-car sales (resale at 79% of purchase price)
B9: Rumo (7.2%) | C9: BRL; FCFE to concession end | D9: ~2070 | E9: 4.0% (real 0%) | F9: 15.3% (1.0) | G9: 11.7% | H9: FCFF - concession fees + net funding | I9: Lucas do Rio Verde project apart
B10: Motiva (5.4%) | C10: BRL; sum of concessions | D10: Each contract | E10: 0% (finite lives) | F10: 14.7% (0.92) | G10: 10.8% | H10: FCFF by concession | I10: No perpetuity
B11: Totvs (5.2%) | C11: BRL; FCFE | D11: 2035 | E11: Exit multiple on 2035 FCFE | F11: 14.4% (0.8) | G11: - | H11: Operating cash flow - capex - lease principal | I11: Ke without the 0.85
B12: Lojas Renner (3.6%) | C12: BRL; FCFF | D12: ~2035 | E12: 4.0% (real 0%) | F12: 14.1% (0.95) | G12: 13.4% | H12: EBIT - taxes + D&A - capex +/- NWC | I12: USD + country-risk Ke
B13: Cyrela (2.3%) | C13: BRL; FCFF | D13: - | E13: 4.5% (real 0%) | F13: 20.0% (1.46) | G13: 17.5% | H13: NOPAT + D&A - capex +/- NWC | I13: ERP 7.7%
