Workbook
Name BetaAn: 'Model Parameters'!$H$13
Name ERPAn: 'Model Parameters'!$G$13
Name g_: 'DDM Financials'!$C$13
Name gAn: 'DDM Financials'!$C$11

Sheet DDM Financials
B1: Financials - DDM with the analysts' logic and the consensus (end-2027)
B2: Dividends 2028-37 + Gordon perpetuity on the 2037 dividend, as the XP Financials models; numbers from the Bloomberg consensus member by member (Members DDM). Ke: the house rate by default.
B3: Legend: | C3: input | D3: assumption | E3: formula
B5: 1. Assumptions
B6: Item | C6: Value | P6: Source / note
B7: Financials, index points today | C7: 60927.304 | P7: Members' weight x Ibovespa close of Oct-5-2026 (Box Shares!C7 of the main model).
B8: Perpetuity growth, house (g) | C8: 0.047 | P8: House DCF (DCF Ibov 2026_Out.xlsx, Target!B54).
B9: Long-term IPCA | C9: 0.04 | P9: Analysts' Macro sheet and the house (Target!B63).
B10: Long-term real GDP growth | C10: 0.02 | P10: Analysts' Macro sheet.
B11: Perpetuity growth, analysts = IPCA + real GDP | C11: =C9+C10 -> 0.06 | P11: Analysts' rule (e.g., ITUB Valuation!F23).
B12: Convention: 1 = house (real rate + beta x ERP, house g); 2 = analysts ((NTN-B + IPCA) x 0.85 + beta x ERP, analysts' g) | C12: 1 | P12: 1 keeps Ke and g coherent with the other boxes and methods (Caio's choice). 2 reproduces the analysts' convention.
B13: g used | C13: =IF(C12=1,C8,C11) -> 0.047 | P13: Target of the growth fade (Members DDM) and the perpetuity.
B14: ERP, house | C14: 0.06 | P14: House ERP (Target!B57).
B15: Beta of Financials (weekly, 5 years, computed from the local box index) | C15: 1.1490637 | P15: Box Betas of the main model.
B16: Share of the risk free kept after tax (analysts' formula) | C16: 0.85 | P16: Analysts: (NTN-B + IPCA) x 0.85.
B17: Beta and ERP of the analysts' models (weighted by index points) | C17: =BetaAn -> 1.0747443 | D17: =ERPAn -> 0.055398885 | P17: Model Parameters.
B18: Earnings beta x normalization (domestic cycle) | C18: 0.732791 | D18: 1.1868588 | P18: Box Earnings!I7 and I16 of the main model: shock of Financials = C x D x the Ibovespa ex-Commodities shock.
B19: Projection: 1 = consensus with the analysts' logic (Members DDM); 2 = the analysts' own projections | C19: 1 | P19: 2 uses the analysts' aggregate growth and payout (Analyst Models) on the box consensus of 2026-28: a memo of what their numbers give.
B21: 2. Cost of equity by scenario
B22: Item | C22: Bear | D22: Base | E22: Bull | P22: How it is calculated
B23: 5-year real rate (NTN-B) | C23: 0.085 | D23: 0.0676 | E23: 0.055 | P23: Same scenarios as the other boxes.
B24: Ke, house = real rate + beta x ERP | C24: =C23+$C$15*$C$14 -> 0.15394382 | D24: =D23+$C$15*$C$14 -> 0.13654382 | E24: =E23+$C$15*$C$14 -> 0.12394382 | P24: Box Rates of the main model (CAPM).
B25: Ke, analysts = (real rate + IPCA) x 0.85 + beta x ERP | C25: =(C23+$C$9)*$C$16+$C$17*$D$17 -> 0.16578963 | D25: =(D23+$C$9)*$C$16+$C$17*$D$17 -> 0.15099963 | E25: =(E23+$C$9)*$C$16+$C$17*$D$17 -> 0.14028963
B26: Ke used | C26: =IF($C$12=1,C24,C25) -> 0.15394382 | D26: =IF($C$12=1,D24,D25) -> 0.13654382 | E26: =IF($C$12=1,E24,E25) -> 0.12394382
B27: Ke - g | C27: =(C26-g_)*100 -> 10.694382 | D27: =(D26-g_)*100 -> 8.954382 | E27: =(E26-g_)*100 -> 7.694382
B29: 3. Box projection (index points)
B30: Line | C30: 2026 | D30: 2027 | E30: 2028 | F30: 2029 | G30: 2030 | H30: 2031 | I30: 2032 | J30: 2033 | K30: 2034 | L30: 2035 | M30: 2036 | N30: 2037 | P30: How it is calculated / source
B31: Net income: consensus + analysts' logic (sum of the members) | C31: ='Members DDM'!C147 -> 5708.1181 | D31: ='Members DDM'!D147 -> 6447.8435 | E31: ='Members DDM'!E147 -> 7167.1074 | F31: ='Members DDM'!F147 -> 7926.3944 | G31: ='Members DDM'!G147 -> 8717.4464 | H31: ='Members DDM'!H147 -> 9529.7932 | I31: ='Members DDM'!I147 -> 10350.873 | J31: ='Members DDM'!J147 -> 11166.303 | ... N31: ='Members DDM'!N147 -> 14048.28 | P31: Members DDM.
B32: Net income growth | D32: =D31/C31-1 -> 0.12959182 | E32: =E31/D31-1 -> 0.11155109 | F32: =F31/E31-1 -> 0.1059405 | G32: =G31/F31-1 -> 0.099799727 | H32: =H31/G31-1 -> 0.093186326 | I32: =I31/H31-1 -> 0.086159216 | J32: =J31/I31-1 -> 0.07877894 | K32: =K31/J31-1 -> 0.071107816 | ... N32: =N31/M31-1 -> 0.047
B33: Dividends: consensus + analysts' logic | D33: ='Members DDM'!D148 -> 4337.0465 | E33: ='Members DDM'!E148 -> 4278.3379 | F33: ='Members DDM'!F148 -> 3864.243 | G33: ='Members DDM'!G148 -> 4474.0081 | H33: ='Members DDM'!H148 -> 5166.6557 | I33: ='Members DDM'!I148 -> 5942.8373 | J33: ='Members DDM'!J148 -> 6799.7019 | K33: ='Members DDM'!K148 -> 7730.2754 | ... N33: ='Members DDM'!N148 -> 10826.064
B34: Payout | D34: =D33/D31 -> 0.6726352 | E34: =E33/E31 -> 0.59694067 | F34: =F33/F31 -> 0.48751586 | G34: =G33/G31 -> 0.51322462 | H34: =H33/H31 -> 0.54215821 | I34: =I33/I31 -> 0.57413877 | J34: =J33/J31 -> 0.60894833 | K34: =K33/K31 -> 0.64632708 | ... N34: =N33/N31 -> 0.77063271
B35: ROE = net income / average book value | D35: =D31/AVERAGE('Members DDM'!C149,'Members DDM'!D149) -> 0.20605983 | E35: =E31/AVERAGE('Members DDM'!D149,'Members DDM'!E149) -> 0.21210167 | F35: =F31/AVERAGE('Members DDM'!E149,'Members DDM'!F149) -> 0.21269566 | G35: =G31/AVERAGE('Members DDM'!F149,'Members DDM'!G149) -> 0.21046893 | H35: =H31/AVERAGE('Members DDM'!G149,'Members DDM'!H149) -> 0.20842701 | I35: =I31/AVERAGE('Members DDM'!H149,'Members DDM'!I149) -> 0.20657111 | J35: =J31/AVERAGE('Members DDM'!I149,'Members DDM'!J149) -> 0.20490377 | K35: =K31/AVERAGE('Members DDM'!J149,'Members DDM'!K149) -> 0.2034286 | ... N35: =N31/AVERAGE('Members DDM'!M149,'Members DDM'!N149) -> 0.20020666
B36: Memo: analysts' aggregate net income growth | D36: ='Analyst Models'!D90 -> 0.14209296 | E36: ='Analyst Models'!E90 -> 0.12498035 | F36: ='Analyst Models'!F90 -> 0.099600603 | G36: ='Analyst Models'!G90 -> 0.091378032 | H36: ='Analyst Models'!H90 -> 0.083168313 | I36: ='Analyst Models'!I90 -> 0.075274289 | J36: ='Analyst Models'!J90 -> 0.071817703 | K36: ='Analyst Models'!K90 -> 0.066585954 | ... N36: ='Analyst Models'!N90 -> 0.059515705 | P36: Analyst Models.
B37: Memo: analysts' aggregate payout | C37: ='Analyst Models'!C91 -> 0.53677148 | D37: ='Analyst Models'!D91 -> 0.57363999 | E37: ='Analyst Models'!E91 -> 0.5989664 | F37: ='Analyst Models'!F91 -> 0.61404933 | G37: ='Analyst Models'!G91 -> 0.63785097 | H37: ='Analyst Models'!H91 -> 0.66424496 | I37: ='Analyst Models'!I91 -> 0.6824072 | J37: ='Analyst Models'!J91 -> 0.69850557 | ... N37: ='Analyst Models'!N91 -> 0.75906369 | P37: Analyst Models.
B38: Memo: net income on the analysts' path (consensus 2026-28, then their growth) | C38: =C31 -> 5708.1181 | D38: =D31 -> 6447.8435 | E38: =E31 -> 7167.1074 | F38: =E38*(1+F36) -> 7880.9556 | G38: =F38*(1+G36) -> 8601.1019 | H38: =G38*(1+H36) -> 9316.441 | I38: =H38*(1+I36) -> 10017.729 | J38: =I38*(1+J36) -> 10737.18 | K38: =J38*(1+K36) -> 11452.125 | L38: =K38*(1+L36) -> 12191.556 | M38: =L38*(1+M36) -> 12964.063 | N38: =M38*(1+N36) -> 13735.628
B39: Memo: dividends on the analysts' path | C39: =C38*C37 -> 3063.955 | D39: =D38*D37 -> 3698.7409 | E39: =E38*E37 -> 4292.8565 | F39: =F38*F37 -> 4839.2955 | G39: =G38*G37 -> 5486.2212 | H39: =H38*H37 -> 6188.399 | I39: =I38*I37 -> 6836.1707 | J39: =J38*J37 -> 7499.9798 | ... N39: =N38*N37 -> 10426.217
B40: Dividends used (switch in row 19) | D40: =IF($C$19=1,D33,D39) -> 4337.0465 | E40: =IF($C$19=1,E33,E39) -> 4278.3379 | F40: =IF($C$19=1,F33,F39) -> 3864.243 | G40: =IF($C$19=1,G33,G39) -> 4474.0081 | H40: =IF($C$19=1,H33,H39) -> 5166.6557 | I40: =IF($C$19=1,I33,I39) -> 5942.8373 | J40: =IF($C$19=1,J33,J39) -> 6799.7019 | K40: =IF($C$19=1,K33,K39) -> 7730.2754 | ... N40: =IF($C$19=1,N33,N39) -> 10826.064
B42: 4. Valuation at the end of 2027
B43: Item | C43: Bear | D43: Base | E43: Bull | P43: How it is calculated
B44: Ke used | C44: =C26 -> 0.15394382 | D44: =D26 -> 0.13654382 | E44: =E26 -> 0.12394382
...

Sheet Members DDM
B1: Financials - member by member, the analysts' logic on the consensus
B2: Consensus net income and ROE FY26-28 (R$ mn; Bloomberg BEST, Oct-7-2026, Members sheet and dcf_members.parquet). 2029-37: ROE held at FY28; growth fades linearly from the 2028 growth to g in 2037; dividend = net income - change in book value. Index points = R$ x points / market cap.
B3: Legend: | C3: input | D3: assumption | E3: formula
B5: Itaú Unibanco (ITUB4)
B6: Line | C6: 2026 | D6: 2027 | E6: 2028 | F6: 2029 | G6: 2030 | H6: 2031 | I6: 2032 | J6: 2033 | K6: 2034 | L6: 2035 | M6: 2036 | N6: 2037 | P6: How it is calculated / source
B7: Net income (R$ mn) | C7: 50677.333 | D7: 55448.917 | E7: 60687.636 | F7: =E7*(1+F8) -> 66101.151 | G7: =F7*(1+G8) -> 71648.859 | H7: =G7*(1+H8) -> 77284.199 | I7: =H7*(1+I8) -> 82955.069 | J7: =I7*(1+J8) -> 88604.43 | K7: =J7*(1+K8) -> 94171.101 | L7: =K7*(1+L8) -> 99590.716 | M7: =L7*(1+M8) -> 104796.86 | N7: =M7*(1+N8) -> 109722.31 | P7: 2026-28: consensus (BEST_NET_INCOME); then previous x (1 + growth).
B8: Net income growth | D8: =D7/C7-1 -> 0.094156178 | E8: =E7/D7-1 -> 0.094478293 | F8: =$E$8+(g_-$E$8)*1/9 -> 0.089202927 | G8: =$E$8+(g_-$E$8)*2/9 -> 0.083927561 | H8: =$E$8+(g_-$E$8)*3/9 -> 0.078652195 | I8: =$E$8+(g_-$E$8)*4/9 -> 0.073376829 | J8: =$E$8+(g_-$E$8)*5/9 -> 0.068101463 | K8: =$E$8+(g_-$E$8)*6/9 -> 0.062826098 | L8: =$E$8+(g_-$E$8)*7/9 -> 0.057550732 | M8: =$E$8+(g_-$E$8)*8/9 -> 0.052275366 | N8: =$E$8+(g_-$E$8)*9/9 -> 0.047 | P8: 2027-28: consensus; 2029-37: linear from the 2028 growth to g in 2037.
B9: ROE | C9: 0.24574 | D9: 0.24478 | E9: 0.24343 | F9: =$E$9 -> 0.24343 | G9: =$E$9 -> 0.24343 | H9: =$E$9 -> 0.24343 | I9: =$E$9 -> 0.24343 | J9: =$E$9 -> 0.24343 | K9: =$E$9 -> 0.24343 | L9: =$E$9 -> 0.24343 | M9: =$E$9 -> 0.24343 | N9: =$E$9 -> 0.24343 | P9: 2026-28: consensus (BEST_ROE); 2029-37: held at FY28, as the analysts keep ROE about flat.
B10: Book value = net income / ROE (R$ mn) | C10: =C7/C9 -> 206223.38 | D10: =D7/D9 -> 226525.52 | E10: =E7/E9 -> 249302.21 | F10: =F7/F9 -> 271540.69 | G10: =G7/G9 -> 294330.44 | H10: =H7/H9 -> 317480.18 | I10: =I7/I9 -> 340775.86 | J10: =J7/J9 -> 363983.2 | ... N10: =N7/N9 -> 450734.54
B11: Dividends = net income - change in book value (R$ mn) | D11: =D7-(D10-C10) -> 35146.774 | E11: =E7-(E10-D10) -> 37910.951 | F11: =F7-(F10-E10) -> 43862.664 | G11: =G7-(G10-F10) -> 48859.111 | H11: =H7-(H10-G10) -> 54134.464 | I11: =I7-(I10-H10) -> 59659.38 | J11: =J7-(J10-I10) -> 65397.095 | K11: =K7-(K10-J10) -> 71303.457 | ... N11: =N7-(N10-M10) -> 89488.763 | P11: Clean surplus: what is not retained to grow the book value is paid out (dividends, IoC, buybacks).
B12: Payout = dividends / net income | D12: =D11/D7 -> 0.63385863 | E12: =E11/E7 -> 0.62468986 | F12: =F11/F7 -> 0.66356885 | G12: =G11/G7 -> 0.68192448 | H12: =H11/H7 -> 0.70045966 | I12: =I11/I7 -> 0.71917703 | J12: =J11/J7 -> 0.73807929 | K12: =K11/K7 -> 0.7571692 | ... N12: =N11/N7 -> 0.81559314 | P12: Converges to about 1 - g / ROE as growth reaches g.
B13: Index points / market cap (R$ mn) | C13: 19089.265 | D13: 564225.23 | E13: =C13/D13 -> 0.033832704 | P13: Members sheet of the main model (Oct-5-2026).
B14: Net income (index pts) | C14: =C7*$E$13 -> 1714.5512 | D14: =D7*$E$13 -> 1875.9868 | E14: =E7*$E$13 -> 2053.2268 | F14: =F7*$E$13 -> 2236.3807 | G14: =G7*$E$13 -> 2424.0746 | H14: =H7*$E$13 -> 2614.7334 | I14: =I7*$E$13 -> 2806.5943 | J14: =J7*$E$13 -> 2997.7275 | ... N14: =N7*$E$13 -> 3712.2024
B15: Dividends (index pts) | D15: =D11*$E$13 -> 1189.1104 | E15: =E11*$E$13 -> 1282.63 | F15: =F11*$E$13 -> 1483.9925 | G15: =G11*$E$13 -> 1653.0358 | H15: =H11*$E$13 -> 1831.5153 | I15: =I11*$E$13 -> 2018.4381 | J15: =J11*$E$13 -> 2212.5606 | K15: =K11*$E$13 -> 2412.3887 | ... N15: =N11*$E$13 -> 3027.6468
B16: Book value (index pts) | C16: =C10*$E$13 -> 6977.0945 | D16: =D10*$E$13 -> 7663.9709 | E16: =E10*$E$13 -> 8434.5677 | F16: =F10*$E$13 -> 9186.9559 | G16: =G10*$E$13 -> 9957.9947 | H16: =H10*$E$13 -> 10741.213 | I16: =I10*$E$13 -> 11529.369 | J16: =J10*$E$13 -> 12314.536 | ... N16: =N10*$E$13 -> 15249.568
B19: Bradesco (BBDC4 + BBDC3)
B20: Line | C20: 2026 | D20: 2027 | E20: 2028 | F20: 2029 | G20: 2030 | H20: 2031 | I20: 2032 | J20: 2033 | K20: 2034 | L20: 2035 | M20: 2036 | N20: 2037 | P20: How it is calculated / source
B21: Net income (R$ mn) | C21: 27739.923 | D21: 30648.077 | E21: 33619.083 | F21: =E21*(1+F22) -> 36691.55 | G21: =F21*(1+G22) -> 39841.217 | H21: =G21*(1+H22) -> 43040.185 | I21: =H21*(1+I22) -> 46257.185 | J21: =I21*(1+J22) -> 49457.965 | K21: =J21*(1+K22) -> 52605.789 | L21: =K21*(1+L22) -> 55662.062 | M21: =L21*(1+M22) -> 58587.037 | N21: =M21*(1+N22) -> 61340.628 | P21: 2026-28: consensus (BEST_NET_INCOME); then previous x (1 + growth).
B22: Net income growth | D22: =D21/C21-1 -> 0.10483641 | E22: =E21/D21-1 -> 0.096939394 | F22: =$E$22+(g_-$E$22)*1/9 -> 0.091390572 | G22: =$E$22+(g_-$E$22)*2/9 -> 0.085841751 | H22: =$E$22+(g_-$E$22)*3/9 -> 0.080292929 | I22: =$E$22+(g_-$E$22)*4/9 -> 0.074744108 | J22: =$E$22+(g_-$E$22)*5/9 -> 0.069195286 | K22: =$E$22+(g_-$E$22)*6/9 -> 0.063646465 | L22: =$E$22+(g_-$E$22)*7/9 -> 0.058097643 | M22: =$E$22+(g_-$E$22)*8/9 -> 0.052548822 | N22: =$E$22+(g_-$E$22)*9/9 -> 0.047 | P22: 2027-28: consensus; 2029-37: linear from the 2028 growth to g in 2037.
B23: ROE | C23: 0.15379 | D23: 0.15855 | E23: 0.1615 | F23: =$E$23 -> 0.1615 | G23: =$E$23 -> 0.1615 | H23: =$E$23 -> 0.1615 | I23: =$E$23 -> 0.1615 | J23: =$E$23 -> 0.1615 | K23: =$E$23 -> 0.1615 | L23: =$E$23 -> 0.1615 | M23: =$E$23 -> 0.1615 | N23: =$E$23 -> 0.1615 | P23: 2026-28: consensus (BEST_ROE); 2029-37: held at FY28, as the analysts keep ROE about flat.
B24: Book value = net income / ROE (R$ mn) | C24: =C21/C23 -> 180375.34 | D24: =D21/D23 -> 193302.28 | E24: =E21/E23 -> 208167.7 | F24: =F21/F23 -> 227192.26 | G24: =G21/G23 -> 246694.84 | H24: =H21/H23 -> 266502.69 | I24: =I21/I23 -> 286422.2 | J24: =J21/J23 -> 306241.27 | ... N24: =N21/N23 -> 379818.13
B25: Dividends = net income - change in book value (R$ mn) | D25: =D21-(D24-C24) -> 17721.13 | E25: =E21-(E24-D24) -> 18753.67 | F25: =F21-(F24-E24) -> 17666.985 | G25: =G21-(G24-F24) -> 20338.636 | H25: =H21-(H24-G24) -> 23232.334 | I25: =I21-(I24-H24) -> 26337.679 | J25: =J21-(J24-I24) -> 29638.898 | K25: =K21-(K24-J24) -> 33114.615 | ... N25: =N21-(N24-M24) -> 44290.53 | P25: Clean surplus: what is not retained to grow the book value is paid out (dividends, IoC, buybacks).
B26: Payout = dividends / net income | D26: =D25/D21 -> 0.57821345 | E26: =E25/E21 -> 0.55782811 | F26: =F25/F21 -> 0.48150011 | G26: =G25/G21 -> 0.51049233 | H26: =H25/H21 -> 0.53978238 | I26: =I25/I21 -> 0.56937488 | J26: =J25/J21 -> 0.59927453 | K26: =K25/K21 -> 0.62948614 | ... N26: =N25/N21 -> 0.72204234 | P26: Converges to about 1 - g / ROE as growth reaches g.
B27: Index points / market cap (R$ mn) | C27: 10039.703 | D27: 226447.76 | E27: =C27/D27 -> 0.044335627 | P27: Members sheet of the main model (Oct-5-2026).
B28: Net income (index pts) | C28: =C21*$E$27 -> 1229.8669 | D28: =D21*$E$27 -> 1358.8017 | E28: =E21*$E$27 -> 1490.5231 | F28: =F21*$E$27 -> 1626.7429 | G28: =G21*$E$27 -> 1766.3853 | H28: =H21*$E$27 -> 1908.2136 | I28: =I21*$E$27 -> 2050.8413 | J28: =J21*$E$27 -> 2192.7499 | ... N28: =N21*$E$27 -> 2719.5752
B29: Dividends (index pts) | D29: =D25*$E$27 -> 785.67743 | E29: =E25*$E$27 -> 831.4557 | F29: =F25*$E$27 -> 783.27687 | G29: =G25*$E$27 -> 901.72617 | H29: =H25*$E$27 -> 1030.0201 | I29: =I25*$E$27 -> 1167.6975 | J29: =J25*$E$27 -> 1314.0592 | K29: =K25*$E$27 -> 1468.1572 | ... N29: =N25*$E$27 -> 1963.6484
B30: Book value (index pts) | C30: =C24*$E$27 -> 7997.0537 | D30: =D24*$E$27 -> 8570.1779 | E30: =E24*$E$27 -> 9229.2454 | F30: =F24*$E$27 -> 10072.711 | G30: =G24*$E$27 -> 10937.371 | H30: =H24*$E$27 -> 11815.564 | I30: =I24*$E$27 -> 12698.708 | J30: =J24*$E$27 -> 13577.399 | ... N30: =N24*$E$27 -> 16839.475
B33: B3 (B3SA3)
B34: Line | C34: 2026 | D34: 2027 | E34: 2028 | F34: 2029 | G34: 2030 | H34: 2031 | I34: 2032 | J34: 2033 | K34: 2034 | L34: 2035 | M34: 2036 | N34: 2037 | P34: How it is calculated / source
B35: Net income (R$ mn) | C35: 5982 | D35: 6425.4 | E35: 6561.222 | F35: =E35*(1+F36) -> 6718.7689 | G35: =F35*(1+G36) -> 6899.4053 | H35: =G35*(1+H36) -> 7104.7237 | I35: =H35*(1+I36) -> 7336.5678 | J35: =I35*(1+J36) -> 7597.0593 | K35: =J35*(1+K36) -> 7888.6301 | L35: =K35*(1+L36) -> 8214.0594 | M35: =L35*(1+M36) -> 8576.5169 | N35: =M35*(1+N36) -> 8979.6132 | P35: 2026-28: consensus (BEST_NET_INCOME); then previous x (1 + growth).
B36: Net income growth | D36: =D35/C35-1 -> 0.074122367 | E36: =E35/D35-1 -> 0.021138295 | F36: =$E$36+(g_-$E$36)*1/9 -> 0.024011818 | G36: =$E$36+(g_-$E$36)*2/9 -> 0.02688534 | H36: =$E$36+(g_-$E$36)*3/9 -> 0.029758863 | I36: =$E$36+(g_-$E$36)*4/9 -> 0.032632386 | J36: =$E$36+(g_-$E$36)*5/9 -> 0.035505909 | K36: =$E$36+(g_-$E$36)*6/9 -> 0.038379432 | L36: =$E$36+(g_-$E$36)*7/9 -> 0.041252954 | M36: =$E$36+(g_-$E$36)*8/9 -> 0.044126477 | N36: =$E$36+(g_-$E$36)*9/9 -> 0.047 | P36: 2027-28: consensus; 2029-37: linear from the 2028 growth to g in 2037.
B37: ROE | C37: 0.3363 | D37: 0.34744 | E37: 0.37809 | F37: =$E$37 -> 0.37809 | G37: =$E$37 -> 0.37809 | H37: =$E$37 -> 0.37809 | I37: =$E$37 -> 0.37809 | J37: =$E$37 -> 0.37809 | K37: =$E$37 -> 0.37809 | L37: =$E$37 -> 0.37809 | M37: =$E$37 -> 0.37809 | N37: =$E$37 -> 0.37809 | P37: 2026-28: consensus (BEST_ROE); 2029-37: held at FY28, as the analysts keep ROE about flat.
B38: Book value = net income / ROE (R$ mn) | C38: =C35/C37 -> 17787.69 | D38: =D35/D37 -> 18493.553 | E38: =E35/E37 -> 17353.598 | F38: =F35/F37 -> 17770.29 | G38: =G35/G37 -> 18248.05 | H38: =H35/H37 -> 18791.091 | I38: =I35/I37 -> 19404.289 | J38: =J35/J37 -> 20093.256 | ... N38: =N35/N37 -> 23749.936
B39: Dividends = net income - change in book value (R$ mn) | D39: =D35-(D38-C38) -> 5719.5367 | E39: =E35-(E38-D38) -> 7701.1765 | F39: =F35-(F38-E38) -> 6302.0774 | G39: =G35-(G38-F38) -> 6421.645 | H39: =H35-(H38-G38) -> 6561.6825 | I39: =I35-(I38-H38) -> 6723.3697 | J39: =J35-(J38-I38) -> 6908.0924 | K39: =K35-(K38-J38) -> 7117.4624 | ... N39: =N35-(N38-M38) -> 7913.4748 | P39: Clean surplus: what is not retained to grow the book value is paid out (dividends, IoC, buybacks).
B40: Payout = dividends / net income | D40: =D39/D35 -> 0.89014485 | E40: =E39/E35 -> 1.1737412 | F40: =F39/F35 -> 0.93798098 | G40: =G39/G35 -> 0.93075341 | H40: =H39/H35 -> 0.92356617 | I40: =I39/I35 -> 0.91641894 | J40: =J39/J35 -> 0.90931137 | K40: =K39/K35 -> 0.90224313 | ... N40: =N39/N35 -> 0.88127123 | P40: Converges to about 1 - g / ROE as growth reaches g.
B41: Index points / market cap (R$ mn) | C41: 8337.4035 | D41: 112688.35 | E41: =C41/D41 -> 0.073986387 | P41: Members sheet of the main model (Oct-5-2026).
B42: Net income (index pts) | C42: =C35*$E$41 -> 442.58656 | D42: =D35*$E$41 -> 475.39213 | E42: =E35*$E$41 -> 485.44111 | F42: =F35*$E$41 -> 497.09743 | G42: =G35*$E$41 -> 510.46206 | H42: =H35*$E$41 -> 525.65283 | I42: =I35*$E$41 -> 542.80614 | J42: =J35*$E$41 -> 562.07897 | ... N42: =N35*$E$41 -> 664.36914
B43: Dividends (index pts) | D43: =D39*$E$41 -> 423.16785 | E43: =E39*$E$41 -> 569.78222 | F43: =F39*$E$41 -> 466.26794 | G43: =G39*$E$41 -> 475.11431 | H43: =H39*$E$41 -> 485.47518 | I43: =I39*$E$41 -> 497.43783 | J43: =J39*$E$41 -> 511.10479 | K43: =K39*$E$41 -> 526.59532 | ... N43: =N39*$E$41 -> 585.4894
B44: Book value (index pts) | C44: =C38*$E$41 -> 1316.0469 | D44: =D38*$E$41 -> 1368.2711 | E44: =E38*$E$41 -> 1283.93 | F44: =F38*$E$41 -> 1314.7595 | G44: =G38*$E$41 -> 1350.1073 | H44: =H38*$E$41 -> 1390.2849 | I44: =I38*$E$41 -> 1435.6533 | J44: =J38*$E$41 -> 1486.6274 | ... N44: =N38*$E$41 -> 1757.1719
B47: Itausa (ITSA4)
...

Sheet Analyst Models
B1: Financials - analysts' projections, aggregated (index points)
B2: Net income and dividends of the XP Financials models (R$ mn, files in inputs/analyst_models/Financials/). After a model's last year: net income grows at g and the payout stays at its last value, as the model's own perpetuity. Index points = R$ x the member's index points / market cap (Members sheet of the main model, Oct-5-2026).
B3: Legend: | C3: input | D3: assumption | E3: formula
B5: Itaú Unibanco (ITUB4) | ITUB Model Official 2Q26_vCSStrategy.xlsx
B6: Line | C6: 2026 | D6: 2027 | E6: 2028 | F6: 2029 | G6: 2030 | H6: 2031 | I6: 2032 | J6: 2033 | K6: 2034 | L6: 2035 | M6: 2036 | N6: 2037 | P6: How it is calculated / source
B7: Net income (R$ mn) | C7: 50922 | D7: 56028 | E7: 61318 | F7: 66407 | G7: 71853 | H7: 76890 | I7: 81937 | J7: 87124 | K7: 92891 | L7: 99086 | M7: 105569 | N7: 112362 | P7: Model: Income Statement r61 Recurring Net Income.
B8: Dividends + IoC (R$ mn) | C8: 29433 | D8: 36310 | E8: 42954 | F8: 47031 | G8: 52633 | H8: 58205 | I8: 62018 | J8: 65938 | K8: 72614 | L8: 77433 | M8: 83534 | N8: 90010 | P8: Model: Income Statement r66 Dividends/IoC Provisioned.
B9: Payout | C9: =C8/C7 -> 0.57800165 | D9: =D8/D7 -> 0.64806882 | E9: =E8/E7 -> 0.70051208 | F9: =F8/F7 -> 0.70822353 | G9: =G8/G7 -> 0.73250943 | H9: =H8/H7 -> 0.75699051 | I9: =I8/I7 -> 0.75689859 | J9: =J8/J7 -> 0.75682935 | ... N9: =N8/N7 -> 0.80107154 | P9: Dividends / net income.
B10: Index points / market cap (R$ mn) | C10: 19089.265 | D10: 564225.23 | E10: =C10/D10 -> 0.033832704 | P10: C: index points (Members); D: market cap (Members); E: factor that turns R$ mn into index points.
B11: Net income (index pts) | C11: =C7*$E$10 -> 1722.829 | D11: =D7*$E$10 -> 1895.5787 | E11: =E7*$E$10 -> 2074.5537 | F11: =F7*$E$10 -> 2246.7284 | G11: =G7*$E$10 -> 2430.9813 | H11: =H7*$E$10 -> 2601.3966 | I11: =I7*$E$10 -> 2772.1503 | J11: =J7*$E$10 -> 2947.6405 | ... N11: =N7*$E$10 -> 3801.5103
B12: Dividends (index pts) | C12: =C8*$E$10 -> 995.79798 | D12: =D8*$E$10 -> 1228.4655 | E12: =E8*$E$10 -> 1453.25 | F12: =F8*$E$10 -> 1591.1859 | G12: =G8*$E$10 -> 1780.7167 | H12: =H8*$E$10 -> 1969.2325 | I12: =I8*$E$10 -> 2098.2366 | J12: =J8*$E$10 -> 2230.8608 | ... N12: =N8*$E$10 -> 3045.2817
B15: Bradesco (BBDC4 + BBDC3) | BBDC Model Official 2Q26_vCSStrategy.xlsx
B16: Line | C16: 2026 | D16: 2027 | E16: 2028 | F16: 2029 | G16: 2030 | H16: 2031 | I16: 2032 | J16: 2033 | K16: 2034 | L16: 2035 | M16: 2036 | N16: 2037 | P16: How it is calculated / source
B17: Net income (R$ mn) | C17: 28221 | D17: 31178 | E17: 34548 | F17: 37971 | G17: 41533 | H17: 44699 | I17: 47964 | J17: 51319 | K17: 54749 | L17: 58243 | M17: 61788 | N17: 65372 | P17: Model: Income Statement r73 Recurring Net Income.
B18: Dividends + IoC (R$ mn) | C18: 13727 | D18: 15095 | E18: 16726 | F18: 19903 | G18: 23431 | H18: 26111 | I18: 28978 | J18: 31517 | K18: 34171 | L18: 36934 | M18: 39801 | N18: 42763 | P18: Model: Income Statement r78 Dividends/IoC Provisioned - Net.
B19: Payout | C19: =C18/C17 -> 0.48641083 | D19: =D18/D17 -> 0.48415549 | E19: =E18/E17 -> 0.48413801 | F19: =F18/F17 -> 0.52416318 | G19: =G18/G17 -> 0.56415381 | H19: =H18/H17 -> 0.58415177 | I19: =I18/I17 -> 0.60416145 | J19: =J18/J17 -> 0.61413901 | ... N19: =N18/N17 -> 0.65414857 | P19: Dividends / net income.
B20: Index points / market cap (R$ mn) | C20: 10039.703 | D20: 226447.76 | E20: =C20/D20 -> 0.044335627 | P20: C: index points (Members); D: market cap (Members); E: factor that turns R$ mn into index points.
B21: Net income (index pts) | C21: =C17*$E$20 -> 1251.1957 | D21: =D17*$E$20 -> 1382.2962 | E21: =E17*$E$20 -> 1531.7072 | F21: =F17*$E$20 -> 1683.4681 | G21: =G17*$E$20 -> 1841.3916 | H21: =H17*$E$20 -> 1981.7582 | I21: =I17*$E$20 -> 2126.514 | J21: =J17*$E$20 -> 2275.26 | ... N21: =N17*$E$20 -> 2898.3086
B22: Dividends (index pts) | C22: =C18*$E$20 -> 608.59515 | D22: =D18*$E$20 -> 669.24629 | E22: =E18*$E$20 -> 741.5577 | F22: =F18*$E$20 -> 882.41199 | G22: =G18*$E$20 -> 1038.8281 | H22: =H18*$E$20 -> 1157.6476 | I22: =I18*$E$20 -> 1284.7578 | J22: =J18*$E$20 -> 1397.326 | ... N22: =N18*$E$20 -> 1895.9244
B25: B3 (B3SA3) | B3SA3 Model Official 3Q25_vCSStrategy.xlsx
B26: Line | C26: 2026 | D26: 2027 | E26: 2028 | F26: 2029 | G26: 2030 | H26: 2031 | I26: 2032 | J26: 2033 | K26: 2034 | L26: 2035 | M26: 2036 | N26: 2037 | P26: How it is calculated / source
B27: Net income (R$ mn) | C27: 6537 | D27: 7215 | E27: 7971 | F27: 8876 | G27: 9881 | H27: 10905 | I27: 11848 | J27: 13062 | K27: =J27*(1+gAn) -> 13845.72 | L27: =K27*(1+gAn) -> 14676.463 | M27: =L27*(1+gAn) -> 15557.051 | N27: =M27*(1+gAn) -> 16490.474 | P27: Model: Income Statement r52 Recurring Net Income. After 2033: x (1 + g).
B28: Dividends + IoC (R$ mn) | C28: 6203 | D28: 6859 | E28: 7612 | F28: 8513 | G28: 9413 | H28: 10358 | I28: 11364 | J28: 12526 | K28: =K27*J29 -> 13277.56 | L28: =L27*J29 -> 14074.214 | M28: =M27*J29 -> 14918.666 | N28: =N27*J29 -> 15813.786 | P28: Model: Income Statement r58 Dividends/IoC. After 2033: net income x the 2033 payout.
B29: Payout | C29: =C28/C27 -> 0.94890623 | D29: =D28/D27 -> 0.95065835 | E29: =E28/E27 -> 0.95496174 | F29: =F28/F27 -> 0.9591032 | G29: =G28/G27 -> 0.95263637 | H29: =H28/H27 -> 0.94983952 | I29: =I28/I27 -> 0.95914922 | J29: =J28/J27 -> 0.95896494 | ... N29: =N28/N27 -> 0.95896494 | P29: Dividends / net income.
B30: Index points / market cap (R$ mn) | C30: 8337.4035 | D30: 112688.35 | E30: =C30/D30 -> 0.073986387 | P30: C: index points (Members); D: market cap (Members); E: factor that turns R$ mn into index points.
B31: Net income (index pts) | C31: =C27*$E$30 -> 483.64901 | D31: =D27*$E$30 -> 533.81178 | E31: =E27*$E$30 -> 589.74549 | F31: =F27*$E$30 -> 656.70317 | G31: =G27*$E$30 -> 731.05949 | H31: =H27*$E$30 -> 806.82155 | I31: =I27*$E$30 -> 876.59071 | J31: =J27*$E$30 -> 966.41018 | ... N31: =N27*$E$30 -> 1220.0706
B32: Dividends (index pts) | C32: =C28*$E$30 -> 458.93756 | D32: =D28*$E$30 -> 507.47263 | E32: =E28*$E$30 -> 563.18437 | F32: =F28*$E$30 -> 629.84611 | G32: =G28*$E$30 -> 696.43386 | H32: =H28*$E$30 -> 766.35099 | I32: =I28*$E$30 -> 840.7813 | J32: =J28*$E$30 -> 926.75348 | ... N32: =N28*$E$30 -> 1170.0049
B35: BTG Pactual (BPAC11) | BPAC Model Official 3Q25_vCSStrategy.xlsx
B36: Line | C36: 2026 | D36: 2027 | E36: 2028 | F36: 2029 | G36: 2030 | H36: 2031 | I36: 2032 | J36: 2033 | K36: 2034 | L36: 2035 | M36: 2036 | N36: 2037 | P36: How it is calculated / source
B37: Net income (R$ mn) | C37: 19103 | D37: 21961 | E37: 25043 | F37: 28704 | G37: 32446 | H37: 36374 | I37: 40448 | J37: 44253 | K37: 48504 | L37: 52818 | M37: 57507 | N37: =M37*(1+gAn) -> 60957.42 | P37: Model: Income Statement r50 Net Income. After 2036: x (1 + g).
B38: Dividends + IoC (R$ mn) | C38: 6686 | D38: 9882 | E38: 13774 | F38: 17222 | G38: 21090 | H38: 25462 | I38: 30336 | J38: 35403 | K38: 41228 | L38: 47536 | M38: 54632 | N38: =N37*M39 -> 57909.92 | P38: Model: Income Statement r56 Dividends/IoC. After 2036: net income x the 2036 payout.
B39: Payout | C39: =C38/C37 -> 0.34999738 | D39: =D38/D37 -> 0.44997951 | E39: =E38/E37 -> 0.55001398 | F39: =F38/F37 -> 0.59998606 | G39: =G38/G37 -> 0.65000308 | H39: =H38/H37 -> 0.7000055 | I39: =I38/I37 -> 0.75 | J39: =J38/J37 -> 0.80001356 | ... N39: =N38/N37 -> 0.95000609 | P39: Dividends / net income.
B40: Index points / market cap (R$ mn) | C40: 6925.2189 | D40: 305584.14 | E40: =C40/D40 -> 0.022662232 | P40: C: index points (Members); D: market cap (Members); E: factor that turns R$ mn into index points.
B41: Net income (index pts) | C41: =C37*$E$40 -> 432.91662 | D41: =D37*$E$40 -> 497.68528 | E41: =E37*$E$40 -> 567.53028 | F41: =F37*$E$40 -> 650.49672 | G41: =G37*$E$40 -> 735.29879 | H41: =H37*$E$40 -> 824.31604 | I41: =I37*$E$40 -> 916.64197 | J41: =J37*$E$40 -> 1002.8718 | ... N41: =N37*$E$40 -> 1381.4312
B42: Dividends (index pts) | C42: =C38*$E$40 -> 151.51969 | D42: =D38*$E$40 -> 223.94818 | E42: =E38*$E$40 -> 312.14959 | F42: =F38*$E$40 -> 390.28897 | G42: =G38*$E$40 -> 477.94648 | H42: =H38*$E$40 -> 577.02576 | I42: =I38*$E$40 -> 687.48148 | J42: =J38*$E$40 -> 802.31101 | ... N42: =N38*$E$40 -> 1312.3681
B45: Banco do Brasil (BBAS3) | BBAS Model Official 2Q26_vCSStrategy.xlsx
B46: Line | C46: 2026 | D46: 2027 | E46: 2028 | F46: 2029 | G46: 2030 | H46: 2031 | I46: 2032 | J46: 2033 | K46: 2034 | L46: 2035 | M46: 2036 | N46: 2037 | P46: How it is calculated / source
B47: Net income (R$ mn) | C47: =C48/C49 -> 16916.667 | D47: =D48/D49 -> 23713.333 | E47: =E48/E49 -> 29783.333 | F47: =F48/F49 -> 33300 | G47: =G48/G49 -> 36153.333 | H47: =H48/H49 -> 39662.857 | I47: =I48/I49 -> 42732.5 | J47: =J48/J49 -> 45604.444 | ... N47: =N48/N49 -> 55570.909 | P47: Model: = dividends / payout.
B48: Dividends + IoC (R$ mn) | C48: 4060 | D48: 7114 | E48: 8935 | F48: 9990 | G48: 10846 | H48: 13882 | I48: 17093 | J48: 20522 | K48: 24056 | L48: 27771 | M48: 29140 | N48: 30564 | P48: Model: Valuation r5 Total Return; payout: Model r26.
B49: Payout | C49: 0.24 | D49: 0.3 | E49: 0.3 | F49: 0.3 | G49: 0.3 | H49: 0.35 | I49: 0.4 | J49: 0.45 | K49: 0.5 | L49: 0.55 | M49: 0.55 | N49: 0.55 | P49: Model: Model r26 (input).
...

Sheet Model Parameters
B1: Financials - valuation parameters of the analysts' models
B2: Valuation sheet of each model. Ke = (NTN-B + long-term IPCA) x 0.85 + beta x ERP; g = long-term IPCA + real GDP (Macro sheet).
B3: Legend: | C3: input | D3: assumption | E3: formula
B5: Member | C5: Ke | D5: NTN-B | E5: IPCA LT | F5: Risk free = (NTN-B + IPCA) x 0.85 | G5: ERP | H5: Beta | I5: g | J5: Perpetuity share of value | K5: Last explicit year | L5: Value date | M5: Index points
B6: ITUB4 + ITSA4 | C6: 0.1513 | D6: 0.076 | E6: 0.04 | F6: 0.0986 | G6: 0.055 | H6: 0.958 | I6: 0.06 | J6: 0.4623 | K6: 2037 | L6: End-2027 | M6: 26109.889
B7: BBDC4 + BBDC3 | C7: 0.1619 | D7: 0.076 | E7: 0.04 | F7: 0.0986 | G7: 0.055 | H7: 1.15 | I7: 0.06 | J7: 0.4371 | K7: 2037 | L7: End-2027 | M7: 10039.703
B8: B3SA3 | C8: 0.1583 | D8: 0.0732 | E8: 0.04 | F8: 0.0962 | G8: 0.055 | H8: 1.129 | I8: 0.06 | J8: 0.4358 | K8: 2033 | L8: n/a | M8: 8337.403
B9: BPAC11 | C9: 0.1637 | D9: 0.0741 | E9: 0.04 | F9: 0.097 | G9: 0.055 | H9: 1.213 | I9: 0.06 | J9: 0.5183 | K9: 2036 | L9: End-2026 | M9: 6925.219
B10: BBAS3 | C10: 0.1809 | D10: 0.081 | E10: 0.04 | F10: 0.1029 | G10: 0.06 | H10: 1.3 | I10: 0.06 | J10: 0.4185 | K10: 2037 | L10: End-2027 | M10: 5397.318
B11: CXSE3 | C11: 0.1386 | D11: 0.0751 | E11: 0.04 | F11: 0.0978 | G11: 0.055 | H11: 0.742 | I11: 0.06 | J11: 0.5003 | K11: 2036 | L11: End-2026 | M11: 895.119
B12: SANB11 | C12: 0.149 | D12: 0.0749 | E12: 0.04 | F12: 0.0977 | G12: 0.05 | H12: 1.027 | I12: 0.06 | J12: 0.4541 | K12: 2036 | L12: End-2026 | M12: 735.16
B13: Weighted by index points | C13: =SUMPRODUCT(C6:C12,$M$6:$M$12)/SUM($M$6:$M$12) -> 0.15809943 | D13: =SUMPRODUCT(D6:D12,$M$6:$M$12)/SUM($M$6:$M$12) -> 0.075809542 | F13: =SUMPRODUCT(F6:F12,$M$6:$M$12)/SUM($M$6:$M$12) -> 0.098441557 | G13: =SUMPRODUCT(G6:G12,$M$6:$M$12)/SUM($M$6:$M$12) -> 0.055398885 | H13: =SUMPRODUCT(H6:H12,$M$6:$M$12)/SUM($M$6:$M$12) -> 1.0747443 | I13: =SUMPRODUCT(I6:I12,$M$6:$M$12)/SUM($M$6:$M$12) -> 0.06 | J13: =SUMPRODUCT(J6:J12,$M$6:$M$12)/SUM($M$6:$M$12) -> 0.45725984
B15: Itaúsa takes Itaú's parameters; Bradesco's two share classes are added. Source: Valuation sheet of each file (Ke, NTN-B, risk free, ERP, beta, g, 'Perpetuity' = PV of the terminal value / fair equity value).
