Workbook
Name ConsDate: Assumptions!$C$12
Name ERPBasis: Assumptions!$C$38
Name ErpHistIbov: History!$V$8
Name ErpSdIbov: History!$V$9
Name FYleft: Assumptions!$C$18
Name GicsMap: Assumptions!$B$89:$C$99
Name GlobalList: Assumptions!$B$102:$B$105
Name GrowthYear: Assumptions!$C$44
Name HistG: Assumptions!$C$41
Name HistGn: History!$C$14
Name Horizon: Assumptions!$C$39
Name IbovMem: Assumptions!$C$11
Name IbovNow: Assumptions!$C$7
Name IPCA1: Assumptions!$C$15
Name IPCA2: Assumptions!$C$16
Name IPCALT: Assumptions!$C$17
Name MemDate: Assumptions!$C$10
Name PEmax: Assumptions!$C$48
Name PEmin: Assumptions!$C$47
Name PxDate: Assumptions!$C$6
Name RateConv: Assumptions!$C$37
Name RoeLT: Assumptions!$C$40
Name ROEmax: Assumptions!$C$50
Name ROEmin: Assumptions!$C$49
Name RoeYear: Assumptions!$C$45
Name RR5Now: Assumptions!$C$9
Name SelicNow: Assumptions!$C$8
Name UseEPS: Assumptions!$C$46
Name WinEnd: Assumptions!$C$43
Name WinStart: Assumptions!$C$42

Sheet Cover
C3: Ibovespa | DCF by box
C4: VALUATION MODEL · EQUITY STRATEGY
C7: Main tabs >>
C8: Summary | E8: Assumptions | G8: DCF Base | I8: Implied ERP | K8: Ibovespa close | M8: =IbovNow -> 208431.92
K9: Pricing date | M9: =PxDate -> 46300
K10: Fair value, base case | M10: =Summary!E21 -> 223718.33
C11: Auxiliary tabs >> | K11: Upside, base case | M11: =Summary!J21 -> 0.073340058
C12: DCF Bear | E12: DCF Bull | G12: DCF Custom | I12: Sensitivity (real rate x ERP) | K12: Model checks | M12: =Checks!C5 -> All checks OK
K14: Equity Strategy | XP Research
C15: Boxes Now (consensus by box) | E15: History (ROE, P/E, ERP) | G15: Members (76 stocks) | I15: Checks (tests) | K15: How this model works >>
K16: Prices Oct-5; consensus Oct-7-2026.
C19: DCF summary >>
C20: Ibovespa | F20: Bear | G20: Base | H20: Bull | I20: Custom
C21: 5-year real rate | F21: =Summary!D9 -> 0.085 | G21: =Summary!E9 -> 0.0676 | H21: =Summary!F9 -> 0.06 | I21: =Summary!G9 -> 0.0676
C22: ERP used | F22: =Summary!D10 -> 0.06 | G22: =Summary!E10 -> 0.06 | H22: =Summary!F10 -> 0.06 | I22: =Summary!G10 -> 0.06
C23: Fair value (index pts) | F23: =Summary!D21 -> 169580.37 | G23: =Summary!E21 -> 223718.33 | H23: =Summary!F21 -> 276936.37 | I23: =Summary!G21 -> 223718.33
C24: Upside | F24: =Summary!I21 -> -0.18639922 | G24: =Summary!J21 -> 0.073340058 | H24: =Summary!K21 -> 0.32866581 | I24: =Summary!L21 -> 0.073340058
C25: Implied 12m fwd P/E | F25: =Summary!D32 -> 7.3508359 | G25: =Summary!E32 -> 9.187307 | H25: =Summary!F32 -> 10.728055 | I25: =Summary!G32 -> 9.187307
C26: Implied ERP at today's price | F26: =Summary!D40 -> 0.036072978 | G26: =Summary!E40 -> 0.059938855 | H26: =Summary!F40 -> 0.073981108 | I26: =Summary!G40 -> 0.059938855
C28: DCF = sum of four boxes, each valued by free cash flow to equity (consensus earnings, ROE converging to its 10-year average). House premises: 5y real rate + ERP 6.0%, g 4.7%.

Sheet Summary
B1: Ibovespa - DCF by box: bear / base / bull
B2: Separate from the multiples model. Construction: DCF Bear / Base / Bull / Custom sheets.
B3: Pricing date | C3: =PxDate -> 46300 | D3: Ibovespa | E3: =IbovNow -> 208431.92 | F3: Checks | G3: =Checks!C5 -> All checks OK | H3: Horizon | I3: =IF(Horizon=1,"12 months (fair value in 12m)","today") -> 12 months (fair value in 12m)
B5: Scenario levers in use (Assumptions)
C6: Today | D6: Bear | E6: Base | F6: Bull | G6: Custom
B7: Narrative | D7: =Assumptions!D22 -> Moderate populist | E7: =Assumptions!E22 -> Base | F7: =Assumptions!F22 -> Reformist | G7: =Assumptions!G22 -> User-defined
B8: Selic at the end of the horizon | C8: =SelicNow -> 0.1375 | D8: =Assumptions!D23 -> 0.132 | E8: =Assumptions!E23 -> 0.115 | F8: =Assumptions!F23 -> 0.095 | G8: =Assumptions!G23 -> 0.115
B9: 5-year real rate (NTN-B) | C9: =RR5Now -> 0.0676 | D9: =Assumptions!D25 -> 0.085 | E9: =Assumptions!E25 -> 0.0676 | F9: =Assumptions!F25 -> 0.06 | G9: =Assumptions!G25 -> 0.0676
B10: ERP used, Ibovespa level | D10: =Assumptions!D29 -> 0.06 | E10: =Assumptions!E29 -> 0.06 | F10: =Assumptions!F29 -> 0.06 | G10: =Assumptions!G29 -> 0.06
B11: Cost of equity = real rate + ERP, Ibovespa level | D11: =Assumptions!D30 -> 0.145 | E11: =Assumptions!E30 -> 0.1276 | F11: =Assumptions!F30 -> 0.12 | G11: =Assumptions!G30 -> 0.1276
B12: Earnings growth vs consensus path, years 2-5 (pp/yr) | D12: =Assumptions!D31 -> -2 | E12: =Assumptions!E31 -> 0 | F12: =Assumptions!F31 -> 2 | G12: =Assumptions!G31 -> 0
B13: Long-term nominal growth (g) | D13: =Assumptions!D32 -> 0.042 | E13: =Assumptions!E32 -> 0.047 | F13: =Assumptions!F32 -> 0.052 | G13: =Assumptions!G32 -> 0.047
B14: Settings (Assumptions section 4) | C14: ="ERP basis "&CHOOSE(ERPBasis,"1: typed","2: Ibovespa 10y average","3: each box's 10y average")&" · rate convention "&CHOOSE(RateConv,"1: house","2: Fisher")&" · long-term ROE "&CHOOSE(RoeLT,"1: 10y average","2: consensus") -> ERP basis 1: typed · rate convention 1: house · long-term ROE 2: consensus
B15: DCF fair value by box (index pts, at the horizon in H3) and upside
B16: Group | C16: Index points | D16: Bear | E16: Base | F16: Bull | G16: Custom | I16: Upside: Bear | J16: Base | K16: Bull | L16: Custom
B17: Financials | C17: ='DCF Base'!C49 -> 60927.304 | D17: ='DCF Bear'!C68 -> 52444.51 | E17: ='DCF Base'!C68 -> 70757.467 | F17: ='DCF Bull'!C68 -> 89467 | G17: ='DCF Custom'!C68 -> 70757.467 | I17: ='DCF Bear'!C69 -> -0.13922811 | J17: ='DCF Base'!C69 -> 0.16134251 | K17: ='DCF Bull'!C69 -> 0.46842212 | L17: ='DCF Custom'!C69 -> 0.16134251
B18: Defensives | C18: ='DCF Base'!C78 -> 55822.367 | D18: ='DCF Bear'!C97 -> 32005.698 | E18: ='DCF Base'!C97 -> 42151.986 | F18: ='DCF Bull'!C97 -> 51639.749 | G18: ='DCF Custom'!C97 -> 42151.986 | I18: ='DCF Bear'!C98 -> -0.42665102 | J18: ='DCF Base'!C98 -> -0.24489075 | K18: ='DCF Bull'!C98 -> -0.074927277 | L18: ='DCF Custom'!C98 -> -0.24489075
B19: Cyclicals | C19: ='DCF Base'!C107 -> 26271.075 | D19: ='DCF Bear'!C126 -> 18307.282 | E19: ='DCF Base'!C126 -> 24905.989 | F19: ='DCF Bull'!C126 -> 31645.333 | G19: ='DCF Custom'!C126 -> 24905.989 | I19: ='DCF Bear'!C127 -> -0.30313921 | J19: ='DCF Base'!C127 -> -0.051961535 | K19: ='DCF Bull'!C127 -> 0.20456941 | L19: ='DCF Custom'!C127 -> -0.051961535
B20: Commodities | C20: ='DCF Base'!C136 -> 65411.174 | D20: ='DCF Bear'!C155 -> 66822.884 | E20: ='DCF Base'!C155 -> 85902.887 | F20: ='DCF Bull'!C155 -> 104184.28 | G20: ='DCF Custom'!C155 -> 85902.887 | I20: ='DCF Bear'!C156 -> 0.021582082 | J20: ='DCF Base'!C156 -> 0.3132754 | K20: ='DCF Bull'!C156 -> 0.59275971 | L20: ='DCF Custom'!C156 -> 0.3132754
B21: Ibovespa | C21: ='DCF Base'!C27 -> 208431.92 | D21: ='DCF Bear'!C34 -> 169580.37 | E21: ='DCF Base'!C34 -> 223718.33 | F21: ='DCF Bull'!C34 -> 276936.37 | G21: ='DCF Custom'!C34 -> 223718.33 | I21: ='DCF Bear'!C35 -> -0.18639922 | J21: ='DCF Base'!C35 -> 0.073340058 | K21: ='DCF Bull'!C35 -> 0.32866581 | L21: ='DCF Custom'!C35 -> 0.073340058
B22: Memo
B23: Cyclicals ex-WEG & Embraer | C23: ='DCF Base'!C165 -> 16066.52 | D23: ='DCF Bear'!C184 -> 13017.737 | E23: ='DCF Base'!C184 -> 17779.836 | F23: ='DCF Bull'!C184 -> 22714.745 | G23: ='DCF Custom'!C184 -> 17779.836 | I23: ='DCF Bear'!C185 -> -0.18976001 | J23: ='DCF Base'!C185 -> 0.10663891 | K23: ='DCF Bull'!C185 -> 0.41379373 | L23: ='DCF Custom'!C185 -> 0.10663891
B24: WEG & Embraer | C24: ='DCF Base'!C194 -> 10204.555 | D24: ='DCF Bear'!C213 -> 5365.8281 | E24: ='DCF Base'!C213 -> 7139.5859 | F24: ='DCF Bull'!C213 -> 8819.4219 | G24: ='DCF Custom'!C213 -> 7139.5859 | I24: ='DCF Bear'!C214 -> -0.47417325 | J24: ='DCF Base'!C214 -> -0.30035305 | K24: ='DCF Bull'!C214 -> -0.13573676 | L24: ='DCF Custom'!C214 -> -0.30035305
B26: Implied 12m fwd P/E at the horizon (fair value / next 12m earnings) vs today
B27: Group | C27: Today | D27: Bear | E27: Base | F27: Bull | G27: Custom
B28: Financials | C28: ='DCF Base'!C71 -> 9.9676747 | D28: ='DCF Bear'!C70 -> 7.7051116 | E28: ='DCF Base'!C70 -> 9.7581887 | F28: ='DCF Bull'!C70 -> 11.522169 | G28: ='DCF Custom'!C70 -> 9.7581887
B29: Defensives | C29: ='DCF Base'!C100 -> 14.663346 | D29: ='DCF Bear'!C99 -> 6.9711384 | E29: ='DCF Base'!C99 -> 8.7170961 | F29: ='DCF Bull'!C99 -> 10.094805 | G29: ='DCF Custom'!C99 -> 8.7170961
B30: Cyclicals | C30: ='DCF Base'!C129 -> 12.926128 | D30: ='DCF Bear'!C128 -> 7.5749765 | E30: ='DCF Base'!C128 -> 9.6025738 | F30: ='DCF Bull'!C128 -> 11.304248 | G30: ='DCF Custom'!C128 -> 9.6025738
B31: Commodities | C31: ='DCF Base'!C158 -> 6.7361561 | D31: ='DCF Bear'!C157 -> 7.2201177 | E31: ='DCF Base'!C157 -> 8.8829944 | F31: ='DCF Bull'!C157 -> 10.280107 | G31: ='DCF Custom'!C157 -> 8.8829944
B32: Ibovespa | C32: ='DCF Base'!C38 -> 9.6218817 | D32: ='DCF Bear'!C37 -> 7.3508359 | E32: ='DCF Base'!C37 -> 9.187307 | F32: ='DCF Bull'!C37 -> 10.728055 | G32: ='DCF Custom'!C37 -> 9.187307
B34: Implied ERP at today's prices (cost of equity - 5y real rate that makes the DCF = index points)
B35: Group | C35: ERP used (Base) | D35: Bear | E35: Base | F35: Bull | G35: Custom
B36: Financials | C36: ='DCF Base'!C51 -> 0.06 | D36: ='Implied ERP'!$C$7 -> 0.040959388 | E36: ='Implied ERP'!$D$7 -> 0.066374616 | F36: ='Implied ERP'!$E$7 -> 0.082091167 | G36: ='Implied ERP'!$F$7 -> 0.066374616
B37: Defensives | C37: ='DCF Base'!C80 -> 0.06 | D37: ='Implied ERP'!$C$8 -> 0.015094707 | E37: ='Implied ERP'!$D$8 -> 0.037952038 | F37: ='Implied ERP'!$E$8 -> 0.050920125 | G37: ='Implied ERP'!$F$8 -> 0.037952038
B38: Cyclicals | C38: ='DCF Base'!C109 -> 0.06 | D38: ='Implied ERP'!$C$9 -> 0.026174653 | E38: ='Implied ERP'!$D$9 -> 0.051297126 | F38: ='Implied ERP'!$E$9 -> 0.066691219 | G38: ='Implied ERP'!$F$9 -> 0.051297126
B39: Commodities | C39: ='DCF Base'!C138 -> 0.06 | D39: ='Implied ERP'!$C$10 -> 0.056091266 | E39: ='Implied ERP'!$D$10 -> 0.078554438 | F39: ='Implied ERP'!$E$10 -> 0.09112991 | G39: ='Implied ERP'!$F$10 -> 0.078554438
B40: Ibovespa | C40: =Assumptions!E29 -> 0.06 | D40: ='Implied ERP'!$C$11 -> 0.036072978 | E40: ='Implied ERP'!$D$11 -> 0.059938855 | F40: ='Implied ERP'!$E$11 -> 0.073981108 | G40: ='Implied ERP'!$F$11 -> 0.059938855
B42: Implied ERP history in DCF terms (History; 5y real rate, steady state)
B43: Group | C43: 10y average | D43: Std. dev. | E43: Now | F43: Now vs average (sd)
B44: Financials | C44: =History!R8 -> 0.083556934 | D44: =History!R9 -> 0.013433563 | E44: =History!R11 -> 0.055359543 | F44: =History!R12 -> -2.0990255
...

Sheet Assumptions
B1: Ibovespa - DCF assumptions
B2: The only sheet to edit: change the pink cells (dotted border); the DCF sheets recalculate.
B3: Legend: | C3: input | D3: assumption | E3: formula
B5: 1. Market snapshot
B6: Pricing date (prices and index weights) | C6: 46300 | H6: Close of Oct-5-2026, the same snapshot as the multiples model.
B7: Ibovespa close (index pts) | C7: 208431.92 | H7: Bloomberg IBOV Index PX_LAST.
B8: Selic target today | C8: 0.1375 | H8: BCB (BZSTSETA Index).
B9: 5-year real rate today (NTN-B) | C9: 0.0676 | H9: ANBIMA, Oct-5 (as in the multiples model). The house model uses the 5y (BZRFB5PY Index, Target!B56). For reference, the 10y (IPCA+ 2035/2037) was 6.86%.
B10: Ibovespa membership date | C10: 46295 | H10: Members and weights: Economatica Ibovespa composition, drifted by price to the pricing date.
B11: Ibovespa close on the membership date (index pts) | C11: 186340.46 | H11: Used only in Checks.
B12: Consensus snapshot date (Bloomberg) | C12: 46302 | H12: BEST_PE_RATIO and BEST_ROE, FY26/FY27/FY28; earnings = price on this date / P/E.
B14: 2. Macro
B15: IPCA, forward year 1 | C15: 0.04 | H15: House Ibovespa model (DCF Ibov 2026_Out.xlsx, Target sheet): 2027 4.0%. Used only with the Fisher convention (RateConv = 2).
B16: IPCA, forward year 2 | C16: 0.04 | H16: House model: 2028 4.0%.
B17: IPCA, long term (year 3 onwards, terminal and history) | C17: 0.04 | H17: House model long-term inflation 4.0% (Target!B63).
B18: Share of FY2026 still ahead on the pricing date | C18: =(DATE(2026,12,31)-PxDate)/365 -> 0.23835616 | H18: Forward year 1 = this share of FY26 + the rest of FY27; year 2 = the same split of FY27 and FY28 (12m-forward convention).
B20: 3. Scenario levers
B21: Lever | C21: Today | D21: Bear | E21: Base | F21: Bull | G21: Custom | H21: How it is used
B22: Narrative | D22: Moderate populist | E22: Base | F22: Reformist | G22: User-defined | H22: Labels only.
B23: Selic at the end of the horizon | C23: =SelicNow -> 0.1375 | D23: 0.132 | E23: 0.115 | F23: 0.095 | G23: 0.115 | H23: Same scenarios as the multiples model; drives the rate-driven change in earnings (section 5).
B24: Selic cut vs today (pp; positive = cut) | D24: =(SelicNow-D23)*100 -> 0.55 | E24: =(SelicNow-E23)*100 -> 2.25 | F24: =(SelicNow-F23)*100 -> 4.25 | G24: =(SelicNow-G23)*100 -> 2.25 | H24: Formula: (Selic today - Selic in the scenario) x 100.
B25: 5-year real rate (NTN-B) | C25: =RR5Now -> 0.0676 | D25: 0.085 | E25: =RR5Now -> 0.0676 | F25: 0.06 | G25: =RR5Now -> 0.0676 | H25: As the house model (Target sheet): bear 8.5%, base = today's 5y real rate, bull 6.0%.
B26: ERP, typed (used when the ERP basis = 1) | D26: 0.06 | E26: 0.06 | F26: 0.06 | G26: 0.06 | H26: House ERP 6.0% (Target!B57), the same in every scenario.
B27: ERP shift (pp, added to the ERP of any basis) | D27: 0 | E27: 0 | F27: 0 | G27: 0 | H27: Added to the ERP of the basis in use (typed, Ibovespa or box 10-year average).
B28: ERP move in std. dev. of its history (k; +1 = ERP 1 sd lower) | D28: 0 | E28: 0 | F28: 0 | G28: 0 | H28: Mirrors the multiples model (target multiple = 10y average + k x sd): ERP moves by -k x the sd of the 10-year implied ERP (Ibovespa; each box with basis 3).
B29: ERP used, Ibovespa level | D29: =CHOOSE(ERPBasis,D26,ErpHistIbov,ErpHistIbov)+D27/100-D28*ErpSdIbov -> 0.06 | E29: =CHOOSE(ERPBasis,E26,ErpHistIbov,ErpHistIbov)+E27/100-E28*ErpSdIbov -> 0.06 | F29: =CHOOSE(ERPBasis,F26,ErpHistIbov,ErpHistIbov)+F27/100-F28*ErpSdIbov -> 0.06 | G29: =CHOOSE(ERPBasis,G26,ErpHistIbov,ErpHistIbov)+G27/100-G28*ErpSdIbov -> 0.06 | H29: Basis ERP (typed, or the Ibovespa's 10-year average) + shift - k x sd. With basis 3 each box uses its own average and sd (DCF sheets).
B30: Cost of equity, Ibovespa level = real rate + ERP | D30: =D25+D29 -> 0.145 | E30: =E25+E29 -> 0.1276 | F30: =F25+F29 -> 0.12 | G30: =G25+G29 -> 0.1276 | H30: RateConv 1 (house): the discount rate of the nominal cash flows, as Target!B55. RateConv 2 (Fisher): turned nominal year by year with the IPCA.
B31: Earnings growth vs consensus path, years 2-5 (pp per year) | D31: -2 | E31: 0 | F31: 2 | G31: 0 | H31: Added to the earnings growth of every box in years 2-5 (consensus in year 2, then the path to the long term); bear -2 / bull +2 pp (proposal). The terminal grows at g.
B32: Long-term nominal growth (g) | D32: 0.042 | E32: 0.047 | F32: 0.052 | G32: 0.047 | H32: Base = house perpetuity growth 4.7% (Target!B54), nominal. Bear / bull -/+ 0.5 pp (proposal). Earnings growth reaches it by GrowthYear.
B33: Long-term ROE vs the box's 10-year average (pp) | D33: 0 | E33: 0 | F33: 0 | G33: 0 | H33: Shifts every box's long-term ROE (10-year average of its 12m fwd ROE, History).
B35: 4. Settings
B36: Setting | C36: Value | H36: Notes
B37: Discount-rate convention: 1 = house (real rate + ERP), 2 = Fisher (with IPCA) | C37: 1 | H37: 1: real rate + ERP discounts the nominal cash flows, as the house model (Target!B55 = BZRFB5PY + ERP). 2: (1 + real rate + ERP) x (1 + IPCA) - 1. Same ERP, about 4 pp more discount rate.
B38: ERP basis: 1 = typed, 2 = Ibovespa 10y average, 3 = each box's 10y average | C38: 1 | H38: 1 = the house's 6.0%. 2 and 3: implied ERP measured each month in the same convention (History): Ke = g + (1 - g / ROE) / P/E, minus the 5y real rate.
B39: Valuation horizon: 0 = today, 1 = 12 months (end of forward year 1) | C39: 1 | H39: 1: fair value in 12 months = value today x (1 + year-1 discount rate) - year-1 FCFE (paid out during the year), as a 12-month target price. 0: value today.
B40: Long-term ROE: 1 = box's 10-year average, 2 = consensus year 2 (no mean reversion) | C40: 2 | H40: 1: ROE converges to the box's 10-year average 12m fwd ROE (History). 2: ROE stays at the consensus year-2 level, as the house model keeps consensus profitability.
B41: Long-term nominal growth behind the historical implied ERP | C41: 0.047 | H41: g used to read the ERP out of each month's P/E and ROE (History); house 4.7%.
B42: ROE and ERP history window: first month | C42: 42674 | H42: Averages over the window (any day counts the whole month).
B43: ROE and ERP history window: last month | C43: 46295
B44: Year by which growth reaches the long term | C44: 5 | H44: Growth converges linearly from the consensus year-2 growth (years 3 to GrowthYear). 3-5.
...

Sheet DCF Base
B1: Ibovespa - DCF, Base case
B2: FCFE by box in Ibovespa points. Scenario levers: Assumptions column E. Years 1-5 + terminal; Ibovespa = sum of the four boxes.
B3: Legend: | C3: input | D3: assumption | E3: formula
B5: Scenario parameters (Base; Assumptions column E)
B6: 5-year real rate (NTN-B) | C6: =Assumptions!E25 -> 0.0676
B7: ERP, typed (ERP basis 1) | C7: =Assumptions!E26 -> 0.06
B8: ERP shift (pp) | C8: =Assumptions!E27 -> 0
B9: ERP move in std. dev. of its history (k) | C9: =Assumptions!E28 -> 0
B10: ERP basis (1 typed, 2 Ibovespa 10y average, 3 each box's 10y average) | C10: =ERPBasis -> 1
B11: Earnings growth vs consensus path, years 2-5 (pp per year) | C11: =Assumptions!E31 -> 0
B12: Long-term nominal growth (default) | C12: =Assumptions!E32 -> 0.047
B13: Long-term ROE vs 10y average (pp) | C13: =Assumptions!E33 -> 0
B14: Selic cut vs today (pp) | C14: =Assumptions!E24 -> 2.25
B15: Discount-rate convention (1 house: real rate + ERP; 2 Fisher: with IPCA) | C15: =RateConv -> 1
B17: Timeline (shared by every box)
C18: Today | D18: Year 1 | E18: Year 2 | F18: Year 3 | G18: Year 4 | H18: Year 5 | I18: Terminal | J18: How it is calculated
B19: Year (t) | C19: 0 | D19: 1 | E19: 2 | F19: 3 | G19: 4 | H19: 5
B20: End of the forward year | C20: =PxDate -> 46300 | D20: =EDATE(PxDate,12*D19) -> 46665 | E20: =EDATE(PxDate,12*E19) -> 47031 | F20: =EDATE(PxDate,12*F19) -> 47396 | G20: =EDATE(PxDate,12*G19) -> 47761 | H20: =EDATE(PxDate,12*H19) -> 48126
B21: Inflation (IPCA) | D21: =IPCA1 -> 0.04 | E21: =IPCA2 -> 0.04 | F21: =IPCALT -> 0.04 | G21: =IPCALT -> 0.04 | H21: =IPCALT -> 0.04 | I21: =IPCALT -> 0.04
B22: Price index (today = 1) | C22: 1 | D22: =C22*(1+D21) -> 1.04 | E22: =D22*(1+E21) -> 1.0816 | F22: =E22*(1+F21) -> 1.124864 | G22: =F22*(1+G21) -> 1.1698586 | H22: =G22*(1+H21) -> 1.2166529 | J22: Cash flows are nominal (consensus). House convention: discounted at real rate + ERP. Fisher: at (1 + real rate + ERP) x (1 + IPCA) - 1.
B23: Deflator for discounting (1 under the house convention) | C23: 1 | D23: =IF(RateConv=1,1,D22) -> 1 | E23: =IF(RateConv=1,1,E22) -> 1 | F23: =IF(RateConv=1,1,F22) -> 1 | G23: =IF(RateConv=1,1,G22) -> 1 | H23: =IF(RateConv=1,1,H22) -> 1 | J23: Used by the closed-form checks: FCFE / deflator discounted at (1 + real rate + ERP) gives the same value under either convention.
B25: Ibovespa = sum of the four boxes (Base)
C26: Today | D26: Year 1 | E26: Year 2 | F26: Year 3 | G26: Year 4 | H26: Year 5 | I26: Terminal | J26: How it is calculated
B27: Index points | C27: =C49+C78+C107+C136 -> 208431.92
B28: Earnings (index pts) | D28: =D58+D87+D116+D145 -> 22676.853 | E28: =E58+E87+E116+E145 -> 24350.806 | F28: =F58+F87+F116+F145 -> 26086.104 | G28: =G58+G87+G116+G145 -> 27684.137 | H28: =H58+H87+H116+H145 -> 28985.291
B29: Book value at the start of the year | D29: =D60+D89+D118+D147 -> 126386.42 | E29: =E60+E89+E118+E147 -> 137942.6 | F29: =F60+F89+F118+F147 -> 148132.24 | G29: =G60+G89+G118+G147 -> 157415.3 | H29: =H60+H89+H118+H147 -> 164813.82 | I29: =I60+I89+I118+I147 -> 172560.07
B30: Free cash flow to equity (FCFE) | D30: =D62+D91+D120+D149 -> 11120.667 | E30: =E62+E91+E120+E149 -> 14161.17 | F30: =F62+F91+F120+F149 -> 16803.038 | G30: =G62+G91+G120+G149 -> 20285.618 | H30: =H62+H91+H120+H149 -> 21239.042
B31: Present value of FCFE | C31: =C64+C93+C122+C151 -> 56918.357 | D31: =D64+D93+D122+D151 -> 9862.245 | E31: =E64+E93+E122+E151 -> 11137.533 | F31: =F64+F93+F122+F151 -> 11719.865 | G31: =G64+G93+G122+G151 -> 12547.811 | H31: =H64+H93+H122+H151 -> 11650.903
B32: Present value of the terminal value | C32: =C66+C95+C124+C153 -> 151346.1
B33: Equity value today (index pts) | C33: =C67+C96+C125+C154 -> 208264.45
B34: Fair value at the horizon (index pts) | C34: =C68+C97+C126+C155 -> 223718.33
B35: Upside (fair value / index points today - 1) | C35: =C34/C27-1 -> 0.073340058
B36: ROE (sum of earnings / sum of book value) | D36: =D28/D29 -> 0.17942476 | E36: =E28/E29 -> 0.17652854 | F36: =F28/F29 -> 0.17610011 | G36: =G28/G29 -> 0.17586687 | H36: =H28/H29 -> 0.17586687
B37: Implied 12m fwd P/E at the horizon (fair value / next 12m earnings) | C37: =C34/IF(Horizon=1,E28,D28) -> 9.187307
B38: 12m fwd P/E today (consensus year-1 earnings) | C38: ='Boxes Now'!Y10 -> 9.6218817
B39: Terminal value / equity value | C39: =C32/C33 -> 0.72670153
B40: Contribution to the Ibovespa upside (pp)
B41: Financials | C41: =(C68-C49)/C27*100 -> 4.7162468
B42: Defensives | C42: =(C97-C78)/C27*100 -> -6.5586793
B43: Cyclicals | C43: =(C126-C107)/C27*100 -> -0.65493106
...

Sheet DCF Bear
B1: Ibovespa - DCF, Bear case
B2: FCFE by box in Ibovespa points. Scenario levers: Assumptions column D. Years 1-5 + terminal; Ibovespa = sum of the four boxes.
B3: Legend: | C3: input | D3: assumption | E3: formula
B5: Scenario parameters (Bear; Assumptions column D)
B6: 5-year real rate (NTN-B) | C6: =Assumptions!D25 -> 0.085
B7: ERP, typed (ERP basis 1) | C7: =Assumptions!D26 -> 0.06
B8: ERP shift (pp) | C8: =Assumptions!D27 -> 0
B9: ERP move in std. dev. of its history (k) | C9: =Assumptions!D28 -> 0
B10: ERP basis (1 typed, 2 Ibovespa 10y average, 3 each box's 10y average) | C10: =ERPBasis -> 1
B11: Earnings growth vs consensus path, years 2-5 (pp per year) | C11: =Assumptions!D31 -> -2
B12: Long-term nominal growth (default) | C12: =Assumptions!D32 -> 0.042
B13: Long-term ROE vs 10y average (pp) | C13: =Assumptions!D33 -> 0
B14: Selic cut vs today (pp) | C14: =Assumptions!D24 -> 0.55
B15: Discount-rate convention (1 house: real rate + ERP; 2 Fisher: with IPCA) | C15: =RateConv -> 1
B17: Timeline (shared by every box)
C18: Today | D18: Year 1 | E18: Year 2 | F18: Year 3 | G18: Year 4 | H18: Year 5 | I18: Terminal | J18: How it is calculated
B19: Year (t) | C19: 0 | D19: 1 | E19: 2 | F19: 3 | G19: 4 | H19: 5
B20: End of the forward year | C20: =PxDate -> 46300 | D20: =EDATE(PxDate,12*D19) -> 46665 | E20: =EDATE(PxDate,12*E19) -> 47031 | F20: =EDATE(PxDate,12*F19) -> 47396 | G20: =EDATE(PxDate,12*G19) -> 47761 | H20: =EDATE(PxDate,12*H19) -> 48126
B21: Inflation (IPCA) | D21: =IPCA1 -> 0.04 | E21: =IPCA2 -> 0.04 | F21: =IPCALT -> 0.04 | G21: =IPCALT -> 0.04 | H21: =IPCALT -> 0.04 | I21: =IPCALT -> 0.04
B22: Price index (today = 1) | C22: 1 | D22: =C22*(1+D21) -> 1.04 | E22: =D22*(1+E21) -> 1.0816 | F22: =E22*(1+F21) -> 1.124864 | G22: =F22*(1+G21) -> 1.1698586 | H22: =G22*(1+H21) -> 1.2166529 | J22: Cash flows are nominal (consensus). House convention: discounted at real rate + ERP. Fisher: at (1 + real rate + ERP) x (1 + IPCA) - 1.
B23: Deflator for discounting (1 under the house convention) | C23: 1 | D23: =IF(RateConv=1,1,D22) -> 1 | E23: =IF(RateConv=1,1,E22) -> 1 | F23: =IF(RateConv=1,1,F22) -> 1 | G23: =IF(RateConv=1,1,G22) -> 1 | H23: =IF(RateConv=1,1,H22) -> 1 | J23: Used by the closed-form checks: FCFE / deflator discounted at (1 + real rate + ERP) gives the same value under either convention.
B25: Ibovespa = sum of the four boxes (Bear)
C26: Today | D26: Year 1 | E26: Year 2 | F26: Year 3 | G26: Year 4 | H26: Year 5 | I26: Terminal | J26: How it is calculated
B27: Index points | C27: =C49+C78+C107+C136 -> 208431.92
B28: Earnings (index pts) | D28: =D58+D87+D116+D145 -> 21910.289 | E28: =E58+E87+E116+E145 -> 23069.536 | F28: =F58+F87+F116+F145 -> 24203.009 | G28: =G58+G87+G116+G145 -> 25116.639 | H28: =H58+H87+H116+H145 -> 25669.205
B29: Book value at the start of the year | D29: =D60+D89+D118+D147 -> 122032.81 | E29: =E60+E89+E118+E147 -> 130736.79 | F29: =F60+F89+F118+F147 -> 137503.25 | G29: =G60+G89+G118+G147 -> 142888.88 | H29: =H60+H89+H118+H147 -> 146032.43 | I29: =I60+I89+I118+I147 -> 152165.79
B30: Free cash flow to equity (FCFE) | D30: =D62+D91+D120+D149 -> 13206.306 | E30: =E62+E91+E120+E149 -> 16303.08 | F30: =F62+F91+F120+F149 -> 18817.379 | G30: =G62+G91+G120+G149 -> 21973.084 | H30: =H62+H91+H120+H149 -> 19535.843
B31: Present value of FCFE | C31: =C64+C93+C122+C151 -> 59215.553 | D31: =D64+D93+D122+D151 -> 11533.891 | E31: =E64+E93+E122+E151 -> 12435.369 | F31: =F64+F93+F122+F151 -> 12535.529 | G31: =G64+G93+G122+G151 -> 12784.068 | H31: =H64+H93+H122+H151 -> 9926.6959
B32: Present value of the terminal value | C32: =C66+C95+C124+C153 -> 100423.47
B33: Equity value today (index pts) | C33: =C67+C96+C125+C154 -> 159639.02
B34: Fair value at the horizon (index pts) | C34: =C68+C97+C126+C155 -> 169580.37
B35: Upside (fair value / index points today - 1) | C35: =C34/C27-1 -> -0.18639922
B36: ROE (sum of earnings / sum of book value) | D36: =D28/D29 -> 0.17954425 | E36: =E28/E29 -> 0.17645787 | F36: =F28/F29 -> 0.17601773 | G36: =G28/G29 -> 0.17577743 | H36: =H28/H29 -> 0.17577743
B37: Implied 12m fwd P/E at the horizon (fair value / next 12m earnings) | C37: =C34/IF(Horizon=1,E28,D28) -> 7.3508359
B38: 12m fwd P/E today (consensus year-1 earnings) | C38: ='Boxes Now'!Y10 -> 9.6218817
B39: Terminal value / equity value | C39: =C32/C33 -> 0.62906592
B40: Contribution to the Ibovespa upside (pp)
B41: Financials | C41: =(C68-C49)/C27*100 -> -4.0698148
B42: Defensives | C42: =(C97-C78)/C27*100 -> -11.426594
B43: Cyclicals | C43: =(C126-C107)/C27*100 -> -3.8208125
...

Sheet DCF Bull
B1: Ibovespa - DCF, Bull case
B2: FCFE by box in Ibovespa points. Scenario levers: Assumptions column F. Years 1-5 + terminal; Ibovespa = sum of the four boxes.
B3: Legend: | C3: input | D3: assumption | E3: formula
B5: Scenario parameters (Bull; Assumptions column F)
B6: 5-year real rate (NTN-B) | C6: =Assumptions!F25 -> 0.06
B7: ERP, typed (ERP basis 1) | C7: =Assumptions!F26 -> 0.06
B8: ERP shift (pp) | C8: =Assumptions!F27 -> 0
B9: ERP move in std. dev. of its history (k) | C9: =Assumptions!F28 -> 0
B10: ERP basis (1 typed, 2 Ibovespa 10y average, 3 each box's 10y average) | C10: =ERPBasis -> 1
B11: Earnings growth vs consensus path, years 2-5 (pp per year) | C11: =Assumptions!F31 -> 2
B12: Long-term nominal growth (default) | C12: =Assumptions!F32 -> 0.052
B13: Long-term ROE vs 10y average (pp) | C13: =Assumptions!F33 -> 0
B14: Selic cut vs today (pp) | C14: =Assumptions!F24 -> 4.25
B15: Discount-rate convention (1 house: real rate + ERP; 2 Fisher: with IPCA) | C15: =RateConv -> 1
B17: Timeline (shared by every box)
C18: Today | D18: Year 1 | E18: Year 2 | F18: Year 3 | G18: Year 4 | H18: Year 5 | I18: Terminal | J18: How it is calculated
B19: Year (t) | C19: 0 | D19: 1 | E19: 2 | F19: 3 | G19: 4 | H19: 5
B20: End of the forward year | C20: =PxDate -> 46300 | D20: =EDATE(PxDate,12*D19) -> 46665 | E20: =EDATE(PxDate,12*E19) -> 47031 | F20: =EDATE(PxDate,12*F19) -> 47396 | G20: =EDATE(PxDate,12*G19) -> 47761 | H20: =EDATE(PxDate,12*H19) -> 48126
B21: Inflation (IPCA) | D21: =IPCA1 -> 0.04 | E21: =IPCA2 -> 0.04 | F21: =IPCALT -> 0.04 | G21: =IPCALT -> 0.04 | H21: =IPCALT -> 0.04 | I21: =IPCALT -> 0.04
B22: Price index (today = 1) | C22: 1 | D22: =C22*(1+D21) -> 1.04 | E22: =D22*(1+E21) -> 1.0816 | F22: =E22*(1+F21) -> 1.124864 | G22: =F22*(1+G21) -> 1.1698586 | H22: =G22*(1+H21) -> 1.2166529 | J22: Cash flows are nominal (consensus). House convention: discounted at real rate + ERP. Fisher: at (1 + real rate + ERP) x (1 + IPCA) - 1.
B23: Deflator for discounting (1 under the house convention) | C23: 1 | D23: =IF(RateConv=1,1,D22) -> 1 | E23: =IF(RateConv=1,1,E22) -> 1 | F23: =IF(RateConv=1,1,F22) -> 1 | G23: =IF(RateConv=1,1,G22) -> 1 | H23: =IF(RateConv=1,1,H22) -> 1 | J23: Used by the closed-form checks: FCFE / deflator discounted at (1 + real rate + ERP) gives the same value under either convention.
B25: Ibovespa = sum of the four boxes (Bull)
C26: Today | D26: Year 1 | E26: Year 2 | F26: Year 3 | G26: Year 4 | H26: Year 5 | I26: Terminal | J26: How it is calculated
B27: Index points | C27: =C49+C78+C107+C136 -> 208431.92
B28: Earnings (index pts) | D28: =D58+D87+D116+D145 -> 23578.693 | E28: =E58+E87+E116+E145 -> 25814.22 | F28: =F58+F87+F116+F145 -> 28226.581 | G28: =G58+G87+G116+G145 -> 30620.243 | H28: =H58+H87+H116+H145 -> 32824.901
B29: Book value at the start of the year | D29: =D60+D89+D118+D147 -> 131508.31 | E29: =E60+E89+E118+E147 -> 146169.89 | F29: =F60+F89+F118+F147 -> 160207.98 | G29: =G60+G89+G118+G147 -> 174017.57 | H29: =H60+H89+H118+H147 -> 186546.83 | I29: =I60+I89+I118+I147 -> 196247.27
B30: Free cash flow to equity (FCFE) | D30: =D62+D91+D120+D149 -> 8917.1089 | E30: =E62+E91+E120+E149 -> 11776.13 | F30: =F62+F91+F120+F149 -> 14416.994 | G30: =G62+G91+G120+G149 -> 18090.978 | H30: =H62+H91+H120+H149 -> 23124.465
B31: Present value of FCFE | C31: =C64+C93+C122+C151 -> 52229.881 | D31: =D64+D93+D122+D151 -> 7961.7043 | E31: =E64+E93+E122+E151 -> 9387.8589 | F31: =F64+F93+F122+F151 -> 10261.732 | G31: =G64+G93+G122+G151 -> 11497.144 | H31: =H64+H93+H122+H151 -> 13121.443
B32: Present value of the terminal value | C32: =C66+C95+C124+C153 -> 202996.44
B33: Equity value today (index pts) | C33: =C67+C96+C125+C154 -> 255226.32
B34: Fair value at the horizon (index pts) | C34: =C68+C97+C126+C155 -> 276936.37
B35: Upside (fair value / index points today - 1) | C35: =C34/C27-1 -> 0.32866581
B36: ROE (sum of earnings / sum of book value) | D36: =D28/D29 -> 0.17929432 | E36: =E28/E29 -> 0.17660422 | F36: =F28/F29 -> 0.17618711 | G36: =G28/G29 -> 0.17596064 | H36: =H28/H29 -> 0.17596064
B37: Implied 12m fwd P/E at the horizon (fair value / next 12m earnings) | C37: =C34/IF(Horizon=1,E28,D28) -> 10.728055
B38: 12m fwd P/E today (consensus year-1 earnings) | C38: ='Boxes Now'!Y10 -> 9.6218817
B39: Terminal value / equity value | C39: =C32/C33 -> 0.79535856
B40: Contribution to the Ibovespa upside (pp)
B41: Financials | C41: =(C68-C49)/C27*100 -> 13.692575
B42: Defensives | C42: =(C97-C78)/C27*100 -> -2.006707
B43: Cyclicals | C43: =(C126-C107)/C27*100 -> 2.5784239
...

Sheet DCF Custom
B1: Ibovespa - DCF, Custom case
B2: FCFE by box in Ibovespa points. Scenario levers: Assumptions column G. Years 1-5 + terminal; Ibovespa = sum of the four boxes.
B3: Legend: | C3: input | D3: assumption | E3: formula
B5: Scenario parameters (Custom; Assumptions column G)
B6: 5-year real rate (NTN-B) | C6: =Assumptions!G25 -> 0.0676
B7: ERP, typed (ERP basis 1) | C7: =Assumptions!G26 -> 0.06
B8: ERP shift (pp) | C8: =Assumptions!G27 -> 0
B9: ERP move in std. dev. of its history (k) | C9: =Assumptions!G28 -> 0
B10: ERP basis (1 typed, 2 Ibovespa 10y average, 3 each box's 10y average) | C10: =ERPBasis -> 1
B11: Earnings growth vs consensus path, years 2-5 (pp per year) | C11: =Assumptions!G31 -> 0
B12: Long-term nominal growth (default) | C12: =Assumptions!G32 -> 0.047
B13: Long-term ROE vs 10y average (pp) | C13: =Assumptions!G33 -> 0
B14: Selic cut vs today (pp) | C14: =Assumptions!G24 -> 2.25
B15: Discount-rate convention (1 house: real rate + ERP; 2 Fisher: with IPCA) | C15: =RateConv -> 1
B17: Timeline (shared by every box)
C18: Today | D18: Year 1 | E18: Year 2 | F18: Year 3 | G18: Year 4 | H18: Year 5 | I18: Terminal | J18: How it is calculated
B19: Year (t) | C19: 0 | D19: 1 | E19: 2 | F19: 3 | G19: 4 | H19: 5
B20: End of the forward year | C20: =PxDate -> 46300 | D20: =EDATE(PxDate,12*D19) -> 46665 | E20: =EDATE(PxDate,12*E19) -> 47031 | F20: =EDATE(PxDate,12*F19) -> 47396 | G20: =EDATE(PxDate,12*G19) -> 47761 | H20: =EDATE(PxDate,12*H19) -> 48126
B21: Inflation (IPCA) | D21: =IPCA1 -> 0.04 | E21: =IPCA2 -> 0.04 | F21: =IPCALT -> 0.04 | G21: =IPCALT -> 0.04 | H21: =IPCALT -> 0.04 | I21: =IPCALT -> 0.04
B22: Price index (today = 1) | C22: 1 | D22: =C22*(1+D21) -> 1.04 | E22: =D22*(1+E21) -> 1.0816 | F22: =E22*(1+F21) -> 1.124864 | G22: =F22*(1+G21) -> 1.1698586 | H22: =G22*(1+H21) -> 1.2166529 | J22: Cash flows are nominal (consensus). House convention: discounted at real rate + ERP. Fisher: at (1 + real rate + ERP) x (1 + IPCA) - 1.
B23: Deflator for discounting (1 under the house convention) | C23: 1 | D23: =IF(RateConv=1,1,D22) -> 1 | E23: =IF(RateConv=1,1,E22) -> 1 | F23: =IF(RateConv=1,1,F22) -> 1 | G23: =IF(RateConv=1,1,G22) -> 1 | H23: =IF(RateConv=1,1,H22) -> 1 | J23: Used by the closed-form checks: FCFE / deflator discounted at (1 + real rate + ERP) gives the same value under either convention.
B25: Ibovespa = sum of the four boxes (Custom)
C26: Today | D26: Year 1 | E26: Year 2 | F26: Year 3 | G26: Year 4 | H26: Year 5 | I26: Terminal | J26: How it is calculated
B27: Index points | C27: =C49+C78+C107+C136 -> 208431.92
B28: Earnings (index pts) | D28: =D58+D87+D116+D145 -> 22676.853 | E28: =E58+E87+E116+E145 -> 24350.806 | F28: =F58+F87+F116+F145 -> 26086.104 | G28: =G58+G87+G116+G145 -> 27684.137 | H28: =H58+H87+H116+H145 -> 28985.291
B29: Book value at the start of the year | D29: =D60+D89+D118+D147 -> 126386.42 | E29: =E60+E89+E118+E147 -> 137942.6 | F29: =F60+F89+F118+F147 -> 148132.24 | G29: =G60+G89+G118+G147 -> 157415.3 | H29: =H60+H89+H118+H147 -> 164813.82 | I29: =I60+I89+I118+I147 -> 172560.07
B30: Free cash flow to equity (FCFE) | D30: =D62+D91+D120+D149 -> 11120.667 | E30: =E62+E91+E120+E149 -> 14161.17 | F30: =F62+F91+F120+F149 -> 16803.038 | G30: =G62+G91+G120+G149 -> 20285.618 | H30: =H62+H91+H120+H149 -> 21239.042
B31: Present value of FCFE | C31: =C64+C93+C122+C151 -> 56918.357 | D31: =D64+D93+D122+D151 -> 9862.245 | E31: =E64+E93+E122+E151 -> 11137.533 | F31: =F64+F93+F122+F151 -> 11719.865 | G31: =G64+G93+G122+G151 -> 12547.811 | H31: =H64+H93+H122+H151 -> 11650.903
B32: Present value of the terminal value | C32: =C66+C95+C124+C153 -> 151346.1
B33: Equity value today (index pts) | C33: =C67+C96+C125+C154 -> 208264.45
B34: Fair value at the horizon (index pts) | C34: =C68+C97+C126+C155 -> 223718.33
B35: Upside (fair value / index points today - 1) | C35: =C34/C27-1 -> 0.073340058
B36: ROE (sum of earnings / sum of book value) | D36: =D28/D29 -> 0.17942476 | E36: =E28/E29 -> 0.17652854 | F36: =F28/F29 -> 0.17610011 | G36: =G28/G29 -> 0.17586687 | H36: =H28/H29 -> 0.17586687
B37: Implied 12m fwd P/E at the horizon (fair value / next 12m earnings) | C37: =C34/IF(Horizon=1,E28,D28) -> 9.187307
B38: 12m fwd P/E today (consensus year-1 earnings) | C38: ='Boxes Now'!Y10 -> 9.6218817
B39: Terminal value / equity value | C39: =C32/C33 -> 0.72670153
B40: Contribution to the Ibovespa upside (pp)
B41: Financials | C41: =(C68-C49)/C27*100 -> 4.7162468
B42: Defensives | C42: =(C97-C78)/C27*100 -> -6.5586793
B43: Cyclicals | C43: =(C126-C107)/C27*100 -> -0.65493106
...

Sheet Implied ERP
B1: Ibovespa - Implied ERP: the risk premium that makes the DCF equal today's price
B2: Each column re-discounts the scenario's cash flows at real rate + ERP (convention in use) for ERP = 0.0% to 15.0%; the implied ERP is interpolated where the value crosses the index points.
B3: Legend: | C3: input | D3: assumption | E3: formula
B5: Implied ERP at today's prices, by box and scenario (each scenario's real rate and cash flows)
B6: Group | C6: Bear | D6: Base | E6: Bull | F6: Custom | G6: 10y average (History)
B7: Financials | C7: =IFERROR(IF(C$18>C$21,"< 0%",INDEX($B$21:$B$171,MATCH(C$18,C$21:C$171,-1))+(INDEX(C$21:C$171,MATCH(C$18,C$21:C$171,-1))-C$18)/(INDEX(C$21:C$171,MATCH(C$18,C$21:C$171,-1))-INDEX(C$21:C$171,MATCH(C$18,C$21:C$171,-1)+1))*0.001),"> 15%") -> 0.040959388 | D7: =IFERROR(IF(H$18>H$21,"< 0%",INDEX($B$21:$B$171,MATCH(H$18,H$21:H$171,-1))+(INDEX(H$21:H$171,MATCH(H$18,H$21:H$171,-1))-H$18)/(INDEX(H$21:H$171,MATCH(H$18,H$21:H$171,-1))-INDEX(H$21:H$171,MATCH(H$18,H$21:H$171,-1)+1))*0.001),"> 15%") -> 0.066374616 | E7: =IFERROR(IF(M$18>M$21,"< 0%",INDEX($B$21:$B$171,MATCH(M$18,M$21:M$171,-1))+(INDEX(M$21:M$171,MATCH(M$18,M$21:M$171,-1))-M$18)/(INDEX(M$21:M$171,MATCH(M$18,M$21:M$171,-1))-INDEX(M$21:M$171,MATCH(M$18,M$21:M$171,-1)+1))*0.001),"> 15%") -> 0.082091167 | F7: =IFERROR(IF(R$18>R$21,"< 0%",INDEX($B$21:$B$171,MATCH(R$18,R$21:R$171,-1))+(INDEX(R$21:R$171,MATCH(R$18,R$21:R$171,-1))-R$18)/(INDEX(R$21:R$171,MATCH(R$18,R$21:R$171,-1))-INDEX(R$21:R$171,MATCH(R$18,R$21:R$171,-1)+1))*0.001),"> 15%") -> 0.066374616 | G7: =History!R8 -> 0.083556934
B8: Defensives | C8: =IFERROR(IF(D$18>D$21,"< 0%",INDEX($B$21:$B$171,MATCH(D$18,D$21:D$171,-1))+(INDEX(D$21:D$171,MATCH(D$18,D$21:D$171,-1))-D$18)/(INDEX(D$21:D$171,MATCH(D$18,D$21:D$171,-1))-INDEX(D$21:D$171,MATCH(D$18,D$21:D$171,-1)+1))*0.001),"> 15%") -> 0.015094707 | D8: =IFERROR(IF(I$18>I$21,"< 0%",INDEX($B$21:$B$171,MATCH(I$18,I$21:I$171,-1))+(INDEX(I$21:I$171,MATCH(I$18,I$21:I$171,-1))-I$18)/(INDEX(I$21:I$171,MATCH(I$18,I$21:I$171,-1))-INDEX(I$21:I$171,MATCH(I$18,I$21:I$171,-1)+1))*0.001),"> 15%") -> 0.037952038 | E8: =IFERROR(IF(N$18>N$21,"< 0%",INDEX($B$21:$B$171,MATCH(N$18,N$21:N$171,-1))+(INDEX(N$21:N$171,MATCH(N$18,N$21:N$171,-1))-N$18)/(INDEX(N$21:N$171,MATCH(N$18,N$21:N$171,-1))-INDEX(N$21:N$171,MATCH(N$18,N$21:N$171,-1)+1))*0.001),"> 15%") -> 0.050920125 | F8: =IFERROR(IF(S$18>S$21,"< 0%",INDEX($B$21:$B$171,MATCH(S$18,S$21:S$171,-1))+(INDEX(S$21:S$171,MATCH(S$18,S$21:S$171,-1))-S$18)/(INDEX(S$21:S$171,MATCH(S$18,S$21:S$171,-1))-INDEX(S$21:S$171,MATCH(S$18,S$21:S$171,-1)+1))*0.001),"> 15%") -> 0.037952038 | G8: =History!S8 -> 0.040024755
B9: Cyclicals | C9: =IFERROR(IF(E$18>E$21,"< 0%",INDEX($B$21:$B$171,MATCH(E$18,E$21:E$171,-1))+(INDEX(E$21:E$171,MATCH(E$18,E$21:E$171,-1))-E$18)/(INDEX(E$21:E$171,MATCH(E$18,E$21:E$171,-1))-INDEX(E$21:E$171,MATCH(E$18,E$21:E$171,-1)+1))*0.001),"> 15%") -> 0.026174653 | D9: =IFERROR(IF(J$18>J$21,"< 0%",INDEX($B$21:$B$171,MATCH(J$18,J$21:J$171,-1))+(INDEX(J$21:J$171,MATCH(J$18,J$21:J$171,-1))-J$18)/(INDEX(J$21:J$171,MATCH(J$18,J$21:J$171,-1))-INDEX(J$21:J$171,MATCH(J$18,J$21:J$171,-1)+1))*0.001),"> 15%") -> 0.051297126 | E9: =IFERROR(IF(O$18>O$21,"< 0%",INDEX($B$21:$B$171,MATCH(O$18,O$21:O$171,-1))+(INDEX(O$21:O$171,MATCH(O$18,O$21:O$171,-1))-O$18)/(INDEX(O$21:O$171,MATCH(O$18,O$21:O$171,-1))-INDEX(O$21:O$171,MATCH(O$18,O$21:O$171,-1)+1))*0.001),"> 15%") -> 0.066691219 | F9: =IFERROR(IF(T$18>T$21,"< 0%",INDEX($B$21:$B$171,MATCH(T$18,T$21:T$171,-1))+(INDEX(T$21:T$171,MATCH(T$18,T$21:T$171,-1))-T$18)/(INDEX(T$21:T$171,MATCH(T$18,T$21:T$171,-1))-INDEX(T$21:T$171,MATCH(T$18,T$21:T$171,-1)+1))*0.001),"> 15%") -> 0.051297126 | G9: =History!T8 -> 0.031540174
B10: Commodities | C10: =IFERROR(IF(F$18>F$21,"< 0%",INDEX($B$21:$B$171,MATCH(F$18,F$21:F$171,-1))+(INDEX(F$21:F$171,MATCH(F$18,F$21:F$171,-1))-F$18)/(INDEX(F$21:F$171,MATCH(F$18,F$21:F$171,-1))-INDEX(F$21:F$171,MATCH(F$18,F$21:F$171,-1)+1))*0.001),"> 15%") -> 0.056091266 | D10: =IFERROR(IF(K$18>K$21,"< 0%",INDEX($B$21:$B$171,MATCH(K$18,K$21:K$171,-1))+(INDEX(K$21:K$171,MATCH(K$18,K$21:K$171,-1))-K$18)/(INDEX(K$21:K$171,MATCH(K$18,K$21:K$171,-1))-INDEX(K$21:K$171,MATCH(K$18,K$21:K$171,-1)+1))*0.001),"> 15%") -> 0.078554438 | E10: =IFERROR(IF(P$18>P$21,"< 0%",INDEX($B$21:$B$171,MATCH(P$18,P$21:P$171,-1))+(INDEX(P$21:P$171,MATCH(P$18,P$21:P$171,-1))-P$18)/(INDEX(P$21:P$171,MATCH(P$18,P$21:P$171,-1))-INDEX(P$21:P$171,MATCH(P$18,P$21:P$171,-1)+1))*0.001),"> 15%") -> 0.09112991 | F10: =IFERROR(IF(U$18>U$21,"< 0%",INDEX($B$21:$B$171,MATCH(U$18,U$21:U$171,-1))+(INDEX(U$21:U$171,MATCH(U$18,U$21:U$171,-1))-U$18)/(INDEX(U$21:U$171,MATCH(U$18,U$21:U$171,-1))-INDEX(U$21:U$171,MATCH(U$18,U$21:U$171,-1)+1))*0.001),"> 15%") -> 0.078554438 | G10: =History!U8 -> 0.10567744
B11: Ibovespa | C11: =IFERROR(IF(G$18>G$21,"< 0%",INDEX($B$21:$B$171,MATCH(G$18,G$21:G$171,-1))+(INDEX(G$21:G$171,MATCH(G$18,G$21:G$171,-1))-G$18)/(INDEX(G$21:G$171,MATCH(G$18,G$21:G$171,-1))-INDEX(G$21:G$171,MATCH(G$18,G$21:G$171,-1)+1))*0.001),"> 15%") -> 0.036072978 | D11: =IFERROR(IF(L$18>L$21,"< 0%",INDEX($B$21:$B$171,MATCH(L$18,L$21:L$171,-1))+(INDEX(L$21:L$171,MATCH(L$18,L$21:L$171,-1))-L$18)/(INDEX(L$21:L$171,MATCH(L$18,L$21:L$171,-1))-INDEX(L$21:L$171,MATCH(L$18,L$21:L$171,-1)+1))*0.001),"> 15%") -> 0.059938855 | E11: =IFERROR(IF(Q$18>Q$21,"< 0%",INDEX($B$21:$B$171,MATCH(Q$18,Q$21:Q$171,-1))+(INDEX(Q$21:Q$171,MATCH(Q$18,Q$21:Q$171,-1))-Q$18)/(INDEX(Q$21:Q$171,MATCH(Q$18,Q$21:Q$171,-1))-INDEX(Q$21:Q$171,MATCH(Q$18,Q$21:Q$171,-1)+1))*0.001),"> 15%") -> 0.073981108 | F11: =IFERROR(IF(V$18>V$21,"< 0%",INDEX($B$21:$B$171,MATCH(V$18,V$21:V$171,-1))+(INDEX(V$21:V$171,MATCH(V$18,V$21:V$171,-1))-V$18)/(INDEX(V$21:V$171,MATCH(V$18,V$21:V$171,-1))-INDEX(V$21:V$171,MATCH(V$18,V$21:V$171,-1)+1))*0.001),"> 15%") -> 0.059938855 | G11: =History!V8 -> 0.074470831
B13: ERP = cost of equity - 5y real rate, read with each scenario's cash flows and the discount-rate convention in use (RateConv). The History column uses steady-state cash flows.
B15: Grid: equity value (index pts) at each ERP
C16: Bear (real rate: DCF Bear!C6) | H16: Base (real rate: DCF Base!C6) | M16: Bull (real rate: DCF Bull!C6) | R16: Custom (real rate: DCF Custom!C6)
B17: ERP | C17: Financials | D17: Defensives | E17: Cyclicals | F17: Commodities | G17: Ibovespa | H17: Financials | I17: Defensives | J17: Cyclicals | K17: Commodities | L17: Ibovespa | M17: Financials | N17: Defensives | O17: Cyclicals | P17: Commodities | Q17: Ibovespa | R17: Financials | S17: Defensives | T17: Cyclicals | U17: Commodities | V17: Ibovespa
B18: Index points today | C18: ='DCF Bear'!$C$49 -> 60927.304 | D18: ='DCF Bear'!$C$78 -> 55822.367 | E18: ='DCF Bear'!$C$107 -> 26271.075 | F18: ='DCF Bear'!$C$136 -> 65411.174 | G18: ='DCF Bear'!$C$27 -> 208431.92 | H18: ='DCF Base'!$C$49 -> 60927.304 | I18: ='DCF Base'!$C$78 -> 55822.367 | J18: ='DCF Base'!$C$107 -> 26271.075 | K18: ='DCF Base'!$C$136 -> 65411.174 | L18: ='DCF Base'!$C$27 -> 208431.92 | M18: ='DCF Bull'!$C$49 -> 60927.304 | N18: ='DCF Bull'!$C$78 -> 55822.367 | O18: ='DCF Bull'!$C$107 -> 26271.075 | P18: ='DCF Bull'!$C$136 -> 65411.174 | Q18: ='DCF Bull'!$C$27 -> 208431.92 | R18: ='DCF Custom'!$C$49 -> 60927.304 | S18: ='DCF Custom'!$C$78 -> 55822.367 | T18: ='DCF Custom'!$C$107 -> 26271.075 | U18: ='DCF Custom'!$C$136 -> 65411.174 | V18: ='DCF Custom'!$C$27 -> 208431.92
B19: DCF value today (DCF sheet) | C19: ='DCF Bear'!$C$67 -> 49428.491 | D19: ='DCF Bear'!$C$96 -> 29906.892 | E19: ='DCF Bear'!$C$125 -> 17214.384 | F19: ='DCF Bear'!$C$154 -> 63089.254 | G19: ='DCF Bear'!$C$33 -> 159639.02 | H19: ='DCF Base'!$C$67 -> 66024.902 | I19: ='DCF Base'!$C$96 -> 38959.323 | J19: ='DCF Base'!$C$125 -> 23184.563 | K19: ='DCF Base'!$C$154 -> 80095.664 | L19: ='DCF Base'!$C$33 -> 208264.45 | M19: ='DCF Bull'!$C$67 -> 82737.941 | N19: ='DCF Bull'!$C$96 -> 47258.379 | O19: ='DCF Bull'!$C$125 -> 29196.162 | P19: ='DCF Bull'!$C$154 -> 96033.835 | Q19: ='DCF Bull'!$C$33 -> 255226.32 | R19: ='DCF Custom'!$C$67 -> 66024.902 | S19: ='DCF Custom'!$C$96 -> 38959.323 | T19: ='DCF Custom'!$C$125 -> 23184.563 | U19: ='DCF Custom'!$C$154 -> 80095.664 | V19: ='DCF Custom'!$C$33 -> 208264.45
B20: Check: closed form at the ERP used | C20: =SUMPRODUCT('DCF Bear'!$D$73:$H$73,(1+'DCF Bear'!$C$52)^(-'DCF Bear'!$D$19:$H$19))+'DCF Bear'!$I$58*(1-'DCF Bear'!$I$57/'DCF Bear'!$I$59)/((1+'DCF Bear'!$C$52)*IF(RateConv=1,1,1+IPCALT)-1-'DCF Bear'!$I$57)/'DCF Bear'!$H$23*(1+'DCF Bear'!$C$52)^(-5) -> 49428.491 | D20: =SUMPRODUCT('DCF Bear'!$D$102:$H$102,(1+'DCF Bear'!$C$81)^(-'DCF Bear'!$D$19:$H$19))+'DCF Bear'!$I$87*(1-'DCF Bear'!$I$86/'DCF Bear'!$I$88)/((1+'DCF Bear'!$C$81)*IF(RateConv=1,1,1+IPCALT)-1-'DCF Bear'!$I$86)/'DCF Bear'!$H$23*(1+'DCF Bear'!$C$81)^(-5) -> 29906.892 | E20: =SUMPRODUCT('DCF Bear'!$D$131:$H$131,(1+'DCF Bear'!$C$110)^(-'DCF Bear'!$D$19:$H$19))+'DCF Bear'!$I$116*(1-'DCF Bear'!$I$115/'DCF Bear'!$I$117)/((1+'DCF Bear'!$C$110)*IF(RateConv=1,1,1+IPCALT)-1-'DCF Bear'!$I$115)/'DCF Bear'!$H$23*(1+'DCF Bear'!$C$110)^(-5) -> 17214.384 | F20: =SUMPRODUCT('DCF Bear'!$D$160:$H$160,(1+'DCF Bear'!$C$139)^(-'DCF Bear'!$D$19:$H$19))+'DCF Bear'!$I$145*(1-'DCF Bear'!$I$144/'DCF Bear'!$I$146)/((1+'DCF Bear'!$C$139)*IF(RateConv=1,1,1+IPCALT)-1-'DCF Bear'!$I$144)/'DCF Bear'!$H$23*(1+'DCF Bear'!$C$139)^(-5) -> 63089.254 | G20: =C20+D20+E20+F20 -> 159639.02 | H20: =SUMPRODUCT('DCF Base'!$D$73:$H$73,(1+'DCF Base'!$C$52)^(-'DCF Base'!$D$19:$H$19))+'DCF Base'!$I$58*(1-'DCF Base'!$I$57/'DCF Base'!$I$59)/((1+'DCF Base'!$C$52)*IF(RateConv=1,1,1+IPCALT)-1-'DCF Base'!$I$57)/'DCF Base'!$H$23*(1+'DCF Base'!$C$52)^(-5) -> 66024.902 | I20: =SUMPRODUCT('DCF Base'!$D$102:$H$102,(1+'DCF Base'!$C$81)^(-'DCF Base'!$D$19:$H$19))+'DCF Base'!$I$87*(1-'DCF Base'!$I$86/'DCF Base'!$I$88)/((1+'DCF Base'!$C$81)*IF(RateConv=1,1,1+IPCALT)-1-'DCF Base'!$I$86)/'DCF Base'!$H$23*(1+'DCF Base'!$C$81)^(-5) -> 38959.323 | J20: =SUMPRODUCT('DCF Base'!$D$131:$H$131,(1+'DCF Base'!$C$110)^(-'DCF Base'!$D$19:$H$19))+'DCF Base'!$I$116*(1-'DCF Base'!$I$115/'DCF Base'!$I$117)/((1+'DCF Base'!$C$110)*IF(RateConv=1,1,1+IPCALT)-1-'DCF Base'!$I$115)/'DCF Base'!$H$23*(1+'DCF Base'!$C$110)^(-5) -> 23184.563 | K20: =SUMPRODUCT('DCF Base'!$D$160:$H$160,(1+'DCF Base'!$C$139)^(-'DCF Base'!$D$19:$H$19))+'DCF Base'!$I$145*(1-'DCF Base'!$I$144/'DCF Base'!$I$146)/((1+'DCF Base'!$C$139)*IF(RateConv=1,1,1+IPCALT)-1-'DCF Base'!$I$144)/'DCF Base'!$H$23*(1+'DCF Base'!$C$139)^(-5) -> 80095.664 | L20: =H20+I20+J20+K20 -> 208264.45 | M20: =SUMPRODUCT('DCF Bull'!$D$73:$H$73,(1+'DCF Bull'!$C$52)^(-'DCF Bull'!$D$19:$H$19))+'DCF Bull'!$I$58*(1-'DCF Bull'!$I$57/'DCF Bull'!$I$59)/((1+'DCF Bull'!$C$52)*IF(RateConv=1,1,1+IPCALT)-1-'DCF Bull'!$I$57)/'DCF Bull'!$H$23*(1+'DCF Bull'!$C$52)^(-5) -> 82737.941 | N20: =SUMPRODUCT('DCF Bull'!$D$102:$H$102,(1+'DCF Bull'!$C$81)^(-'DCF Bull'!$D$19:$H$19))+'DCF Bull'!$I$87*(1-'DCF Bull'!$I$86/'DCF Bull'!$I$88)/((1+'DCF Bull'!$C$81)*IF(RateConv=1,1,1+IPCALT)-1-'DCF Bull'!$I$86)/'DCF Bull'!$H$23*(1+'DCF Bull'!$C$81)^(-5) -> 47258.379 | O20: =SUMPRODUCT('DCF Bull'!$D$131:$H$131,(1+'DCF Bull'!$C$110)^(-'DCF Bull'!$D$19:$H$19))+'DCF Bull'!$I$116*(1-'DCF Bull'!$I$115/'DCF Bull'!$I$117)/((1+'DCF Bull'!$C$110)*IF(RateConv=1,1,1+IPCALT)-1-'DCF Bull'!$I$115)/'DCF Bull'!$H$23*(1+'DCF Bull'!$C$110)^(-5) -> 29196.162 | P20: =SUMPRODUCT('DCF Bull'!$D$160:$H$160,(1+'DCF Bull'!$C$139)^(-'DCF Bull'!$D$19:$H$19))+'DCF Bull'!$I$145*(1-'DCF Bull'!$I$144/'DCF Bull'!$I$146)/((1+'DCF Bull'!$C$139)*IF(RateConv=1,1,1+IPCALT)-1-'DCF Bull'!$I$144)/'DCF Bull'!$H$23*(1+'DCF Bull'!$C$139)^(-5) -> 96033.835 | Q20: =M20+N20+O20+P20 -> 255226.32 | R20: =SUMPRODUCT('DCF Custom'!$D$73:$H$73,(1+'DCF Custom'!$C$52)^(-'DCF Custom'!$D$19:$H$19))+'DCF Custom'!$I$58*(1-'DCF Custom'!$I$57/'DCF Custom'!$I$59)/((1+'DCF Custom'!$C$52)*IF(RateConv=1,1,1+IPCALT)-1-'DCF Custom'!$I$57)/'DCF Custom'!$H$23*(1+'DCF Custom'!$C$52)^(-5) -> 66024.902 | S20: =SUMPRODUCT('DCF Custom'!$D$102:$H$102,(1+'DCF Custom'!$C$81)^(-'DCF Custom'!$D$19:$H$19))+'DCF Custom'!$I$87*(1-'DCF Custom'!$I$86/'DCF Custom'!$I$88)/((1+'DCF Custom'!$C$81)*IF(RateConv=1,1,1+IPCALT)-1-'DCF Custom'!$I$86)/'DCF Custom'!$H$23*(1+'DCF Custom'!$C$81)^(-5) -> 38959.323 | T20: =SUMPRODUCT('DCF Custom'!$D$131:$H$131,(1+'DCF Custom'!$C$110)^(-'DCF Custom'!$D$19:$H$19))+'DCF Custom'!$I$116*(1-'DCF Custom'!$I$115/'DCF Custom'!$I$117)/((1+'DCF Custom'!$C$110)*IF(RateConv=1,1,1+IPCALT)-1-'DCF Custom'!$I$115)/'DCF Custom'!$H$23*(1+'DCF Custom'!$C$110)^(-5) -> 23184.563 | U20: =SUMPRODUCT('DCF Custom'!$D$160:$H$160,(1+'DCF Custom'!$C$139)^(-'DCF Custom'!$D$19:$H$19))+'DCF Custom'!$I$145*(1-'DCF Custom'!$I$144/'DCF Custom'!$I$146)/((1+'DCF Custom'!$C$139)*IF(RateConv=1,1,1+IPCALT)-1-'DCF Custom'!$I$144)/'DCF Custom'!$H$23*(1+'DCF Custom'!$C$139)^(-5) -> 80095.664 | V20: =R20+S20+T20+U20 -> 208264.45
B21: 0 | C21: =SUMPRODUCT('DCF Bear'!$D$73:$H$73,(1+'DCF Bear'!$C$6+$B21)^(-'DCF Bear'!$D$19:$H$19))+'DCF Bear'!$I$58*(1-'DCF Bear'!$I$57/'DCF Bear'!$I$59)/((1+'DCF Bear'!$C$6+$B21)*IF(RateConv=1,1,1+IPCALT)-1-'DCF Bear'!$I$57)/'DCF Bear'!$H$23*(1+'DCF Bear'!$C$6+$B21)^(-5) -> 120215.66 | D21: =SUMPRODUCT('DCF Bear'!$D$102:$H$102,(1+'DCF Bear'!$C$6+$B21)^(-'DCF Bear'!$D$19:$H$19))+'DCF Bear'!$I$87*(1-'DCF Bear'!$I$86/'DCF Bear'!$I$88)/((1+'DCF Bear'!$C$6+$B21)*IF(RateConv=1,1,1+IPCALT)-1-'DCF Bear'!$I$86)/'DCF Bear'!$H$23*(1+'DCF Bear'!$C$6+$B21)^(-5) -> 76811.279 | E21: =SUMPRODUCT('DCF Bear'!$D$131:$H$131,(1+'DCF Bear'!$C$6+$B21)^(-'DCF Bear'!$D$19:$H$19))+'DCF Bear'!$I$116*(1-'DCF Bear'!$I$115/'DCF Bear'!$I$117)/((1+'DCF Bear'!$C$6+$B21)*IF(RateConv=1,1,1+IPCALT)-1-'DCF Bear'!$I$115)/'DCF Bear'!$H$23*(1+'DCF Bear'!$C$6+$B21)^(-5) -> 43128.962 | F21: =SUMPRODUCT('DCF Bear'!$D$160:$H$160,(1+'DCF Bear'!$C$6+$B21)^(-'DCF Bear'!$D$19:$H$19))+'DCF Bear'!$I$145*(1-'DCF Bear'!$I$144/'DCF Bear'!$I$146)/((1+'DCF Bear'!$C$6+$B21)*IF(RateConv=1,1,1+IPCALT)-1-'DCF Bear'!$I$144)/'DCF Bear'!$H$23*(1+'DCF Bear'!$C$6+$B21)^(-5) -> 144279.06 | G21: =C21+D21+E21+F21 -> 384434.96 | H21: =SUMPRODUCT('DCF Base'!$D$73:$H$73,(1+'DCF Base'!$C$6+$B21)^(-'DCF Base'!$D$19:$H$19))+'DCF Base'!$I$58*(1-'DCF Base'!$I$57/'DCF Base'!$I$59)/((1+'DCF Base'!$C$6+$B21)*IF(RateConv=1,1,1+IPCALT)-1-'DCF Base'!$I$57)/'DCF Base'!$H$23*(1+'DCF Base'!$C$6+$B21)^(-5) -> 269869.25 | I21: =SUMPRODUCT('DCF Base'!$D$102:$H$102,(1+'DCF Base'!$C$6+$B21)^(-'DCF Base'!$D$19:$H$19))+'DCF Base'!$I$87*(1-'DCF Base'!$I$86/'DCF Base'!$I$88)/((1+'DCF Base'!$C$6+$B21)*IF(RateConv=1,1,1+IPCALT)-1-'DCF Base'!$I$86)/'DCF Base'!$H$23*(1+'DCF Base'!$C$6+$B21)^(-5) -> 170656.42 | J21: =SUMPRODUCT('DCF Base'!$D$131:$H$131,(1+'DCF Base'!$C$6+$B21)^(-'DCF Base'!$D$19:$H$19))+'DCF Base'!$I$116*(1-'DCF Base'!$I$115/'DCF Base'!$I$117)/((1+'DCF Base'!$C$6+$B21)*IF(RateConv=1,1,1+IPCALT)-1-'DCF Base'!$I$115)/'DCF Base'!$H$23*(1+'DCF Base'!$C$6+$B21)^(-5) -> 98091.15 | K21: =SUMPRODUCT('DCF Base'!$D$160:$H$160,(1+'DCF Base'!$C$6+$B21)^(-'DCF Base'!$D$19:$H$19))+'DCF Base'!$I$145*(1-'DCF Base'!$I$144/'DCF Base'!$I$146)/((1+'DCF Base'!$C$6+$B21)*IF(RateConv=1,1,1+IPCALT)-1-'DCF Base'!$I$144)/'DCF Base'!$H$23*(1+'DCF Base'!$C$6+$B21)^(-5) -> 307306.78 | L21: =H21+I21+J21+K21 -> 845923.6 | M21: =SUMPRODUCT('DCF Bull'!$D$73:$H$73,(1+'DCF Bull'!$C$6+$B21)^(-'DCF Bull'!$D$19:$H$19))+'DCF Bull'!$I$58*(1-'DCF Bull'!$I$57/'DCF Bull'!$I$59)/((1+'DCF Bull'!$C$6+$B21)*IF(RateConv=1,1,1+IPCALT)-1-'DCF Bull'!$I$57)/'DCF Bull'!$H$23*(1+'DCF Bull'!$C$6+$B21)^(-5) -> 757768.63 | N21: =SUMPRODUCT('DCF Bull'!$D$102:$H$102,(1+'DCF Bull'!$C$6+$B21)^(-'DCF Bull'!$D$19:$H$19))+'DCF Bull'!$I$87*(1-'DCF Bull'!$I$86/'DCF Bull'!$I$88)/((1+'DCF Bull'!$C$6+$B21)*IF(RateConv=1,1,1+IPCALT)-1-'DCF Bull'!$I$86)/'DCF Bull'!$H$23*(1+'DCF Bull'!$C$6+$B21)^(-5) -> 470848.43 | O21: =SUMPRODUCT('DCF Bull'!$D$131:$H$131,(1+'DCF Bull'!$C$6+$B21)^(-'DCF Bull'!$D$19:$H$19))+'DCF Bull'!$I$116*(1-'DCF Bull'!$I$115/'DCF Bull'!$I$117)/((1+'DCF Bull'!$C$6+$B21)*IF(RateConv=1,1,1+IPCALT)-1-'DCF Bull'!$I$115)/'DCF Bull'!$H$23*(1+'DCF Bull'!$C$6+$B21)^(-5) -> 277905.39 | P21: =SUMPRODUCT('DCF Bull'!$D$160:$H$160,(1+'DCF Bull'!$C$6+$B21)^(-'DCF Bull'!$D$19:$H$19))+'DCF Bull'!$I$145*(1-'DCF Bull'!$I$144/'DCF Bull'!$I$146)/((1+'DCF Bull'!$C$6+$B21)*IF(RateConv=1,1,1+IPCALT)-1-'DCF Bull'!$I$144)/'DCF Bull'!$H$23*(1+'DCF Bull'!$C$6+$B21)^(-5) -> 828397.96 | Q21: =M21+N21+O21+P21 -> 2334920.4 | R21: =SUMPRODUCT('DCF Custom'!$D$73:$H$73,(1+'DCF Custom'!$C$6+$B21)^(-'DCF Custom'!$D$19:$H$19))+'DCF Custom'!$I$58*(1-'DCF Custom'!$I$57/'DCF Custom'!$I$59)/((1+'DCF Custom'!$C$6+$B21)*IF(RateConv=1,1,1+IPCALT)-1-'DCF Custom'!$I$57)/'DCF Custom'!$H$23*(1+'DCF Custom'!$C$6+$B21)^(-5) -> 269869.25 | S21: =SUMPRODUCT('DCF Custom'!$D$102:$H$102,(1+'DCF Custom'!$C$6+$B21)^(-'DCF Custom'!$D$19:$H$19))+'DCF Custom'!$I$87*(1-'DCF Custom'!$I$86/'DCF Custom'!$I$88)/((1+'DCF Custom'!$C$6+$B21)*IF(RateConv=1,1,1+IPCALT)-1-'DCF Custom'!$I$86)/'DCF Custom'!$H$23*(1+'DCF Custom'!$C$6+$B21)^(-5) -> 170656.42 | T21: =SUMPRODUCT('DCF Custom'!$D$131:$H$131,(1+'DCF Custom'!$C$6+$B21)^(-'DCF Custom'!$D$19:$H$19))+'DCF Custom'!$I$116*(1-'DCF Custom'!$I$115/'DCF Custom'!$I$117)/((1+'DCF Custom'!$C$6+$B21)*IF(RateConv=1,1,1+IPCALT)-1-'DCF Custom'!$I$115)/'DCF Custom'!$H$23*(1+'DCF Custom'!$C$6+$B21)^(-5) -> 98091.15 | U21: =SUMPRODUCT('DCF Custom'!$D$160:$H$160,(1+'DCF Custom'!$C$6+$B21)^(-'DCF Custom'!$D$19:$H$19))+'DCF Custom'!$I$145*(1-'DCF Custom'!$I$144/'DCF Custom'!$I$146)/((1+'DCF Custom'!$C$6+$B21)*IF(RateConv=1,1,1+IPCALT)-1-'DCF Custom'!$I$144)/'DCF Custom'!$H$23*(1+'DCF Custom'!$C$6+$B21)^(-5) -> 307306.78 | V21: =R21+S21+T21+U21 -> 845923.6
B22: 0.001 | C22: =SUMPRODUCT('DCF Bear'!$D$73:$H$73,(1+'DCF Bear'!$C$6+$B22)^(-'DCF Bear'!$D$19:$H$19))+'DCF Bear'!$I$58*(1-'DCF Bear'!$I$57/'DCF Bear'!$I$59)/((1+'DCF Bear'!$C$6+$B22)*IF(RateConv=1,1,1+IPCALT)-1-'DCF Bear'!$I$57)/'DCF Bear'!$H$23*(1+'DCF Bear'!$C$6+$B22)^(-5) -> 117453.02 | D22: =SUMPRODUCT('DCF Bear'!$D$102:$H$102,(1+'DCF Bear'!$C$6+$B22)^(-'DCF Bear'!$D$19:$H$19))+'DCF Bear'!$I$87*(1-'DCF Bear'!$I$86/'DCF Bear'!$I$88)/((1+'DCF Bear'!$C$6+$B22)*IF(RateConv=1,1,1+IPCALT)-1-'DCF Bear'!$I$86)/'DCF Bear'!$H$23*(1+'DCF Bear'!$C$6+$B22)^(-5) -> 74973.21 | E22: =SUMPRODUCT('DCF Bear'!$D$131:$H$131,(1+'DCF Bear'!$C$6+$B22)^(-'DCF Bear'!$D$19:$H$19))+'DCF Bear'!$I$116*(1-'DCF Bear'!$I$115/'DCF Bear'!$I$117)/((1+'DCF Bear'!$C$6+$B22)*IF(RateConv=1,1,1+IPCALT)-1-'DCF Bear'!$I$115)/'DCF Bear'!$H$23*(1+'DCF Bear'!$C$6+$B22)^(-5) -> 42115.141 | F22: =SUMPRODUCT('DCF Bear'!$D$160:$H$160,(1+'DCF Bear'!$C$6+$B22)^(-'DCF Bear'!$D$19:$H$19))+'DCF Bear'!$I$145*(1-'DCF Bear'!$I$144/'DCF Bear'!$I$146)/((1+'DCF Bear'!$C$6+$B22)*IF(RateConv=1,1,1+IPCALT)-1-'DCF Bear'!$I$144)/'DCF Bear'!$H$23*(1+'DCF Bear'!$C$6+$B22)^(-5) -> 141128.91 | G22: =C22+D22+E22+F22 -> 375670.27 | H22: =SUMPRODUCT('DCF Base'!$D$73:$H$73,(1+'DCF Base'!$C$6+$B22)^(-'DCF Base'!$D$19:$H$19))+'DCF Base'!$I$58*(1-'DCF Base'!$I$57/'DCF Base'!$I$59)/((1+'DCF Base'!$C$6+$B22)*IF(RateConv=1,1,1+IPCALT)-1-'DCF Base'!$I$57)/'DCF Base'!$H$23*(1+'DCF Base'!$C$6+$B22)^(-5) -> 257173.48 | I22: =SUMPRODUCT('DCF Base'!$D$102:$H$102,(1+'DCF Base'!$C$6+$B22)^(-'DCF Base'!$D$19:$H$19))+'DCF Base'!$I$87*(1-'DCF Base'!$I$86/'DCF Base'!$I$88)/((1+'DCF Base'!$C$6+$B22)*IF(RateConv=1,1,1+IPCALT)-1-'DCF Base'!$I$86)/'DCF Base'!$H$23*(1+'DCF Base'!$C$6+$B22)^(-5) -> 162432.85 | J22: =SUMPRODUCT('DCF Base'!$D$131:$H$131,(1+'DCF Base'!$C$6+$B22)^(-'DCF Base'!$D$19:$H$19))+'DCF Base'!$I$116*(1-'DCF Base'!$I$115/'DCF Base'!$I$117)/((1+'DCF Base'!$C$6+$B22)*IF(RateConv=1,1,1+IPCALT)-1-'DCF Base'!$I$115)/'DCF Base'!$H$23*(1+'DCF Base'!$C$6+$B22)^(-5) -> 93419.473 | K22: =SUMPRODUCT('DCF Base'!$D$160:$H$160,(1+'DCF Base'!$C$6+$B22)^(-'DCF Base'!$D$19:$H$19))+'DCF Base'!$I$145*(1-'DCF Base'!$I$144/'DCF Base'!$I$146)/((1+'DCF Base'!$C$6+$B22)*IF(RateConv=1,1,1+IPCALT)-1-'DCF Base'!$I$144)/'DCF Base'!$H$23*(1+'DCF Base'!$C$6+$B22)^(-5) -> 293194.96 | L22: =H22+I22+J22+K22 -> 806220.76 | M22: =SUMPRODUCT('DCF Bull'!$D$73:$H$73,(1+'DCF Bull'!$C$6+$B22)^(-'DCF Bull'!$D$19:$H$19))+'DCF Bull'!$I$58*(1-'DCF Bull'!$I$57/'DCF Bull'!$I$59)/((1+'DCF Bull'!$C$6+$B22)*IF(RateConv=1,1,1+IPCALT)-1-'DCF Bull'!$I$57)/'DCF Bull'!$H$23*(1+'DCF Bull'!$C$6+$B22)^(-5) -> 672668.89 | N22: =SUMPRODUCT('DCF Bull'!$D$102:$H$102,(1+'DCF Bull'!$C$6+$B22)^(-'DCF Bull'!$D$19:$H$19))+'DCF Bull'!$I$87*(1-'DCF Bull'!$I$86/'DCF Bull'!$I$88)/((1+'DCF Bull'!$C$6+$B22)*IF(RateConv=1,1,1+IPCALT)-1-'DCF Bull'!$I$86)/'DCF Bull'!$H$23*(1+'DCF Bull'!$C$6+$B22)^(-5) -> 417379.63 | O22: =SUMPRODUCT('DCF Bull'!$D$131:$H$131,(1+'DCF Bull'!$C$6+$B22)^(-'DCF Bull'!$D$19:$H$19))+'DCF Bull'!$I$116*(1-'DCF Bull'!$I$115/'DCF Bull'!$I$117)/((1+'DCF Bull'!$C$6+$B22)*IF(RateConv=1,1,1+IPCALT)-1-'DCF Bull'!$I$115)/'DCF Bull'!$H$23*(1+'DCF Bull'!$C$6+$B22)^(-5) -> 246532.16 | P22: =SUMPRODUCT('DCF Bull'!$D$160:$H$160,(1+'DCF Bull'!$C$6+$B22)^(-'DCF Bull'!$D$19:$H$19))+'DCF Bull'!$I$145*(1-'DCF Bull'!$I$144/'DCF Bull'!$I$146)/((1+'DCF Bull'!$C$6+$B22)*IF(RateConv=1,1,1+IPCALT)-1-'DCF Bull'!$I$144)/'DCF Bull'!$H$23*(1+'DCF Bull'!$C$6+$B22)^(-5) -> 736162.82 | Q22: =M22+N22+O22+P22 -> 2072743.5 | R22: =SUMPRODUCT('DCF Custom'!$D$73:$H$73,(1+'DCF Custom'!$C$6+$B22)^(-'DCF Custom'!$D$19:$H$19))+'DCF Custom'!$I$58*(1-'DCF Custom'!$I$57/'DCF Custom'!$I$59)/((1+'DCF Custom'!$C$6+$B22)*IF(RateConv=1,1,1+IPCALT)-1-'DCF Custom'!$I$57)/'DCF Custom'!$H$23*(1+'DCF Custom'!$C$6+$B22)^(-5) -> 257173.48 | S22: =SUMPRODUCT('DCF Custom'!$D$102:$H$102,(1+'DCF Custom'!$C$6+$B22)^(-'DCF Custom'!$D$19:$H$19))+'DCF Custom'!$I$87*(1-'DCF Custom'!$I$86/'DCF Custom'!$I$88)/((1+'DCF Custom'!$C$6+$B22)*IF(RateConv=1,1,1+IPCALT)-1-'DCF Custom'!$I$86)/'DCF Custom'!$H$23*(1+'DCF Custom'!$C$6+$B22)^(-5) -> 162432.85 | T22: =SUMPRODUCT('DCF Custom'!$D$131:$H$131,(1+'DCF Custom'!$C$6+$B22)^(-'DCF Custom'!$D$19:$H$19))+'DCF Custom'!$I$116*(1-'DCF Custom'!$I$115/'DCF Custom'!$I$117)/((1+'DCF Custom'!$C$6+$B22)*IF(RateConv=1,1,1+IPCALT)-1-'DCF Custom'!$I$115)/'DCF Custom'!$H$23*(1+'DCF Custom'!$C$6+$B22)^(-5) -> 93419.473 | U22: =SUMPRODUCT('DCF Custom'!$D$160:$H$160,(1+'DCF Custom'!$C$6+$B22)^(-'DCF Custom'!$D$19:$H$19))+'DCF Custom'!$I$145*(1-'DCF Custom'!$I$144/'DCF Custom'!$I$146)/((1+'DCF Custom'!$C$6+$B22)*IF(RateConv=1,1,1+IPCALT)-1-'DCF Custom'!$I$144)/'DCF Custom'!$H$23*(1+'DCF Custom'!$C$6+$B22)^(-5) -> 293194.96 | V22: =R22+S22+T22+U22 -> 806220.76
