Workbook
Name BetaAdj: Assumptions!$C$45
Name BetaYears: Assumptions!$C$44
Name BoxRate: Assumptions!$C$42
Name ERPfloor: Assumptions!$C$43
Name FinROE: 'Box Shares'!$C$39
Name FinROEovr: Assumptions!$C$40
Name FixInfl: Assumptions!$C$29
Name FixND: Assumptions!$C$27
Name FixNWC: Assumptions!$C$26
Name FixTV: Assumptions!$C$28
Name FV27Base: DCF!$D$57
Name FV27Bear: DCF!$C$57
Name FV27Bull: DCF!$E$57
Name gLT: Assumptions!$C$13
Name IbovUsed: Assumptions!$E$7
Name InflLT: Assumptions!$C$14
Name NDmult: Assumptions!$C$16
Name NWCpct: Assumptions!$C$15
Name RRUsed: Assumptions!$E$8
Name ScaleBox: Assumptions!$C$39
Name Vintage: Assumptions!$C$9

Sheet Cover
C3: Ibovespa | DCF by box (house model), end-2027
C4: VALUATION MODEL · EQUITY STRATEGY
C7: Main tabs >>
C8: Summary | E8: Assumptions | G8: DCF by Box | I8: DCF (Ibovespa) | K8: Ibovespa used | M8: =IbovUsed -> 208431.92
K9: Fair value end-2027, base | M9: =Summary!E11 -> 235695.44
K10: Upside, base | M10: =Summary!I11 -> 0.13080299
C11: Auxiliary tabs >> | K11: Fair value end-2027, bear | M11: =Summary!D11 -> 191722.24
C12: Sensitivity | E12: Box Shares | G12: Members (76 stocks) | I12: Checks | K12: Fair value end-2027, bull | M12: =Summary!F11 -> 261607.54
K13: Model checks | M13: =Checks!C5 -> All checks OK
K15: How this model works >>
K16: Equity Strategy | XP Research
C18: Base case by box >>
C19: Box | F19: Index points | G19: Fair value | H19: Upside
C20: Financials | F20: =Summary!C7 -> 60927.304 | G20: =Summary!E7 -> 64254.945 | H20: =Summary!I7 -> 0.054616589
C21: Defensives | F21: =Summary!C8 -> 55822.367 | G21: =Summary!E8 -> 65034.096 | H21: =Summary!I8 -> 0.1650186
C22: Cyclicals | F22: =Summary!C9 -> 26271.075 | G22: =Summary!E9 -> 42289.695 | H22: =Summary!I9 -> 0.60974361
C23: Commodities | F23: =Summary!C10 -> 65411.174 | G23: =Summary!E10 -> 64116.702 | H23: =Summary!I10 -> -0.01978978
C24: Ibovespa | F24: =Summary!C11 -> 208431.92 | G24: =Summary!E11 -> 235695.44 | H24: =Summary!I11 -> 0.13080299
C26: House DCF rolled to end-2027 and split by box: FCFF for Defensives, Cyclicals and Commodities, FCFE for Financials; boxes scaled to the house total.

Sheet Summary
B1: Ibovespa - DCF by box (house model): fair value at the end of 2027
B2: House DCF rolled to end-2027 and split by box; box rates keep each box's historical relative valuation. Construction: DCF by Box, Box Rates, DCF.
B3: Ibovespa used | C3: =IbovUsed -> 208431.92 | D3: Market data | E3: =CHOOSE(Vintage,"house file","Oct-5-2026") -> Oct-5-2026 | F3: Checks | G3: =Checks!C5 -> All checks OK | H3: Boxes scaled | I3: =IF(ScaleBox=1,"yes","no") -> yes
B4: Box discount rates | C4: =CHOOSE(BoxRate+1,"the house rate for every box","relative to each box's history (Box Rates)","CAPM: real rate + box beta x ERP (Box Betas)") -> relative to each box's history (Box Rates)
B5: 1. Fair value at the end of 2027 by box (index pts)
B6: Group | C6: Index points | D6: Bear | E6: Base | F6: Bull | H6: Upside: Bear | I6: Base | J6: Bull
B7: Financials | C7: ='Box Shares'!C7 -> 60927.304 | D7: ='DCF by Box'!C57 -> 54797.695 | E7: ='DCF by Box'!D57 -> 64254.945 | F7: ='DCF by Box'!E57 -> 71234.793 | H7: =D7/$C7-1 -> -0.10060529 | I7: =E7/$C7-1 -> 0.054616589 | J7: =F7/$C7-1 -> 0.16917685
B8: Defensives | C8: ='Box Shares'!C8 -> 55822.367 | D8: ='DCF by Box'!C98 -> 55244.064 | E8: ='DCF by Box'!D98 -> 65034.096 | F8: ='DCF by Box'!E98 -> 72213.386 | H8: =D8/$C8-1 -> -0.010359706 | I8: =E8/$C8-1 -> 0.1650186 | J8: =F8/$C8-1 -> 0.29362816
B9: Cyclicals | C9: ='Box Shares'!C9 -> 26271.075 | D9: ='DCF by Box'!C139 -> 27251.182 | E9: ='DCF by Box'!D139 -> 42289.695 | F9: ='DCF by Box'!E139 -> 46906.281 | H9: =D9/$C9-1 -> 0.037307468 | I9: =E9/$C9-1 -> 0.60974361 | J9: =F9/$C9-1 -> 0.78547248
B10: Commodities | C10: ='Box Shares'!C10 -> 65411.174 | D10: ='DCF by Box'!C180 -> 54429.3 | E10: ='DCF by Box'!D180 -> 64116.702 | F10: ='DCF by Box'!E180 -> 71253.079 | H10: =D10/$C10-1 -> -0.16788988 | I10: =E10/$C10-1 -> -0.01978978 | J10: =F10/$C10-1 -> 0.089310501
B11: Ibovespa | C11: =SUM(C7:C10) -> 208431.92 | D11: =SUM(D7:D10) -> 191722.24 | E11: =SUM(E7:E10) -> 235695.44 | F11: =SUM(F7:F10) -> 261607.54 | H11: =D11/$C11-1 -> -0.080168523 | I11: =E11/$C11-1 -> 0.13080299 | J11: =F11/$C11-1 -> 0.25512225
B12: Memo (inside Cyclicals; own rates, not additive)
B13: Cyclicals ex-WEG & Embraer | C13: ='Box Shares'!C14 -> 16066.52 | D13: ='DCF by Box'!C221 -> 20090.494 | E13: ='DCF by Box'!D221 -> 28924.182 | F13: ='DCF by Box'!E221 -> 32105.636 | H13: =D13/$C13-1 -> 0.25045715 | I13: =E13/$C13-1 -> 0.80027678 | J13: =F13/$C13-1 -> 0.9982944
B14: WEG & Embraer | C14: ='Box Shares'!C15 -> 10204.555 | D14: ='DCF by Box'!C262 -> 7160.6877 | E14: ='DCF by Box'!D262 -> 12859.72 | F14: ='DCF by Box'!E262 -> 15715.205 | H14: =D14/$C14-1 -> -0.29828517 | I14: =E14/$C14-1 -> 0.2601941 | J14: =F14/$C14-1 -> 0.54001865
B16: 2. Upside by box: this DCF vs. the multiples model (Oct-6 table) and vs. the DCF at the house rate
B17: Group | D17: DCF: Bear | E17: Multiples: Bear | F17: DCF: Base | G17: Multiples: Base | H17: DCF: Bull | I17: Multiples: Bull | J17: Base, DCF at the house rate
B18: Financials | D18: =H7 -> -0.10060529 | E18: =$D$68/$C$7-1 -> -0.26279942 | F18: =I7 -> 0.054616589 | G18: =$D$69/$C$7-1 -> -0.075462708 | H18: =J7 -> 0.16917685 | I18: =$D$70/$C$7-1 -> 0.1764631 | J18: ='DCF by Box'!$D$61*IF(ScaleBox=1,'DCF by Box'!$D$14,1)/$C$7-1 -> 0.081885096
B19: Defensives | D19: =H8 -> -0.010359706 | E19: =$E$68/$C$8-1 -> -0.13463029 | F19: =I8 -> 0.1650186 | G19: =$E$69/$C$8-1 -> 0.070674259 | H19: =J8 -> 0.29362816 | I19: =$E$70/$C$8-1 -> 0.31471271 | J19: ='DCF by Box'!$D$102*IF(ScaleBox=1,'DCF by Box'!$D$14,1)/$C$8-1 -> -0.19702917
B20: Cyclicals | D20: =H9 -> 0.037307468 | E20: =$F$68/$C$9-1 -> 0.015544907 | F20: =I9 -> 0.60974361 | G20: =$F$69/$C$9-1 -> 0.39651752 | H20: =J9 -> 0.78547248 | I20: =$F$70/$C$9-1 -> 0.846917 | J20: ='DCF by Box'!$D$143*IF(ScaleBox=1,'DCF by Box'!$D$14,1)/$C$9-1 -> -0.50629096
B21: Commodities | D21: =H10 -> -0.16788988 | E21: =$G$68/$C$10-1 -> -0.16662894 | F21: =I10 -> -0.01978978 | G21: =$G$69/$C$10-1 -> 0.16870547 | H21: =J10 -> 0.089310501 | I21: =$G$70/$C$10-1 -> 0.54777705 | J21: ='DCF by Box'!$D$184*IF(ScaleBox=1,'DCF by Box'!$D$14,1)/$C$10-1 -> 0.71201782
B22: Ibovespa | D22: =H11 -> -0.080168523 | E22: =$H$68/$C$11-1 -> -0.16320943 | F22: =I11 -> 0.13080299 | G22: =$H$69/$C$11-1 -> 0.099791 | H22: =J11 -> 0.25512225 | I22: =$H$70/$C$11-1 -> 0.41452187 | J22: ='DCF by Box'!$D$13*IF(ScaleBox=1,'DCF by Box'!$D$14,1)/$C$11-1 -> 0.13080299
B23: Memo (inside Cyclicals)
B24: Cyclicals ex-WEG & Embraer | D24: =H13 -> 0.25045715 | E24: =$I$68/$C$13-1 -> 0.13423127 | F24: =I13 -> 0.80027678 | G24: =$I$69/$C$13-1 -> 0.62781467 | H24: =J13 -> 0.9982944 | I24: =$I$70/$C$13-1 -> 1.2146051 | J24: ='DCF by Box'!$D$225*IF(ScaleBox=1,'DCF by Box'!$D$14,1)/$C$13-1 -> -0.41012576
B25: WEG & Embraer | D25: =H14 -> -0.29828517 | E25: =$J$68/$C$14-1 -> -0.25637845 | F25: =I14 -> 0.2601941 | G25: =$J$69/$C$14-1 -> 0.25783362 | H25: =J14 -> 0.54001865 | I25: =$J$70/$C$14-1 -> 0.82151303 | J25: ='DCF by Box'!$D$266*IF(ScaleBox=1,'DCF by Box'!$D$14,1)/$C$14-1 -> -0.65769786
B26: Average absolute gap to the multiples, four boxes | D26: =AVERAGE(ABS(D18-E18),ABS(D19-E19),ABS(D20-E20),ABS(D21-E21)) -> 0.077372054 | F26: =AVERAGE(ABS(F18-G18),ABS(F19-G19),ABS(F20-G20),ABS(F21-G21)) -> 0.15653625 | H26: =AVERAGE(ABS(H18-I18),ABS(H19-I19),ABS(H20-I20),ABS(H21-I21)) -> 0.13707046 | J26: =AVERAGE(ABS(J18-G18),ABS(J19-G19),ABS(J20-G20),ABS(J21-G21)) -> 0.46779302
B27: Gap in points of upside. Last column: the house mechanics with one rate (BoxRate = 0), against the multiples' base.
B29: 3. Discount rate by box (Box Rates)
B30: Group | C30: Relative cash yield | D30: Rate: Bear | E30: Base | F30: Bull | G30: CAPM beta | H30: Risk premium: Bear | I30: Base | J30: Bull
B31: Financials | C31: ='Box Rates'!G7 -> 0.9245176 | D31: ='Box Rates'!C21 -> 0.13760273 | E31: ='Box Rates'!D21 -> 0.12151612 | F31: ='Box Rates'!E21 -> 0.11448979 | G31: ='Box Betas'!I7 -> 1.1490637 | H31: ='Box Rates'!G21 -> 0.052602725 | I31: ='Box Rates'!H21 -> 0.053916119 | J31: ='Box Rates'!I21 -> 0.054489785
B32: Defensives | C32: ='Box Rates'!G8 -> 0.63524349 | D32: ='Box Rates'!C22 -> 0.10925386 | E32: ='Box Rates'!D22 -> 0.098200625 | F32: ='Box Rates'!E22 -> 0.093372774 | G32: ='Box Betas'!I8 -> 0.92867396 | H32: ='Box Rates'!G22 -> 0.024253862 | I32: ='Box Rates'!H22 -> 0.030600625 | J32: ='Box Rates'!I22 -> 0.033372774
B33: Cyclicals | C33: ='Box Rates'!G9 -> 0.29730445 | D33: ='Box Rates'!C23 -> 0.085 | E33: ='Box Rates'!D23 -> 0.070962739 | F33: ='Box Rates'!E23 -> 0.068703225 | G33: ='Box Betas'!I9 -> 1.1504511 | H33: ='Box Rates'!G23 -> 0 | I33: ='Box Rates'!H23 -> 0.003362739 | J33: ='Box Rates'!I23 -> 0.0087032252
B34: Commodities | C34: ='Box Rates'!G10 -> 1.53528 | D34: ='Box Rates'!C24 -> 0.19745744 | E34: ='Box Rates'!D24 -> 0.17074357 | F34: ='Box Rates'!E24 -> 0.15907544 | G34: ='Box Betas'!I10 -> 0.87168584 | H34: ='Box Rates'!G24 -> 0.11245744 | I34: ='Box Rates'!H24 -> 0.10314357 | J34: ='Box Rates'!I24 -> 0.099075438
B35: Ibovespa (house rate) | C35: ='Box Rates'!G11 -> 1 | D35: ='Box Rates'!C19 -> 0.145 | E35: ='Box Rates'!D19 -> 0.1276 | F35: ='Box Rates'!E19 -> 0.12 | G35: ='Box Betas'!I11 -> 1 | H35: ='Box Rates'!G19 -> 0.06 | I35: ='Box Rates'!H19 -> 0.06 | J35: ='Box Rates'!I19 -> 0.06
B36: Memo (inside Cyclicals)
B37: Cyclicals ex-WEG & Embraer | C37: ='Box Rates'!G13 -> 0.32038362 | D37: ='Box Rates'!C26 -> 0.085 | E37: ='Box Rates'!D26 -> 0.072822919 | F37: ='Box Rates'!E26 -> 0.070388004 | G37: ='Box Betas'!I13 -> 1.3187146 | H37: ='Box Rates'!G26 -> 0 | I37: ='Box Rates'!H26 -> 0.0052229195 | J37: ='Box Rates'!I26 -> 0.010388004
B38: WEG & Embraer | C38: ='Box Rates'!G14 -> 0.23199022 | D38: ='Box Rates'!C27 -> 0.085 | E38: ='Box Rates'!D27 -> 0.0676 | F38: ='Box Rates'!E27 -> 0.063935286 | G38: ='Box Betas'!I14 -> 0.71783452 | H38: ='Box Rates'!G27 -> 0 | I38: ='Box Rates'!H27 -> 0 | J38: ='Box Rates'!I27 -> 0.0039352858
B39: Rates in use (BoxRate). Relative cash yield = (10y average earnings yield x cash conversion) of the box / the Ibovespa's; CAPM beta: Box Betas.
B41: 4. Each box with its own value, before scaling (box rates; Financials by FCFE)
D42: Bear | E42: Base | F42: Bull | H42: Upside: Bear | I42: Base | J42: Bull
B43: Financials | D43: ='DCF by Box'!C54 -> 56491.129 | E43: ='DCF by Box'!D54 -> 69096.294 | F43: ='DCF by Box'!E54 -> 76515.629 | H43: ='DCF by Box'!C56 -> -0.072810939 | I43: ='DCF by Box'!D56 -> 0.13407767 | J43: ='DCF by Box'!E56 -> 0.25585122
...

Sheet Assumptions
B1: Ibovespa - DCF assumptions (house model by box, end-2027)
B2: Change the pink cells; the DCF sheet recalculates. Projection rules for 2028-2031 are pink cells in the DCF sheet.
B3: Legend: | C3: input | D3: assumption | E3: formula
B5: 1. Market data
B6: Item | C6: House file | D6: Oct-5-2026 | E6: Used | G6: Source
B7: Ibovespa (index pts) | C7: 182419.73 | D7: 208431.92 | E7: =CHOOSE(Vintage,C7,D7) -> 208431.92 | G7: House file: Target!B61 (BDP IBOV Index, as saved). Oct-5: Bloomberg IBOV Index PX_LAST.
B8: 5-year real rate (NTN-B) | C8: 0.0742 | D8: 0.0676 | E8: =CHOOSE(Vintage,C8,D8) -> 0.0676 | G8: House file: Target!C56 (BZRFB5PY Index, 7.42%). Oct-5: ANBIMA 5-year NTN-B (Bloomberg was down; check BZRFB5PY before publishing).
B9: Market data used: 1 = house file, 2 = Oct-5-2026 | C9: 2 | G9: Consensus and history are the house file's in both cases (not refreshed: the consensus moved little).
B11: 2. Valuation parameters (house Target sheet)
B12: Parameter | C12: Value | G12: Source
B13: Long-term growth of the FCFF (g) | C13: 0.047 | G13: Target!B54 (4.7%).
B14: Long-term inflation (Fisher switch and the implied-return block) | C14: 0.04 | G14: Target!B63 (4.0%).
B15: Working capital, % of sales | C15: 0.04 | G15: Target row 43: NWC = -4% of sales.
B16: Net debt / EBITDA of two years before (net debt switch) | C16: 1.6 | G16: Target rows 70-71 (EV/EBITDA method): net debt = 1.6x the EBITDA of two years before the value date.
B18: 3. Scenarios (fair value at the end of 2027)
B19: Lever | C19: Bear | D19: Base | E19: Bull | G19: Source
B20: 5-year real rate (NTN-B) | C20: 0.085 | D20: =RRUsed -> 0.0676 | E20: 0.06 | G20: As the house (Target rows 131-151): bear 8.5%, base = the market rate, bull 6.0%.
B21: ERP | C21: 0.06 | D21: 0.06 | E21: 0.06 | G21: Target!B57 (6.0%), the same in every scenario.
B22: Discount rate (house: real rate + ERP) | C22: =IF(FixInfl=1,(1+C20+C21)*(1+InflLT)-1,C20+C21) -> 0.145 | D22: =IF(FixInfl=1,(1+D20+D21)*(1+InflLT)-1,D20+D21) -> 0.1276 | E22: =IF(FixInfl=1,(1+E20+E21)*(1+InflLT)-1,E20+E21) -> 0.12 | G22: Target!B55 = BZRFB5PY + ERP. With the inflation switch on: (1 + real rate + ERP) x (1 + inflation) - 1.
B24: 4. Corrections to the house mechanics (0 = as the house, 1 = corrected)
B25: Switch | C25: Value | G25: What it changes
B26: Working capital: 0 = level (house), 1 = change | C26: 0 | G26: House row 44 adds the whole NWC level (-4% of sales) every year; the cash flow is the change in NWC.
B27: Net debt: 0 = not subtracted (house), 1 = subtracted | C27: 0 | G27: FCFF values the firm; equity = firm value - net debt (1.6x EBITDA two years before, as the house's EV/EBITDA method).
B28: Terminal value: 0 = one period after the last flow (house), 1 = with the last flow | C28: 0 | G28: NPV(rate, flows, TV) puts the TV one year after the last explicit year; it is a value at the end of that year.
B29: Inflation in the rate: 0 = real rate + ERP (house), 1 = Fisher | C29: 0 | G29: The flows are nominal (sales grow with nominal GDP); real rate + ERP is a real rate.
B31: 5. Projection rules (pink cells in the DCF sheet, 2028-2031 columns)
B32: Real GDP and inflation 2028-2031: 2.0% and 4.0% (house); sales grow with nominal GDP x ratio (1.0).
B33: EBITDA margin 2029-2031: 30% (house). EBIT margin, interest and gross margin: held at the 2028 level (house: same % as the year before).
B34: Capex % of sales: 11% in 2028-2029, 9% from 2030 (house); 2031, the year added here, keeps 2030's 9%.
B35: Consensus: sales and capex to 2027, EBIT, EBITDA and EPS to 2028 (IBOV Index, as in the house file).
B37: 6. By box
B38: Setting | C38: Value | G38: What it does
B39: Scale the boxes to the house's Ibovespa value: 1 = yes, 0 = no | C39: 1 | G39: 1: each box x (house Ibovespa value / sum of the boxes), so the boxes add up to the house number. 0: each box with its own value.
B40: Financials ROE for the FCFE (blank = consensus FY28, Box Shares) | G40: FCFE = net income x (1 - g / ROE): the earnings left after keeping the bank's equity growing at g.
B41: Index points of the members: Ibovespa on Oct-5-2026 (Assumptions D7) x price-drifted Sep-30 weights.
B42: Box discount rates: 0 = house rate, 1 = relative to history, 2 = CAPM (box beta) | C42: 1 | G42: 0: every box at the house rate. 1: box rate - g = (house rate - g) x the box's 10y cash yield relative to the Ibovespa (Box Rates), as the multiples. 2: CAPM, real rate + box beta x ERP (Box Betas).
B43: Lowest risk premium of a box (box rate >= real rate + this) | C43: 0 | G43: Keeps a box's risk premium from going below this; at 0% it binds only for Cyclicals in the bear.
B44: CAPM beta window (years of weekly returns: 2, 5 or 10) | C44: 5 | G44: Weekly total returns of the box indices up to Sep-25-2026 (Box Betas).
B45: CAPM beta: 1 = raw, 2 = Blume adjusted (0.67 x raw + 0.33) | C45: 1 | G45: The adjustment pulls the betas toward 1 (Bloomberg's default adjusted beta).

Sheet DCF by Box
B1: Ibovespa - DCF by box (house mechanics, end-2027)
B2: Each box gets its share of every house line (Box Shares). FCFF as the house for Defensives, Cyclicals and Commodities; FCFE for Financials. Rates and switches: Assumptions.
B3: Legend: | C3: input | D3: assumption | E3: formula
B5: Ibovespa = sum of the four boxes (end-2027)
C6: Bear | D6: Base | E6: Bull
B7: Sum of the box values, own mechanics and box rates (Financials by FCFE) | C7: =C54+C95+C136+C177 -> 197647.11 | D7: =D54+D95+D136+D177 -> 253454.13 | E7: =E54+E95+E136+E177 -> 281001.24 | J7: Defensives + Cyclicals + Commodities (FCFF) + Financials (FCFE), each at its box rate (Box Rates).
B8: House DCF fair value for the Ibovespa (DCF sheet) | C8: =DCF!C57 -> 191722.24 | D8: =DCF!D57 -> 235695.44 | E8: =DCF!E57 -> 261607.54
B9: Scale factor = house value / sum of the boxes | C9: =C8/C7 -> 0.970023 | D9: =D8/D7 -> 0.9299333 | E9: =E8/E7 -> 0.93098357 | J9: Close to 1: the boxes' own values add up to about the house number.
B10: Factor applied (ScaleBox in Assumptions) | C10: =IF(ScaleBox=1,C9,1) -> 0.970023 | D10: =IF(ScaleBox=1,D9,1) -> 0.9299333 | E10: =IF(ScaleBox=1,E9,1) -> 0.93098357
B11: Sum of the box fair values | C11: =C57+C98+C139+C180 -> 191722.24 | D11: =D57+D98+D139+D180 -> 235695.44 | E11: =E57+E98+E139+E180 -> 261607.54
B12: Memo: sum of the FCFF pieces at the house rate (house mechanics) = house value | C12: =C60+C101+C142+C183 -> 191722.24 | D12: =D60+D101+D142+D183 -> 235695.44 | E12: =E60+E101+E142+E183 -> 261607.54 | J12: The split itself is exact: with every box on the house mechanics and the house rate, the boxes add up to the house value.
B13: Memo: sum of the box values at the house rate (Financials by FCFE) | C13: =C61+C102+C143+C184 -> 185570.93 | D13: =D61+D102+D143+D184 -> 227874.08 | E13: =E61+E102+E143+E184 -> 252798.07 | J13: The boxes as in the house (one rate), for comparison.
B14: Memo: scale factor at the house rate | C14: =C8/C13 -> 1.033148 | D14: =D8/D13 -> 1.0343232 | E14: =E8/E13 -> 1.0348478
B16: Financials (FCFE)
C17: 2026 | D17: 2027 | E17: 2028 | F17: 2029 | G17: 2030 | H17: 2031 | J17: How it is calculated
B18: Share of sales | C18: ='Box Shares'!D19 -> 0.16009415 | D18: ='Box Shares'!E19 -> 0.1642579 | E18: =D18 -> 0.1642579 | F18: =E18 -> 0.1642579 | G18: =F18 -> 0.1642579 | H18: =G18 -> 0.1642579 | J18: Box Shares: 2026-27 consensus; 2028+ as 2027 (the house projects sales from 2027).
B19: Sales | C19: =DCF!N13*C18 -> 25442.323 | D19: =DCF!O13*D18 -> 26900.352 | E19: =DCF!P13*E18 -> 28535.894 | F19: =DCF!Q13*F18 -> 30270.876 | G19: =DCF!R13*G18 -> 32111.345 | H19: =DCF!S13*H18 -> 34063.715 | J19: House sales (DCF sheet) x share.
B20: Share of EBIT | C20: ='Box Shares'!G19 -> 0.20683299 | D20: ='Box Shares'!H19 -> 0.22119544 | E20: ='Box Shares'!I19 -> 0.22985575 | F20: =E20 -> 0.22985575 | G20: =F20 -> 0.22985575 | H20: =G20 -> 0.22985575 | J20: Box Shares: 2026-28 consensus; 2029+ as 2028.
B21: EBIT | C21: =DCF!N19*C20 -> 6842.0354 | D21: =DCF!O19*D20 -> 7715.9607 | E21: =DCF!P19*E20 -> 8578.6786 | F21: =DCF!Q19*F20 -> 9100.2623 | G21: =DCF!R19*G20 -> 9653.5582 | H21: =DCF!S19*H20 -> 10240.495
B22: Share of EBITDA | C22: ='Box Shares'!J19 -> 0.25196485 | D22: ='Box Shares'!K19 -> 0.25096616 | E22: ='Box Shares'!L19 -> 0.2555345 | F22: =E22 -> 0.2555345 | G22: =F22 -> 0.2555345 | H22: =G22 -> 0.2555345 | J22: Box Shares: 2026-28; 2029+ as 2028. Financials includes the EBITDA the index imputes to banks.
B23: EBITDA | C23: =DCF!N21*C22 -> 12427.914 | D23: =DCF!O21*D22 -> 12728.251 | E23: =DCF!P21*E22 -> 13287.025 | F23: =DCF!Q21*F22 -> 14127.636 | G23: =DCF!R21*G22 -> 14986.597 | H23: =DCF!S21*H22 -> 15897.782
B24: Share of capex | C24: ='Box Shares'!P19 -> 0.24802703 | D24: ='Box Shares'!Q19 -> 0.24938824 | E24: =D24 -> 0.24938824 | F24: =E24 -> 0.24938824 | G24: =F24 -> 0.24938824 | H24: =G24 -> 0.24938824 | J24: Box Shares: 2026-27; 2028+ as 2027.
B25: Capex | C25: =DCF!N33*C24 -> -4751.9498 | D25: =DCF!O33*D24 -> -4821.4228 | E25: =DCF!P33*E24 -> -4765.7786 | F25: =DCF!Q33*F24 -> -5055.5379 | G25: =DCF!R33*G24 -> -4387.8392 | H25: =DCF!S33*H24 -> -4654.6199
B26: Share of net income | C26: ='Box Shares'!M19 -> 0.27229092 | D26: ='Box Shares'!N19 -> 0.29478935 | E26: ='Box Shares'!O19 -> 0.3064974 | F26: =E26 -> 0.3064974 | G26: =F26 -> 0.3064974 | H26: =G26 -> 0.3064974 | J26: Box Shares: 2026-28; 2029+ as 2028.
B27: Net income | C27: =DCF!N29*C26 -> 5706.6731 | D27: =DCF!O29*D26 -> 6386.9061 | E27: =DCF!P29*E26 -> 7103.6903 | F27: =DCF!Q29*F26 -> 7535.5947 | G27: =DCF!R29*G26 -> 7993.7588 | H27: =DCF!S29*H26 -> 8479.7794
B28: D&A = EBITDA - EBIT | C28: =C23-C21 -> 5585.8788 | D28: =D23-D21 -> 5012.2903 | E28: =E23-E21 -> 4708.346 | F28: =F23-F21 -> 5027.3741 | G28: =G23-G21 -> 5333.0385 | H28: =H23-H21 -> 5657.2872
B29: Tax rate (house) | C29: =DCF!N25 -> -0.24 | D29: =DCF!O25 -> -0.24 | E29: =DCF!P25 -> -0.24 | F29: =DCF!Q25 -> -0.24 | G29: =DCF!R25 -> -0.24 | H29: =DCF!S25 -> -0.24 | J29: DCF sheet (house, -24%).
B30: NOPAT = EBIT x (1 + tax rate) | C30: =C21*(1+C29) -> 5199.9469 | D30: =D21*(1+D29) -> 5864.1301 | E30: =E21*(1+E29) -> 6519.7958 | F30: =F21*(1+F29) -> 6916.1993 | G30: =G21*(1+G29) -> 7336.7043 | H30: =H21*(1+H29) -> 7782.7759
B31: Working capital (NWC) = -NWC % x sales | C31: =-NWCpct*C19 -> -1017.6929 | D31: =-NWCpct*D19 -> -1076.0141 | E31: =-NWCpct*E19 -> -1141.4357 | F31: =-NWCpct*F19 -> -1210.835 | G31: =-NWCpct*G19 -> -1284.4538 | H31: =-NWCpct*H19 -> -1362.5486
B32: Change in NWC | D32: =D31-C31 -> -58.321171 | E32: =E31-D31 -> -65.421657 | F32: =F31-E31 -> -69.399293 | G32: =G31-F31 -> -73.61877 | H32: =H31-G31 -> -78.094792
B33: FCFF, house = D&A + NOPAT + capex + NWC (level) | C33: =C28+C30+C25+C31 -> 5016.1829 | D33: =D28+D30+D25+D31 -> 4978.9835 | E33: =E28+E30+E25+E31 -> 5320.9274 | F33: =F28+F30+F25+F31 -> 5677.2005 | G33: =G28+G30+G25+G31 -> 6997.4497 | H33: =H28+H30+H25+H31 -> 7422.8946
B34: FCFF with the change in NWC | D34: =D28+D30+D25+D32 -> 5996.6764 | E34: =E28+E30+E25+E32 -> 6396.9415 | F34: =F28+F30+F25+F32 -> 6818.6362 | G34: =G28+G30+G25+G32 -> 8208.2847 | H34: =H28+H30+H25+H32 -> 8707.3484
B35: FCFF used (switch FixNWC) | C35: =C33 -> 5016.1829 | D35: =IF(FixNWC=1,D34,D33) -> 4978.9835 | E35: =IF(FixNWC=1,E34,E33) -> 5320.9274 | F35: =IF(FixNWC=1,F34,F33) -> 5677.2005 | G35: =IF(FixNWC=1,G34,G33) -> 6997.4497 | H35: =IF(FixNWC=1,H34,H33) -> 7422.8946 | J35: FixNWC = 0: house row; 1: corrected row. Sum of the boxes = house FCFF (Checks).
B36: ROE (Financials, Box Shares section 4) | C36: =FinROE -> 0.19870618 | D36: =FinROE -> 0.19870618 | E36: =FinROE -> 0.19870618 | F36: =FinROE -> 0.19870618 | G36: =FinROE -> 0.19870618 | H36: =FinROE -> 0.19870618
B37: FCFE = net income x (1 - g / ROE) | C37: =C27*(1-gLT/C36) -> 4356.8729 | D37: =D27*(1-gLT/D36) -> 4876.2103 | E37: =E27*(1-gLT/E36) -> 5423.4535 | F37: =F27*(1-gLT/F36) -> 5753.1994 | G37: =G27*(1-gLT/G36) -> 6102.994 | H37: =H27*(1-gLT/H36) -> 6474.056 | J37: Financials only: the value used for the box (same rate and g as the house).
B39: Valuation at the end of 2027 | C39: Bear | D39: Base | E39: Bull
B40: Discount rate of the box (Box Rates) | C40: ='Box Rates'!C21 -> 0.13760273 | D40: ='Box Rates'!D21 -> 0.12151612 | E40: ='Box Rates'!E21 -> 0.11448979 | J40: BoxRate 0: the house rate; 1: g + (house rate - g) x the box's relative cash yield, at least real rate + floor; 2: CAPM, real rate + beta x ERP.
B41: FCFF 2031 | C41: =$H$35 -> 7422.8946 | D41: =$H$35 -> 7422.8946 | E41: =$H$35 -> 7422.8946
B42: Terminal value = FCFF 2031 x (1 + g) / (rate - g) | C42: =C41*(1+gLT)/(C40-gLT) -> 85778.553 | D42: =D41*(1+gLT)/(D40-gLT) -> 104296.5 | E42: =E41*(1+gLT)/(E40-gLT) -> 115154.77
B43: Periods the TV is discounted | C43: =5-FixTV -> 5 | D43: =5-FixTV -> 5 | E43: =5-FixTV -> 5
...

Sheet DCF
B1: Ibovespa - DCF (house model rolled to end-2027)
B2: Replica of Target rows 17-65 of DCF Ibov 2026_Out.xlsx, in Ibovespa points, extended to 2031. Blue = house file input; pink = projection rule.
B3: Legend: | C3: input | D3: assumption | E3: formula
B5: Projections (index points)
C6: 2015 | D6: 2016 | E6: 2017 | F6: 2018 | G6: 2019 | H6: 2020 | I6: 2021 | J6: 2022 | K6: 2023 | L6: 2024 | M6: 2025 | N6: 2026 | O6: 2027 | P6: 2028 | Q6: 2029 | R6: 2030 | S6: 2031 | U6: How it is calculated (house Target row)
C7: Actual | D7: Actual | E7: Actual | F7: Actual | G7: Actual | H7: Actual | I7: Actual | J7: Actual | K7: Actual | L7: Actual | M7: Actual | N7: Consensus | O7: Consensus | P7: Consensus | Q7: Projection | R7: Projection | S7: Projection
B8: Real GDP | J8: 0.029 | K8: 0.029 | L8: 0.031 | M8: 0.021 | N8: 0.018 | O8: 0.01 | P8: 0.02 | Q8: 0.02 | R8: 0.02 | S8: 0.02
B9: Inflation | C9: 0.1067 | D9: 0.0629 | E9: 0.0295 | F9: 0.0375 | G9: 0.0431 | H9: 0.045 | I9: 0.101 | J9: 0.058 | K9: 0.046 | L9: 0.046 | M9: 0.045 | N9: 0.038 | O9: 0.04 | P9: 0.04 | Q9: 0.04 | R9: 0.04 | S9: 0.04
B10: Nominal GDP | C10: =(1+C8)*(1+C9)-1 -> 0.1067 | D10: =(1+D8)*(1+D9)-1 -> 0.0629 | E10: =(1+E8)*(1+E9)-1 -> 0.0295 | F10: =(1+F8)*(1+F9)-1 -> 0.0375 | G10: =(1+G8)*(1+G9)-1 -> 0.0431 | H10: =(1+H8)*(1+H9)-1 -> 0.045 | I10: =(1+I8)*(1+I9)-1 -> 0.101 | J10: =(1+J8)*(1+J9)-1 -> 0.088682 | ... S10: =(1+S8)*(1+S9)-1 -> 0.0608 | U10: (1 + real GDP) x (1 + inflation) - 1 (row 20).
B11: Sales growth | D11: =D13/C13-1 -> 0.031809353 | E11: =E13/D13-1 -> 0.014830489 | F11: =F13/E13-1 -> 0.16663413 | G11: =G13/F13-1 -> 0.12933978 | H11: =H13/G13-1 -> 0.081369435 | I11: =I13/H13-1 -> 0.33636272 | J11: =J13/I13-1 -> 0.20564508 | K11: =K13/J13-1 -> 0.058209825 | ... O11: =O13/N13-1 -> 0.030505723 | P11: =P10*P12 -> 0.0608 | Q11: =Q10*Q12 -> 0.0608 | R11: =R10*R12 -> 0.0608 | S11: =S10*S12 -> 0.0608 | U11: Actual/consensus: sales / previous - 1. Projection: nominal GDP x ratio (row 21).
B12: Ratio (sales growth / nominal GDP) | D12: =D11/D10 -> 0.50571309 | E12: =E11/E10 -> 0.50272844 | F12: =F11/F10 -> 4.4435767 | G12: =G11/G10 -> 3.0009229 | H12: =H11/H10 -> 1.8082097 | I12: =I11/I10 -> 3.3303239 | J12: =J11/J10 -> 2.3189044 | K12: =K11/K10 -> 0.76256746 | ... O12: =O11/O10 -> 0.60527228 | P12: 1 | Q12: 1 | R12: 1 | S12: 1
B13: Sales | C13: 51357.85 | D13: 52991.51 | E13: 53777.4 | F13: 62738.55 | G13: 70853.14 | H13: 76618.42 | I13: 102390 | J13: 123446 | K13: 130631.77 | L13: 138166 | M13: 150140 | N13: 158921 | O13: 163769 | P13: =O13*(1+P11) -> 173726.16 | Q13: =P13*(1+Q11) -> 184288.71 | R13: =Q13*(1+R11) -> 195493.46 | S13: =R13*(1+S11) -> 207379.46 | U13: To 2027: house file (consensus 2026-27). 2028+: previous x (1 + growth) (row 25).
B14: COGS | C14: =C13*(C15-1) -> -38374.586 | D14: =D13*(D15-1) -> -39865.513 | E14: =E13*(E15-1) -> -38940.215 | F14: =F13*(F15-1) -> -44801.599 | G14: =G13*(G15-1) -> -50192.364 | H14: =H13*(H15-1) -> -53939.368 | I14: =I13*(I15-1) -> -65529.6 | J14: =J13*(J15-1) -> -82708.82 | ... S14: =S13*(S15-1) -> -133199.83 | U14: Sales x (gross margin - 1) (row 26).
B15: Gross margin % | C15: 0.2528 | D15: 0.2477 | E15: 0.2759 | F15: 0.2859 | G15: 0.2916 | H15: 0.296 | I15: 0.36 | J15: 0.33 | K15: 0.2757 | L15: 0.2514 | M15: 0.2737 | N15: 0.388 | O15: 0.3827 | P15: 0.3577 | Q15: =P15 -> 0.3577 | R15: =Q15 -> 0.3577 | S15: =R15 -> 0.3577 | U15: To 2028: house file. 2029+: previous year (row 27).
B16: Gross profit | C16: =C13+C14 -> 12983.264 | D16: =D13+D14 -> 13125.997 | E16: =E13+E14 -> 14837.185 | F16: =F13+F14 -> 17936.951 | G16: =G13+G14 -> 20660.776 | H16: =H13+H14 -> 22679.052 | I16: =I13+I14 -> 36860.4 | J16: =J13+J14 -> 40737.18 | ... S16: =S13+S14 -> 74179.633
B17: SG&A | C17: =C19-C16 -> -11461.954 | D17: =D19-D16 -> -6806.437 | E17: =E19-E16 -> -7556.5447 | F17: =F19-F16 -> -8126.6114 | G17: =G19-G16 -> -11860.076 | H17: =H19-H16 -> -11988.992 | I17: =I19-I16 -> -13266.4 | J17: =J19-J16 -> -14963.67 | ... P17: =P19-P16 -> -24819.836 | Q17: =Q13*Q18 -> -26328.882 | R17: =R13*R18 -> -27929.678 | S17: =S13*S18 -> -29627.802 | U17: To 2028: EBIT - gross profit. 2029+: sales x SG&A % (row 29).
B18: SG&A % of sales | C18: =C17/C13 -> -0.22317824 | D18: =D17/D13 -> -0.12844392 | E18: =E17/E13 -> -0.14051525 | F18: =F17/F13 -> -0.12953139 | G18: =G17/G13 -> -0.16738956 | H18: =H17/H13 -> -0.15647663 | I18: =I17/I13 -> -0.12956734 | J18: =J17/J13 -> -0.12121632 | ... P18: =P17/P13 -> -0.14286758 | Q18: =P18 -> -0.14286758 | R18: =Q18 -> -0.14286758 | S18: =R18 -> -0.14286758 | U18: 2029+: previous year's % (row 30).
B19: EBIT | C19: 1521.31 | D19: 6319.56 | E19: 7280.64 | F19: 9810.34 | G19: 8800.7 | H19: 10690.06 | I19: 23594 | J19: 25773.51 | K19: 21324.34 | L19: 25291.3 | M19: 20846 | N19: 33080 | O19: 34883 | P19: 37322.01 | Q19: =Q16+Q17 -> 39591.188 | R19: =R16+R17 -> 41998.332 | S19: =S16+S17 -> 44551.831 | U19: To 2028: house file (consensus). 2029+: gross profit + SG&A (row 31).
B20: EBIT margin % | C20: =C19/C13 -> 0.029621762 | D20: =D19/D13 -> 0.11925608 | E20: =E19/E13 -> 0.13538475 | F20: =F19/F13 -> 0.15636861 | G20: =G19/G13 -> 0.12421044 | H20: =H19/H13 -> 0.13952337 | I20: =I19/I13 -> 0.23043266 | J20: =J19/J13 -> 0.20878368 | ... S20: =S19/S13 -> 0.21483242
B21: EBITDA | C21: 11322.26 | D21: 11803.92 | E21: 13642.8 | F21: 17850.25 | G21: 18979.35 | H21: 19022.66 | I21: 31545 | J21: 36387.17 | K21: 32032.37 | L21: 37339 | M21: 33801 | N21: 49324 | O21: 50717 | P21: 51996.99 | Q21: =Q13*Q22 -> 55286.612 | R21: =R13*R22 -> 58648.038 | S21: =S13*S22 -> 62213.838 | U21: To 2028: house file (consensus). 2029+: sales x EBITDA margin (row 33).
B22: EBITDA margin % | C22: =C21/C13 -> 0.22045822 | D22: =D21/D13 -> 0.22275115 | E22: =E21/E13 -> 0.25369021 | F22: =F21/F13 -> 0.28451805 | G22: =G21/G13 -> 0.26786886 | H22: =H21/H13 -> 0.24827789 | I22: =I21/I13 -> 0.30808673 | J22: =J21/J13 -> 0.29476184 | ... P22: =P21/P13 -> 0.29930433 | Q22: 0.3 | R22: 0.3 | S22: 0.3 | U22: 2029+: 30% (house, row 34).
B23: D&A | C23: =C21-C19 -> 9800.95 | D23: =D21-D19 -> 5484.36 | E23: =E21-E19 -> 6362.16 | F23: =F21-F19 -> 8039.91 | G23: =G21-G19 -> 10178.65 | H23: =H21-H19 -> 8332.6 | I23: =I21-I19 -> 7951 | J23: =J21-J19 -> 10613.66 | ... S23: =S21-S19 -> 17662.007 | U23: EBITDA - EBIT (row 35).
B24: D&A % of sales | C24: =C23/C13 -> 0.19083645 | D24: =D23/D13 -> 0.10349507 | E24: =E23/E13 -> 0.11830546 | F24: =F23/F13 -> 0.12814944 | G24: =G23/G13 -> 0.14365842 | H24: =H23/H13 -> 0.10875453 | I24: =I23/I13 -> 0.077654068 | J24: =J23/J13 -> 0.08597816 | ... S24: =S23/S13 -> 0.085167582
B25: Tax rate | C25: -0.25 | D25: =C25 -> -0.25 | E25: =D25 -> -0.25 | F25: =E25 -> -0.25 | G25: =F25 -> -0.25 | H25: =G25 -> -0.25 | I25: =H25 -> -0.25 | J25: =I25 -> -0.25 | K25: =J25 -> -0.25 | L25: -0.24 | M25: =L25 -> -0.24 | N25: =M25 -> -0.24 | O25: =N25 -> -0.24 | P25: =O25 -> -0.24 | Q25: =P25 -> -0.24 | R25: =Q25 -> -0.24 | S25: =R25 -> -0.24 | U25: -25% to 2023, -24% from 2024 (row 37).
B26: NOPAT | C26: =C19*(1+C25) -> 1140.9825 | D26: =D19*(1+D25) -> 4739.67 | E26: =E19*(1+E25) -> 5460.48 | F26: =F19*(1+F25) -> 7357.755 | G26: =G19*(1+G25) -> 6600.525 | H26: =H19*(1+H25) -> 8017.545 | I26: =I19*(1+I25) -> 17695.5 | J26: =J19*(1+J25) -> 19330.132 | ... S26: =S19*(1+S25) -> 33859.392 | U26: EBIT x (1 + tax rate) (row 38).
B27: Net interest expense | C27: =C29-C26 -> -1992.7125 | D27: =D29-D26 -> -1693.5 | E27: =E29-E26 -> -1553.31 | F27: =F29-F26 -> -1433.345 | G27: =G29-G26 -> -1239.105 | H27: =H29-H26 -> -4140.545 | I27: =I29-I26 -> -2007.5 | J27: =J29-J26 -> -561.0525 | ... P27: =P29-P26 -> -5187.7276 | Q27: =Q13*Q28 -> -5503.1414 | R27: =R13*R28 -> -5837.7324 | S27: =S13*S28 -> -6192.6666 | U27: To 2028: net income - NOPAT. 2029+: sales x interest % (row 39).
B28: Interest % of sales | C28: =C27/C13 -> -0.038800544 | D28: =D27/D13 -> -0.031957949 | E28: =E27/E13 -> -0.028884067 | F28: =F27/F13 -> -0.02284632 | G28: =G27/G13 -> -0.017488357 | H28: =H27/H13 -> -0.054041117 | I28: =I27/I13 -> -0.019606407 | J28: =J27/J13 -> -0.0045449225 | ... P28: =P27/P13 -> -0.029861523 | Q28: =P28 -> -0.029861523 | R28: =Q28 -> -0.029861523 | S28: =R28 -> -0.029861523 | U28: 2029+: previous year's % (row 40).
B29: Net income (EPS, index pts) | C29: -851.73 | D29: 3046.17 | E29: 3907.17 | F29: 5924.41 | G29: 5361.42 | H29: 3877 | I29: 15688 | J29: 18769.08 | K29: 13729.57 | L29: 14944 | M29: 13889 | N29: 20958 | O29: 21666 | P29: 23177 | Q29: =Q26+Q27 -> 24586.162 | R29: =R26+R27 -> 26081 | S29: =S26+S27 -> 27666.725 | U29: To 2028: house file (consensus EPS). 2029+: NOPAT + net interest (row 41).
B30: Net margin % | C30: =C29/C13 -> -0.016584222 | D30: =D29/D13 -> 0.057484114 | E30: =E29/E13 -> 0.072654498 | F30: =F29/F13 -> 0.094430139 | G30: =G29/G13 -> 0.075669476 | H30: =H29/H13 -> 0.050601409 | I30: =I29/I13 -> 0.15321809 | J30: =J29/J13 -> 0.15204284 | ... S30: =S29/S13 -> 0.13341111
B31: Working capital (NWC) | C31: =-NWCpct*C13 -> -2054.314 | D31: =-NWCpct*D13 -> -2119.6604 | E31: =-NWCpct*E13 -> -2151.096 | F31: =-NWCpct*F13 -> -2509.542 | G31: =-NWCpct*G13 -> -2834.1256 | H31: =-NWCpct*H13 -> -3064.7368 | I31: =-NWCpct*I13 -> -4095.6 | J31: =-NWCpct*J13 -> -4937.84 | ... S31: =-NWCpct*S13 -> -8295.1784 | U31: -NWC % x sales (Assumptions; row 43).
B32: Change in NWC | D32: =D31-C31 -> -65.3464 | E32: =E31-D31 -> -31.4356 | F32: =F31-E31 -> -358.446 | G32: =G31-F31 -> -324.5836 | H32: =H31-G31 -> -230.6112 | I32: =I31-H31 -> -1030.8632 | J32: =J31-I31 -> -842.24 | K32: =K31-J31 -> -287.4308 | ... S32: =S31-R31 -> -475.44009
B33: Capex | C33: -5294.22 | D33: -3805.46 | E33: -3278.37 | F33: -3699.48 | G33: -3779.44 | H33: -3672 | I33: -4618.18 | J33: -6641.75 | K33: -8753.81 | L33: -10938 | M33: -18822 | N33: -19159 | O33: -19333 | P33: =P13*P34 -> -19109.877 | Q33: =Q13*Q34 -> -20271.758 | R33: =R13*R34 -> -17594.411 | S33: =S13*S34 -> -18664.151 | U33: To 2027: house file. 2028+: sales x capex % (row 46).
B34: Capex % of sales | C34: =C33/C13 -> -0.10308492 | D34: =D33/D13 -> -0.071812636 | E34: =E33/E13 -> -0.060961854 | F34: =F33/F13 -> -0.058966616 | G34: =G33/G13 -> -0.053341884 | H34: =H33/H13 -> -0.047925812 | I34: =I33/I13 -> -0.045103819 | J34: =J33/J13 -> -0.053802877 | ... O34: =O33/O13 -> -0.11805042 | P34: -0.11 | Q34: =P34 -> -0.11 | R34: -0.09 | S34: =R34 -> -0.09 | U34: 2028-29: -11%; 2030: -9% (house); 2031: as 2030 (row 47).
B35: FCFF, house = D&A + NOPAT + capex + NWC (level) | C35: =C23+C26+C33+C31 -> 3593.3985 | D35: =D23+D26+D33+D31 -> 4298.9096 | E35: =E23+E26+E33+E31 -> 6393.174 | F35: =F23+F26+F33+F31 -> 9188.643 | G35: =G23+G26+G33+G31 -> 10165.609 | H35: =H23+H26+H33+H31 -> 9613.4082 | I35: =I23+I26+I33+I31 -> 16932.72 | J35: =J23+J26+J33+J31 -> 18364.202 | ... S35: =S23+S26+S33+S31 -> 24562.069 | U35: D&A + NOPAT + capex + NWC level (row 44): what the house discounts.
B36: FCFF with the change in NWC | D36: =D23+D26+D33+D32 -> 6353.2236 | E36: =E23+E26+E33+E32 -> 8512.8344 | F36: =F23+F26+F33+F32 -> 11339.739 | G36: =G23+G26+G33+G32 -> 12675.151 | H36: =H23+H26+H33+H32 -> 12447.534 | I36: =I23+I26+I33+I32 -> 19997.457 | J36: =J23+J26+J33+J32 -> 22459.802 | K36: =K23+K26+K33+K32 -> 17660.044 | ... S36: =S23+S26+S33+S32 -> 32381.807 | U36: D&A + NOPAT + capex + change in NWC.
B37: FCFF used in the valuation (switch FixNWC) | C37: =C35 -> 3593.3985 | D37: =IF(FixNWC=1,D36,D35) -> 4298.9096 | E37: =IF(FixNWC=1,E36,E35) -> 6393.174 | F37: =IF(FixNWC=1,F36,F35) -> 9188.643 | G37: =IF(FixNWC=1,G36,G35) -> 10165.609 | H37: =IF(FixNWC=1,H36,H35) -> 9613.4082 | I37: =IF(FixNWC=1,I36,I35) -> 16932.72 | J37: =IF(FixNWC=1,J36,J35) -> 18364.202 | K37: =IF(FixNWC=1,K36,K35) -> 12722.204 | ... S37: =IF(FixNWC=1,S36,S35) -> 24562.069 | U37: FixNWC = 0: the house row; 1: the corrected row.
B38: memo: FCFF = EBITDA x (1 - tax) + capex | C38: 3875.1 | D38: 3414.98 | E38: 3131.8 | F38: 5798.58 | G38: 7840.38 | H38: 10543 | I38: 15220 | J38: 21728 | K38: 10626.16 | L38: 12342 | M38: 13051 | N38: =N21*(1+N25)+N33 -> 18327.24 | O38: =O21*(1+O25)+O33 -> 19211.92 | P38: =P21*(1+P25)+P33 -> 20407.835 | Q38: =Q21*(1+Q25)+Q33 -> 21746.067 | R38: =R21*(1+R25)+R33 -> 26978.097 | S38: =S21*(1+S25)+S33 -> 28618.366 | U38: To 2025: house file. 2026+: EBITDA x (1 + tax) + capex (row 49).
B39: memo: Ibovespa (average to 2020, then the price used) | C39: 49828 | D39: 53350 | E39: 67784 | F39: 81677 | G39: 101000 | H39: 99143 | I39: =IbovUsed -> 208431.92 | J39: =IbovUsed -> 208431.92 | K39: =IbovUsed -> 208431.92 | L39: =IbovUsed -> 208431.92 | M39: =IbovUsed -> 208431.92 | N39: =IbovUsed -> 208431.92 | O39: =IbovUsed -> 208431.92 | P39: =IbovUsed -> 208431.92 | ... S39: =IbovUsed -> 208431.92 | U39: Row 50: average to 2020 (house file), then the Ibovespa price used.
B40: memo: FCF yield | C40: =C38/C39 -> 0.077769527 | D40: =D38/D39 -> 0.064010872 | E40: =E38/E39 -> 0.046202644 | F40: =F38/F39 -> 0.070994037 | G40: =G38/G39 -> 0.077627525 | H40: =H38/H39 -> 0.10634135 | I40: =I38/I39 -> 0.073021445 | J40: =J38/J39 -> 0.10424507 | ... S40: =S38/S39 -> 0.13730318 | U40: Simple FCFF / Ibovespa (row 51).
B42: Valuation: fair value at the end of the year (house Target rows 53-59)
...

Sheet Sensitivity
B1: Ibovespa - Sensitivity: real rate and ERP
B2: The house's real-rate table (tie-out) and a real rate x ERP grid for the end-2027 fair value with the current settings.
B3: Legend: | C3: input | D3: assumption | E3: formula
B5: House table: 5-year real rate vs DCF value (Target rows 120-129)
B6: 5-year real rate | C6: House file, end-2026 | D6: Replica, end-2026 (house settings) | E6: Difference | G6: End-2027, current settings
B7: 0.055 | C7: 263358.81 | D7: =NPV(($B7+0.06),DCF!$O$35:$R$35)+DCF!$R$35*(1+0.047)/(($B7+0.06)-0.047)/(1+($B7+0.06))^5-0 -> 263358.81 | E7: =D7-C7 -> 0 | G7: =NPV(IF(FixInfl=1,(1+$B7+Assumptions!$D$21)*(1+InflLT)-1,$B7+Assumptions!$D$21),DCF!$P$37:$S$37)+DCF!$S$37*(1+gLT)/(IF(FixInfl=1,(1+$B7+Assumptions!$D$21)*(1+InflLT)-1,$B7+Assumptions!$D$21)-gLT)/(1+IF(FixInfl=1,(1+$B7+Assumptions!$D$21)*(1+InflLT)-1,$B7+Assumptions!$D$21))^(4+1-FixTV)-IF(FixND=1,NDmult*DCF!$M$21,0) -> 281862.98
B8: 0.06 | C8: 244298.81 | D8: =NPV(($B8+0.06),DCF!$O$35:$R$35)+DCF!$R$35*(1+0.047)/(($B8+0.06)-0.047)/(1+($B8+0.06))^5-0 -> 244298.81 | E8: =D8-C8 -> 0 | G8: =NPV(IF(FixInfl=1,(1+$B8+Assumptions!$D$21)*(1+InflLT)-1,$B8+Assumptions!$D$21),DCF!$P$37:$S$37)+DCF!$S$37*(1+gLT)/(IF(FixInfl=1,(1+$B8+Assumptions!$D$21)*(1+InflLT)-1,$B8+Assumptions!$D$21)-gLT)/(1+IF(FixInfl=1,(1+$B8+Assumptions!$D$21)*(1+InflLT)-1,$B8+Assumptions!$D$21))^(4+1-FixTV)-IF(FixND=1,NDmult*DCF!$M$21,0) -> 261607.54
B9: 0.07 | C9: 213168.52 | D9: =NPV(($B9+0.06),DCF!$O$35:$R$35)+DCF!$R$35*(1+0.047)/(($B9+0.06)-0.047)/(1+($B9+0.06))^5-0 -> 213168.52 | E9: =D9-C9 -> 0 | G9: =NPV(IF(FixInfl=1,(1+$B9+Assumptions!$D$21)*(1+InflLT)-1,$B9+Assumptions!$D$21),DCF!$P$37:$S$37)+DCF!$S$37*(1+gLT)/(IF(FixInfl=1,(1+$B9+Assumptions!$D$21)*(1+InflLT)-1,$B9+Assumptions!$D$21)-gLT)/(1+IF(FixInfl=1,(1+$B9+Assumptions!$D$21)*(1+InflLT)-1,$B9+Assumptions!$D$21))^(4+1-FixTV)-IF(FixND=1,NDmult*DCF!$M$21,0) -> 228513.31
B10: 0.0742 | C10: 202259.17 | D10: =NPV(($B10+0.06),DCF!$O$35:$R$35)+DCF!$R$35*(1+0.047)/(($B10+0.06)-0.047)/(1+($B10+0.06))^5-0 -> 202259.17 | E10: =D10-C10 -> 0 | G10: =NPV(IF(FixInfl=1,(1+$B10+Assumptions!$D$21)*(1+InflLT)-1,$B10+Assumptions!$D$21),DCF!$P$37:$S$37)+DCF!$S$37*(1+gLT)/(IF(FixInfl=1,(1+$B10+Assumptions!$D$21)*(1+InflLT)-1,$B10+Assumptions!$D$21)-gLT)/(1+IF(FixInfl=1,(1+$B10+Assumptions!$D$21)*(1+InflLT)-1,$B10+Assumptions!$D$21))^(4+1-FixTV)-IF(FixND=1,NDmult*DCF!$M$21,0) -> 216911.5
B11: 0.075 | C11: 200301.58 | D11: =NPV(($B11+0.06),DCF!$O$35:$R$35)+DCF!$R$35*(1+0.047)/(($B11+0.06)-0.047)/(1+($B11+0.06))^5-0 -> 200301.58 | E11: =D11-C11 -> 0 | G11: =NPV(IF(FixInfl=1,(1+$B11+Assumptions!$D$21)*(1+InflLT)-1,$B11+Assumptions!$D$21),DCF!$P$37:$S$37)+DCF!$S$37*(1+gLT)/(IF(FixInfl=1,(1+$B11+Assumptions!$D$21)*(1+InflLT)-1,$B11+Assumptions!$D$21)-gLT)/(1+IF(FixInfl=1,(1+$B11+Assumptions!$D$21)*(1+InflLT)-1,$B11+Assumptions!$D$21))^(4+1-FixTV)-IF(FixND=1,NDmult*DCF!$M$21,0) -> 214829.39
B12: 0.08 | C12: 188845.17 | D12: =NPV(($B12+0.06),DCF!$O$35:$R$35)+DCF!$R$35*(1+0.047)/(($B12+0.06)-0.047)/(1+($B12+0.06))^5-0 -> 188845.17 | E12: =D12-C12 -> 0 | G12: =NPV(IF(FixInfl=1,(1+$B12+Assumptions!$D$21)*(1+InflLT)-1,$B12+Assumptions!$D$21),DCF!$P$37:$S$37)+DCF!$S$37*(1+gLT)/(IF(FixInfl=1,(1+$B12+Assumptions!$D$21)*(1+InflLT)-1,$B12+Assumptions!$D$21)-gLT)/(1+IF(FixInfl=1,(1+$B12+Assumptions!$D$21)*(1+InflLT)-1,$B12+Assumptions!$D$21))^(4+1-FixTV)-IF(FixND=1,NDmult*DCF!$M$21,0) -> 202642.39
B13: 0.085 | C13: 178582.43 | D13: =NPV(($B13+0.06),DCF!$O$35:$R$35)+DCF!$R$35*(1+0.047)/(($B13+0.06)-0.047)/(1+($B13+0.06))^5-0 -> 178582.43 | E13: =D13-C13 -> 0 | G13: =NPV(IF(FixInfl=1,(1+$B13+Assumptions!$D$21)*(1+InflLT)-1,$B13+Assumptions!$D$21),DCF!$P$37:$S$37)+DCF!$S$37*(1+gLT)/(IF(FixInfl=1,(1+$B13+Assumptions!$D$21)*(1+InflLT)-1,$B13+Assumptions!$D$21)-gLT)/(1+IF(FixInfl=1,(1+$B13+Assumptions!$D$21)*(1+InflLT)-1,$B13+Assumptions!$D$21))^(4+1-FixTV)-IF(FixND=1,NDmult*DCF!$M$21,0) -> 191722.24
B14: 0.09 | C14: 169338.66 | D14: =NPV(($B14+0.06),DCF!$O$35:$R$35)+DCF!$R$35*(1+0.047)/(($B14+0.06)-0.047)/(1+($B14+0.06))^5-0 -> 169338.66 | E14: =D14-C14 -> 0 | G14: =NPV(IF(FixInfl=1,(1+$B14+Assumptions!$D$21)*(1+InflLT)-1,$B14+Assumptions!$D$21),DCF!$P$37:$S$37)+DCF!$S$37*(1+gLT)/(IF(FixInfl=1,(1+$B14+Assumptions!$D$21)*(1+InflLT)-1,$B14+Assumptions!$D$21)-gLT)/(1+IF(FixInfl=1,(1+$B14+Assumptions!$D$21)*(1+InflLT)-1,$B14+Assumptions!$D$21))^(4+1-FixTV)-IF(FixND=1,NDmult*DCF!$M$21,0) -> 181883.6
B15: House settings: ERP 6.0%, g 4.7%, no corrections, house FCFF. The house table is an Excel data table on Target!C56.
B18: End-2027 fair value (index pts), current settings
B19: Real rate \ ERP | C19: 0.04 | D19: 0.05 | E19: 0.06 | F19: 0.07 | G19: 0.08
B20: 0.05 | C20: =NPV(IF(FixInfl=1,(1+$B20+C$19)*(1+InflLT)-1,$B20+C$19),DCF!$P$37:$S$37)+DCF!$S$37*(1+gLT)/(IF(FixInfl=1,(1+$B20+C$19)*(1+InflLT)-1,$B20+C$19)-gLT)/(1+IF(FixInfl=1,(1+$B20+C$19)*(1+InflLT)-1,$B20+C$19))^(4+1-FixTV)-IF(FixND=1,NDmult*DCF!$M$21,0) -> 454824.27 | D20: =NPV(IF(FixInfl=1,(1+$B20+D$19)*(1+InflLT)-1,$B20+D$19),DCF!$P$37:$S$37)+DCF!$S$37*(1+gLT)/(IF(FixInfl=1,(1+$B20+D$19)*(1+InflLT)-1,$B20+D$19)-gLT)/(1+IF(FixInfl=1,(1+$B20+D$19)*(1+InflLT)-1,$B20+D$19))^(4+1-FixTV)-IF(FixND=1,NDmult*DCF!$M$21,0) -> 365883.78 | E20: =NPV(IF(FixInfl=1,(1+$B20+E$19)*(1+InflLT)-1,$B20+E$19),DCF!$P$37:$S$37)+DCF!$S$37*(1+gLT)/(IF(FixInfl=1,(1+$B20+E$19)*(1+InflLT)-1,$B20+E$19)-gLT)/(1+IF(FixInfl=1,(1+$B20+E$19)*(1+InflLT)-1,$B20+E$19))^(4+1-FixTV)-IF(FixND=1,NDmult*DCF!$M$21,0) -> 305377.76 | F20: =NPV(IF(FixInfl=1,(1+$B20+F$19)*(1+InflLT)-1,$B20+F$19),DCF!$P$37:$S$37)+DCF!$S$37*(1+gLT)/(IF(FixInfl=1,(1+$B20+F$19)*(1+InflLT)-1,$B20+F$19)-gLT)/(1+IF(FixInfl=1,(1+$B20+F$19)*(1+InflLT)-1,$B20+F$19))^(4+1-FixTV)-IF(FixND=1,NDmult*DCF!$M$21,0) -> 261607.54 | G20: =NPV(IF(FixInfl=1,(1+$B20+G$19)*(1+InflLT)-1,$B20+G$19),DCF!$P$37:$S$37)+DCF!$S$37*(1+gLT)/(IF(FixInfl=1,(1+$B20+G$19)*(1+InflLT)-1,$B20+G$19)-gLT)/(1+IF(FixInfl=1,(1+$B20+G$19)*(1+InflLT)-1,$B20+G$19))^(4+1-FixTV)-IF(FixND=1,NDmult*DCF!$M$21,0) -> 228513.31
B21: 0.055 | C21: =NPV(IF(FixInfl=1,(1+$B21+C$19)*(1+InflLT)-1,$B21+C$19),DCF!$P$37:$S$37)+DCF!$S$37*(1+gLT)/(IF(FixInfl=1,(1+$B21+C$19)*(1+InflLT)-1,$B21+C$19)-gLT)/(1+IF(FixInfl=1,(1+$B21+C$19)*(1+InflLT)-1,$B21+C$19))^(4+1-FixTV)-IF(FixND=1,NDmult*DCF!$M$21,0) -> 405687.66 | D21: =NPV(IF(FixInfl=1,(1+$B21+D$19)*(1+InflLT)-1,$B21+D$19),DCF!$P$37:$S$37)+DCF!$S$37*(1+gLT)/(IF(FixInfl=1,(1+$B21+D$19)*(1+InflLT)-1,$B21+D$19)-gLT)/(1+IF(FixInfl=1,(1+$B21+D$19)*(1+InflLT)-1,$B21+D$19))^(4+1-FixTV)-IF(FixND=1,NDmult*DCF!$M$21,0) -> 332996.75 | E21: =NPV(IF(FixInfl=1,(1+$B21+E$19)*(1+InflLT)-1,$B21+E$19),DCF!$P$37:$S$37)+DCF!$S$37*(1+gLT)/(IF(FixInfl=1,(1+$B21+E$19)*(1+InflLT)-1,$B21+E$19)-gLT)/(1+IF(FixInfl=1,(1+$B21+E$19)*(1+InflLT)-1,$B21+E$19))^(4+1-FixTV)-IF(FixND=1,NDmult*DCF!$M$21,0) -> 281862.98 | F21: =NPV(IF(FixInfl=1,(1+$B21+F$19)*(1+InflLT)-1,$B21+F$19),DCF!$P$37:$S$37)+DCF!$S$37*(1+gLT)/(IF(FixInfl=1,(1+$B21+F$19)*(1+InflLT)-1,$B21+F$19)-gLT)/(1+IF(FixInfl=1,(1+$B21+F$19)*(1+InflLT)-1,$B21+F$19))^(4+1-FixTV)-IF(FixND=1,NDmult*DCF!$M$21,0) -> 243983.24 | G21: =NPV(IF(FixInfl=1,(1+$B21+G$19)*(1+InflLT)-1,$B21+G$19),DCF!$P$37:$S$37)+DCF!$S$37*(1+gLT)/(IF(FixInfl=1,(1+$B21+G$19)*(1+InflLT)-1,$B21+G$19)-gLT)/(1+IF(FixInfl=1,(1+$B21+G$19)*(1+InflLT)-1,$B21+G$19))^(4+1-FixTV)-IF(FixND=1,NDmult*DCF!$M$21,0) -> 214829.39
B22: 0.06 | C22: =NPV(IF(FixInfl=1,(1+$B22+C$19)*(1+InflLT)-1,$B22+C$19),DCF!$P$37:$S$37)+DCF!$S$37*(1+gLT)/(IF(FixInfl=1,(1+$B22+C$19)*(1+InflLT)-1,$B22+C$19)-gLT)/(1+IF(FixInfl=1,(1+$B22+C$19)*(1+InflLT)-1,$B22+C$19))^(4+1-FixTV)-IF(FixND=1,NDmult*DCF!$M$21,0) -> 365883.78 | D22: =NPV(IF(FixInfl=1,(1+$B22+D$19)*(1+InflLT)-1,$B22+D$19),DCF!$P$37:$S$37)+DCF!$S$37*(1+gLT)/(IF(FixInfl=1,(1+$B22+D$19)*(1+InflLT)-1,$B22+D$19)-gLT)/(1+IF(FixInfl=1,(1+$B22+D$19)*(1+InflLT)-1,$B22+D$19))^(4+1-FixTV)-IF(FixND=1,NDmult*DCF!$M$21,0) -> 305377.76 | E22: =NPV(IF(FixInfl=1,(1+$B22+E$19)*(1+InflLT)-1,$B22+E$19),DCF!$P$37:$S$37)+DCF!$S$37*(1+gLT)/(IF(FixInfl=1,(1+$B22+E$19)*(1+InflLT)-1,$B22+E$19)-gLT)/(1+IF(FixInfl=1,(1+$B22+E$19)*(1+InflLT)-1,$B22+E$19))^(4+1-FixTV)-IF(FixND=1,NDmult*DCF!$M$21,0) -> 261607.54 | F22: =NPV(IF(FixInfl=1,(1+$B22+F$19)*(1+InflLT)-1,$B22+F$19),DCF!$P$37:$S$37)+DCF!$S$37*(1+gLT)/(IF(FixInfl=1,(1+$B22+F$19)*(1+InflLT)-1,$B22+F$19)-gLT)/(1+IF(FixInfl=1,(1+$B22+F$19)*(1+InflLT)-1,$B22+F$19))^(4+1-FixTV)-IF(FixND=1,NDmult*DCF!$M$21,0) -> 228513.31 | G22: =NPV(IF(FixInfl=1,(1+$B22+G$19)*(1+InflLT)-1,$B22+G$19),DCF!$P$37:$S$37)+DCF!$S$37*(1+gLT)/(IF(FixInfl=1,(1+$B22+G$19)*(1+InflLT)-1,$B22+G$19)-gLT)/(1+IF(FixInfl=1,(1+$B22+G$19)*(1+InflLT)-1,$B22+G$19))^(4+1-FixTV)-IF(FixND=1,NDmult*DCF!$M$21,0) -> 202642.39
B23: 0.065 | C23: =NPV(IF(FixInfl=1,(1+$B23+C$19)*(1+InflLT)-1,$B23+C$19),DCF!$P$37:$S$37)+DCF!$S$37*(1+gLT)/(IF(FixInfl=1,(1+$B23+C$19)*(1+InflLT)-1,$B23+C$19)-gLT)/(1+IF(FixInfl=1,(1+$B23+C$19)*(1+InflLT)-1,$B23+C$19))^(4+1-FixTV)-IF(FixND=1,NDmult*DCF!$M$21,0) -> 332996.75 | D23: =NPV(IF(FixInfl=1,(1+$B23+D$19)*(1+InflLT)-1,$B23+D$19),DCF!$P$37:$S$37)+DCF!$S$37*(1+gLT)/(IF(FixInfl=1,(1+$B23+D$19)*(1+InflLT)-1,$B23+D$19)-gLT)/(1+IF(FixInfl=1,(1+$B23+D$19)*(1+InflLT)-1,$B23+D$19))^(4+1-FixTV)-IF(FixND=1,NDmult*DCF!$M$21,0) -> 281862.98 | E23: =NPV(IF(FixInfl=1,(1+$B23+E$19)*(1+InflLT)-1,$B23+E$19),DCF!$P$37:$S$37)+DCF!$S$37*(1+gLT)/(IF(FixInfl=1,(1+$B23+E$19)*(1+InflLT)-1,$B23+E$19)-gLT)/(1+IF(FixInfl=1,(1+$B23+E$19)*(1+InflLT)-1,$B23+E$19))^(4+1-FixTV)-IF(FixND=1,NDmult*DCF!$M$21,0) -> 243983.24 | F23: =NPV(IF(FixInfl=1,(1+$B23+F$19)*(1+InflLT)-1,$B23+F$19),DCF!$P$37:$S$37)+DCF!$S$37*(1+gLT)/(IF(FixInfl=1,(1+$B23+F$19)*(1+InflLT)-1,$B23+F$19)-gLT)/(1+IF(FixInfl=1,(1+$B23+F$19)*(1+InflLT)-1,$B23+F$19))^(4+1-FixTV)-IF(FixND=1,NDmult*DCF!$M$21,0) -> 214829.39 | G23: =NPV(IF(FixInfl=1,(1+$B23+G$19)*(1+InflLT)-1,$B23+G$19),DCF!$P$37:$S$37)+DCF!$S$37*(1+gLT)/(IF(FixInfl=1,(1+$B23+G$19)*(1+InflLT)-1,$B23+G$19)-gLT)/(1+IF(FixInfl=1,(1+$B23+G$19)*(1+InflLT)-1,$B23+G$19))^(4+1-FixTV)-IF(FixND=1,NDmult*DCF!$M$21,0) -> 191722.24
B24: 0.0676 | C24: =NPV(IF(FixInfl=1,(1+$B24+C$19)*(1+InflLT)-1,$B24+C$19),DCF!$P$37:$S$37)+DCF!$S$37*(1+gLT)/(IF(FixInfl=1,(1+$B24+C$19)*(1+InflLT)-1,$B24+C$19)-gLT)/(1+IF(FixInfl=1,(1+$B24+C$19)*(1+InflLT)-1,$B24+C$19))^(4+1-FixTV)-IF(FixND=1,NDmult*DCF!$M$21,0) -> 318060.01 | D24: =NPV(IF(FixInfl=1,(1+$B24+D$19)*(1+InflLT)-1,$B24+D$19),DCF!$P$37:$S$37)+DCF!$S$37*(1+gLT)/(IF(FixInfl=1,(1+$B24+D$19)*(1+InflLT)-1,$B24+D$19)-gLT)/(1+IF(FixInfl=1,(1+$B24+D$19)*(1+InflLT)-1,$B24+D$19))^(4+1-FixTV)-IF(FixND=1,NDmult*DCF!$M$21,0) -> 270967.27 | E24: =NPV(IF(FixInfl=1,(1+$B24+E$19)*(1+InflLT)-1,$B24+E$19),DCF!$P$37:$S$37)+DCF!$S$37*(1+gLT)/(IF(FixInfl=1,(1+$B24+E$19)*(1+InflLT)-1,$B24+E$19)-gLT)/(1+IF(FixInfl=1,(1+$B24+E$19)*(1+InflLT)-1,$B24+E$19))^(4+1-FixTV)-IF(FixND=1,NDmult*DCF!$M$21,0) -> 235695.44 | F24: =NPV(IF(FixInfl=1,(1+$B24+F$19)*(1+InflLT)-1,$B24+F$19),DCF!$P$37:$S$37)+DCF!$S$37*(1+gLT)/(IF(FixInfl=1,(1+$B24+F$19)*(1+InflLT)-1,$B24+F$19)-gLT)/(1+IF(FixInfl=1,(1+$B24+F$19)*(1+InflLT)-1,$B24+F$19))^(4+1-FixTV)-IF(FixND=1,NDmult*DCF!$M$21,0) -> 208321.07 | G24: =NPV(IF(FixInfl=1,(1+$B24+G$19)*(1+InflLT)-1,$B24+G$19),DCF!$P$37:$S$37)+DCF!$S$37*(1+gLT)/(IF(FixInfl=1,(1+$B24+G$19)*(1+InflLT)-1,$B24+G$19)-gLT)/(1+IF(FixInfl=1,(1+$B24+G$19)*(1+InflLT)-1,$B24+G$19))^(4+1-FixTV)-IF(FixND=1,NDmult*DCF!$M$21,0) -> 186481.43
B25: 0.07 | C25: =NPV(IF(FixInfl=1,(1+$B25+C$19)*(1+InflLT)-1,$B25+C$19),DCF!$P$37:$S$37)+DCF!$S$37*(1+gLT)/(IF(FixInfl=1,(1+$B25+C$19)*(1+InflLT)-1,$B25+C$19)-gLT)/(1+IF(FixInfl=1,(1+$B25+C$19)*(1+InflLT)-1,$B25+C$19))^(4+1-FixTV)-IF(FixND=1,NDmult*DCF!$M$21,0) -> 305377.76 | D25: =NPV(IF(FixInfl=1,(1+$B25+D$19)*(1+InflLT)-1,$B25+D$19),DCF!$P$37:$S$37)+DCF!$S$37*(1+gLT)/(IF(FixInfl=1,(1+$B25+D$19)*(1+InflLT)-1,$B25+D$19)-gLT)/(1+IF(FixInfl=1,(1+$B25+D$19)*(1+InflLT)-1,$B25+D$19))^(4+1-FixTV)-IF(FixND=1,NDmult*DCF!$M$21,0) -> 261607.54 | E25: =NPV(IF(FixInfl=1,(1+$B25+E$19)*(1+InflLT)-1,$B25+E$19),DCF!$P$37:$S$37)+DCF!$S$37*(1+gLT)/(IF(FixInfl=1,(1+$B25+E$19)*(1+InflLT)-1,$B25+E$19)-gLT)/(1+IF(FixInfl=1,(1+$B25+E$19)*(1+InflLT)-1,$B25+E$19))^(4+1-FixTV)-IF(FixND=1,NDmult*DCF!$M$21,0) -> 228513.31 | F25: =NPV(IF(FixInfl=1,(1+$B25+F$19)*(1+InflLT)-1,$B25+F$19),DCF!$P$37:$S$37)+DCF!$S$37*(1+gLT)/(IF(FixInfl=1,(1+$B25+F$19)*(1+InflLT)-1,$B25+F$19)-gLT)/(1+IF(FixInfl=1,(1+$B25+F$19)*(1+InflLT)-1,$B25+F$19))^(4+1-FixTV)-IF(FixND=1,NDmult*DCF!$M$21,0) -> 202642.39 | G25: =NPV(IF(FixInfl=1,(1+$B25+G$19)*(1+InflLT)-1,$B25+G$19),DCF!$P$37:$S$37)+DCF!$S$37*(1+gLT)/(IF(FixInfl=1,(1+$B25+G$19)*(1+InflLT)-1,$B25+G$19)-gLT)/(1+IF(FixInfl=1,(1+$B25+G$19)*(1+InflLT)-1,$B25+G$19))^(4+1-FixTV)-IF(FixND=1,NDmult*DCF!$M$21,0) -> 181883.6
B26: 0.075 | C26: =NPV(IF(FixInfl=1,(1+$B26+C$19)*(1+InflLT)-1,$B26+C$19),DCF!$P$37:$S$37)+DCF!$S$37*(1+gLT)/(IF(FixInfl=1,(1+$B26+C$19)*(1+InflLT)-1,$B26+C$19)-gLT)/(1+IF(FixInfl=1,(1+$B26+C$19)*(1+InflLT)-1,$B26+C$19))^(4+1-FixTV)-IF(FixND=1,NDmult*DCF!$M$21,0) -> 281862.98 | D26: =NPV(IF(FixInfl=1,(1+$B26+D$19)*(1+InflLT)-1,$B26+D$19),DCF!$P$37:$S$37)+DCF!$S$37*(1+gLT)/(IF(FixInfl=1,(1+$B26+D$19)*(1+InflLT)-1,$B26+D$19)-gLT)/(1+IF(FixInfl=1,(1+$B26+D$19)*(1+InflLT)-1,$B26+D$19))^(4+1-FixTV)-IF(FixND=1,NDmult*DCF!$M$21,0) -> 243983.24 | E26: =NPV(IF(FixInfl=1,(1+$B26+E$19)*(1+InflLT)-1,$B26+E$19),DCF!$P$37:$S$37)+DCF!$S$37*(1+gLT)/(IF(FixInfl=1,(1+$B26+E$19)*(1+InflLT)-1,$B26+E$19)-gLT)/(1+IF(FixInfl=1,(1+$B26+E$19)*(1+InflLT)-1,$B26+E$19))^(4+1-FixTV)-IF(FixND=1,NDmult*DCF!$M$21,0) -> 214829.39 | F26: =NPV(IF(FixInfl=1,(1+$B26+F$19)*(1+InflLT)-1,$B26+F$19),DCF!$P$37:$S$37)+DCF!$S$37*(1+gLT)/(IF(FixInfl=1,(1+$B26+F$19)*(1+InflLT)-1,$B26+F$19)-gLT)/(1+IF(FixInfl=1,(1+$B26+F$19)*(1+InflLT)-1,$B26+F$19))^(4+1-FixTV)-IF(FixND=1,NDmult*DCF!$M$21,0) -> 191722.24 | G26: =NPV(IF(FixInfl=1,(1+$B26+G$19)*(1+InflLT)-1,$B26+G$19),DCF!$P$37:$S$37)+DCF!$S$37*(1+gLT)/(IF(FixInfl=1,(1+$B26+G$19)*(1+InflLT)-1,$B26+G$19)-gLT)/(1+IF(FixInfl=1,(1+$B26+G$19)*(1+InflLT)-1,$B26+G$19))^(4+1-FixTV)-IF(FixND=1,NDmult*DCF!$M$21,0) -> 172975.46
B27: 0.08 | C27: =NPV(IF(FixInfl=1,(1+$B27+C$19)*(1+InflLT)-1,$B27+C$19),DCF!$P$37:$S$37)+DCF!$S$37*(1+gLT)/(IF(FixInfl=1,(1+$B27+C$19)*(1+InflLT)-1,$B27+C$19)-gLT)/(1+IF(FixInfl=1,(1+$B27+C$19)*(1+InflLT)-1,$B27+C$19))^(4+1-FixTV)-IF(FixND=1,NDmult*DCF!$M$21,0) -> 261607.54 | D27: =NPV(IF(FixInfl=1,(1+$B27+D$19)*(1+InflLT)-1,$B27+D$19),DCF!$P$37:$S$37)+DCF!$S$37*(1+gLT)/(IF(FixInfl=1,(1+$B27+D$19)*(1+InflLT)-1,$B27+D$19)-gLT)/(1+IF(FixInfl=1,(1+$B27+D$19)*(1+InflLT)-1,$B27+D$19))^(4+1-FixTV)-IF(FixND=1,NDmult*DCF!$M$21,0) -> 228513.31 | E27: =NPV(IF(FixInfl=1,(1+$B27+E$19)*(1+InflLT)-1,$B27+E$19),DCF!$P$37:$S$37)+DCF!$S$37*(1+gLT)/(IF(FixInfl=1,(1+$B27+E$19)*(1+InflLT)-1,$B27+E$19)-gLT)/(1+IF(FixInfl=1,(1+$B27+E$19)*(1+InflLT)-1,$B27+E$19))^(4+1-FixTV)-IF(FixND=1,NDmult*DCF!$M$21,0) -> 202642.39 | F27: =NPV(IF(FixInfl=1,(1+$B27+F$19)*(1+InflLT)-1,$B27+F$19),DCF!$P$37:$S$37)+DCF!$S$37*(1+gLT)/(IF(FixInfl=1,(1+$B27+F$19)*(1+InflLT)-1,$B27+F$19)-gLT)/(1+IF(FixInfl=1,(1+$B27+F$19)*(1+InflLT)-1,$B27+F$19))^(4+1-FixTV)-IF(FixND=1,NDmult*DCF!$M$21,0) -> 181883.6 | G27: =NPV(IF(FixInfl=1,(1+$B27+G$19)*(1+InflLT)-1,$B27+G$19),DCF!$P$37:$S$37)+DCF!$S$37*(1+gLT)/(IF(FixInfl=1,(1+$B27+G$19)*(1+InflLT)-1,$B27+G$19)-gLT)/(1+IF(FixInfl=1,(1+$B27+G$19)*(1+InflLT)-1,$B27+G$19))^(4+1-FixTV)-IF(FixND=1,NDmult*DCF!$M$21,0) -> 164873.6
B28: 0.085 | C28: =NPV(IF(FixInfl=1,(1+$B28+C$19)*(1+InflLT)-1,$B28+C$19),DCF!$P$37:$S$37)+DCF!$S$37*(1+gLT)/(IF(FixInfl=1,(1+$B28+C$19)*(1+InflLT)-1,$B28+C$19)-gLT)/(1+IF(FixInfl=1,(1+$B28+C$19)*(1+InflLT)-1,$B28+C$19))^(4+1-FixTV)-IF(FixND=1,NDmult*DCF!$M$21,0) -> 243983.24 | D28: =NPV(IF(FixInfl=1,(1+$B28+D$19)*(1+InflLT)-1,$B28+D$19),DCF!$P$37:$S$37)+DCF!$S$37*(1+gLT)/(IF(FixInfl=1,(1+$B28+D$19)*(1+InflLT)-1,$B28+D$19)-gLT)/(1+IF(FixInfl=1,(1+$B28+D$19)*(1+InflLT)-1,$B28+D$19))^(4+1-FixTV)-IF(FixND=1,NDmult*DCF!$M$21,0) -> 214829.39 | E28: =NPV(IF(FixInfl=1,(1+$B28+E$19)*(1+InflLT)-1,$B28+E$19),DCF!$P$37:$S$37)+DCF!$S$37*(1+gLT)/(IF(FixInfl=1,(1+$B28+E$19)*(1+InflLT)-1,$B28+E$19)-gLT)/(1+IF(FixInfl=1,(1+$B28+E$19)*(1+InflLT)-1,$B28+E$19))^(4+1-FixTV)-IF(FixND=1,NDmult*DCF!$M$21,0) -> 191722.24 | F28: =NPV(IF(FixInfl=1,(1+$B28+F$19)*(1+InflLT)-1,$B28+F$19),DCF!$P$37:$S$37)+DCF!$S$37*(1+gLT)/(IF(FixInfl=1,(1+$B28+F$19)*(1+InflLT)-1,$B28+F$19)-gLT)/(1+IF(FixInfl=1,(1+$B28+F$19)*(1+InflLT)-1,$B28+F$19))^(4+1-FixTV)-IF(FixND=1,NDmult*DCF!$M$21,0) -> 172975.46 | G28: =NPV(IF(FixInfl=1,(1+$B28+G$19)*(1+InflLT)-1,$B28+G$19),DCF!$P$37:$S$37)+DCF!$S$37*(1+gLT)/(IF(FixInfl=1,(1+$B28+G$19)*(1+InflLT)-1,$B28+G$19)-gLT)/(1+IF(FixInfl=1,(1+$B28+G$19)*(1+InflLT)-1,$B28+G$19))^(4+1-FixTV)-IF(FixND=1,NDmult*DCF!$M$21,0) -> 157474.85
B29: 0.09 | C29: =NPV(IF(FixInfl=1,(1+$B29+C$19)*(1+InflLT)-1,$B29+C$19),DCF!$P$37:$S$37)+DCF!$S$37*(1+gLT)/(IF(FixInfl=1,(1+$B29+C$19)*(1+InflLT)-1,$B29+C$19)-gLT)/(1+IF(FixInfl=1,(1+$B29+C$19)*(1+InflLT)-1,$B29+C$19))^(4+1-FixTV)-IF(FixND=1,NDmult*DCF!$M$21,0) -> 228513.31 | D29: =NPV(IF(FixInfl=1,(1+$B29+D$19)*(1+InflLT)-1,$B29+D$19),DCF!$P$37:$S$37)+DCF!$S$37*(1+gLT)/(IF(FixInfl=1,(1+$B29+D$19)*(1+InflLT)-1,$B29+D$19)-gLT)/(1+IF(FixInfl=1,(1+$B29+D$19)*(1+InflLT)-1,$B29+D$19))^(4+1-FixTV)-IF(FixND=1,NDmult*DCF!$M$21,0) -> 202642.39 | E29: =NPV(IF(FixInfl=1,(1+$B29+E$19)*(1+InflLT)-1,$B29+E$19),DCF!$P$37:$S$37)+DCF!$S$37*(1+gLT)/(IF(FixInfl=1,(1+$B29+E$19)*(1+InflLT)-1,$B29+E$19)-gLT)/(1+IF(FixInfl=1,(1+$B29+E$19)*(1+InflLT)-1,$B29+E$19))^(4+1-FixTV)-IF(FixND=1,NDmult*DCF!$M$21,0) -> 181883.6 | F29: =NPV(IF(FixInfl=1,(1+$B29+F$19)*(1+InflLT)-1,$B29+F$19),DCF!$P$37:$S$37)+DCF!$S$37*(1+gLT)/(IF(FixInfl=1,(1+$B29+F$19)*(1+InflLT)-1,$B29+F$19)-gLT)/(1+IF(FixInfl=1,(1+$B29+F$19)*(1+InflLT)-1,$B29+F$19))^(4+1-FixTV)-IF(FixND=1,NDmult*DCF!$M$21,0) -> 164873.6 | G29: =NPV(IF(FixInfl=1,(1+$B29+G$19)*(1+InflLT)-1,$B29+G$19),DCF!$P$37:$S$37)+DCF!$S$37*(1+gLT)/(IF(FixInfl=1,(1+$B29+G$19)*(1+InflLT)-1,$B29+G$19)-gLT)/(1+IF(FixInfl=1,(1+$B29+G$19)*(1+InflLT)-1,$B29+G$19))^(4+1-FixTV)-IF(FixND=1,NDmult*DCF!$M$21,0) -> 150692.86
B30: 0.095 | C30: =NPV(IF(FixInfl=1,(1+$B30+C$19)*(1+InflLT)-1,$B30+C$19),DCF!$P$37:$S$37)+DCF!$S$37*(1+gLT)/(IF(FixInfl=1,(1+$B30+C$19)*(1+InflLT)-1,$B30+C$19)-gLT)/(1+IF(FixInfl=1,(1+$B30+C$19)*(1+InflLT)-1,$B30+C$19))^(4+1-FixTV)-IF(FixND=1,NDmult*DCF!$M$21,0) -> 214829.39 | D30: =NPV(IF(FixInfl=1,(1+$B30+D$19)*(1+InflLT)-1,$B30+D$19),DCF!$P$37:$S$37)+DCF!$S$37*(1+gLT)/(IF(FixInfl=1,(1+$B30+D$19)*(1+InflLT)-1,$B30+D$19)-gLT)/(1+IF(FixInfl=1,(1+$B30+D$19)*(1+InflLT)-1,$B30+D$19))^(4+1-FixTV)-IF(FixND=1,NDmult*DCF!$M$21,0) -> 191722.24 | E30: =NPV(IF(FixInfl=1,(1+$B30+E$19)*(1+InflLT)-1,$B30+E$19),DCF!$P$37:$S$37)+DCF!$S$37*(1+gLT)/(IF(FixInfl=1,(1+$B30+E$19)*(1+InflLT)-1,$B30+E$19)-gLT)/(1+IF(FixInfl=1,(1+$B30+E$19)*(1+InflLT)-1,$B30+E$19))^(4+1-FixTV)-IF(FixND=1,NDmult*DCF!$M$21,0) -> 172975.46 | F30: =NPV(IF(FixInfl=1,(1+$B30+F$19)*(1+InflLT)-1,$B30+F$19),DCF!$P$37:$S$37)+DCF!$S$37*(1+gLT)/(IF(FixInfl=1,(1+$B30+F$19)*(1+InflLT)-1,$B30+F$19)-gLT)/(1+IF(FixInfl=1,(1+$B30+F$19)*(1+InflLT)-1,$B30+F$19))^(4+1-FixTV)-IF(FixND=1,NDmult*DCF!$M$21,0) -> 157474.85 | G30: =NPV(IF(FixInfl=1,(1+$B30+G$19)*(1+InflLT)-1,$B30+G$19),DCF!$P$37:$S$37)+DCF!$S$37*(1+gLT)/(IF(FixInfl=1,(1+$B30+G$19)*(1+InflLT)-1,$B30+G$19)-gLT)/(1+IF(FixInfl=1,(1+$B30+G$19)*(1+InflLT)-1,$B30+G$19))^(4+1-FixTV)-IF(FixND=1,NDmult*DCF!$M$21,0) -> 144454.79
B34: Upside vs the Ibovespa used
B35: Real rate \ ERP | C35: =C$19 -> 0.04 | D35: =D$19 -> 0.05 | E35: =E$19 -> 0.06 | F35: =F$19 -> 0.07 | G35: =G$19 -> 0.08
B36: =$B$20 -> 0.05 | C36: =C20/IbovUsed-1 -> 1.1821239 | D36: =D20/IbovUsed-1 -> 0.75541144 | E36: =E20/IbovUsed-1 -> 0.46511993 | F36: =F20/IbovUsed-1 -> 0.25512225 | G36: =G20/IbovUsed-1 -> 0.096345059
B37: =$B$21 -> 0.055 | C37: =C21/IbovUsed-1 -> 0.94637972 | D37: =D21/IbovUsed-1 -> 0.5976284 | E37: =E21/IbovUsed-1 -> 0.35230239 | F37: =F21/IbovUsed-1 -> 0.1705656 | G37: =G21/IbovUsed-1 -> 0.030693331
B38: =$B$22 -> 0.06 | C38: =C22/IbovUsed-1 -> 0.75541144 | D38: =D22/IbovUsed-1 -> 0.46511993 | E38: =E22/IbovUsed-1 -> 0.25512225 | F38: =F22/IbovUsed-1 -> 0.096345059 | G38: =G22/IbovUsed-1 -> -0.027776609
B39: =$B$23 -> 0.065 | C39: =C23/IbovUsed-1 -> 0.5976284 | D39: =D23/IbovUsed-1 -> 0.35230239 | E39: =E23/IbovUsed-1 -> 0.1705656 | F39: =F23/IbovUsed-1 -> 0.030693331 | G39: =G23/IbovUsed-1 -> -0.080168523
B40: =$B$24 -> 0.0676 | C40: =C24/IbovUsed-1 -> 0.52596591 | D40: =D24/IbovUsed-1 -> 0.30002773 | E40: =E24/IbovUsed-1 -> 0.13080299 | F40: =F24/IbovUsed-1 -> -0.00053182661 | G40: =G24/IbovUsed-1 -> -0.10531254
B41: =$B$25 -> 0.07 | C41: =C25/IbovUsed-1 -> 0.46511993 | D41: =D25/IbovUsed-1 -> 0.25512225 | E41: =E25/IbovUsed-1 -> 0.096345059 | F41: =F25/IbovUsed-1 -> -0.027776609 | G41: =G25/IbovUsed-1 -> -0.12737168
B42: =$B$26 -> 0.075 | C42: =C26/IbovUsed-1 -> 0.35230239 | D42: =D26/IbovUsed-1 -> 0.1705656 | E42: =E26/IbovUsed-1 -> 0.030693331 | F42: =F26/IbovUsed-1 -> -0.080168523 | G42: =G26/IbovUsed-1 -> -0.1701105
B43: =$B$27 -> 0.08 | C43: =C27/IbovUsed-1 -> 0.25512225 | D43: =D27/IbovUsed-1 -> 0.096345059 | E43: =E27/IbovUsed-1 -> -0.027776609 | F43: =F27/IbovUsed-1 -> -0.12737168 | G43: =G27/IbovUsed-1 -> -0.20898106
B44: =$B$28 -> 0.085 | C44: =C28/IbovUsed-1 -> 0.1705656 | D44: =D28/IbovUsed-1 -> 0.030693331 | E44: =E28/IbovUsed-1 -> -0.080168523 | F44: =F28/IbovUsed-1 -> -0.1701105 | G44: =G28/IbovUsed-1 -> -0.24447826
B45: =$B$29 -> 0.09 | C45: =C29/IbovUsed-1 -> 0.096345059 | D45: =D29/IbovUsed-1 -> -0.027776609 | E45: =E29/IbovUsed-1 -> -0.12737168 | F45: =F29/IbovUsed-1 -> -0.20898106 | G45: =G29/IbovUsed-1 -> -0.27701641
B46: =$B$30 -> 0.095 | C46: =C30/IbovUsed-1 -> 0.030693331 | D46: =D30/IbovUsed-1 -> -0.080168523 | E46: =E30/IbovUsed-1 -> -0.1701105 | F46: =F30/IbovUsed-1 -> -0.24447826 | G46: =G30/IbovUsed-1 -> -0.30694497
...

Sheet Support >

Sheet Box Rates
B1: Ibovespa - Box discount rates: house, relative to history or CAPM
B2: Box rate - g = (house rate - g) x relative cash yield; relative cash yield = (10y average earnings yield x cash conversion) / the same for the Ibovespa.
B3: Legend: | C3: input | D3: assumption | E3: formula
B5: 1. Historical cash yield relative to the Ibovespa (12m fwd, Oct-16..Sep-26)
B6: Group | C6: Cash conversion 2031 (FCFF or FCFE / net income) | D6: Average earnings yield (section 3) | E6: Average P/E = 1 / yield | F6: Cash yield = conversion x earnings yield | G6: Relative to the Ibovespa | H6: CAPM beta used (Box Betas)
B7: Financials | C7: ='DCF by Box'!$H$37/'DCF by Box'!$H$27 -> 0.76346986 | D7: =AVERAGE(C$32:C$151) -> 0.12075605 | E7: =1/D7 -> 8.2811588 | F7: =C7*D7 -> 0.092193602 | G7: =F7/$F$11 -> 0.9245176 | H7: ='Box Betas'!I7 -> 1.1490637
B8: Defensives | C8: ='DCF by Box'!$H$83/'DCF by Box'!$H$75 -> 0.84896206 | D8: =AVERAGE(D$32:D$151) -> 0.074616957 | E8: =1/D8 -> 13.401779 | F8: =C8*D8 -> 0.063346966 | G8: =F8/$F$11 -> 0.63524349 | H8: ='Box Betas'!I8 -> 0.92867396
B9: Cyclicals | C9: ='DCF by Box'!$H$124/'DCF by Box'!$H$116 -> 0.49913291 | D9: =AVERAGE(E$32:E$151) -> 0.059397862 | E9: =1/D9 -> 16.835623 | F9: =C9*D9 -> 0.029647427 | G9: =F9/$F$11 -> 0.29730445 | H9: ='Box Betas'!I9 -> 1.1504511
