Workbook
Name FixInfl: Assumptions!$C$29
Name FixND: Assumptions!$C$27
Name FixNWC: Assumptions!$C$26
Name FixTV: Assumptions!$C$28
Name FV27Base: DCF!$D$57
Name FV27Bear: DCF!$C$57
Name FV27Bull: DCF!$E$57
Name gLT: Assumptions!$C$13
Name IbovUsed: Assumptions!$E$7
Name InflLT: Assumptions!$C$14
Name NDmult: Assumptions!$C$16
Name NWCpct: Assumptions!$C$15
Name RRUsed: Assumptions!$E$8
Name Vintage: Assumptions!$C$9

Sheet Cover
C3: Ibovespa | DCF (house model), end-2027
C4: VALUATION MODEL · EQUITY STRATEGY
C7: Main tabs >>
C8: Summary | E8: Assumptions | G8: DCF | I8: Sensitivity | K8: Ibovespa used | M8: =IbovUsed -> 208431.92
K9: Fair value end-2027, base | M9: =FV27Base -> 235695.44
K10: Upside, base | M10: =FV27Base/IbovUsed-1 -> 0.13080299
C11: Auxiliary tabs >> | K11: Fair value end-2027, bear | M11: =FV27Bear -> 191722.24
C12: Checks (tie-out with the house) | E12: Read Me | K12: Fair value end-2027, bull | M12: =FV27Bull -> 261607.54
K13: Model checks | M13: =Checks!C5 -> All checks OK
K15: How this model works >>
K16: Equity Strategy | XP Research
C19: Replica of the house DCF (DCF Ibov 2026_Out.xlsx) rolled to end-2027: FCFF 2028-2031 + terminal value at 5y NTN-B + 6.0% ERP, g 4.7%.

Sheet Summary
B1: Ibovespa - DCF (house model): fair value at the end of 2027
B2: Replica of the house DCF (DCF Ibov 2026_Out.xlsx), rolled forward one year. Construction: DCF sheet.
B3: Ibovespa used | C3: =IbovUsed -> 208431.92 | D3: Market data | E3: =CHOOSE(Vintage,"house file","Oct-5-2026") -> Oct-5-2026 | F3: Checks | G3: =Checks!C5 -> All checks OK
B5: Fair value at the end of 2027 (index pts)
C6: Bear | D6: Base | E6: Bull | G6: Base, end-2026
B7: 5-year real rate (NTN-B) | C7: =DCF!C46 -> 0.085 | D7: =DCF!D46 -> 0.0676 | E7: =DCF!E46 -> 0.06 | G7: =DCF!G46 -> 0.0676
B8: ERP | C8: =DCF!C47 -> 0.06 | D8: =DCF!D47 -> 0.06 | E8: =DCF!E47 -> 0.06 | G8: =DCF!G47 -> 0.06
B9: Discount rate | C9: =DCF!C48 -> 0.145 | D9: =DCF!D48 -> 0.1276 | E9: =DCF!E48 -> 0.12 | G9: =DCF!G48 -> 0.1276
B10: Fair value (index pts) | C10: =DCF!C57 -> 191722.24 | D10: =DCF!D57 -> 235695.44 | E10: =DCF!E57 -> 261607.54 | G10: =DCF!G57 -> 219923.12
B11: Upside vs the Ibovespa used | C11: =DCF!C59 -> -0.080168523 | D11: =DCF!D59 -> 0.13080299 | E11: =DCF!E59 -> 0.25512225 | G11: =DCF!G59 -> 0.055131656
B12: Terminal value / value | C12: =DCF!C60 -> 0.69548156 | D12: =DCF!D60 -> 0.74259167 | E12: =DCF!E60 -> 0.76409683 | G12: =DCF!G60 -> 0.7502342
B13: Implied P/E on next year's EPS | C13: =DCF!C61 -> 8.2720905 | D13: =DCF!D61 -> 10.169368 | E13: =DCF!E61 -> 11.287377 | G13: =DCF!G61 -> 10.15061
B14: Corrections in use (Assumptions section 4) | C14: =IF(FixNWC+FixND+FixTV+FixInfl=0,"none: as the house","on: "&IF(FixNWC=1,"NWC change ","")&IF(FixND=1,"net debt ","")&IF(FixTV=1,"TV timing ","")&IF(FixInfl=1,"inflation","")) -> none: as the house
B16: Correcting the house mechanics one step at a time (base, end-2027)
B17: Step | C17: Fair value | D17: Change | E17: Upside
B18: House mechanics | C18: =NPV((Assumptions!$D$20+Assumptions!$D$21),DCF!$P$35:$S$35)+DCF!$S$35*(1+gLT)/((Assumptions!$D$20+Assumptions!$D$21)-gLT)/(1+(Assumptions!$D$20+Assumptions!$D$21))^5-0 -> 235695.44 | E18: =C18/IbovUsed-1 -> 0.13080299
B19: + terminal value discounted with the last flow | C19: =NPV((Assumptions!$D$20+Assumptions!$D$21),DCF!$P$35:$S$35)+DCF!$S$35*(1+gLT)/((Assumptions!$D$20+Assumptions!$D$21)-gLT)/(1+(Assumptions!$D$20+Assumptions!$D$21))^4-0 -> 258028.69 | D19: =C19-C18 -> 22333.25 | E19: =C19/IbovUsed-1 -> 0.23795188
B20: + working capital by change, not level | C20: =NPV((Assumptions!$D$20+Assumptions!$D$21),DCF!$P$36:$S$36)+DCF!$S$36*(1+gLT)/((Assumptions!$D$20+Assumptions!$D$21)-gLT)/(1+(Assumptions!$D$20+Assumptions!$D$21))^4-0 -> 342114.36 | D20: =C20-C19 -> 84085.674 | E20: =C20/IbovUsed-1 -> 0.64137221
B21: + net debt subtracted | C21: =NPV((Assumptions!$D$20+Assumptions!$D$21),DCF!$P$36:$S$36)+DCF!$S$36*(1+gLT)/((Assumptions!$D$20+Assumptions!$D$21)-gLT)/(1+(Assumptions!$D$20+Assumptions!$D$21))^4-NDmult*DCF!$M$21 -> 288032.76 | D21: =C21-C20 -> -54081.6 | E21: =C21/IbovUsed-1 -> 0.38190332
B22: + inflation in the rate (Fisher) = fully corrected | C22: =NPV(((1+Assumptions!$D$20+Assumptions!$D$21)*(1+InflLT)-1),DCF!$P$36:$S$36)+DCF!$S$36*(1+gLT)/(((1+Assumptions!$D$20+Assumptions!$D$21)*(1+InflLT)-1)-gLT)/(1+((1+Assumptions!$D$20+Assumptions!$D$21)*(1+InflLT)-1))^4-NDmult*DCF!$M$21 -> 162886.95 | D22: =C22-C21 -> -125145.81 | E22: =C22/IbovUsed-1 -> -0.21851244
B24: Each step keeps the previous ones. Base real rate and ERP; projection rules as in the DCF sheet.
B26: Tie-out with the house file and reference values (not linked)
B27: Ibovespa fair value (index pts) | C27: House file | D27: Replica | E27: Difference
B28: End-2026, house data and settings (Target!F59) | C28: 202259.17 | D28: =NPV((Checks!$C$31+Checks!$C$32),DCF!$O$35:$R$35)+DCF!$R$35*(1+Checks!$C$33)/((Checks!$C$31+Checks!$C$32)-Checks!$C$33)/(1+(Checks!$C$31+Checks!$C$32))^5-0 -> 202259.17 | E28: =D28-C28 -> 0
B29: End-2027 column of the house file, to 2030 (Target!G59) | C29: 212941.03 | D29: =NPV((Checks!$C$31+Checks!$C$32),DCF!$P$35:$R$35)+DCF!$R$35*(1+Checks!$C$33)/((Checks!$C$31+Checks!$C$32)-Checks!$C$33)/(1+(Checks!$C$31+Checks!$C$32))^4-0 -> 212941.03 | E29: =D29-C29 -> 0
B30: Other models, bear / base / bull:
B31: DCF by box (Ibov_DCF_by_box_XP.xlsx, 12 months) | C31: 169580 | D31: 223718 | E31: 276936
B32: Multiples model, average of methods (Oct-6 table) | C32: 174414 | D32: 229232 | E32: 294832

Sheet Assumptions
B1: Ibovespa - DCF assumptions (house model, end-2027)
B2: Change the pink cells; the DCF sheet recalculates. Projection rules for 2028-2031 are pink cells in the DCF sheet.
B3: Legend: | C3: input | D3: assumption | E3: formula
B5: 1. Market data
B6: Item | C6: House file | D6: Oct-5-2026 | E6: Used | G6: Source
B7: Ibovespa (index pts) | C7: 182419.73 | D7: 208431.92 | E7: =CHOOSE(Vintage,C7,D7) -> 208431.92 | G7: House file: Target!B61 (BDP IBOV Index, as saved). Oct-5: Bloomberg IBOV Index PX_LAST.
B8: 5-year real rate (NTN-B) | C8: 0.0742 | D8: 0.0676 | E8: =CHOOSE(Vintage,C8,D8) -> 0.0676 | G8: House file: Target!C56 (BZRFB5PY Index, 7.42%). Oct-5: ANBIMA 5-year NTN-B (Bloomberg was down; check BZRFB5PY before publishing).
B9: Market data used: 1 = house file, 2 = Oct-5-2026 | C9: 2 | G9: Consensus and history are the house file's in both cases (not refreshed: the consensus moved little).
B11: 2. Valuation parameters (house Target sheet)
B12: Parameter | C12: Value | G12: Source
B13: Long-term growth of the FCFF (g) | C13: 0.047 | G13: Target!B54 (4.7%).
B14: Long-term inflation (Fisher switch and the implied-return block) | C14: 0.04 | G14: Target!B63 (4.0%).
B15: Working capital, % of sales | C15: 0.04 | G15: Target row 43: NWC = -4% of sales.
B16: Net debt / EBITDA of two years before (net debt switch) | C16: 1.6 | G16: Target rows 70-71 (EV/EBITDA method): net debt = 1.6x the EBITDA of two years before the value date.
B18: 3. Scenarios (fair value at the end of 2027)
B19: Lever | C19: Bear | D19: Base | E19: Bull | G19: Source
B20: 5-year real rate (NTN-B) | C20: 0.085 | D20: =RRUsed -> 0.0676 | E20: 0.06 | G20: As the house (Target rows 131-151): bear 8.5%, base = the market rate, bull 6.0%.
B21: ERP | C21: 0.06 | D21: 0.06 | E21: 0.06 | G21: Target!B57 (6.0%), the same in every scenario.
B22: Discount rate (house: real rate + ERP) | C22: =IF(FixInfl=1,(1+C20+C21)*(1+InflLT)-1,C20+C21) -> 0.145 | D22: =IF(FixInfl=1,(1+D20+D21)*(1+InflLT)-1,D20+D21) -> 0.1276 | E22: =IF(FixInfl=1,(1+E20+E21)*(1+InflLT)-1,E20+E21) -> 0.12 | G22: Target!B55 = BZRFB5PY + ERP. With the inflation switch on: (1 + real rate + ERP) x (1 + inflation) - 1.
B24: 4. Corrections to the house mechanics (0 = as the house, 1 = corrected)
B25: Switch | C25: Value | G25: What it changes
B26: Working capital: 0 = level (house), 1 = change | C26: 0 | G26: House row 44 adds the whole NWC level (-4% of sales) every year; the cash flow is the change in NWC.
B27: Net debt: 0 = not subtracted (house), 1 = subtracted | C27: 0 | G27: FCFF values the firm; equity = firm value - net debt (1.6x EBITDA two years before, as the house's EV/EBITDA method).
B28: Terminal value: 0 = one period after the last flow (house), 1 = with the last flow | C28: 0 | G28: NPV(rate, flows, TV) puts the TV one year after the last explicit year; it is a value at the end of that year.
B29: Inflation in the rate: 0 = real rate + ERP (house), 1 = Fisher | C29: 0 | G29: The flows are nominal (sales grow with nominal GDP); real rate + ERP is a real rate.
B31: 5. Projection rules (pink cells in the DCF sheet, 2028-2031 columns)
B32: Real GDP and inflation 2028-2031: 2.0% and 4.0% (house); sales grow with nominal GDP x ratio (1.0).
B33: EBITDA margin 2029-2031: 30% (house). EBIT margin, interest and gross margin: held at the 2028 level (house: same % as the year before).
B34: Capex % of sales: 11% in 2028-2029, 9% from 2030 (house); 2031, the year added here, keeps 2030's 9%.
B35: Consensus: sales and capex to 2027, EBIT, EBITDA and EPS to 2028 (IBOV Index, as in the house file).

Sheet DCF
B1: Ibovespa - DCF (house model rolled to end-2027)
B2: Replica of Target rows 17-65 of DCF Ibov 2026_Out.xlsx, in Ibovespa points, extended to 2031. Blue = house file input; pink = projection rule.
B3: Legend: | C3: input | D3: assumption | E3: formula
B5: Projections (index points)
C6: 2015 | D6: 2016 | E6: 2017 | F6: 2018 | G6: 2019 | H6: 2020 | I6: 2021 | J6: 2022 | K6: 2023 | L6: 2024 | M6: 2025 | N6: 2026 | O6: 2027 | P6: 2028 | Q6: 2029 | R6: 2030 | S6: 2031 | U6: How it is calculated (house Target row)
C7: Actual | D7: Actual | E7: Actual | F7: Actual | G7: Actual | H7: Actual | I7: Actual | J7: Actual | K7: Actual | L7: Actual | M7: Actual | N7: Consensus | O7: Consensus | P7: Consensus | Q7: Projection | R7: Projection | S7: Projection
B8: Real GDP | J8: 0.029 | K8: 0.029 | L8: 0.031 | M8: 0.021 | N8: 0.018 | O8: 0.01 | P8: 0.02 | Q8: 0.02 | R8: 0.02 | S8: 0.02
B9: Inflation | C9: 0.1067 | D9: 0.0629 | E9: 0.0295 | F9: 0.0375 | G9: 0.0431 | H9: 0.045 | I9: 0.101 | J9: 0.058 | K9: 0.046 | L9: 0.046 | M9: 0.045 | N9: 0.038 | O9: 0.04 | P9: 0.04 | Q9: 0.04 | R9: 0.04 | S9: 0.04
B10: Nominal GDP | C10: =(1+C8)*(1+C9)-1 -> 0.1067 | D10: =(1+D8)*(1+D9)-1 -> 0.0629 | E10: =(1+E8)*(1+E9)-1 -> 0.0295 | F10: =(1+F8)*(1+F9)-1 -> 0.0375 | G10: =(1+G8)*(1+G9)-1 -> 0.0431 | H10: =(1+H8)*(1+H9)-1 -> 0.045 | I10: =(1+I8)*(1+I9)-1 -> 0.101 | J10: =(1+J8)*(1+J9)-1 -> 0.088682 | ... S10: =(1+S8)*(1+S9)-1 -> 0.0608 | U10: (1 + real GDP) x (1 + inflation) - 1 (row 20).
B11: Sales growth | D11: =D13/C13-1 -> 0.031809353 | E11: =E13/D13-1 -> 0.014830489 | F11: =F13/E13-1 -> 0.16663413 | G11: =G13/F13-1 -> 0.12933978 | H11: =H13/G13-1 -> 0.081369435 | I11: =I13/H13-1 -> 0.33636272 | J11: =J13/I13-1 -> 0.20564508 | K11: =K13/J13-1 -> 0.058209825 | ... O11: =O13/N13-1 -> 0.030505723 | P11: =P10*P12 -> 0.0608 | Q11: =Q10*Q12 -> 0.0608 | R11: =R10*R12 -> 0.0608 | S11: =S10*S12 -> 0.0608 | U11: Actual/consensus: sales / previous - 1. Projection: nominal GDP x ratio (row 21).
B12: Ratio (sales growth / nominal GDP) | D12: =D11/D10 -> 0.50571309 | E12: =E11/E10 -> 0.50272844 | F12: =F11/F10 -> 4.4435767 | G12: =G11/G10 -> 3.0009229 | H12: =H11/H10 -> 1.8082097 | I12: =I11/I10 -> 3.3303239 | J12: =J11/J10 -> 2.3189044 | K12: =K11/K10 -> 0.76256746 | ... O12: =O11/O10 -> 0.60527228 | P12: 1 | Q12: 1 | R12: 1 | S12: 1
B13: Sales | C13: 51357.85 | D13: 52991.51 | E13: 53777.4 | F13: 62738.55 | G13: 70853.14 | H13: 76618.42 | I13: 102390 | J13: 123446 | K13: 130631.77 | L13: 138166 | M13: 150140 | N13: 158921 | O13: 163769 | P13: =O13*(1+P11) -> 173726.16 | Q13: =P13*(1+Q11) -> 184288.71 | R13: =Q13*(1+R11) -> 195493.46 | S13: =R13*(1+S11) -> 207379.46 | U13: To 2027: house file (consensus 2026-27). 2028+: previous x (1 + growth) (row 25).
B14: COGS | C14: =C13*(C15-1) -> -38374.586 | D14: =D13*(D15-1) -> -39865.513 | E14: =E13*(E15-1) -> -38940.215 | F14: =F13*(F15-1) -> -44801.599 | G14: =G13*(G15-1) -> -50192.364 | H14: =H13*(H15-1) -> -53939.368 | I14: =I13*(I15-1) -> -65529.6 | J14: =J13*(J15-1) -> -82708.82 | ... S14: =S13*(S15-1) -> -133199.83 | U14: Sales x (gross margin - 1) (row 26).
B15: Gross margin % | C15: 0.2528 | D15: 0.2477 | E15: 0.2759 | F15: 0.2859 | G15: 0.2916 | H15: 0.296 | I15: 0.36 | J15: 0.33 | K15: 0.2757 | L15: 0.2514 | M15: 0.2737 | N15: 0.388 | O15: 0.3827 | P15: 0.3577 | Q15: =P15 -> 0.3577 | R15: =Q15 -> 0.3577 | S15: =R15 -> 0.3577 | U15: To 2028: house file. 2029+: previous year (row 27).
B16: Gross profit | C16: =C13+C14 -> 12983.264 | D16: =D13+D14 -> 13125.997 | E16: =E13+E14 -> 14837.185 | F16: =F13+F14 -> 17936.951 | G16: =G13+G14 -> 20660.776 | H16: =H13+H14 -> 22679.052 | I16: =I13+I14 -> 36860.4 | J16: =J13+J14 -> 40737.18 | ... S16: =S13+S14 -> 74179.633
B17: SG&A | C17: =C19-C16 -> -11461.954 | D17: =D19-D16 -> -6806.437 | E17: =E19-E16 -> -7556.5447 | F17: =F19-F16 -> -8126.6114 | G17: =G19-G16 -> -11860.076 | H17: =H19-H16 -> -11988.992 | I17: =I19-I16 -> -13266.4 | J17: =J19-J16 -> -14963.67 | ... P17: =P19-P16 -> -24819.836 | Q17: =Q13*Q18 -> -26328.882 | R17: =R13*R18 -> -27929.678 | S17: =S13*S18 -> -29627.802 | U17: To 2028: EBIT - gross profit. 2029+: sales x SG&A % (row 29).
B18: SG&A % of sales | C18: =C17/C13 -> -0.22317824 | D18: =D17/D13 -> -0.12844392 | E18: =E17/E13 -> -0.14051525 | F18: =F17/F13 -> -0.12953139 | G18: =G17/G13 -> -0.16738956 | H18: =H17/H13 -> -0.15647663 | I18: =I17/I13 -> -0.12956734 | J18: =J17/J13 -> -0.12121632 | ... P18: =P17/P13 -> -0.14286758 | Q18: =P18 -> -0.14286758 | R18: =Q18 -> -0.14286758 | S18: =R18 -> -0.14286758 | U18: 2029+: previous year's % (row 30).
B19: EBIT | C19: 1521.31 | D19: 6319.56 | E19: 7280.64 | F19: 9810.34 | G19: 8800.7 | H19: 10690.06 | I19: 23594 | J19: 25773.51 | K19: 21324.34 | L19: 25291.3 | M19: 20846 | N19: 33080 | O19: 34883 | P19: 37322.01 | Q19: =Q16+Q17 -> 39591.188 | R19: =R16+R17 -> 41998.332 | S19: =S16+S17 -> 44551.831 | U19: To 2028: house file (consensus). 2029+: gross profit + SG&A (row 31).
B20: EBIT margin % | C20: =C19/C13 -> 0.029621762 | D20: =D19/D13 -> 0.11925608 | E20: =E19/E13 -> 0.13538475 | F20: =F19/F13 -> 0.15636861 | G20: =G19/G13 -> 0.12421044 | H20: =H19/H13 -> 0.13952337 | I20: =I19/I13 -> 0.23043266 | J20: =J19/J13 -> 0.20878368 | ... S20: =S19/S13 -> 0.21483242
B21: EBITDA | C21: 11322.26 | D21: 11803.92 | E21: 13642.8 | F21: 17850.25 | G21: 18979.35 | H21: 19022.66 | I21: 31545 | J21: 36387.17 | K21: 32032.37 | L21: 37339 | M21: 33801 | N21: 49324 | O21: 50717 | P21: 51996.99 | Q21: =Q13*Q22 -> 55286.612 | R21: =R13*R22 -> 58648.038 | S21: =S13*S22 -> 62213.838 | U21: To 2028: house file (consensus). 2029+: sales x EBITDA margin (row 33).
B22: EBITDA margin % | C22: =C21/C13 -> 0.22045822 | D22: =D21/D13 -> 0.22275115 | E22: =E21/E13 -> 0.25369021 | F22: =F21/F13 -> 0.28451805 | G22: =G21/G13 -> 0.26786886 | H22: =H21/H13 -> 0.24827789 | I22: =I21/I13 -> 0.30808673 | J22: =J21/J13 -> 0.29476184 | ... P22: =P21/P13 -> 0.29930433 | Q22: 0.3 | R22: 0.3 | S22: 0.3 | U22: 2029+: 30% (house, row 34).
B23: D&A | C23: =C21-C19 -> 9800.95 | D23: =D21-D19 -> 5484.36 | E23: =E21-E19 -> 6362.16 | F23: =F21-F19 -> 8039.91 | G23: =G21-G19 -> 10178.65 | H23: =H21-H19 -> 8332.6 | I23: =I21-I19 -> 7951 | J23: =J21-J19 -> 10613.66 | ... S23: =S21-S19 -> 17662.007 | U23: EBITDA - EBIT (row 35).
B24: D&A % of sales | C24: =C23/C13 -> 0.19083645 | D24: =D23/D13 -> 0.10349507 | E24: =E23/E13 -> 0.11830546 | F24: =F23/F13 -> 0.12814944 | G24: =G23/G13 -> 0.14365842 | H24: =H23/H13 -> 0.10875453 | I24: =I23/I13 -> 0.077654068 | J24: =J23/J13 -> 0.08597816 | ... S24: =S23/S13 -> 0.085167582
B25: Tax rate | C25: -0.25 | D25: =C25 -> -0.25 | E25: =D25 -> -0.25 | F25: =E25 -> -0.25 | G25: =F25 -> -0.25 | H25: =G25 -> -0.25 | I25: =H25 -> -0.25 | J25: =I25 -> -0.25 | K25: =J25 -> -0.25 | L25: -0.24 | M25: =L25 -> -0.24 | N25: =M25 -> -0.24 | O25: =N25 -> -0.24 | P25: =O25 -> -0.24 | Q25: =P25 -> -0.24 | R25: =Q25 -> -0.24 | S25: =R25 -> -0.24 | U25: -25% to 2023, -24% from 2024 (row 37).
B26: NOPAT | C26: =C19*(1+C25) -> 1140.9825 | D26: =D19*(1+D25) -> 4739.67 | E26: =E19*(1+E25) -> 5460.48 | F26: =F19*(1+F25) -> 7357.755 | G26: =G19*(1+G25) -> 6600.525 | H26: =H19*(1+H25) -> 8017.545 | I26: =I19*(1+I25) -> 17695.5 | J26: =J19*(1+J25) -> 19330.132 | ... S26: =S19*(1+S25) -> 33859.392 | U26: EBIT x (1 + tax rate) (row 38).
B27: Net interest expense | C27: =C29-C26 -> -1992.7125 | D27: =D29-D26 -> -1693.5 | E27: =E29-E26 -> -1553.31 | F27: =F29-F26 -> -1433.345 | G27: =G29-G26 -> -1239.105 | H27: =H29-H26 -> -4140.545 | I27: =I29-I26 -> -2007.5 | J27: =J29-J26 -> -561.0525 | ... P27: =P29-P26 -> -5187.7276 | Q27: =Q13*Q28 -> -5503.1414 | R27: =R13*R28 -> -5837.7324 | S27: =S13*S28 -> -6192.6666 | U27: To 2028: net income - NOPAT. 2029+: sales x interest % (row 39).
B28: Interest % of sales | C28: =C27/C13 -> -0.038800544 | D28: =D27/D13 -> -0.031957949 | E28: =E27/E13 -> -0.028884067 | F28: =F27/F13 -> -0.02284632 | G28: =G27/G13 -> -0.017488357 | H28: =H27/H13 -> -0.054041117 | I28: =I27/I13 -> -0.019606407 | J28: =J27/J13 -> -0.0045449225 | ... P28: =P27/P13 -> -0.029861523 | Q28: =P28 -> -0.029861523 | R28: =Q28 -> -0.029861523 | S28: =R28 -> -0.029861523 | U28: 2029+: previous year's % (row 40).
B29: Net income (EPS, index pts) | C29: -851.73 | D29: 3046.17 | E29: 3907.17 | F29: 5924.41 | G29: 5361.42 | H29: 3877 | I29: 15688 | J29: 18769.08 | K29: 13729.57 | L29: 14944 | M29: 13889 | N29: 20958 | O29: 21666 | P29: 23177 | Q29: =Q26+Q27 -> 24586.162 | R29: =R26+R27 -> 26081 | S29: =S26+S27 -> 27666.725 | U29: To 2028: house file (consensus EPS). 2029+: NOPAT + net interest (row 41).
B30: Net margin % | C30: =C29/C13 -> -0.016584222 | D30: =D29/D13 -> 0.057484114 | E30: =E29/E13 -> 0.072654498 | F30: =F29/F13 -> 0.094430139 | G30: =G29/G13 -> 0.075669476 | H30: =H29/H13 -> 0.050601409 | I30: =I29/I13 -> 0.15321809 | J30: =J29/J13 -> 0.15204284 | ... S30: =S29/S13 -> 0.13341111
B31: Working capital (NWC) | C31: =-NWCpct*C13 -> -2054.314 | D31: =-NWCpct*D13 -> -2119.6604 | E31: =-NWCpct*E13 -> -2151.096 | F31: =-NWCpct*F13 -> -2509.542 | G31: =-NWCpct*G13 -> -2834.1256 | H31: =-NWCpct*H13 -> -3064.7368 | I31: =-NWCpct*I13 -> -4095.6 | J31: =-NWCpct*J13 -> -4937.84 | ... S31: =-NWCpct*S13 -> -8295.1784 | U31: -NWC % x sales (Assumptions; row 43).
B32: Change in NWC | D32: =D31-C31 -> -65.3464 | E32: =E31-D31 -> -31.4356 | F32: =F31-E31 -> -358.446 | G32: =G31-F31 -> -324.5836 | H32: =H31-G31 -> -230.6112 | I32: =I31-H31 -> -1030.8632 | J32: =J31-I31 -> -842.24 | K32: =K31-J31 -> -287.4308 | ... S32: =S31-R31 -> -475.44009
B33: Capex | C33: -5294.22 | D33: -3805.46 | E33: -3278.37 | F33: -3699.48 | G33: -3779.44 | H33: -3672 | I33: -4618.18 | J33: -6641.75 | K33: -8753.81 | L33: -10938 | M33: -18822 | N33: -19159 | O33: -19333 | P33: =P13*P34 -> -19109.877 | Q33: =Q13*Q34 -> -20271.758 | R33: =R13*R34 -> -17594.411 | S33: =S13*S34 -> -18664.151 | U33: To 2027: house file. 2028+: sales x capex % (row 46).
B34: Capex % of sales | C34: =C33/C13 -> -0.10308492 | D34: =D33/D13 -> -0.071812636 | E34: =E33/E13 -> -0.060961854 | F34: =F33/F13 -> -0.058966616 | G34: =G33/G13 -> -0.053341884 | H34: =H33/H13 -> -0.047925812 | I34: =I33/I13 -> -0.045103819 | J34: =J33/J13 -> -0.053802877 | ... O34: =O33/O13 -> -0.11805042 | P34: -0.11 | Q34: =P34 -> -0.11 | R34: -0.09 | S34: =R34 -> -0.09 | U34: 2028-29: -11%; 2030: -9% (house); 2031: as 2030 (row 47).
B35: FCFF, house = D&A + NOPAT + capex + NWC (level) | C35: =C23+C26+C33+C31 -> 3593.3985 | D35: =D23+D26+D33+D31 -> 4298.9096 | E35: =E23+E26+E33+E31 -> 6393.174 | F35: =F23+F26+F33+F31 -> 9188.643 | G35: =G23+G26+G33+G31 -> 10165.609 | H35: =H23+H26+H33+H31 -> 9613.4082 | I35: =I23+I26+I33+I31 -> 16932.72 | J35: =J23+J26+J33+J31 -> 18364.202 | ... S35: =S23+S26+S33+S31 -> 24562.069 | U35: D&A + NOPAT + capex + NWC level (row 44): what the house discounts.
B36: FCFF with the change in NWC | D36: =D23+D26+D33+D32 -> 6353.2236 | E36: =E23+E26+E33+E32 -> 8512.8344 | F36: =F23+F26+F33+F32 -> 11339.739 | G36: =G23+G26+G33+G32 -> 12675.151 | H36: =H23+H26+H33+H32 -> 12447.534 | I36: =I23+I26+I33+I32 -> 19997.457 | J36: =J23+J26+J33+J32 -> 22459.802 | K36: =K23+K26+K33+K32 -> 17660.044 | ... S36: =S23+S26+S33+S32 -> 32381.807 | U36: D&A + NOPAT + capex + change in NWC.
B37: FCFF used in the valuation (switch FixNWC) | C37: =C35 -> 3593.3985 | D37: =IF(FixNWC=1,D36,D35) -> 4298.9096 | E37: =IF(FixNWC=1,E36,E35) -> 6393.174 | F37: =IF(FixNWC=1,F36,F35) -> 9188.643 | G37: =IF(FixNWC=1,G36,G35) -> 10165.609 | H37: =IF(FixNWC=1,H36,H35) -> 9613.4082 | I37: =IF(FixNWC=1,I36,I35) -> 16932.72 | J37: =IF(FixNWC=1,J36,J35) -> 18364.202 | K37: =IF(FixNWC=1,K36,K35) -> 12722.204 | ... S37: =IF(FixNWC=1,S36,S35) -> 24562.069 | U37: FixNWC = 0: the house row; 1: the corrected row.
B38: memo: FCFF = EBITDA x (1 - tax) + capex | C38: 3875.1 | D38: 3414.98 | E38: 3131.8 | F38: 5798.58 | G38: 7840.38 | H38: 10543 | I38: 15220 | J38: 21728 | K38: 10626.16 | L38: 12342 | M38: 13051 | N38: =N21*(1+N25)+N33 -> 18327.24 | O38: =O21*(1+O25)+O33 -> 19211.92 | P38: =P21*(1+P25)+P33 -> 20407.835 | Q38: =Q21*(1+Q25)+Q33 -> 21746.067 | R38: =R21*(1+R25)+R33 -> 26978.097 | S38: =S21*(1+S25)+S33 -> 28618.366 | U38: To 2025: house file. 2026+: EBITDA x (1 + tax) + capex (row 49).
B39: memo: Ibovespa (average to 2020, then the price used) | C39: 49828 | D39: 53350 | E39: 67784 | F39: 81677 | G39: 101000 | H39: 99143 | I39: =IbovUsed -> 208431.92 | J39: =IbovUsed -> 208431.92 | K39: =IbovUsed -> 208431.92 | L39: =IbovUsed -> 208431.92 | M39: =IbovUsed -> 208431.92 | N39: =IbovUsed -> 208431.92 | O39: =IbovUsed -> 208431.92 | P39: =IbovUsed -> 208431.92 | ... S39: =IbovUsed -> 208431.92 | U39: Row 50: average to 2020 (house file), then the Ibovespa price used.
B40: memo: FCF yield | C40: =C38/C39 -> 0.077769527 | D40: =D38/D39 -> 0.064010872 | E40: =E38/E39 -> 0.046202644 | F40: =F38/F39 -> 0.070994037 | G40: =G38/G39 -> 0.077627525 | H40: =H38/H39 -> 0.10634135 | I40: =I38/I39 -> 0.073021445 | J40: =J38/J39 -> 0.10424507 | ... S40: =S38/S39 -> 0.13730318 | U40: Simple FCFF / Ibovespa (row 51).
B42: Valuation: fair value at the end of the year (house Target rows 53-59)
...

Sheet Sensitivity
B1: Ibovespa - Sensitivity: real rate and ERP
B2: The house's real-rate table (tie-out) and a real rate x ERP grid for the end-2027 fair value with the current settings.
B3: Legend: | C3: input | D3: assumption | E3: formula
B5: House table: 5-year real rate vs DCF value (Target rows 120-129)
B6: 5-year real rate | C6: House file, end-2026 | D6: Replica, end-2026 (house settings) | E6: Difference | G6: End-2027, current settings
B7: 0.055 | C7: 263358.81 | D7: =NPV(($B7+0.06),DCF!$O$35:$R$35)+DCF!$R$35*(1+0.047)/(($B7+0.06)-0.047)/(1+($B7+0.06))^5-0 -> 263358.81 | E7: =D7-C7 -> 0 | G7: =NPV(IF(FixInfl=1,(1+$B7+Assumptions!$D$21)*(1+InflLT)-1,$B7+Assumptions!$D$21),DCF!$P$37:$S$37)+DCF!$S$37*(1+gLT)/(IF(FixInfl=1,(1+$B7+Assumptions!$D$21)*(1+InflLT)-1,$B7+Assumptions!$D$21)-gLT)/(1+IF(FixInfl=1,(1+$B7+Assumptions!$D$21)*(1+InflLT)-1,$B7+Assumptions!$D$21))^(4+1-FixTV)-IF(FixND=1,NDmult*DCF!$M$21,0) -> 281862.98
B8: 0.06 | C8: 244298.81 | D8: =NPV(($B8+0.06),DCF!$O$35:$R$35)+DCF!$R$35*(1+0.047)/(($B8+0.06)-0.047)/(1+($B8+0.06))^5-0 -> 244298.81 | E8: =D8-C8 -> 0 | G8: =NPV(IF(FixInfl=1,(1+$B8+Assumptions!$D$21)*(1+InflLT)-1,$B8+Assumptions!$D$21),DCF!$P$37:$S$37)+DCF!$S$37*(1+gLT)/(IF(FixInfl=1,(1+$B8+Assumptions!$D$21)*(1+InflLT)-1,$B8+Assumptions!$D$21)-gLT)/(1+IF(FixInfl=1,(1+$B8+Assumptions!$D$21)*(1+InflLT)-1,$B8+Assumptions!$D$21))^(4+1-FixTV)-IF(FixND=1,NDmult*DCF!$M$21,0) -> 261607.54
B9: 0.07 | C9: 213168.52 | D9: =NPV(($B9+0.06),DCF!$O$35:$R$35)+DCF!$R$35*(1+0.047)/(($B9+0.06)-0.047)/(1+($B9+0.06))^5-0 -> 213168.52 | E9: =D9-C9 -> 0 | G9: =NPV(IF(FixInfl=1,(1+$B9+Assumptions!$D$21)*(1+InflLT)-1,$B9+Assumptions!$D$21),DCF!$P$37:$S$37)+DCF!$S$37*(1+gLT)/(IF(FixInfl=1,(1+$B9+Assumptions!$D$21)*(1+InflLT)-1,$B9+Assumptions!$D$21)-gLT)/(1+IF(FixInfl=1,(1+$B9+Assumptions!$D$21)*(1+InflLT)-1,$B9+Assumptions!$D$21))^(4+1-FixTV)-IF(FixND=1,NDmult*DCF!$M$21,0) -> 228513.31
B10: 0.0742 | C10: 202259.17 | D10: =NPV(($B10+0.06),DCF!$O$35:$R$35)+DCF!$R$35*(1+0.047)/(($B10+0.06)-0.047)/(1+($B10+0.06))^5-0 -> 202259.17 | E10: =D10-C10 -> 0 | G10: =NPV(IF(FixInfl=1,(1+$B10+Assumptions!$D$21)*(1+InflLT)-1,$B10+Assumptions!$D$21),DCF!$P$37:$S$37)+DCF!$S$37*(1+gLT)/(IF(FixInfl=1,(1+$B10+Assumptions!$D$21)*(1+InflLT)-1,$B10+Assumptions!$D$21)-gLT)/(1+IF(FixInfl=1,(1+$B10+Assumptions!$D$21)*(1+InflLT)-1,$B10+Assumptions!$D$21))^(4+1-FixTV)-IF(FixND=1,NDmult*DCF!$M$21,0) -> 216911.5
B11: 0.075 | C11: 200301.58 | D11: =NPV(($B11+0.06),DCF!$O$35:$R$35)+DCF!$R$35*(1+0.047)/(($B11+0.06)-0.047)/(1+($B11+0.06))^5-0 -> 200301.58 | E11: =D11-C11 -> 0 | G11: =NPV(IF(FixInfl=1,(1+$B11+Assumptions!$D$21)*(1+InflLT)-1,$B11+Assumptions!$D$21),DCF!$P$37:$S$37)+DCF!$S$37*(1+gLT)/(IF(FixInfl=1,(1+$B11+Assumptions!$D$21)*(1+InflLT)-1,$B11+Assumptions!$D$21)-gLT)/(1+IF(FixInfl=1,(1+$B11+Assumptions!$D$21)*(1+InflLT)-1,$B11+Assumptions!$D$21))^(4+1-FixTV)-IF(FixND=1,NDmult*DCF!$M$21,0) -> 214829.39
B12: 0.08 | C12: 188845.17 | D12: =NPV(($B12+0.06),DCF!$O$35:$R$35)+DCF!$R$35*(1+0.047)/(($B12+0.06)-0.047)/(1+($B12+0.06))^5-0 -> 188845.17 | E12: =D12-C12 -> 0 | G12: =NPV(IF(FixInfl=1,(1+$B12+Assumptions!$D$21)*(1+InflLT)-1,$B12+Assumptions!$D$21),DCF!$P$37:$S$37)+DCF!$S$37*(1+gLT)/(IF(FixInfl=1,(1+$B12+Assumptions!$D$21)*(1+InflLT)-1,$B12+Assumptions!$D$21)-gLT)/(1+IF(FixInfl=1,(1+$B12+Assumptions!$D$21)*(1+InflLT)-1,$B12+Assumptions!$D$21))^(4+1-FixTV)-IF(FixND=1,NDmult*DCF!$M$21,0) -> 202642.39
B13: 0.085 | C13: 178582.43 | D13: =NPV(($B13+0.06),DCF!$O$35:$R$35)+DCF!$R$35*(1+0.047)/(($B13+0.06)-0.047)/(1+($B13+0.06))^5-0 -> 178582.43 | E13: =D13-C13 -> 0 | G13: =NPV(IF(FixInfl=1,(1+$B13+Assumptions!$D$21)*(1+InflLT)-1,$B13+Assumptions!$D$21),DCF!$P$37:$S$37)+DCF!$S$37*(1+gLT)/(IF(FixInfl=1,(1+$B13+Assumptions!$D$21)*(1+InflLT)-1,$B13+Assumptions!$D$21)-gLT)/(1+IF(FixInfl=1,(1+$B13+Assumptions!$D$21)*(1+InflLT)-1,$B13+Assumptions!$D$21))^(4+1-FixTV)-IF(FixND=1,NDmult*DCF!$M$21,0) -> 191722.24
B14: 0.09 | C14: 169338.66 | D14: =NPV(($B14+0.06),DCF!$O$35:$R$35)+DCF!$R$35*(1+0.047)/(($B14+0.06)-0.047)/(1+($B14+0.06))^5-0 -> 169338.66 | E14: =D14-C14 -> 0 | G14: =NPV(IF(FixInfl=1,(1+$B14+Assumptions!$D$21)*(1+InflLT)-1,$B14+Assumptions!$D$21),DCF!$P$37:$S$37)+DCF!$S$37*(1+gLT)/(IF(FixInfl=1,(1+$B14+Assumptions!$D$21)*(1+InflLT)-1,$B14+Assumptions!$D$21)-gLT)/(1+IF(FixInfl=1,(1+$B14+Assumptions!$D$21)*(1+InflLT)-1,$B14+Assumptions!$D$21))^(4+1-FixTV)-IF(FixND=1,NDmult*DCF!$M$21,0) -> 181883.6
B15: House settings: ERP 6.0%, g 4.7%, no corrections, house FCFF. The house table is an Excel data table on Target!C56.
B18: End-2027 fair value (index pts), current settings
B19: Real rate \ ERP | C19: 0.04 | D19: 0.05 | E19: 0.06 | F19: 0.07 | G19: 0.08
B20: 0.05 | C20: =NPV(IF(FixInfl=1,(1+$B20+C$19)*(1+InflLT)-1,$B20+C$19),DCF!$P$37:$S$37)+DCF!$S$37*(1+gLT)/(IF(FixInfl=1,(1+$B20+C$19)*(1+InflLT)-1,$B20+C$19)-gLT)/(1+IF(FixInfl=1,(1+$B20+C$19)*(1+InflLT)-1,$B20+C$19))^(4+1-FixTV)-IF(FixND=1,NDmult*DCF!$M$21,0) -> 454824.27 | D20: =NPV(IF(FixInfl=1,(1+$B20+D$19)*(1+InflLT)-1,$B20+D$19),DCF!$P$37:$S$37)+DCF!$S$37*(1+gLT)/(IF(FixInfl=1,(1+$B20+D$19)*(1+InflLT)-1,$B20+D$19)-gLT)/(1+IF(FixInfl=1,(1+$B20+D$19)*(1+InflLT)-1,$B20+D$19))^(4+1-FixTV)-IF(FixND=1,NDmult*DCF!$M$21,0) -> 365883.78 | E20: =NPV(IF(FixInfl=1,(1+$B20+E$19)*(1+InflLT)-1,$B20+E$19),DCF!$P$37:$S$37)+DCF!$S$37*(1+gLT)/(IF(FixInfl=1,(1+$B20+E$19)*(1+InflLT)-1,$B20+E$19)-gLT)/(1+IF(FixInfl=1,(1+$B20+E$19)*(1+InflLT)-1,$B20+E$19))^(4+1-FixTV)-IF(FixND=1,NDmult*DCF!$M$21,0) -> 305377.76 | F20: =NPV(IF(FixInfl=1,(1+$B20+F$19)*(1+InflLT)-1,$B20+F$19),DCF!$P$37:$S$37)+DCF!$S$37*(1+gLT)/(IF(FixInfl=1,(1+$B20+F$19)*(1+InflLT)-1,$B20+F$19)-gLT)/(1+IF(FixInfl=1,(1+$B20+F$19)*(1+InflLT)-1,$B20+F$19))^(4+1-FixTV)-IF(FixND=1,NDmult*DCF!$M$21,0) -> 261607.54 | G20: =NPV(IF(FixInfl=1,(1+$B20+G$19)*(1+InflLT)-1,$B20+G$19),DCF!$P$37:$S$37)+DCF!$S$37*(1+gLT)/(IF(FixInfl=1,(1+$B20+G$19)*(1+InflLT)-1,$B20+G$19)-gLT)/(1+IF(FixInfl=1,(1+$B20+G$19)*(1+InflLT)-1,$B20+G$19))^(4+1-FixTV)-IF(FixND=1,NDmult*DCF!$M$21,0) -> 228513.31
B21: 0.055 | C21: =NPV(IF(FixInfl=1,(1+$B21+C$19)*(1+InflLT)-1,$B21+C$19),DCF!$P$37:$S$37)+DCF!$S$37*(1+gLT)/(IF(FixInfl=1,(1+$B21+C$19)*(1+InflLT)-1,$B21+C$19)-gLT)/(1+IF(FixInfl=1,(1+$B21+C$19)*(1+InflLT)-1,$B21+C$19))^(4+1-FixTV)-IF(FixND=1,NDmult*DCF!$M$21,0) -> 405687.66 | D21: =NPV(IF(FixInfl=1,(1+$B21+D$19)*(1+InflLT)-1,$B21+D$19),DCF!$P$37:$S$37)+DCF!$S$37*(1+gLT)/(IF(FixInfl=1,(1+$B21+D$19)*(1+InflLT)-1,$B21+D$19)-gLT)/(1+IF(FixInfl=1,(1+$B21+D$19)*(1+InflLT)-1,$B21+D$19))^(4+1-FixTV)-IF(FixND=1,NDmult*DCF!$M$21,0) -> 332996.75 | E21: =NPV(IF(FixInfl=1,(1+$B21+E$19)*(1+InflLT)-1,$B21+E$19),DCF!$P$37:$S$37)+DCF!$S$37*(1+gLT)/(IF(FixInfl=1,(1+$B21+E$19)*(1+InflLT)-1,$B21+E$19)-gLT)/(1+IF(FixInfl=1,(1+$B21+E$19)*(1+InflLT)-1,$B21+E$19))^(4+1-FixTV)-IF(FixND=1,NDmult*DCF!$M$21,0) -> 281862.98 | F21: =NPV(IF(FixInfl=1,(1+$B21+F$19)*(1+InflLT)-1,$B21+F$19),DCF!$P$37:$S$37)+DCF!$S$37*(1+gLT)/(IF(FixInfl=1,(1+$B21+F$19)*(1+InflLT)-1,$B21+F$19)-gLT)/(1+IF(FixInfl=1,(1+$B21+F$19)*(1+InflLT)-1,$B21+F$19))^(4+1-FixTV)-IF(FixND=1,NDmult*DCF!$M$21,0) -> 243983.24 | G21: =NPV(IF(FixInfl=1,(1+$B21+G$19)*(1+InflLT)-1,$B21+G$19),DCF!$P$37:$S$37)+DCF!$S$37*(1+gLT)/(IF(FixInfl=1,(1+$B21+G$19)*(1+InflLT)-1,$B21+G$19)-gLT)/(1+IF(FixInfl=1,(1+$B21+G$19)*(1+InflLT)-1,$B21+G$19))^(4+1-FixTV)-IF(FixND=1,NDmult*DCF!$M$21,0) -> 214829.39
B22: 0.06 | C22: =NPV(IF(FixInfl=1,(1+$B22+C$19)*(1+InflLT)-1,$B22+C$19),DCF!$P$37:$S$37)+DCF!$S$37*(1+gLT)/(IF(FixInfl=1,(1+$B22+C$19)*(1+InflLT)-1,$B22+C$19)-gLT)/(1+IF(FixInfl=1,(1+$B22+C$19)*(1+InflLT)-1,$B22+C$19))^(4+1-FixTV)-IF(FixND=1,NDmult*DCF!$M$21,0) -> 365883.78 | D22: =NPV(IF(FixInfl=1,(1+$B22+D$19)*(1+InflLT)-1,$B22+D$19),DCF!$P$37:$S$37)+DCF!$S$37*(1+gLT)/(IF(FixInfl=1,(1+$B22+D$19)*(1+InflLT)-1,$B22+D$19)-gLT)/(1+IF(FixInfl=1,(1+$B22+D$19)*(1+InflLT)-1,$B22+D$19))^(4+1-FixTV)-IF(FixND=1,NDmult*DCF!$M$21,0) -> 305377.76 | E22: =NPV(IF(FixInfl=1,(1+$B22+E$19)*(1+InflLT)-1,$B22+E$19),DCF!$P$37:$S$37)+DCF!$S$37*(1+gLT)/(IF(FixInfl=1,(1+$B22+E$19)*(1+InflLT)-1,$B22+E$19)-gLT)/(1+IF(FixInfl=1,(1+$B22+E$19)*(1+InflLT)-1,$B22+E$19))^(4+1-FixTV)-IF(FixND=1,NDmult*DCF!$M$21,0) -> 261607.54 | F22: =NPV(IF(FixInfl=1,(1+$B22+F$19)*(1+InflLT)-1,$B22+F$19),DCF!$P$37:$S$37)+DCF!$S$37*(1+gLT)/(IF(FixInfl=1,(1+$B22+F$19)*(1+InflLT)-1,$B22+F$19)-gLT)/(1+IF(FixInfl=1,(1+$B22+F$19)*(1+InflLT)-1,$B22+F$19))^(4+1-FixTV)-IF(FixND=1,NDmult*DCF!$M$21,0) -> 228513.31 | G22: =NPV(IF(FixInfl=1,(1+$B22+G$19)*(1+InflLT)-1,$B22+G$19),DCF!$P$37:$S$37)+DCF!$S$37*(1+gLT)/(IF(FixInfl=1,(1+$B22+G$19)*(1+InflLT)-1,$B22+G$19)-gLT)/(1+IF(FixInfl=1,(1+$B22+G$19)*(1+InflLT)-1,$B22+G$19))^(4+1-FixTV)-IF(FixND=1,NDmult*DCF!$M$21,0) -> 202642.39
B23: 0.065 | C23: =NPV(IF(FixInfl=1,(1+$B23+C$19)*(1+InflLT)-1,$B23+C$19),DCF!$P$37:$S$37)+DCF!$S$37*(1+gLT)/(IF(FixInfl=1,(1+$B23+C$19)*(1+InflLT)-1,$B23+C$19)-gLT)/(1+IF(FixInfl=1,(1+$B23+C$19)*(1+InflLT)-1,$B23+C$19))^(4+1-FixTV)-IF(FixND=1,NDmult*DCF!$M$21,0) -> 332996.75 | D23: =NPV(IF(FixInfl=1,(1+$B23+D$19)*(1+InflLT)-1,$B23+D$19),DCF!$P$37:$S$37)+DCF!$S$37*(1+gLT)/(IF(FixInfl=1,(1+$B23+D$19)*(1+InflLT)-1,$B23+D$19)-gLT)/(1+IF(FixInfl=1,(1+$B23+D$19)*(1+InflLT)-1,$B23+D$19))^(4+1-FixTV)-IF(FixND=1,NDmult*DCF!$M$21,0) -> 281862.98 | E23: =NPV(IF(FixInfl=1,(1+$B23+E$19)*(1+InflLT)-1,$B23+E$19),DCF!$P$37:$S$37)+DCF!$S$37*(1+gLT)/(IF(FixInfl=1,(1+$B23+E$19)*(1+InflLT)-1,$B23+E$19)-gLT)/(1+IF(FixInfl=1,(1+$B23+E$19)*(1+InflLT)-1,$B23+E$19))^(4+1-FixTV)-IF(FixND=1,NDmult*DCF!$M$21,0) -> 243983.24 | F23: =NPV(IF(FixInfl=1,(1+$B23+F$19)*(1+InflLT)-1,$B23+F$19),DCF!$P$37:$S$37)+DCF!$S$37*(1+gLT)/(IF(FixInfl=1,(1+$B23+F$19)*(1+InflLT)-1,$B23+F$19)-gLT)/(1+IF(FixInfl=1,(1+$B23+F$19)*(1+InflLT)-1,$B23+F$19))^(4+1-FixTV)-IF(FixND=1,NDmult*DCF!$M$21,0) -> 214829.39 | G23: =NPV(IF(FixInfl=1,(1+$B23+G$19)*(1+InflLT)-1,$B23+G$19),DCF!$P$37:$S$37)+DCF!$S$37*(1+gLT)/(IF(FixInfl=1,(1+$B23+G$19)*(1+InflLT)-1,$B23+G$19)-gLT)/(1+IF(FixInfl=1,(1+$B23+G$19)*(1+InflLT)-1,$B23+G$19))^(4+1-FixTV)-IF(FixND=1,NDmult*DCF!$M$21,0) -> 191722.24
B24: 0.0676 | C24: =NPV(IF(FixInfl=1,(1+$B24+C$19)*(1+InflLT)-1,$B24+C$19),DCF!$P$37:$S$37)+DCF!$S$37*(1+gLT)/(IF(FixInfl=1,(1+$B24+C$19)*(1+InflLT)-1,$B24+C$19)-gLT)/(1+IF(FixInfl=1,(1+$B24+C$19)*(1+InflLT)-1,$B24+C$19))^(4+1-FixTV)-IF(FixND=1,NDmult*DCF!$M$21,0) -> 318060.01 | D24: =NPV(IF(FixInfl=1,(1+$B24+D$19)*(1+InflLT)-1,$B24+D$19),DCF!$P$37:$S$37)+DCF!$S$37*(1+gLT)/(IF(FixInfl=1,(1+$B24+D$19)*(1+InflLT)-1,$B24+D$19)-gLT)/(1+IF(FixInfl=1,(1+$B24+D$19)*(1+InflLT)-1,$B24+D$19))^(4+1-FixTV)-IF(FixND=1,NDmult*DCF!$M$21,0) -> 270967.27 | E24: =NPV(IF(FixInfl=1,(1+$B24+E$19)*(1+InflLT)-1,$B24+E$19),DCF!$P$37:$S$37)+DCF!$S$37*(1+gLT)/(IF(FixInfl=1,(1+$B24+E$19)*(1+InflLT)-1,$B24+E$19)-gLT)/(1+IF(FixInfl=1,(1+$B24+E$19)*(1+InflLT)-1,$B24+E$19))^(4+1-FixTV)-IF(FixND=1,NDmult*DCF!$M$21,0) -> 235695.44 | F24: =NPV(IF(FixInfl=1,(1+$B24+F$19)*(1+InflLT)-1,$B24+F$19),DCF!$P$37:$S$37)+DCF!$S$37*(1+gLT)/(IF(FixInfl=1,(1+$B24+F$19)*(1+InflLT)-1,$B24+F$19)-gLT)/(1+IF(FixInfl=1,(1+$B24+F$19)*(1+InflLT)-1,$B24+F$19))^(4+1-FixTV)-IF(FixND=1,NDmult*DCF!$M$21,0) -> 208321.07 | G24: =NPV(IF(FixInfl=1,(1+$B24+G$19)*(1+InflLT)-1,$B24+G$19),DCF!$P$37:$S$37)+DCF!$S$37*(1+gLT)/(IF(FixInfl=1,(1+$B24+G$19)*(1+InflLT)-1,$B24+G$19)-gLT)/(1+IF(FixInfl=1,(1+$B24+G$19)*(1+InflLT)-1,$B24+G$19))^(4+1-FixTV)-IF(FixND=1,NDmult*DCF!$M$21,0) -> 186481.43
B25: 0.07 | C25: =NPV(IF(FixInfl=1,(1+$B25+C$19)*(1+InflLT)-1,$B25+C$19),DCF!$P$37:$S$37)+DCF!$S$37*(1+gLT)/(IF(FixInfl=1,(1+$B25+C$19)*(1+InflLT)-1,$B25+C$19)-gLT)/(1+IF(FixInfl=1,(1+$B25+C$19)*(1+InflLT)-1,$B25+C$19))^(4+1-FixTV)-IF(FixND=1,NDmult*DCF!$M$21,0) -> 305377.76 | D25: =NPV(IF(FixInfl=1,(1+$B25+D$19)*(1+InflLT)-1,$B25+D$19),DCF!$P$37:$S$37)+DCF!$S$37*(1+gLT)/(IF(FixInfl=1,(1+$B25+D$19)*(1+InflLT)-1,$B25+D$19)-gLT)/(1+IF(FixInfl=1,(1+$B25+D$19)*(1+InflLT)-1,$B25+D$19))^(4+1-FixTV)-IF(FixND=1,NDmult*DCF!$M$21,0) -> 261607.54 | E25: =NPV(IF(FixInfl=1,(1+$B25+E$19)*(1+InflLT)-1,$B25+E$19),DCF!$P$37:$S$37)+DCF!$S$37*(1+gLT)/(IF(FixInfl=1,(1+$B25+E$19)*(1+InflLT)-1,$B25+E$19)-gLT)/(1+IF(FixInfl=1,(1+$B25+E$19)*(1+InflLT)-1,$B25+E$19))^(4+1-FixTV)-IF(FixND=1,NDmult*DCF!$M$21,0) -> 228513.31 | F25: =NPV(IF(FixInfl=1,(1+$B25+F$19)*(1+InflLT)-1,$B25+F$19),DCF!$P$37:$S$37)+DCF!$S$37*(1+gLT)/(IF(FixInfl=1,(1+$B25+F$19)*(1+InflLT)-1,$B25+F$19)-gLT)/(1+IF(FixInfl=1,(1+$B25+F$19)*(1+InflLT)-1,$B25+F$19))^(4+1-FixTV)-IF(FixND=1,NDmult*DCF!$M$21,0) -> 202642.39 | G25: =NPV(IF(FixInfl=1,(1+$B25+G$19)*(1+InflLT)-1,$B25+G$19),DCF!$P$37:$S$37)+DCF!$S$37*(1+gLT)/(IF(FixInfl=1,(1+$B25+G$19)*(1+InflLT)-1,$B25+G$19)-gLT)/(1+IF(FixInfl=1,(1+$B25+G$19)*(1+InflLT)-1,$B25+G$19))^(4+1-FixTV)-IF(FixND=1,NDmult*DCF!$M$21,0) -> 181883.6
B26: 0.075 | C26: =NPV(IF(FixInfl=1,(1+$B26+C$19)*(1+InflLT)-1,$B26+C$19),DCF!$P$37:$S$37)+DCF!$S$37*(1+gLT)/(IF(FixInfl=1,(1+$B26+C$19)*(1+InflLT)-1,$B26+C$19)-gLT)/(1+IF(FixInfl=1,(1+$B26+C$19)*(1+InflLT)-1,$B26+C$19))^(4+1-FixTV)-IF(FixND=1,NDmult*DCF!$M$21,0) -> 281862.98 | D26: =NPV(IF(FixInfl=1,(1+$B26+D$19)*(1+InflLT)-1,$B26+D$19),DCF!$P$37:$S$37)+DCF!$S$37*(1+gLT)/(IF(FixInfl=1,(1+$B26+D$19)*(1+InflLT)-1,$B26+D$19)-gLT)/(1+IF(FixInfl=1,(1+$B26+D$19)*(1+InflLT)-1,$B26+D$19))^(4+1-FixTV)-IF(FixND=1,NDmult*DCF!$M$21,0) -> 243983.24 | E26: =NPV(IF(FixInfl=1,(1+$B26+E$19)*(1+InflLT)-1,$B26+E$19),DCF!$P$37:$S$37)+DCF!$S$37*(1+gLT)/(IF(FixInfl=1,(1+$B26+E$19)*(1+InflLT)-1,$B26+E$19)-gLT)/(1+IF(FixInfl=1,(1+$B26+E$19)*(1+InflLT)-1,$B26+E$19))^(4+1-FixTV)-IF(FixND=1,NDmult*DCF!$M$21,0) -> 214829.39 | F26: =NPV(IF(FixInfl=1,(1+$B26+F$19)*(1+InflLT)-1,$B26+F$19),DCF!$P$37:$S$37)+DCF!$S$37*(1+gLT)/(IF(FixInfl=1,(1+$B26+F$19)*(1+InflLT)-1,$B26+F$19)-gLT)/(1+IF(FixInfl=1,(1+$B26+F$19)*(1+InflLT)-1,$B26+F$19))^(4+1-FixTV)-IF(FixND=1,NDmult*DCF!$M$21,0) -> 191722.24 | G26: =NPV(IF(FixInfl=1,(1+$B26+G$19)*(1+InflLT)-1,$B26+G$19),DCF!$P$37:$S$37)+DCF!$S$37*(1+gLT)/(IF(FixInfl=1,(1+$B26+G$19)*(1+InflLT)-1,$B26+G$19)-gLT)/(1+IF(FixInfl=1,(1+$B26+G$19)*(1+InflLT)-1,$B26+G$19))^(4+1-FixTV)-IF(FixND=1,NDmult*DCF!$M$21,0) -> 172975.46
B27: 0.08 | C27: =NPV(IF(FixInfl=1,(1+$B27+C$19)*(1+InflLT)-1,$B27+C$19),DCF!$P$37:$S$37)+DCF!$S$37*(1+gLT)/(IF(FixInfl=1,(1+$B27+C$19)*(1+InflLT)-1,$B27+C$19)-gLT)/(1+IF(FixInfl=1,(1+$B27+C$19)*(1+InflLT)-1,$B27+C$19))^(4+1-FixTV)-IF(FixND=1,NDmult*DCF!$M$21,0) -> 261607.54 | D27: =NPV(IF(FixInfl=1,(1+$B27+D$19)*(1+InflLT)-1,$B27+D$19),DCF!$P$37:$S$37)+DCF!$S$37*(1+gLT)/(IF(FixInfl=1,(1+$B27+D$19)*(1+InflLT)-1,$B27+D$19)-gLT)/(1+IF(FixInfl=1,(1+$B27+D$19)*(1+InflLT)-1,$B27+D$19))^(4+1-FixTV)-IF(FixND=1,NDmult*DCF!$M$21,0) -> 228513.31 | E27: =NPV(IF(FixInfl=1,(1+$B27+E$19)*(1+InflLT)-1,$B27+E$19),DCF!$P$37:$S$37)+DCF!$S$37*(1+gLT)/(IF(FixInfl=1,(1+$B27+E$19)*(1+InflLT)-1,$B27+E$19)-gLT)/(1+IF(FixInfl=1,(1+$B27+E$19)*(1+InflLT)-1,$B27+E$19))^(4+1-FixTV)-IF(FixND=1,NDmult*DCF!$M$21,0) -> 202642.39 | F27: =NPV(IF(FixInfl=1,(1+$B27+F$19)*(1+InflLT)-1,$B27+F$19),DCF!$P$37:$S$37)+DCF!$S$37*(1+gLT)/(IF(FixInfl=1,(1+$B27+F$19)*(1+InflLT)-1,$B27+F$19)-gLT)/(1+IF(FixInfl=1,(1+$B27+F$19)*(1+InflLT)-1,$B27+F$19))^(4+1-FixTV)-IF(FixND=1,NDmult*DCF!$M$21,0) -> 181883.6 | G27: =NPV(IF(FixInfl=1,(1+$B27+G$19)*(1+InflLT)-1,$B27+G$19),DCF!$P$37:$S$37)+DCF!$S$37*(1+gLT)/(IF(FixInfl=1,(1+$B27+G$19)*(1+InflLT)-1,$B27+G$19)-gLT)/(1+IF(FixInfl=1,(1+$B27+G$19)*(1+InflLT)-1,$B27+G$19))^(4+1-FixTV)-IF(FixND=1,NDmult*DCF!$M$21,0) -> 164873.6
B28: 0.085 | C28: =NPV(IF(FixInfl=1,(1+$B28+C$19)*(1+InflLT)-1,$B28+C$19),DCF!$P$37:$S$37)+DCF!$S$37*(1+gLT)/(IF(FixInfl=1,(1+$B28+C$19)*(1+InflLT)-1,$B28+C$19)-gLT)/(1+IF(FixInfl=1,(1+$B28+C$19)*(1+InflLT)-1,$B28+C$19))^(4+1-FixTV)-IF(FixND=1,NDmult*DCF!$M$21,0) -> 243983.24 | D28: =NPV(IF(FixInfl=1,(1+$B28+D$19)*(1+InflLT)-1,$B28+D$19),DCF!$P$37:$S$37)+DCF!$S$37*(1+gLT)/(IF(FixInfl=1,(1+$B28+D$19)*(1+InflLT)-1,$B28+D$19)-gLT)/(1+IF(FixInfl=1,(1+$B28+D$19)*(1+InflLT)-1,$B28+D$19))^(4+1-FixTV)-IF(FixND=1,NDmult*DCF!$M$21,0) -> 214829.39 | E28: =NPV(IF(FixInfl=1,(1+$B28+E$19)*(1+InflLT)-1,$B28+E$19),DCF!$P$37:$S$37)+DCF!$S$37*(1+gLT)/(IF(FixInfl=1,(1+$B28+E$19)*(1+InflLT)-1,$B28+E$19)-gLT)/(1+IF(FixInfl=1,(1+$B28+E$19)*(1+InflLT)-1,$B28+E$19))^(4+1-FixTV)-IF(FixND=1,NDmult*DCF!$M$21,0) -> 191722.24 | F28: =NPV(IF(FixInfl=1,(1+$B28+F$19)*(1+InflLT)-1,$B28+F$19),DCF!$P$37:$S$37)+DCF!$S$37*(1+gLT)/(IF(FixInfl=1,(1+$B28+F$19)*(1+InflLT)-1,$B28+F$19)-gLT)/(1+IF(FixInfl=1,(1+$B28+F$19)*(1+InflLT)-1,$B28+F$19))^(4+1-FixTV)-IF(FixND=1,NDmult*DCF!$M$21,0) -> 172975.46 | G28: =NPV(IF(FixInfl=1,(1+$B28+G$19)*(1+InflLT)-1,$B28+G$19),DCF!$P$37:$S$37)+DCF!$S$37*(1+gLT)/(IF(FixInfl=1,(1+$B28+G$19)*(1+InflLT)-1,$B28+G$19)-gLT)/(1+IF(FixInfl=1,(1+$B28+G$19)*(1+InflLT)-1,$B28+G$19))^(4+1-FixTV)-IF(FixND=1,NDmult*DCF!$M$21,0) -> 157474.85
B29: 0.09 | C29: =NPV(IF(FixInfl=1,(1+$B29+C$19)*(1+InflLT)-1,$B29+C$19),DCF!$P$37:$S$37)+DCF!$S$37*(1+gLT)/(IF(FixInfl=1,(1+$B29+C$19)*(1+InflLT)-1,$B29+C$19)-gLT)/(1+IF(FixInfl=1,(1+$B29+C$19)*(1+InflLT)-1,$B29+C$19))^(4+1-FixTV)-IF(FixND=1,NDmult*DCF!$M$21,0) -> 228513.31 | D29: =NPV(IF(FixInfl=1,(1+$B29+D$19)*(1+InflLT)-1,$B29+D$19),DCF!$P$37:$S$37)+DCF!$S$37*(1+gLT)/(IF(FixInfl=1,(1+$B29+D$19)*(1+InflLT)-1,$B29+D$19)-gLT)/(1+IF(FixInfl=1,(1+$B29+D$19)*(1+InflLT)-1,$B29+D$19))^(4+1-FixTV)-IF(FixND=1,NDmult*DCF!$M$21,0) -> 202642.39 | E29: =NPV(IF(FixInfl=1,(1+$B29+E$19)*(1+InflLT)-1,$B29+E$19),DCF!$P$37:$S$37)+DCF!$S$37*(1+gLT)/(IF(FixInfl=1,(1+$B29+E$19)*(1+InflLT)-1,$B29+E$19)-gLT)/(1+IF(FixInfl=1,(1+$B29+E$19)*(1+InflLT)-1,$B29+E$19))^(4+1-FixTV)-IF(FixND=1,NDmult*DCF!$M$21,0) -> 181883.6 | F29: =NPV(IF(FixInfl=1,(1+$B29+F$19)*(1+InflLT)-1,$B29+F$19),DCF!$P$37:$S$37)+DCF!$S$37*(1+gLT)/(IF(FixInfl=1,(1+$B29+F$19)*(1+InflLT)-1,$B29+F$19)-gLT)/(1+IF(FixInfl=1,(1+$B29+F$19)*(1+InflLT)-1,$B29+F$19))^(4+1-FixTV)-IF(FixND=1,NDmult*DCF!$M$21,0) -> 164873.6 | G29: =NPV(IF(FixInfl=1,(1+$B29+G$19)*(1+InflLT)-1,$B29+G$19),DCF!$P$37:$S$37)+DCF!$S$37*(1+gLT)/(IF(FixInfl=1,(1+$B29+G$19)*(1+InflLT)-1,$B29+G$19)-gLT)/(1+IF(FixInfl=1,(1+$B29+G$19)*(1+InflLT)-1,$B29+G$19))^(4+1-FixTV)-IF(FixND=1,NDmult*DCF!$M$21,0) -> 150692.86
B30: 0.095 | C30: =NPV(IF(FixInfl=1,(1+$B30+C$19)*(1+InflLT)-1,$B30+C$19),DCF!$P$37:$S$37)+DCF!$S$37*(1+gLT)/(IF(FixInfl=1,(1+$B30+C$19)*(1+InflLT)-1,$B30+C$19)-gLT)/(1+IF(FixInfl=1,(1+$B30+C$19)*(1+InflLT)-1,$B30+C$19))^(4+1-FixTV)-IF(FixND=1,NDmult*DCF!$M$21,0) -> 214829.39 | D30: =NPV(IF(FixInfl=1,(1+$B30+D$19)*(1+InflLT)-1,$B30+D$19),DCF!$P$37:$S$37)+DCF!$S$37*(1+gLT)/(IF(FixInfl=1,(1+$B30+D$19)*(1+InflLT)-1,$B30+D$19)-gLT)/(1+IF(FixInfl=1,(1+$B30+D$19)*(1+InflLT)-1,$B30+D$19))^(4+1-FixTV)-IF(FixND=1,NDmult*DCF!$M$21,0) -> 191722.24 | E30: =NPV(IF(FixInfl=1,(1+$B30+E$19)*(1+InflLT)-1,$B30+E$19),DCF!$P$37:$S$37)+DCF!$S$37*(1+gLT)/(IF(FixInfl=1,(1+$B30+E$19)*(1+InflLT)-1,$B30+E$19)-gLT)/(1+IF(FixInfl=1,(1+$B30+E$19)*(1+InflLT)-1,$B30+E$19))^(4+1-FixTV)-IF(FixND=1,NDmult*DCF!$M$21,0) -> 172975.46 | F30: =NPV(IF(FixInfl=1,(1+$B30+F$19)*(1+InflLT)-1,$B30+F$19),DCF!$P$37:$S$37)+DCF!$S$37*(1+gLT)/(IF(FixInfl=1,(1+$B30+F$19)*(1+InflLT)-1,$B30+F$19)-gLT)/(1+IF(FixInfl=1,(1+$B30+F$19)*(1+InflLT)-1,$B30+F$19))^(4+1-FixTV)-IF(FixND=1,NDmult*DCF!$M$21,0) -> 157474.85 | G30: =NPV(IF(FixInfl=1,(1+$B30+G$19)*(1+InflLT)-1,$B30+G$19),DCF!$P$37:$S$37)+DCF!$S$37*(1+gLT)/(IF(FixInfl=1,(1+$B30+G$19)*(1+InflLT)-1,$B30+G$19)-gLT)/(1+IF(FixInfl=1,(1+$B30+G$19)*(1+InflLT)-1,$B30+G$19))^(4+1-FixTV)-IF(FixND=1,NDmult*DCF!$M$21,0) -> 144454.79
B34: Upside vs the Ibovespa used
B35: Real rate \ ERP | C35: =C$19 -> 0.04 | D35: =D$19 -> 0.05 | E35: =E$19 -> 0.06 | F35: =F$19 -> 0.07 | G35: =G$19 -> 0.08
B36: =$B$20 -> 0.05 | C36: =C20/IbovUsed-1 -> 1.1821239 | D36: =D20/IbovUsed-1 -> 0.75541144 | E36: =E20/IbovUsed-1 -> 0.46511993 | F36: =F20/IbovUsed-1 -> 0.25512225 | G36: =G20/IbovUsed-1 -> 0.096345059
B37: =$B$21 -> 0.055 | C37: =C21/IbovUsed-1 -> 0.94637972 | D37: =D21/IbovUsed-1 -> 0.5976284 | E37: =E21/IbovUsed-1 -> 0.35230239 | F37: =F21/IbovUsed-1 -> 0.1705656 | G37: =G21/IbovUsed-1 -> 0.030693331
B38: =$B$22 -> 0.06 | C38: =C22/IbovUsed-1 -> 0.75541144 | D38: =D22/IbovUsed-1 -> 0.46511993 | E38: =E22/IbovUsed-1 -> 0.25512225 | F38: =F22/IbovUsed-1 -> 0.096345059 | G38: =G22/IbovUsed-1 -> -0.027776609
B39: =$B$23 -> 0.065 | C39: =C23/IbovUsed-1 -> 0.5976284 | D39: =D23/IbovUsed-1 -> 0.35230239 | E39: =E23/IbovUsed-1 -> 0.1705656 | F39: =F23/IbovUsed-1 -> 0.030693331 | G39: =G23/IbovUsed-1 -> -0.080168523
B40: =$B$24 -> 0.0676 | C40: =C24/IbovUsed-1 -> 0.52596591 | D40: =D24/IbovUsed-1 -> 0.30002773 | E40: =E24/IbovUsed-1 -> 0.13080299 | F40: =F24/IbovUsed-1 -> -0.00053182661 | G40: =G24/IbovUsed-1 -> -0.10531254
B41: =$B$25 -> 0.07 | C41: =C25/IbovUsed-1 -> 0.46511993 | D41: =D25/IbovUsed-1 -> 0.25512225 | E41: =E25/IbovUsed-1 -> 0.096345059 | F41: =F25/IbovUsed-1 -> -0.027776609 | G41: =G25/IbovUsed-1 -> -0.12737168
B42: =$B$26 -> 0.075 | C42: =C26/IbovUsed-1 -> 0.35230239 | D42: =D26/IbovUsed-1 -> 0.1705656 | E42: =E26/IbovUsed-1 -> 0.030693331 | F42: =F26/IbovUsed-1 -> -0.080168523 | G42: =G26/IbovUsed-1 -> -0.1701105
B43: =$B$27 -> 0.08 | C43: =C27/IbovUsed-1 -> 0.25512225 | D43: =D27/IbovUsed-1 -> 0.096345059 | E43: =E27/IbovUsed-1 -> -0.027776609 | F43: =F27/IbovUsed-1 -> -0.12737168 | G43: =G27/IbovUsed-1 -> -0.20898106
B44: =$B$28 -> 0.085 | C44: =C28/IbovUsed-1 -> 0.1705656 | D44: =D28/IbovUsed-1 -> 0.030693331 | E44: =E28/IbovUsed-1 -> -0.080168523 | F44: =F28/IbovUsed-1 -> -0.1701105 | G44: =G28/IbovUsed-1 -> -0.24447826
B45: =$B$29 -> 0.09 | C45: =C29/IbovUsed-1 -> 0.096345059 | D45: =D29/IbovUsed-1 -> -0.027776609 | E45: =E29/IbovUsed-1 -> -0.12737168 | F45: =F29/IbovUsed-1 -> -0.20898106 | G45: =G29/IbovUsed-1 -> -0.27701641
B46: =$B$30 -> 0.095 | C46: =C30/IbovUsed-1 -> 0.030693331 | D46: =D30/IbovUsed-1 -> -0.080168523 | E46: =E30/IbovUsed-1 -> -0.1701105 | F46: =F30/IbovUsed-1 -> -0.24447826 | G46: =G30/IbovUsed-1 -> -0.30694497
...

Sheet Checks
B1: Ibovespa - Checks
B2: 'OK' / 'CHECK' drive the status in C5; 'Info' does not. Tie-outs hold while the projection rules are the house's.
B5: Overall status | C5: =IF(COUNTIF(F8:F23,"CHECK")=0,"All checks OK","Some checks need attention") -> All checks OK
B7: Check | C7: Value | D7: Target | E7: Difference | F7: Status | G7: Note
B8: FCFF 2025, house row = Target row 44 | C8: =DCF!M35 -> 3970.36 | D8: =3970.35999999999 -> 3970.36 | E8: =IFERROR(C8-D8,"") -> 8.6401997e-12 | F8: =IF(ABS(C8-D8)<=0.01,"OK","CHECK") -> OK | G8: House file value.
B9: FCFF 2026, house row = Target row 44 | C9: =DCF!N35 -> 15868.96 | D9: =15868.96 -> 15868.96 | E9: =IFERROR(C9-D9,"") -> 3.6379788e-12 | F9: =IF(ABS(C9-D9)<=0.01,"OK","CHECK") -> OK | G9: House file value.
B10: FCFF 2027, house row = Target row 44 | C10: =DCF!O35 -> 16461.32 | D10: =16461.32 -> 16461.32 | E10: =IFERROR(C10-D10,"") -> 0 | F10: =IF(ABS(C10-D10)<=0.01,"OK","CHECK") -> OK | G10: House file value.
B11: FCFF 2028, house row = Target row 44 | C11: =DCF!P35 -> 16980.784 | D11: =16980.7843199999 -> 16980.784 | E11: =IFERROR(C11-D11,"") -> 9.4587449e-11 | F11: =IF(ABS(C11-D11)<=0.01,"OK","CHECK") -> OK | G11: House file value.
B12: FCFF 2029, house row = Target row 44 | C12: =DCF!Q35 -> 18141.421 | D12: =18141.4206455039 -> 18141.421 | E12: =IFERROR(C12-D12,"") -> 9.4587449e-11 | F12: =IF(ABS(C12-D12)<=0.01,"OK","CHECK") -> OK | G12: House file value.
B13: FCFF 2030, house row = Target row 44 | C13: =DCF!R35 -> 23154.288 | D13: =23154.2881952842 -> 23154.288 | E13: =IFERROR(C13-D13,"") -> 1.4551915e-11 | F13: =IF(ABS(C13-D13)<=0.01,"OK","CHECK") -> OK | G13: House file value.
B14: Terminal value on 2030, house rate (Target!R44) | C14: =DCF!R35*(1+Checks!$C$33)/(Checks!$C$31+Checks!$C$32-Checks!$C$33) -> 278010.78 | D14: =278010.776840167 -> 278010.78 | E14: =IFERROR(C14-D14,"") -> 1.1641532e-10 | F14: =IF(ABS(C14-D14)<=0.01,"OK","CHECK") -> OK
B15: Fair value end-2025, house settings (Target!D59) | C15: =NPV((Checks!$C$31+Checks!$C$32),DCF!$M$35:$R$35)+DCF!$R$35*(1+Checks!$C$33)/((Checks!$C$31+Checks!$C$32)-Checks!$C$33)/(1+(Checks!$C$31+Checks!$C$32))^7-0 -> 173064.09 | D15: =173064.087825606 -> 173064.09 | E15: =IFERROR(C15-D15,"") -> 8.7311491e-11 | F15: =IF(ABS(C15-D15)<=0.01,"OK","CHECK") -> OK | G15: Flows 2025-2030 + TV.
B16: Fair value end-2026, house settings (Target!F59) | C16: =Summary!D28 -> 202259.17 | D16: =202259.168604666 -> 202259.17 | E16: =IFERROR(C16-D16,"") -> 2.6193447e-10 | F16: =IF(ABS(C16-D16)<=0.01,"OK","CHECK") -> OK
B17: Fair value end-2027, house file column (Target!G59) | C17: =Summary!D29 -> 212941.03 | D17: =212941.029031412 -> 212941.03 | E17: =IFERROR(C17-D17,"") -> 4.3655746e-10 | F17: =IF(ABS(C17-D17)<=0.01,"OK","CHECK") -> OK
B18: Real-rate table, largest gap to the house (Sensitivity) | C18: =MAX(MAX(Sensitivity!E7:E14),-MIN(Sensitivity!E7:E14)) -> 0 | D18: =0 -> 0 | E18: =IFERROR(C18-D18,"") -> 0 | F18: =IF(ABS(C18-D18)<=0.01,"OK","CHECK") -> OK
B19: House implied return at the house price (Target!B62) | C19: =IRR(Checks!C35:G35) -> 0.17379161 | D19: =0.173791607034303 -> 0.17379161 | E19: =IFERROR(C19-D19,"") -> 3.0531133e-16 | F19: =IF(ABS(C19-D19)<=0.000001,"OK","CHECK") -> OK | G19: Helper row 35.
B20: Corrections switched on (Assumptions section 4) | C20: =FixNWC+FixND+FixTV+FixInfl -> 0 | D20: =0 -> 0 | E20: =IFERROR(C20-D20,"") -> 0 | F20: ="Info" -> Info | G20: Info: 0 = the house mechanics.
B21: Market data used (1 = house file, 2 = Oct-5) | C21: =Vintage -> 2 | D21: =2 -> 2 | E21: =IFERROR(C21-D21,"") -> 0 | F21: ="Info" -> Info | G21: Info.
B22: Formula errors (DCF, Summary, Sensitivity) | C22: =SUMPRODUCT(--ISERROR(DCF!C8:S90))+SUMPRODUCT(--ISERROR(Summary!C5:G40))+SUMPRODUCT(--ISERROR(Sensitivity!C7:G60)) -> 0 | D22: =0 -> 0 | E22: =IFERROR(C22-D22,"") -> 0 | F22: =IF(ABS(C22-D22)<=0,"OK","CHECK") -> OK
B30: House file settings used by the tie-outs (Target sheet)
B31: 5-year real rate (Target!C56) | C31: 0.0742
B32: ERP (Target!B57) | C32: 0.06
B33: g (Target!B54) | C33: 0.047
B34: Ibovespa (Target!B61) | C34: 182419.73
B35: Helper: house implied-return flows (Target row 61) | C35: =-C34 -> -182419.73 | D35: =DCF!N35 -> 15868.96 | E35: =DCF!O35 -> 16461.32 | F35: =DCF!P35 -> 16980.784 | G35: =DCF!R35*(1+C33)/(C31+C32-C33) -> 278010.78

Sheet Read Me
B1: Ibovespa DCF, house model rolled to end-2027
B2: XP Research · Equity Strategy · built Oct-7-2026 · inputs from DCF Ibov 2026_Out.xlsx (Sep-26); market data Oct-5-2026
B4: What it is
B5: Replica | C5: The DCF block of the house Ibovespa model (DCF Ibov 2026_Out.xlsx, Target sheet rows 17-65 and 120-151), with the same inputs, rules and mechanics.
B6: 2027 | C6: Rolled forward one year: fair value at the end of 2027 from the FCFF of 2028-2031 + terminal value, as the house's end-2026 value uses 2027-2030. 2031 is projected with the house's 2029-2030 rules (nominal GDP growth, 30% EBITDA margin, 9% capex).
B8: How to use it
B9: 1. Change | C9: Assumptions: market data (house file or Oct-5), g, NWC %, scenarios (real rate, ERP), the four correction switches. DCF sheet: pink projection rules.
B10: 2. Read | C10: Summary: bear / base / bull, the correction steps and the tie-out with the house file. Sensitivity: real rate x ERP.
B11: 3. Trace | C11: Summary -> DCF (valuation block -> FCFF rows -> house inputs). Checks ties every key number to the house file.
B13: Mechanics (house)
B14: Cash flow | C14: FCFF = D&A + NOPAT + capex + NWC, where NWC is the level (-4% of sales), not the change.
B15: Discount rate | C15: 5-year real rate (BZRFB5PY) + ERP 6.0%, applied to nominal cash flows.
B16: Terminal value | C16: Last FCFF x (1 + g) / (rate - g), g = 4.7%, put one period after the last flow by Excel NPV.
B17: Equity | C17: The value of the FCFF is read as the index value; net debt is not subtracted.
B19: Corrections
B20: Switches | C20: Assumptions section 4, all off by default (= the house): NWC by change, net debt subtracted (1.6x EBITDA two years before), terminal value discounted with the last flow, inflation in the rate (Fisher). Summary shows the effect step by step.
B22: Sources
B23: Inputs | C23: History 2015-2025 and IBOV Index consensus 2026-2028 (sales and capex to 2027; EBIT, EBITDA and EPS to 2028) as saved in the house file; not refreshed.
B24: Market | C24: Ibovespa 208,431.92 (Oct-5 close); 5-year NTN-B 6.76% (ANBIMA, Oct-5). House file: 182,419.73 and 7.42%.
B25: Code | C25: Brazil Bull Case/scripts/build_house2027.py.
