Workbook
Name BetaAdj: Assumptions!$C$45
Name BetaYears: Assumptions!$C$44
Name BoxCF: Assumptions!$C$46
Name BoxGrowth: Assumptions!$C$47
Name BoxRate: Assumptions!$C$42
Name EBNorm: Assumptions!$C$65
Name EBStart: Assumptions!$C$68
Name ERPfloor: Assumptions!$C$43
Name FadeMode: Assumptions!$C$67
Name FadeYears: Assumptions!$C$48
Name FinROE: 'Box Shares'!$C$39
Name FinROEovr: Assumptions!$C$40
Name FixInfl: Assumptions!$C$29
Name FixND: Assumptions!$C$27
Name FixNWC: Assumptions!$C$26
Name FixTV: Assumptions!$C$28
Name FV27Base: DCF!$D$57
Name FV27Bear: DCF!$C$57
Name FV27Bull: DCF!$E$57
Name gLT: Assumptions!$C$13
Name GrowthCap: Assumptions!$C$49
Name IbovUsed: Assumptions!$E$7
Name InflLT: Assumptions!$C$14
Name NDmult: Assumptions!$C$16
Name NWCpct: Assumptions!$C$15
Name RateShock: Assumptions!$C$64
Name RelMult: Assumptions!$C$56
Name RRUsed: Assumptions!$E$8
Name ScaleBox: Assumptions!$C$39
Name ScaleScen: Assumptions!$C$66
Name Vintage: Assumptions!$C$9
Name WBU: Assumptions!$F$57
Name WDCF: Assumptions!$C$57
Name WEV: Assumptions!$E$57
Name WPE: Assumptions!$D$57

Sheet Cover
C3: Ibovespa | target by box (house model), end-2027
C4: VALUATION MODEL · EQUITY STRATEGY
C7: Main tabs >>
C8: Summary | E8: Assumptions | G8: DCF by Box | I8: Multiples by Box | K8: Ibovespa used | M8: =IbovUsed -> 208431.92
K9: Target end-2027, base (average) | M9: =Summary!E11 -> 222319.31
K10: Upside, base | M10: =Summary!I11 -> 0.066627924
C11: Auxiliary tabs >> | K11: Target end-2027, bear | M11: =Summary!D11 -> 164452.23
C12: DCF (Ibovespa) | E12: Sensitivity | G12: Box Rates | I12: Box Betas | K12: Target end-2027, bull | M12: =Summary!F11 -> 276518.12
K13: Model checks | M13: =Checks!C5 -> All checks OK
C15: Box Earnings | E15: Box Fade | G15: Box Shares | I15: Members (76 stocks) | K15: How this model works >>
K16: Equity Strategy | XP Research
C18: Checks
C21: Target by box, base (average of the methods) >>
C22: Box | F22: Index points | G22: Target | H22: Upside
C23: Financials | F23: =Summary!C7 -> 60927.304 | G23: =Summary!E7 -> 56485.165 | H23: =Summary!I7 -> -0.072908827
C24: Defensives | F24: =Summary!C8 -> 55822.367 | G24: =Summary!E8 -> 58266.156 | H24: =Summary!I8 -> 0.043777943
C25: Cyclicals | F25: =Summary!C9 -> 26271.075 | G25: =Summary!E9 -> 31594.945 | H25: =Summary!I9 -> 0.20265141
C26: Commodities | F26: =Summary!C10 -> 65411.174 | G26: =Summary!E10 -> 75973.04 | H26: =Summary!I10 -> 0.16146883
C27: Ibovespa | F27: =Summary!C11 -> 208431.92 | G27: =Summary!E11 -> 222319.31 | H27: =Summary!I11 -> 0.066627924
C29: House target methods rolled to end-2027 and split by box: DCF (CAPM), P/E, EV/EBITDA and bottom-up, and their average.

Sheet Summary
B1: Ibovespa - Target by box at the end of 2027 (house model)
B2: House Target methods rolled to end-2027 and split by box: DCF (CAPM), P/E, EV/EBITDA, bottom-up, and their average. Construction: Multiples by Box, DCF by Box.
B3: Ibovespa used | C3: =IbovUsed -> 208431.92 | D3: Market data | E3: =CHOOSE(Vintage,"house file","Oct-5-2026") -> Oct-5-2026 | F3: Checks | G3: =Checks!C5 -> All checks OK | H3: Boxes scaled | I3: =IF(ScaleBox=1,"yes","no") -> no
B4: DCF box settings | C4: =CHOOSE(BoxRate+1,"house rate","rate relative to history","CAPM rates")&IF(BoxCF=1,", capex funding growth and NWC by change","")&IF(BoxGrowth=1,", consensus growth fading after 2031","")&CHOOSE(FadeMode+1," (H-model)"," (year by year)"," (year by year, growth paid)")&IF(RateShock=1,"; scenario rate shock x beta","")&IF(ScaleScen=1,"; earnings shocks open the bear / bull","")&IF(RelMult=1,"; multiples relative to history","") -> CAPM rates, capex funding growth and NWC by change (H-model); earnings shocks open the bear / bull; multiples relative to history
B5: 1. Target at the end of 2027 by box: average of the methods (index pts)
B6: Group | C6: Index points | D6: Bear | E6: Base | F6: Bull | H6: Upside: Bear | I6: Base | J6: Bull
B7: Financials | C7: ='Box Shares'!C7 -> 60927.304 | D7: ='Multiples by Box'!C57 -> 42178.948 | E7: ='Multiples by Box'!D57 -> 56485.165 | F7: ='Multiples by Box'!E57 -> 70248.12 | H7: =D7/$C7-1 -> -0.30771681 | I7: =E7/$C7-1 -> -0.072908827 | J7: =F7/$C7-1 -> 0.15298259
B8: Defensives | C8: ='Box Shares'!C8 -> 55822.367 | D8: ='Multiples by Box'!C58 -> 44488.458 | E8: ='Multiples by Box'!D58 -> 58266.156 | F8: ='Multiples by Box'!E58 -> 70165.63 | H8: =D8/$C8-1 -> -0.20303528 | I8: =E8/$C8-1 -> 0.043777943 | J8: =F8/$C8-1 -> 0.25694471
B9: Cyclicals | C9: ='Box Shares'!C9 -> 26271.075 | D9: ='Multiples by Box'!C59 -> 23520.141 | E9: ='Multiples by Box'!D59 -> 31594.945 | F9: ='Multiples by Box'!E59 -> 38674.578 | H9: =D9/$C9-1 -> -0.10471341 | I9: =E9/$C9-1 -> 0.20265141 | J9: =F9/$C9-1 -> 0.47213538
B10: Commodities | C10: ='Box Shares'!C10 -> 65411.174 | D10: ='Multiples by Box'!C60 -> 54264.684 | E10: ='Multiples by Box'!D60 -> 75973.04 | F10: ='Multiples by Box'!E60 -> 97429.794 | H10: =D10/$C10-1 -> -0.17040651 | I10: =E10/$C10-1 -> 0.16146883 | J10: =F10/$C10-1 -> 0.48949769
B11: Ibovespa | C11: =SUM(C7:C10) -> 208431.92 | D11: =SUM(D7:D10) -> 164452.23 | E11: =SUM(E7:E10) -> 222319.31 | F11: =SUM(F7:F10) -> 276518.12 | H11: =D11/$C11-1 -> -0.21100266 | I11: =E11/$C11-1 -> 0.066627924 | J11: =F11/$C11-1 -> 0.32665919
B12: Memo (inside Cyclicals; not additive)
B13: Cyclicals ex-WEG & Embraer | C13: ='Box Shares'!C14 -> 16066.52 | D13: ='Multiples by Box'!C63 -> 16435.648 | E13: ='Multiples by Box'!D63 -> 22098.909 | F13: ='Multiples by Box'!E63 -> 26950.299 | H13: =D13/$C13-1 -> 0.022975024 | I13: =E13/$C13-1 -> 0.37546338 | J13: =F13/$C13-1 -> 0.67741988
B14: WEG & Embraer | C14: ='Box Shares'!C15 -> 10204.555 | D14: ='Multiples by Box'!C64 -> 7941.7118 | E14: ='Multiples by Box'!D64 -> 10167.611 | F14: ='Multiples by Box'!E64 -> 12000.448 | H14: =D14/$C14-1 -> -0.22174836 | I14: =E14/$C14-1 -> -0.0036203445 | J14: =F14/$C14-1 -> 0.17598931
B16: 2. Base case by method (upside vs. index points) and the multiples model
B17: Group | D17: DCF (CAPM) | E17: P/E | F17: EV/EBITDA | G17: Bottom-up | H17: Average of the methods | I17: Multiples model (Oct-6)
B18: Financials | D18: ='DCF by Box'!$D$63 -> -0.061509922 | E18: ='Multiples by Box'!$D$23/$C$7-1 -> -0.075806071 | F18: ='Multiples by Box'!$D$35/$C$7-1 -> -0.075806071 | G18: ='Multiples by Box'!$D$46/$C$7-1 -> -0.078513243 | H18: ='Multiples by Box'!$D$57/$C$7-1 -> -0.072908827 | I18: =$D$80/$C$7-1 -> -0.075462708
B19: Defensives | D19: ='DCF by Box'!$D$110 -> -0.13690961 | E19: ='Multiples by Box'!$D$24/$C$8-1 -> -0.027834485 | F19: ='Multiples by Box'!$D$36/$C$8-1 -> 0.21201325 | G19: ='Multiples by Box'!$D$47/$C$8-1 -> 0.12784261 | H19: ='Multiples by Box'!$D$58/$C$8-1 -> 0.043777943 | I19: =$E$80/$C$8-1 -> 0.070674259
B20: Cyclicals | D20: ='DCF by Box'!$D$157 -> -0.2217573 | E20: ='Multiples by Box'!$D$25/$C$9-1 -> 0.37727396 | F20: ='Multiples by Box'!$D$37/$C$9-1 -> 0.46218697 | G20: ='Multiples by Box'!$D$48/$C$9-1 -> 0.19290201 | H20: ='Multiples by Box'!$D$59/$C$9-1 -> 0.20265141 | I20: =$F$80/$C$9-1 -> 0.39651752
B21: Commodities | D21: ='DCF by Box'!$D$204 -> 0.49842633 | E21: ='Multiples by Box'!$D$26/$C$10-1 -> 0.068629466 | F21: ='Multiples by Box'!$D$38/$C$10-1 -> -0.044772022 | G21: ='Multiples by Box'!$D$49/$C$10-1 -> 0.12359153 | H21: ='Multiples by Box'!$D$60/$C$10-1 -> 0.16146883 | I21: =$G$80/$C$10-1 -> 0.16870547
B22: Ibovespa | D22: ='DCF by Box'!$D$11/$C$11-1 -> 0.073820729 | E22: ='Multiples by Box'!$D$27/$C$11-1 -> 0.039476103 | F22: ='Multiples by Box'!$D$39/$C$11-1 -> 0.078826602 | G22: ='Multiples by Box'!$D$50/$C$11-1 -> 0.074388259 | H22: ='Multiples by Box'!$D$61/$C$11-1 -> 0.066627924 | I22: =$H$80/$C$11-1 -> 0.099791
B23: Memo (inside Cyclicals)
B24: Cyclicals ex-WEG & Embraer | D24: ='DCF by Box'!$D$251 -> -0.094200435 | E24: ='Multiples by Box'!$D$29/$C$13-1 -> 0.57091995 | F24: ='Multiples by Box'!$D$41/$C$13-1 -> 0.78305043 | G24: ='Multiples by Box'!$D$52/$C$13-1 -> 0.24208357 | H24: ='Multiples by Box'!$D$63/$C$13-1 -> 0.37546338 | I24: =$I$80/$C$13-1 -> 0.62781467
B25: WEG & Embraer | D25: ='DCF by Box'!$D$298 -> -0.4307139 | E25: ='Multiples by Box'!$D$30/$C$14-1 -> 0.2765069 | F25: ='Multiples by Box'!$D$42/$C$14-1 -> 0.024257311 | G25: ='Multiples by Box'!$D$53/$C$14-1 -> 0.11546831 | H25: ='Multiples by Box'!$D$64/$C$14-1 -> -0.0036203445 | I25: =$J$80/$C$14-1 -> 0.25783362
B26: Average absolute gap to the multiples model, four boxes | D26: =AVERAGE(ABS(D18-I18),ABS(D19-I19),ABS(D20-I20),ABS(D21-I21)) -> 0.29238308 | E26: =AVERAGE(ABS(E18-I18),ABS(E19-I19),ABS(E20-I20),ABS(E21-I21)) -> 0.054542919 | F26: =AVERAGE(ABS(F18-I18),ABS(F19-I19),ABS(F20-I20),ABS(F21-I21)) -> 0.10520732 | G26: =AVERAGE(ABS(G18-I18),ABS(G19-I19),ABS(G20-I20),ABS(G21-I21)) -> 0.077237085 | H26: =AVERAGE(ABS(H18-I18),ABS(H19-I19),ABS(H20-I20),ABS(H21-I21)) -> 0.05763824
B28: 3. DCF by box (CAPM, box cash flows, Gordon after 2031 as the house; not scaled: the Ibovespa is the sum of the boxes)
B29: Group | C29: Index points | D29: Bear | E29: Base | F29: Bull | H29: Upside: Bear | I29: Base | J29: Bull
B30: Financials | C30: ='Box Shares'!C7 -> 60927.304 | D30: ='DCF by Box'!C62 -> 39337.863 | E30: ='DCF by Box'!D62 -> 57179.67 | F30: ='DCF by Box'!E62 -> 78479.292 | H30: =D30/$C30-1 -> -0.35434755 | I30: =E30/$C30-1 -> -0.061509922 | J30: =F30/$C30-1 -> 0.28808083
B31: Defensives | C31: ='Box Shares'!C8 -> 55822.367 | D31: ='DCF by Box'!C109 -> 32906.129 | E31: ='DCF by Box'!D109 -> 48179.749 | F31: ='DCF by Box'!E109 -> 67069.6 | H31: =D31/$C31-1 -> -0.41052071 | I31: =E31/$C31-1 -> -0.13690961 | J31: =F31/$C31-1 -> 0.20148255
B32: Cyclicals | C32: ='Box Shares'!C9 -> 26271.075 | D32: ='DCF by Box'!C156 -> 11003.825 | E32: ='DCF by Box'!D156 -> 20445.272 | F32: ='DCF by Box'!E156 -> 32356.929 | H32: =D32/$C32-1 -> -0.58114295 | I32: =E32/$C32-1 -> -0.2217573 | J32: =F32/$C32-1 -> 0.2316561
B33: Commodities | C33: ='Box Shares'!C10 -> 65411.174 | D33: ='DCF by Box'!C203 -> 58771.759 | E33: ='DCF by Box'!D203 -> 98013.826 | F33: ='DCF by Box'!E203 -> 149230.1 | H33: =D33/$C33-1 -> -0.10150277 | I33: =E33/$C33-1 -> 0.49842633 | J33: =F33/$C33-1 -> 1.281416
B34: Ibovespa | C34: =SUM(C30:C33) -> 208431.92 | D34: =SUM(D30:D33) -> 142019.58 | E34: =SUM(E30:E33) -> 223818.52 | F34: =SUM(F30:F33) -> 327135.92 | H34: =D34/$C34-1 -> -0.31862847 | I34: =E34/$C34-1 -> 0.073820729 | J34: =F34/$C34-1 -> 0.56950969
B35: Memo (inside Cyclicals; not additive)
B36: Cyclicals ex-WEG & Embraer | C36: ='Box Shares'!C14 -> 16066.52 | D36: ='DCF by Box'!C250 -> 7911.5043 | E36: ='DCF by Box'!D250 -> 14553.046 | F36: ='DCF by Box'!E250 -> 22722.518 | H36: =D36/$C36-1 -> -0.50757821 | I36: =E36/$C36-1 -> -0.094200435 | J36: =F36/$C36-1 -> 0.41427753
B37: WEG & Embraer | C37: ='Box Shares'!C15 -> 10204.555 | D37: ='DCF by Box'!C297 -> 4393.0221 | E37: ='DCF by Box'!D297 -> 5809.3114 | F37: ='DCF by Box'!E297 -> 7506.9963 | H37: =D37/$C37-1 -> -0.56950381 | I37: =E37/$C37-1 -> -0.4307139 | J37: =F37/$C37-1 -> -0.2643485
B39: 4. Discount rate by box (Box Rates)
B40: Group | C40: Relative cash yield | D40: Rate: Bear | E40: Base | F40: Bull | G40: CAPM beta | H40: Risk premium: Bear | I40: Base | J40: Bull
B41: Financials | C41: ='Box Rates'!G7 -> 0.9245176 | D41: ='Box Rates'!C21 -> 0.15394382 | E41: ='Box Rates'!D21 -> 0.13654382 | F41: ='Box Rates'!E21 -> 0.12394382 | G41: ='Box Betas'!I7 -> 1.1490637 | H41: ='Box Rates'!G21 -> 0.068943819 | I41: ='Box Rates'!H21 -> 0.068943819 | J41: ='Box Rates'!I21 -> 0.068943819
B42: Defensives | C42: ='Box Rates'!G8 -> 0.63524349 | D42: ='Box Rates'!C22 -> 0.14072044 | E42: ='Box Rates'!D22 -> 0.12332044 | F42: ='Box Rates'!E22 -> 0.11072044 | G42: ='Box Betas'!I8 -> 0.92867396 | H42: ='Box Rates'!G22 -> 0.055720438 | I42: ='Box Rates'!H22 -> 0.055720438 | J42: ='Box Rates'!I22 -> 0.055720438
B43: Cyclicals | C43: ='Box Rates'!G9 -> 0.29730445 | D43: ='Box Rates'!C23 -> 0.15402707 | E43: ='Box Rates'!D23 -> 0.13662707 | F43: ='Box Rates'!E23 -> 0.12402707 | G43: ='Box Betas'!I9 -> 1.1504511 | H43: ='Box Rates'!G23 -> 0.069027066 | I43: ='Box Rates'!H23 -> 0.069027066 | J43: ='Box Rates'!I23 -> 0.069027066
...

Sheet Assumptions
B1: Ibovespa - DCF assumptions (house model by box, end-2027)
B2: Change the pink cells; the DCF sheet recalculates. Projection rules for 2028-2031 are pink cells in the DCF sheet.
B3: Legend: | C3: input | D3: assumption | E3: formula
B5: 1. Market data
B6: Item | C6: House file | D6: Oct-5-2026 | E6: Used | G6: Source
B7: Ibovespa (index pts) | C7: 182419.73 | D7: 208431.92 | E7: =CHOOSE(Vintage,C7,D7) -> 208431.92 | G7: House file: Target!B61 (BDP IBOV Index, as saved). Oct-5: Bloomberg IBOV Index PX_LAST.
B8: 5-year real rate (NTN-B) | C8: 0.0742 | D8: 0.0676 | E8: =CHOOSE(Vintage,C8,D8) -> 0.0676 | G8: House file: Target!C56 (BZRFB5PY Index, 7.42%). Oct-5: ANBIMA 5-year NTN-B (Bloomberg was down; check BZRFB5PY before publishing).
B9: Market data used: 1 = house file, 2 = Oct-5-2026 | C9: 2 | G9: Consensus and history are the house file's in both cases (not refreshed: the consensus moved little).
B11: 2. Valuation parameters (house Target sheet)
B12: Parameter | C12: Value | G12: Source
B13: Long-term growth of the FCFF (g) | C13: 0.047 | G13: Target!B54 (4.7%).
B14: Long-term inflation (Fisher switch and the implied-return block) | C14: 0.04 | G14: Target!B63 (4.0%).
B15: Working capital, % of sales | C15: 0.04 | G15: Target row 43: NWC = -4% of sales.
B16: Net debt / EBITDA of two years before (net debt switch) | C16: 1.6 | G16: Target rows 70-71 (EV/EBITDA method): net debt = 1.6x the EBITDA of two years before the value date.
B18: 3. Scenarios (fair value at the end of 2027)
B19: Lever | C19: Bear | D19: Base | E19: Bull | G19: Source
B20: 5-year real rate (NTN-B) | C20: 0.085 | D20: =RRUsed -> 0.0676 | E20: 0.055 | G20: House (Target rows 131-151): bear 8.5%, base = the market rate, bull 6.0%. Bull here at 5.5% (a row of the house's real-rate table).
B21: ERP | C21: 0.06 | D21: 0.06 | E21: 0.06 | G21: Target!B57 (6.0%), the same in every scenario.
B22: Discount rate (house: real rate + ERP) | C22: =IF(FixInfl=1,(1+C20+C21)*(1+InflLT)-1,C20+C21) -> 0.145 | D22: =IF(FixInfl=1,(1+D20+D21)*(1+InflLT)-1,D20+D21) -> 0.1276 | E22: =IF(FixInfl=1,(1+E20+E21)*(1+InflLT)-1,E20+E21) -> 0.115 | G22: Target!B55 = BZRFB5PY + ERP. With the inflation switch on: (1 + real rate + ERP) x (1 + inflation) - 1.
B24: 4. Corrections to the house mechanics (0 = as the house, 1 = corrected)
B25: Switch | C25: Value | G25: What it changes
B26: Working capital: 0 = level (house), 1 = change | C26: 0 | G26: House row 44 adds the whole NWC level (-4% of sales) every year; the cash flow is the change in NWC.
B27: Net debt: 0 = not subtracted (house), 1 = subtracted | C27: 0 | G27: FCFF values the firm; equity = firm value - net debt (1.6x EBITDA two years before, as the house's EV/EBITDA method).
B28: Terminal value: 0 = one period after the last flow (house), 1 = with the last flow | C28: 0 | G28: NPV(rate, flows, TV) puts the TV one year after the last explicit year; it is a value at the end of that year.
B29: Inflation in the rate: 0 = real rate + ERP (house), 1 = Fisher | C29: 0 | G29: The flows are nominal (sales grow with nominal GDP); real rate + ERP is a real rate.
B31: 5. Projection rules (pink cells in the DCF sheet, 2028-2031 columns)
B32: Real GDP and inflation 2028-2031: 2.0% and 4.0% (house); sales grow with nominal GDP x ratio (1.0).
B33: EBITDA margin 2029-2031: 30% (house). EBIT margin, interest and gross margin: held at the 2028 level (house: same % as the year before).
B34: Capex % of sales: 11% in 2028-2029, 9% from 2030 (house); 2031, the year added here, keeps 2030's 9%.
B35: Consensus: sales and capex to 2027, EBIT, EBITDA and EPS to 2028 (IBOV Index, as in the house file).
B37: 6. By box
B38: Setting | C38: Value | G38: What it does
B39: Scale the boxes to the house's Ibovespa value: 1 = yes, 0 = no | C39: 0 | G39: 1: each box x (house Ibovespa value / sum of the boxes), so the boxes add up to the house number. 0: each box with its own value.
B40: Financials ROE for the FCFE (blank = consensus FY28, Box Shares) | G40: FCFE = net income x (1 - g / ROE): the earnings left after keeping the bank's equity growing at g.
B41: Index points of the members: Ibovespa on Oct-5-2026 (Assumptions D7) x price-drifted Sep-30 weights.
B42: Box discount rates: 0 = house rate, 1 = relative to history, 2 = CAPM (box beta) | C42: 2 | G42: 0: every box at the house rate. 1: box rate - g = (house rate - g) x the box's 10y cash yield relative to the Ibovespa (Box Rates), as the multiples. 2: CAPM, real rate + box beta x ERP (Box Betas).
B43: Lowest risk premium of a box (box rate >= real rate + this) | C43: 0 | G43: Keeps a box's risk premium from going below this; at 0% it binds only for Cyclicals in the bear.
B44: CAPM beta window (years of weekly returns: 2, 5 or 10) | C44: 5 | G44: Weekly total returns of the box indices up to Sep-25-2026 (Box Betas).
B45: CAPM beta: 1 = raw, 2 = Blume adjusted (0.67 x raw + 0.33) | C45: 1 | G45: The adjustment pulls the betas toward 1 (Bloomberg's default adjusted beta).
B46: Box cash-flow rules: 1 = capex funding growth and NWC by change, 0 = the house rules | C46: 1 | G46: 1: capex = D&A + growth x NOPAT / ROE (Box Shares section 5) and working capital by its change, in the box values only; the house aggregate is untouched.
...

Sheet DCF by Box
B1: Ibovespa - DCF by box (end-2027)
B2: Each box gets its share of every house line (Box Shares); box rules for capex and NWC, consensus growth fading in the TV, CAPM rates (Box Rates). FCFE for Financials.
B3: Legend: | C3: input | D3: assumption | E3: formula
B5: Ibovespa = sum of the four boxes (end-2027)
C6: Bear | D6: Base | E6: Bull
B7: Sum of the box values, own mechanics and box rates (Financials by FCFE) | C7: =C59+C106+C153+C200 -> 142019.58 | D7: =D59+D106+D153+D200 -> 223818.52 | E7: =E59+E106+E153+E200 -> 327135.92 | J7: Defensives + Cyclicals + Commodities (FCFF) + Financials (FCFE), each at its box rate (Box Rates).
B8: House DCF fair value for the Ibovespa (DCF sheet) | C8: =DCF!C57 -> 191722.24 | D8: =DCF!D57 -> 235695.44 | E8: =DCF!E57 -> 281862.98
B9: Scale factor = house value / sum of the boxes | C9: =C8/C7 -> 1.3499705 | D9: =D8/D7 -> 1.053065 | E9: =E8/E7 -> 0.86160818 | J9: Close to 1: the boxes' own values add up to about the house number.
B10: Factor applied (ScaleBox; ScaleScen = 1: the base factor in every scenario) | C10: =IF(ScaleBox=1,IF(ScaleScen=1,$D$9,C9),1) -> 1 | D10: =IF(ScaleBox=1,IF(ScaleScen=1,$D$9,D9),1) -> 1 | E10: =IF(ScaleBox=1,IF(ScaleScen=1,$D$9,E9),1) -> 1 | J10: ScaleScen = 1: the bear / bull keep the base factor, so the earnings shocks (Box Earnings) open the Ibovespa's bear / bull; 0: every scenario = house DCF.
B11: Sum of the box fair values = the Ibovespa by box | C11: =C62+C109+C156+C203 -> 142019.58 | D11: =D62+D109+D156+D203 -> 223818.52 | E11: =E62+E109+E156+E203 -> 327135.92
B12: Memo: sum of the FCFF pieces at the house rate (house mechanics) = house value | C12: =C66+C113+C160+C207 -> 191722.24 | D12: =D66+D113+D160+D207 -> 235695.44 | E12: =E66+E113+E160+E207 -> 281862.98 | J12: The split itself is exact: with every box on the house mechanics and the house rate, the boxes add up to the house value.
B13: Memo: sum of the box values at the house rate (Financials by FCFE) | C13: =C67+C114+C161+C208 -> 185570.93 | D13: =D67+D114+D161+D208 -> 227874.08 | E13: =E67+E114+E161+E208 -> 272279.65 | J13: The boxes as in the house (one rate), for comparison.
B14: Memo: scale factor at the house rate | C14: =C8/C13 -> 1.033148 | D14: =D8/D13 -> 1.0343232 | E14: =E8/E13 -> 1.0351967
B15: Ibovespa by box vs. the house DCF (sum / house - 1) | C15: =C11/C8-1 -> -0.25924308 | D15: =D11/D8-1 -> -0.050390968 | E15: =E11/E8-1 -> 0.16062036
B16: Financials (FCFE)
C17: 2026 | D17: 2027 | E17: 2028 | F17: 2029 | G17: 2030 | H17: 2031 | J17: How it is calculated
B18: Share of sales | C18: ='Box Shares'!D19 -> 0.16009415 | D18: ='Box Shares'!E19 -> 0.1642579 | E18: =D18 -> 0.1642579 | F18: =E18 -> 0.1642579 | G18: =F18 -> 0.1642579 | H18: =G18 -> 0.1642579 | J18: Box Shares: 2026-27 consensus; 2028+ as 2027 (the house projects sales from 2027).
B19: Sales | C19: =DCF!N13*C18 -> 25442.323 | D19: =DCF!O13*D18 -> 26900.352 | E19: =DCF!P13*E18 -> 28535.894 | F19: =DCF!Q13*F18 -> 30270.876 | G19: =DCF!R13*G18 -> 32111.345 | H19: =DCF!S13*H18 -> 34063.715 | J19: House sales (DCF sheet) x share.
B20: Share of EBIT | C20: ='Box Shares'!G19 -> 0.20683299 | D20: ='Box Shares'!H19 -> 0.22119544 | E20: ='Box Shares'!I19 -> 0.22985575 | F20: =E20 -> 0.22985575 | G20: =F20 -> 0.22985575 | H20: =G20 -> 0.22985575 | J20: Box Shares: 2026-28 consensus; 2029+ as 2028.
B21: EBIT | C21: =DCF!N19*C20 -> 6842.0354 | D21: =DCF!O19*D20 -> 7715.9607 | E21: =DCF!P19*E20 -> 8578.6786 | F21: =DCF!Q19*F20 -> 9100.2623 | G21: =DCF!R19*G20 -> 9653.5582 | H21: =DCF!S19*H20 -> 10240.495
B22: Share of EBITDA | C22: ='Box Shares'!J19 -> 0.25196485 | D22: ='Box Shares'!K19 -> 0.25096616 | E22: ='Box Shares'!L19 -> 0.2555345 | F22: =E22 -> 0.2555345 | G22: =F22 -> 0.2555345 | H22: =G22 -> 0.2555345 | J22: Box Shares: 2026-28; 2029+ as 2028. Financials includes the EBITDA the index imputes to banks.
B23: EBITDA | C23: =DCF!N21*C22 -> 12427.914 | D23: =DCF!O21*D22 -> 12728.251 | E23: =DCF!P21*E22 -> 13287.025 | F23: =DCF!Q21*F22 -> 14127.636 | G23: =DCF!R21*G22 -> 14986.597 | H23: =DCF!S21*H22 -> 15897.782
B24: Share of capex | C24: ='Box Shares'!P19 -> 0.24802703 | D24: ='Box Shares'!Q19 -> 0.24938824 | E24: =D24 -> 0.24938824 | F24: =E24 -> 0.24938824 | G24: =F24 -> 0.24938824 | H24: =G24 -> 0.24938824 | J24: Box Shares: 2026-27; 2028+ as 2027.
B25: Capex | C25: =DCF!N33*C24 -> -4751.9498 | D25: =DCF!O33*D24 -> -4821.4228 | E25: =DCF!P33*E24 -> -4765.7786 | F25: =DCF!Q33*F24 -> -5055.5379 | G25: =DCF!R33*G24 -> -4387.8392 | H25: =DCF!S33*H24 -> -4654.6199
B26: Share of net income | C26: ='Box Shares'!M19 -> 0.27229092 | D26: ='Box Shares'!N19 -> 0.29478935 | E26: ='Box Shares'!O19 -> 0.3064974 | F26: =E26 -> 0.3064974 | G26: =F26 -> 0.3064974 | H26: =G26 -> 0.3064974 | J26: Box Shares: 2026-28; 2029+ as 2028.
B27: Net income | C27: =DCF!N29*C26 -> 5706.6731 | D27: =DCF!O29*D26 -> 6386.9061 | E27: =DCF!P29*E26 -> 7103.6903 | F27: =DCF!Q29*F26 -> 7535.5947 | G27: =DCF!R29*G26 -> 7993.7588 | H27: =DCF!S29*H26 -> 8479.7794
B28: D&A = EBITDA - EBIT | C28: =C23-C21 -> 5585.8788 | D28: =D23-D21 -> 5012.2903 | E28: =E23-E21 -> 4708.346 | F28: =F23-F21 -> 5027.3741 | G28: =G23-G21 -> 5333.0385 | H28: =H23-H21 -> 5657.2872
B29: Tax rate (house) | C29: =DCF!N25 -> -0.24 | D29: =DCF!O25 -> -0.24 | E29: =DCF!P25 -> -0.24 | F29: =DCF!Q25 -> -0.24 | G29: =DCF!R25 -> -0.24 | H29: =DCF!S25 -> -0.24 | J29: DCF sheet (house, -24%).
B30: NOPAT = EBIT x (1 + tax rate) | C30: =C21*(1+C29) -> 5199.9469 | D30: =D21*(1+D29) -> 5864.1301 | E30: =E21*(1+E29) -> 6519.7958 | F30: =F21*(1+F29) -> 6916.1993 | G30: =G21*(1+G29) -> 7336.7043 | H30: =H21*(1+H29) -> 7782.7759
B31: Working capital (NWC) = -NWC % x sales | C31: =-NWCpct*C19 -> -1017.6929 | D31: =-NWCpct*D19 -> -1076.0141 | E31: =-NWCpct*E19 -> -1141.4357 | F31: =-NWCpct*F19 -> -1210.835 | G31: =-NWCpct*G19 -> -1284.4538 | H31: =-NWCpct*H19 -> -1362.5486
B32: Change in NWC | D32: =D31-C31 -> -58.321171 | E32: =E31-D31 -> -65.421657 | F32: =F31-E31 -> -69.399293 | G32: =G31-F31 -> -73.61877 | H32: =H31-G31 -> -78.094792
B33: FCFF, house = D&A + NOPAT + capex + NWC (level) | C33: =C28+C30+C25+C31 -> 5016.1829 | D33: =D28+D30+D25+D31 -> 4978.9835 | E33: =E28+E30+E25+E31 -> 5320.9274 | F33: =F28+F30+F25+F31 -> 5677.2005 | G33: =G28+G30+G25+G31 -> 6997.4497 | H33: =H28+H30+H25+H31 -> 7422.8946
B34: FCFF with the change in NWC | D34: =D28+D30+D25+D32 -> 5996.6764 | E34: =E28+E30+E25+E32 -> 6396.9415 | F34: =F28+F30+F25+F32 -> 6818.6362 | G34: =G28+G30+G25+G32 -> 8208.2847 | H34: =H28+H30+H25+H32 -> 8707.3484
B35: FCFF, house mechanics (switch FixNWC) | C35: =C33 -> 5016.1829 | D35: =IF(FixNWC=1,D34,D33) -> 4978.9835 | E35: =IF(FixNWC=1,E34,E33) -> 5320.9274 | F35: =IF(FixNWC=1,F34,F33) -> 5677.2005 | G35: =IF(FixNWC=1,G34,G33) -> 6997.4497 | H35: =IF(FixNWC=1,H34,H33) -> 7422.8946 | J35: FixNWC = 0: house row; 1: corrected row. Sum of the boxes = house FCFF (Checks); used for the house-rate memo.
B36: Capex funding growth = -(D&A + growth x NOPAT / ROE) | C36: =C25 -> -4751.9498 | D36: =D25 -> -4821.4228 | E36: =-(E28+DCF!P11*E30/'Box Shares'!$E$44) -> -6703.2692 | F36: =-(F28+DCF!Q11*F30/'Box Shares'!$E$44) -> -7143.5887 | G36: =-(G28+DCF!R11*G30/'Box Shares'!$E$44) -> -7577.9189 | H36: =-(H28+DCF!S11*H30/'Box Shares'!$E$44) -> -8038.6564 | J36: 2028+: D&A + the reinvestment that funds the year's growth (house sales growth) at the box's FY28 ROE (Box Shares section 5); 2026-27: consensus.
B37: FCFF, box rules = D&A + NOPAT + capex funding growth + change in NWC | C37: =C33 -> 5016.1829 | D37: =D28+D30+D36+D32 -> 5996.6764 | E37: =E28+E30+E36+E32 -> 4459.4508 | F37: =F28+F30+F36+F32 -> 4730.5854 | G37: =G28+G30+G36+G32 -> 5018.205 | H37: =H28+H30+H36+H32 -> 5323.3119
B38: FCFF used for the box value (switch BoxCF) | C38: =IF(BoxCF=1,C37,C35) -> 5016.1829 | D38: =IF(BoxCF=1,D37,D35) -> 5996.6764 | E38: =IF(BoxCF=1,E37,E35) -> 4459.4508 | F38: =IF(BoxCF=1,F37,F35) -> 4730.5854 | G38: =IF(BoxCF=1,G37,G35) -> 5018.205 | H38: =IF(BoxCF=1,H37,H35) -> 5323.3119 | J38: BoxCF = 1: box rules (row above); 0: the house mechanics.
B39: ROE (Financials, Box Shares section 4) | C39: =FinROE -> 0.19870618 | D39: =FinROE -> 0.19870618 | E39: =FinROE -> 0.19870618 | F39: =FinROE -> 0.19870618 | G39: =FinROE -> 0.19870618 | H39: =FinROE -> 0.19870618
B40: FCFE = net income x (1 - g / ROE) | C40: =C27*(1-gLT/C39) -> 4356.8729 | D40: =D27*(1-gLT/D39) -> 4876.2103 | E40: =E27*(1-gLT/E39) -> 5423.4535 | F40: =F27*(1-gLT/F39) -> 5753.1994 | G40: =G27*(1-gLT/G39) -> 6102.994 | H40: =H27*(1-gLT/H39) -> 6474.056 | J40: Financials only: the value used for the box (same g as the house).
B42: Valuation at the end of 2027 | C42: Bear | D42: Base | E42: Bull
...

Sheet Multiples by Box
B1: Ibovespa - Target by box: house multiples, bottom-up and the average of the methods (end-2027)
B2: House Target methods for 2027 split by box: P/E and EV/EBITDA at each box's 10y relative multiple (calibrated to the house value), bottom-up from the analysts' TPs.
B3: Legend: | C3: input | D3: assumption | E3: formula
B5: 1. House methods for the Ibovespa, end-2027 (Target rows 67-90)
C6: Bear | D6: Base | E6: Bull
B7: Target P/E on 2027 EPS (Assumptions) | C7: =Assumptions!C53 -> 7.5 | D7: =Assumptions!D53 -> 10 | E7: =Assumptions!E53 -> 12
B8: EPS 2027, house (DCF sheet) | C8: =DCF!$O$29 -> 21666 | D8: =DCF!$O$29 -> 21666 | E8: =DCF!$O$29 -> 21666
B9: P/E method = target P/E x EPS 2027 | C9: =C7*C8 -> 162495 | D9: =D7*D8 -> 216660 | E9: =E7*E8 -> 259992
B10: Target EV/EBITDA on 2027 EBITDA (Assumptions) | C10: =Assumptions!C54 -> 4.5 | D10: =Assumptions!D54 -> 5.5 | E10: =Assumptions!E54 -> 6
B11: EBITDA 2027, house (DCF sheet) | C11: =DCF!$O$21 -> 50717 | D11: =DCF!$O$21 -> 50717 | E11: =DCF!$O$21 -> 50717
B12: Net debt = 1.6x EBITDA 2025 (house) | C12: =NDmult*DCF!$M$21 -> 54081.6 | D12: =NDmult*DCF!$M$21 -> 54081.6 | E12: =NDmult*DCF!$M$21 -> 54081.6
B13: EV/EBITDA method = target x EBITDA 2027 - net debt | C13: =C10*C11-C12 -> 174144.9 | D13: =D10*D11-D12 -> 224861.9 | E13: =E10*E11-E12 -> 250220.4
B14: Bottom-up: members at the analysts' target prices (section 4) | C14: =C50 -> 179149.45 | D14: =D50 -> 223936.81 | E14: =E50 -> 268724.17
B15: DCF: Ibovespa by box (DCF by Box; = the house DCF in the base) | C15: ='DCF by Box'!C11 -> 142019.58 | D15: ='DCF by Box'!D11 -> 223818.52 | E15: ='DCF by Box'!E11 -> 327135.92
B16: Average of the methods (weights in Assumptions) | C16: =(WDCF*C15+WPE*C9+WEV*C13+WBU*C14)/(WDCF+WPE+WEV+WBU) -> 164452.23 | D16: =(WDCF*D15+WPE*D9+WEV*D13+WBU*D14)/(WDCF+WPE+WEV+WBU) -> 222319.31 | E16: =(WDCF*E15+WPE*E9+WEV*E13+WBU*E14)/(WDCF+WPE+WEV+WBU) -> 276518.12
B17: Ibovespa used | C17: =IbovUsed -> 208431.92 | D17: =IbovUsed -> 208431.92 | E17: =IbovUsed -> 208431.92
B18: Upside of the average | C18: =C16/C17-1 -> -0.21100266 | D18: =D16/D17-1 -> 0.066627924 | E18: =E16/E17-1 -> 0.32665919
B20: 2. P/E method by box: house P/E x the box's 10y relative P/E, calibrated to the house value
B21: Group | C21: Bear | D21: Base | E21: Bull | G21: Relative P/E (10y average) | H21: EPS 2027 (pts) | I21: P/E today on 2027 EPS | J21: Target P/E, base
B22: Calibration: house P/E value / sum of (relative P/E x box EPS) | C22: =C9/SUMPRODUCT($G$23:$G$26,$H$23:$H$26) -> 7.131865 | D22: =D9/SUMPRODUCT($G$23:$G$26,$H$23:$H$26) -> 9.5091533 | E22: =E9/SUMPRODUCT($G$23:$G$26,$H$23:$H$26) -> 11.410984
B23: Financials | C23: =C$22*$G23*$H23 -> 42231.483 | D23: =D$22*$G23*$H23 -> 56308.644 | E23: =E$22*$G23*$H23 -> 67570.373 | G23: =IF(RelMult=1,$P$68,1) -> 0.9271344 | H23: =DCF!$O$29*'Box Shares'!N19 -> 6386.9061 | I23: ='Box Shares'!$C$7/H23 -> 9.5394081 | J23: =D$22*G23 -> 8.8162631
B24: Defensives | C24: =C$22*$G24*$H24 -> 40701.435 | D24: =D$22*$G24*$H24 -> 54268.581 | E24: =E$22*$G24*$H24 -> 65122.297 | G24: =IF(RelMult=1,$Q$68,1) -> 1.4978491 | H24: =DCF!$O$29*'Box Shares'!N20 -> 3810.1192 | I24: ='Box Shares'!$C$8/H24 -> 14.651082 | J24: =D$22*G24 -> 14.243276
B25: Cyclicals | C25: =C$22*$G25*$H25 -> 27136.85 | D25: =D$22*$G25*$H25 -> 36182.467 | E25: =E$22*$G25*$H25 -> 43418.96 | G25: =IF(RelMult=1,$R$68,1) -> 1.9750615 | H25: =DCF!$O$29*'Box Shares'!N21 -> 1926.5297 | I25: ='Box Shares'!$C$9/H25 -> 13.636476 | J25: =D$22*G25 -> 18.781163
B26: Commodities | C26: =C$22*$G26*$H26 -> 52425.231 | D26: =D$22*$G26*$H26 -> 69900.308 | E26: =E$22*$G26*$H26 -> 83880.37 | G26: =IF(RelMult=1,$S$68,1) -> 0.77033136 | H26: =DCF!$O$29*'Box Shares'!N22 -> 9542.4451 | I26: ='Box Shares'!$C$10/H26 -> 6.8547604 | J26: =D$22*G26 -> 7.3251989
B27: Ibovespa | C27: =SUM(C23:C26) -> 162495 | D27: =SUM(D23:D26) -> 216660 | E27: =SUM(E23:E26) -> 259992 | H27: =SUM(H23:H26) -> 21666 | I27: ='Box Shares'!$C$11/H27 -> 9.6202308
B28: Memo (inside Cyclicals; own relative multiple, not additive)
B29: Cyclicals ex-WEG & Embraer | C29: =C$22*$G29*$H29 -> 18929.412 | D29: =D$22*$G29*$H29 -> 25239.216 | E29: =E$22*$G29*$H29 -> 30287.059 | G29: =IF(RelMult=1,$T$68,1) -> 1.7945678 | H29: =DCF!$O$29*'Box Shares'!N25 -> 1479.0203 | I29: ='Box Shares'!$C$14/H29 -> 10.862947 | J29: =D$22*G29 -> 17.06482
B30: WEG & Embraer | C30: =C$22*$G30*$H30 -> 9769.6387 | D30: =D$22*$G30*$H30 -> 13026.185 | E30: =E$22*$G30*$H30 -> 15631.422 | G30: =IF(RelMult=1,$U$68,1) -> 3.0610703 | H30: =DCF!$O$29*'Box Shares'!N26 -> 447.50933 | I30: ='Box Shares'!$C$15/H30 -> 22.803 | J30: =D$22*G30 -> 29.108186
B32: 3. EV/EBITDA method by box: house multiple x the box's 10y relative EV/EBITDA, calibrated (Financials: P/E value)
B33: Group | C33: Bear | D33: Base | E33: Bull | G33: Relative EV/EBITDA (10y average) | H33: EBITDA 2027 (pts) | I33: Net debt (pts) | J33: Target EV/EBITDA, base
B34: Calibration: (house value - Financials + others' net debt) / boxes' EV | C34: =(C13-C35+SUM($I$36:$I$38))/(C10*SUMPRODUCT($G$36:$G$38,$H$36:$H$38)) -> 0.96889776 | D34: =(D13-D35+SUM($I$36:$I$38))/(D10*SUMPRODUCT($G$36:$G$38,$H$36:$H$38)) -> 0.9612438 | E34: =(E13-E35+SUM($I$36:$I$38))/(E10*SUMPRODUCT($G$36:$G$38,$H$36:$H$38)) -> 0.94056955
B35: Financials (P/E value: EV/EBITDA does not apply) | C35: =C23 -> 42231.483 | D35: =D23 -> 56308.644 | E35: =E23 -> 67570.373
B36: Defensives | C36: =C$34*C$10*$G36*$H36-$I36 -> 53979.19 | D36: =D$34*D$10*$G36*$H36-$I36 -> 67657.449 | E36: =E$34*E$10*$G36*$H36-$I36 -> 72920.008 | G36: =IF(RelMult=1,$V$68,1) -> 1.3778556 | H36: =DCF!$O$21*'Box Shares'!K20 -> 10711.262 | I36: =NDmult*DCF!$M$21*'Box Shares'!J20 -> 10368.776 | J36: =D$34*D$10*G36 -> 7.2845035
B37: Cyclicals | C37: =C$34*C$10*$G37*$H37-$I37 -> 30868.834 | D37: =D$34*D$10*$G37*$H37-$I37 -> 38413.223 | E37: =E$34*E$10*$G37*$H37-$I37 -> 41315.843 | G37: =IF(RelMult=1,$W$68,1) -> 1.7471493 | H37: =DCF!$O$21*'Box Shares'!K21 -> 4659.1593 | I37: =NDmult*DCF!$M$21*'Box Shares'!J21 -> 4622.9672 | J37: =D$34*D$10*G37 -> 9.2369003
B38: Commodities | C38: =C$34*C$10*$G38*$H38-$I38 -> 47065.393 | D38: =D$34*D$10*$G38*$H38-$I38 -> 62482.584 | E38: =E$34*E$10*$G38*$H38-$I38 -> 68414.177 | G38: =IF(RelMult=1,$X$68,1) -> 0.73545865 | H38: =DCF!$O$21*'Box Shares'!K22 -> 22618.328 | I38: =NDmult*DCF!$M$21*'Box Shares'!J22 -> 25463.195 | J38: =D$34*D$10*G38 -> 3.8882529
B39: Ibovespa | C39: =SUM(C35:C38) -> 174144.9 | D39: =SUM(D35:D38) -> 224861.9 | E39: =SUM(E35:E38) -> 250220.4 | H39: =SUM(H35:H38) -> 37988.749 | I39: =SUM(I35:I38) -> 40454.938
B40: Memo (inside Cyclicals; own relative multiple, not additive)
B41: Cyclicals ex-WEG & Embraer | C41: =C$34*C$10*$G41*$H41-$I41 -> 22936.909 | D41: =D$34*D$10*$G41*$H41-$I41 -> 28647.415 | E41: =E$34*E$10*$G41*$H41-$I41 -> 30844.468 | G41: =IF(RelMult=1,$Y$68,1) -> 1.567039 | H41: =DCF!$O$21*'Box Shares'!K25 -> 3931.9528 | I41: =NDmult*DCF!$M$21*'Box Shares'!J25 -> 3927.5796 | J41: =D$34*D$10*G41 -> 8.2846859
B42: WEG & Embraer | C42: =C$34*C$10*$G42*$H42-$I42 -> 8497.8998 | D42: =D$34*D$10*$G42*$H42-$I42 -> 10452.09 | E42: =E$34*E$10*$G42*$H42-$I42 -> 11203.943 | G42: =IF(RelMult=1,$Z$68,1) -> 2.8994967 | H42: =DCF!$O$21*'Box Shares'!K26 -> 727.20651 | I42: =NDmult*DCF!$M$21*'Box Shares'!J26 -> 695.38762 | J42: =D$34*D$10*G42 -> 15.329178
B44: 4. Bottom-up by box: the members at the analysts' 12m target prices (Members), x (1 + change) in the bear / bull
...

Sheet DCF
B1: Ibovespa - DCF (house model rolled to end-2027)
B2: Replica of Target rows 17-65 of DCF Ibov 2026_Out.xlsx, in Ibovespa points, extended to 2031. Blue = house file input; pink = projection rule.
B3: Legend: | C3: input | D3: assumption | E3: formula
B5: Projections (index points)
C6: 2015 | D6: 2016 | E6: 2017 | F6: 2018 | G6: 2019 | H6: 2020 | I6: 2021 | J6: 2022 | K6: 2023 | L6: 2024 | M6: 2025 | N6: 2026 | O6: 2027 | P6: 2028 | Q6: 2029 | R6: 2030 | S6: 2031 | U6: How it is calculated (house Target row)
C7: Actual | D7: Actual | E7: Actual | F7: Actual | G7: Actual | H7: Actual | I7: Actual | J7: Actual | K7: Actual | L7: Actual | M7: Actual | N7: Consensus | O7: Consensus | P7: Consensus | Q7: Projection | R7: Projection | S7: Projection
B8: Real GDP | J8: 0.029 | K8: 0.029 | L8: 0.031 | M8: 0.021 | N8: 0.018 | O8: 0.01 | P8: 0.02 | Q8: 0.02 | R8: 0.02 | S8: 0.02
B9: Inflation | C9: 0.1067 | D9: 0.0629 | E9: 0.0295 | F9: 0.0375 | G9: 0.0431 | H9: 0.045 | I9: 0.101 | J9: 0.058 | K9: 0.046 | L9: 0.046 | M9: 0.045 | N9: 0.038 | O9: 0.04 | P9: 0.04 | Q9: 0.04 | R9: 0.04 | S9: 0.04
B10: Nominal GDP | C10: =(1+C8)*(1+C9)-1 -> 0.1067 | D10: =(1+D8)*(1+D9)-1 -> 0.0629 | E10: =(1+E8)*(1+E9)-1 -> 0.0295 | F10: =(1+F8)*(1+F9)-1 -> 0.0375 | G10: =(1+G8)*(1+G9)-1 -> 0.0431 | H10: =(1+H8)*(1+H9)-1 -> 0.045 | I10: =(1+I8)*(1+I9)-1 -> 0.101 | J10: =(1+J8)*(1+J9)-1 -> 0.088682 | ... S10: =(1+S8)*(1+S9)-1 -> 0.0608 | U10: (1 + real GDP) x (1 + inflation) - 1 (row 20).
B11: Sales growth | D11: =D13/C13-1 -> 0.031809353 | E11: =E13/D13-1 -> 0.014830489 | F11: =F13/E13-1 -> 0.16663413 | G11: =G13/F13-1 -> 0.12933978 | H11: =H13/G13-1 -> 0.081369435 | I11: =I13/H13-1 -> 0.33636272 | J11: =J13/I13-1 -> 0.20564508 | K11: =K13/J13-1 -> 0.058209825 | ... O11: =O13/N13-1 -> 0.030505723 | P11: =P10*P12 -> 0.0608 | Q11: =Q10*Q12 -> 0.0608 | R11: =R10*R12 -> 0.0608 | S11: =S10*S12 -> 0.0608 | U11: Actual/consensus: sales / previous - 1. Projection: nominal GDP x ratio (row 21).
B12: Ratio (sales growth / nominal GDP) | D12: =D11/D10 -> 0.50571309 | E12: =E11/E10 -> 0.50272844 | F12: =F11/F10 -> 4.4435767 | G12: =G11/G10 -> 3.0009229 | H12: =H11/H10 -> 1.8082097 | I12: =I11/I10 -> 3.3303239 | J12: =J11/J10 -> 2.3189044 | K12: =K11/K10 -> 0.76256746 | ... O12: =O11/O10 -> 0.60527228 | P12: 1 | Q12: 1 | R12: 1 | S12: 1
B13: Sales | C13: 51357.85 | D13: 52991.51 | E13: 53777.4 | F13: 62738.55 | G13: 70853.14 | H13: 76618.42 | I13: 102390 | J13: 123446 | K13: 130631.77 | L13: 138166 | M13: 150140 | N13: 158921 | O13: 163769 | P13: =O13*(1+P11) -> 173726.16 | Q13: =P13*(1+Q11) -> 184288.71 | R13: =Q13*(1+R11) -> 195493.46 | S13: =R13*(1+S11) -> 207379.46 | U13: To 2027: house file (consensus 2026-27). 2028+: previous x (1 + growth) (row 25).
B14: COGS | C14: =C13*(C15-1) -> -38374.586 | D14: =D13*(D15-1) -> -39865.513 | E14: =E13*(E15-1) -> -38940.215 | F14: =F13*(F15-1) -> -44801.599 | G14: =G13*(G15-1) -> -50192.364 | H14: =H13*(H15-1) -> -53939.368 | I14: =I13*(I15-1) -> -65529.6 | J14: =J13*(J15-1) -> -82708.82 | ... S14: =S13*(S15-1) -> -133199.83 | U14: Sales x (gross margin - 1) (row 26).
B15: Gross margin % | C15: 0.2528 | D15: 0.2477 | E15: 0.2759 | F15: 0.2859 | G15: 0.2916 | H15: 0.296 | I15: 0.36 | J15: 0.33 | K15: 0.2757 | L15: 0.2514 | M15: 0.2737 | N15: 0.388 | O15: 0.3827 | P15: 0.3577 | Q15: =P15 -> 0.3577 | R15: =Q15 -> 0.3577 | S15: =R15 -> 0.3577 | U15: To 2028: house file. 2029+: previous year (row 27).
B16: Gross profit | C16: =C13+C14 -> 12983.264 | D16: =D13+D14 -> 13125.997 | E16: =E13+E14 -> 14837.185 | F16: =F13+F14 -> 17936.951 | G16: =G13+G14 -> 20660.776 | H16: =H13+H14 -> 22679.052 | I16: =I13+I14 -> 36860.4 | J16: =J13+J14 -> 40737.18 | ... S16: =S13+S14 -> 74179.633
B17: SG&A | C17: =C19-C16 -> -11461.954 | D17: =D19-D16 -> -6806.437 | E17: =E19-E16 -> -7556.5447 | F17: =F19-F16 -> -8126.6114 | G17: =G19-G16 -> -11860.076 | H17: =H19-H16 -> -11988.992 | I17: =I19-I16 -> -13266.4 | J17: =J19-J16 -> -14963.67 | ... P17: =P19-P16 -> -24819.836 | Q17: =Q13*Q18 -> -26328.882 | R17: =R13*R18 -> -27929.678 | S17: =S13*S18 -> -29627.802 | U17: To 2028: EBIT - gross profit. 2029+: sales x SG&A % (row 29).
B18: SG&A % of sales | C18: =C17/C13 -> -0.22317824 | D18: =D17/D13 -> -0.12844392 | E18: =E17/E13 -> -0.14051525 | F18: =F17/F13 -> -0.12953139 | G18: =G17/G13 -> -0.16738956 | H18: =H17/H13 -> -0.15647663 | I18: =I17/I13 -> -0.12956734 | J18: =J17/J13 -> -0.12121632 | ... P18: =P17/P13 -> -0.14286758 | Q18: =P18 -> -0.14286758 | R18: =Q18 -> -0.14286758 | S18: =R18 -> -0.14286758 | U18: 2029+: previous year's % (row 30).
B19: EBIT | C19: 1521.31 | D19: 6319.56 | E19: 7280.64 | F19: 9810.34 | G19: 8800.7 | H19: 10690.06 | I19: 23594 | J19: 25773.51 | K19: 21324.34 | L19: 25291.3 | M19: 20846 | N19: 33080 | O19: 34883 | P19: 37322.01 | Q19: =Q16+Q17 -> 39591.188 | R19: =R16+R17 -> 41998.332 | S19: =S16+S17 -> 44551.831 | U19: To 2028: house file (consensus). 2029+: gross profit + SG&A (row 31).
B20: EBIT margin % | C20: =C19/C13 -> 0.029621762 | D20: =D19/D13 -> 0.11925608 | E20: =E19/E13 -> 0.13538475 | F20: =F19/F13 -> 0.15636861 | G20: =G19/G13 -> 0.12421044 | H20: =H19/H13 -> 0.13952337 | I20: =I19/I13 -> 0.23043266 | J20: =J19/J13 -> 0.20878368 | ... S20: =S19/S13 -> 0.21483242
B21: EBITDA | C21: 11322.26 | D21: 11803.92 | E21: 13642.8 | F21: 17850.25 | G21: 18979.35 | H21: 19022.66 | I21: 31545 | J21: 36387.17 | K21: 32032.37 | L21: 37339 | M21: 33801 | N21: 49324 | O21: 50717 | P21: 51996.99 | Q21: =Q13*Q22 -> 55286.612 | R21: =R13*R22 -> 58648.038 | S21: =S13*S22 -> 62213.838 | U21: To 2028: house file (consensus). 2029+: sales x EBITDA margin (row 33).
B22: EBITDA margin % | C22: =C21/C13 -> 0.22045822 | D22: =D21/D13 -> 0.22275115 | E22: =E21/E13 -> 0.25369021 | F22: =F21/F13 -> 0.28451805 | G22: =G21/G13 -> 0.26786886 | H22: =H21/H13 -> 0.24827789 | I22: =I21/I13 -> 0.30808673 | J22: =J21/J13 -> 0.29476184 | ... P22: =P21/P13 -> 0.29930433 | Q22: 0.3 | R22: 0.3 | S22: 0.3 | U22: 2029+: 30% (house, row 34).
B23: D&A | C23: =C21-C19 -> 9800.95 | D23: =D21-D19 -> 5484.36 | E23: =E21-E19 -> 6362.16 | F23: =F21-F19 -> 8039.91 | G23: =G21-G19 -> 10178.65 | H23: =H21-H19 -> 8332.6 | I23: =I21-I19 -> 7951 | J23: =J21-J19 -> 10613.66 | ... S23: =S21-S19 -> 17662.007 | U23: EBITDA - EBIT (row 35).
B24: D&A % of sales | C24: =C23/C13 -> 0.19083645 | D24: =D23/D13 -> 0.10349507 | E24: =E23/E13 -> 0.11830546 | F24: =F23/F13 -> 0.12814944 | G24: =G23/G13 -> 0.14365842 | H24: =H23/H13 -> 0.10875453 | I24: =I23/I13 -> 0.077654068 | J24: =J23/J13 -> 0.08597816 | ... S24: =S23/S13 -> 0.085167582
B25: Tax rate | C25: -0.25 | D25: =C25 -> -0.25 | E25: =D25 -> -0.25 | F25: =E25 -> -0.25 | G25: =F25 -> -0.25 | H25: =G25 -> -0.25 | I25: =H25 -> -0.25 | J25: =I25 -> -0.25 | K25: =J25 -> -0.25 | L25: -0.24 | M25: =L25 -> -0.24 | N25: =M25 -> -0.24 | O25: =N25 -> -0.24 | P25: =O25 -> -0.24 | Q25: =P25 -> -0.24 | R25: =Q25 -> -0.24 | S25: =R25 -> -0.24 | U25: -25% to 2023, -24% from 2024 (row 37).
B26: NOPAT | C26: =C19*(1+C25) -> 1140.9825 | D26: =D19*(1+D25) -> 4739.67 | E26: =E19*(1+E25) -> 5460.48 | F26: =F19*(1+F25) -> 7357.755 | G26: =G19*(1+G25) -> 6600.525 | H26: =H19*(1+H25) -> 8017.545 | I26: =I19*(1+I25) -> 17695.5 | J26: =J19*(1+J25) -> 19330.132 | ... S26: =S19*(1+S25) -> 33859.392 | U26: EBIT x (1 + tax rate) (row 38).
B27: Net interest expense | C27: =C29-C26 -> -1992.7125 | D27: =D29-D26 -> -1693.5 | E27: =E29-E26 -> -1553.31 | F27: =F29-F26 -> -1433.345 | G27: =G29-G26 -> -1239.105 | H27: =H29-H26 -> -4140.545 | I27: =I29-I26 -> -2007.5 | J27: =J29-J26 -> -561.0525 | ... P27: =P29-P26 -> -5187.7276 | Q27: =Q13*Q28 -> -5503.1414 | R27: =R13*R28 -> -5837.7324 | S27: =S13*S28 -> -6192.6666 | U27: To 2028: net income - NOPAT. 2029+: sales x interest % (row 39).
B28: Interest % of sales | C28: =C27/C13 -> -0.038800544 | D28: =D27/D13 -> -0.031957949 | E28: =E27/E13 -> -0.028884067 | F28: =F27/F13 -> -0.02284632 | G28: =G27/G13 -> -0.017488357 | H28: =H27/H13 -> -0.054041117 | I28: =I27/I13 -> -0.019606407 | J28: =J27/J13 -> -0.0045449225 | ... P28: =P27/P13 -> -0.029861523 | Q28: =P28 -> -0.029861523 | R28: =Q28 -> -0.029861523 | S28: =R28 -> -0.029861523 | U28: 2029+: previous year's % (row 40).
B29: Net income (EPS, index pts) | C29: -851.73 | D29: 3046.17 | E29: 3907.17 | F29: 5924.41 | G29: 5361.42 | H29: 3877 | I29: 15688 | J29: 18769.08 | K29: 13729.57 | L29: 14944 | M29: 13889 | N29: 20958 | O29: 21666 | P29: 23177 | Q29: =Q26+Q27 -> 24586.162 | R29: =R26+R27 -> 26081 | S29: =S26+S27 -> 27666.725 | U29: To 2028: house file (consensus EPS). 2029+: NOPAT + net interest (row 41).
B30: Net margin % | C30: =C29/C13 -> -0.016584222 | D30: =D29/D13 -> 0.057484114 | E30: =E29/E13 -> 0.072654498 | F30: =F29/F13 -> 0.094430139 | G30: =G29/G13 -> 0.075669476 | H30: =H29/H13 -> 0.050601409 | I30: =I29/I13 -> 0.15321809 | J30: =J29/J13 -> 0.15204284 | ... S30: =S29/S13 -> 0.13341111
B31: Working capital (NWC) | C31: =-NWCpct*C13 -> -2054.314 | D31: =-NWCpct*D13 -> -2119.6604 | E31: =-NWCpct*E13 -> -2151.096 | F31: =-NWCpct*F13 -> -2509.542 | G31: =-NWCpct*G13 -> -2834.1256 | H31: =-NWCpct*H13 -> -3064.7368 | I31: =-NWCpct*I13 -> -4095.6 | J31: =-NWCpct*J13 -> -4937.84 | ... S31: =-NWCpct*S13 -> -8295.1784 | U31: -NWC % x sales (Assumptions; row 43).
B32: Change in NWC | D32: =D31-C31 -> -65.3464 | E32: =E31-D31 -> -31.4356 | F32: =F31-E31 -> -358.446 | G32: =G31-F31 -> -324.5836 | H32: =H31-G31 -> -230.6112 | I32: =I31-H31 -> -1030.8632 | J32: =J31-I31 -> -842.24 | K32: =K31-J31 -> -287.4308 | ... S32: =S31-R31 -> -475.44009
B33: Capex | C33: -5294.22 | D33: -3805.46 | E33: -3278.37 | F33: -3699.48 | G33: -3779.44 | H33: -3672 | I33: -4618.18 | J33: -6641.75 | K33: -8753.81 | L33: -10938 | M33: -18822 | N33: -19159 | O33: -19333 | P33: =P13*P34 -> -19109.877 | Q33: =Q13*Q34 -> -20271.758 | R33: =R13*R34 -> -17594.411 | S33: =S13*S34 -> -18664.151 | U33: To 2027: house file. 2028+: sales x capex % (row 46).
B34: Capex % of sales | C34: =C33/C13 -> -0.10308492 | D34: =D33/D13 -> -0.071812636 | E34: =E33/E13 -> -0.060961854 | F34: =F33/F13 -> -0.058966616 | G34: =G33/G13 -> -0.053341884 | H34: =H33/H13 -> -0.047925812 | I34: =I33/I13 -> -0.045103819 | J34: =J33/J13 -> -0.053802877 | ... O34: =O33/O13 -> -0.11805042 | P34: -0.11 | Q34: =P34 -> -0.11 | R34: -0.09 | S34: =R34 -> -0.09 | U34: 2028-29: -11%; 2030: -9% (house); 2031: as 2030 (row 47).
B35: FCFF, house = D&A + NOPAT + capex + NWC (level) | C35: =C23+C26+C33+C31 -> 3593.3985 | D35: =D23+D26+D33+D31 -> 4298.9096 | E35: =E23+E26+E33+E31 -> 6393.174 | F35: =F23+F26+F33+F31 -> 9188.643 | G35: =G23+G26+G33+G31 -> 10165.609 | H35: =H23+H26+H33+H31 -> 9613.4082 | I35: =I23+I26+I33+I31 -> 16932.72 | J35: =J23+J26+J33+J31 -> 18364.202 | ... S35: =S23+S26+S33+S31 -> 24562.069 | U35: D&A + NOPAT + capex + NWC level (row 44): what the house discounts.
B36: FCFF with the change in NWC | D36: =D23+D26+D33+D32 -> 6353.2236 | E36: =E23+E26+E33+E32 -> 8512.8344 | F36: =F23+F26+F33+F32 -> 11339.739 | G36: =G23+G26+G33+G32 -> 12675.151 | H36: =H23+H26+H33+H32 -> 12447.534 | I36: =I23+I26+I33+I32 -> 19997.457 | J36: =J23+J26+J33+J32 -> 22459.802 | K36: =K23+K26+K33+K32 -> 17660.044 | ... S36: =S23+S26+S33+S32 -> 32381.807 | U36: D&A + NOPAT + capex + change in NWC.
B37: FCFF used in the valuation (switch FixNWC) | C37: =C35 -> 3593.3985 | D37: =IF(FixNWC=1,D36,D35) -> 4298.9096 | E37: =IF(FixNWC=1,E36,E35) -> 6393.174 | F37: =IF(FixNWC=1,F36,F35) -> 9188.643 | G37: =IF(FixNWC=1,G36,G35) -> 10165.609 | H37: =IF(FixNWC=1,H36,H35) -> 9613.4082 | I37: =IF(FixNWC=1,I36,I35) -> 16932.72 | J37: =IF(FixNWC=1,J36,J35) -> 18364.202 | K37: =IF(FixNWC=1,K36,K35) -> 12722.204 | ... S37: =IF(FixNWC=1,S36,S35) -> 24562.069 | U37: FixNWC = 0: the house row; 1: the corrected row.
B38: memo: FCFF = EBITDA x (1 - tax) + capex | C38: 3875.1 | D38: 3414.98 | E38: 3131.8 | F38: 5798.58 | G38: 7840.38 | H38: 10543 | I38: 15220 | J38: 21728 | K38: 10626.16 | L38: 12342 | M38: 13051 | N38: =N21*(1+N25)+N33 -> 18327.24 | O38: =O21*(1+O25)+O33 -> 19211.92 | P38: =P21*(1+P25)+P33 -> 20407.835 | Q38: =Q21*(1+Q25)+Q33 -> 21746.067 | R38: =R21*(1+R25)+R33 -> 26978.097 | S38: =S21*(1+S25)+S33 -> 28618.366 | U38: To 2025: house file. 2026+: EBITDA x (1 + tax) + capex (row 49).
B39: memo: Ibovespa (average to 2020, then the price used) | C39: 49828 | D39: 53350 | E39: 67784 | F39: 81677 | G39: 101000 | H39: 99143 | I39: =IbovUsed -> 208431.92 | J39: =IbovUsed -> 208431.92 | K39: =IbovUsed -> 208431.92 | L39: =IbovUsed -> 208431.92 | M39: =IbovUsed -> 208431.92 | N39: =IbovUsed -> 208431.92 | O39: =IbovUsed -> 208431.92 | P39: =IbovUsed -> 208431.92 | ... S39: =IbovUsed -> 208431.92 | U39: Row 50: average to 2020 (house file), then the Ibovespa price used.
B40: memo: FCF yield | C40: =C38/C39 -> 0.077769527 | D40: =D38/D39 -> 0.064010872 | E40: =E38/E39 -> 0.046202644 | F40: =F38/F39 -> 0.070994037 | G40: =G38/G39 -> 0.077627525 | H40: =H38/H39 -> 0.10634135 | I40: =I38/I39 -> 0.073021445 | J40: =J38/J39 -> 0.10424507 | ... S40: =S38/S39 -> 0.13730318 | U40: Simple FCFF / Ibovespa (row 51).
B42: Valuation: fair value at the end of the year (house Target rows 53-59)
...

Sheet Sensitivity
B1: Ibovespa - Sensitivity: real rate and ERP
B2: The house's real-rate table (tie-out) and a real rate x ERP grid for the end-2027 fair value with the current settings.
B3: Legend: | C3: input | D3: assumption | E3: formula
B5: House table: 5-year real rate vs DCF value (Target rows 120-129)
B6: 5-year real rate | C6: House file, end-2026 | D6: Replica, end-2026 (house settings) | E6: Difference | G6: End-2027, current settings
B7: 0.055 | C7: 263358.81 | D7: =NPV(($B7+0.06),DCF!$O$35:$R$35)+DCF!$R$35*(1+0.047)/(($B7+0.06)-0.047)/(1+($B7+0.06))^5-0 -> 263358.81 | E7: =D7-C7 -> 0 | G7: =NPV(IF(FixInfl=1,(1+$B7+Assumptions!$D$21)*(1+InflLT)-1,$B7+Assumptions!$D$21),DCF!$P$37:$S$37)+DCF!$S$37*(1+gLT)/(IF(FixInfl=1,(1+$B7+Assumptions!$D$21)*(1+InflLT)-1,$B7+Assumptions!$D$21)-gLT)/(1+IF(FixInfl=1,(1+$B7+Assumptions!$D$21)*(1+InflLT)-1,$B7+Assumptions!$D$21))^(4+1-FixTV)-IF(FixND=1,NDmult*DCF!$M$21,0) -> 281862.98
B8: 0.06 | C8: 244298.81 | D8: =NPV(($B8+0.06),DCF!$O$35:$R$35)+DCF!$R$35*(1+0.047)/(($B8+0.06)-0.047)/(1+($B8+0.06))^5-0 -> 244298.81 | E8: =D8-C8 -> 0 | G8: =NPV(IF(FixInfl=1,(1+$B8+Assumptions!$D$21)*(1+InflLT)-1,$B8+Assumptions!$D$21),DCF!$P$37:$S$37)+DCF!$S$37*(1+gLT)/(IF(FixInfl=1,(1+$B8+Assumptions!$D$21)*(1+InflLT)-1,$B8+Assumptions!$D$21)-gLT)/(1+IF(FixInfl=1,(1+$B8+Assumptions!$D$21)*(1+InflLT)-1,$B8+Assumptions!$D$21))^(4+1-FixTV)-IF(FixND=1,NDmult*DCF!$M$21,0) -> 261607.54
B9: 0.07 | C9: 213168.52 | D9: =NPV(($B9+0.06),DCF!$O$35:$R$35)+DCF!$R$35*(1+0.047)/(($B9+0.06)-0.047)/(1+($B9+0.06))^5-0 -> 213168.52 | E9: =D9-C9 -> 0 | G9: =NPV(IF(FixInfl=1,(1+$B9+Assumptions!$D$21)*(1+InflLT)-1,$B9+Assumptions!$D$21),DCF!$P$37:$S$37)+DCF!$S$37*(1+gLT)/(IF(FixInfl=1,(1+$B9+Assumptions!$D$21)*(1+InflLT)-1,$B9+Assumptions!$D$21)-gLT)/(1+IF(FixInfl=1,(1+$B9+Assumptions!$D$21)*(1+InflLT)-1,$B9+Assumptions!$D$21))^(4+1-FixTV)-IF(FixND=1,NDmult*DCF!$M$21,0) -> 228513.31
B10: 0.0742 | C10: 202259.17 | D10: =NPV(($B10+0.06),DCF!$O$35:$R$35)+DCF!$R$35*(1+0.047)/(($B10+0.06)-0.047)/(1+($B10+0.06))^5-0 -> 202259.17 | E10: =D10-C10 -> 0 | G10: =NPV(IF(FixInfl=1,(1+$B10+Assumptions!$D$21)*(1+InflLT)-1,$B10+Assumptions!$D$21),DCF!$P$37:$S$37)+DCF!$S$37*(1+gLT)/(IF(FixInfl=1,(1+$B10+Assumptions!$D$21)*(1+InflLT)-1,$B10+Assumptions!$D$21)-gLT)/(1+IF(FixInfl=1,(1+$B10+Assumptions!$D$21)*(1+InflLT)-1,$B10+Assumptions!$D$21))^(4+1-FixTV)-IF(FixND=1,NDmult*DCF!$M$21,0) -> 216911.5
B11: 0.075 | C11: 200301.58 | D11: =NPV(($B11+0.06),DCF!$O$35:$R$35)+DCF!$R$35*(1+0.047)/(($B11+0.06)-0.047)/(1+($B11+0.06))^5-0 -> 200301.58 | E11: =D11-C11 -> 0 | G11: =NPV(IF(FixInfl=1,(1+$B11+Assumptions!$D$21)*(1+InflLT)-1,$B11+Assumptions!$D$21),DCF!$P$37:$S$37)+DCF!$S$37*(1+gLT)/(IF(FixInfl=1,(1+$B11+Assumptions!$D$21)*(1+InflLT)-1,$B11+Assumptions!$D$21)-gLT)/(1+IF(FixInfl=1,(1+$B11+Assumptions!$D$21)*(1+InflLT)-1,$B11+Assumptions!$D$21))^(4+1-FixTV)-IF(FixND=1,NDmult*DCF!$M$21,0) -> 214829.39
B12: 0.08 | C12: 188845.17 | D12: =NPV(($B12+0.06),DCF!$O$35:$R$35)+DCF!$R$35*(1+0.047)/(($B12+0.06)-0.047)/(1+($B12+0.06))^5-0 -> 188845.17 | E12: =D12-C12 -> 0 | G12: =NPV(IF(FixInfl=1,(1+$B12+Assumptions!$D$21)*(1+InflLT)-1,$B12+Assumptions!$D$21),DCF!$P$37:$S$37)+DCF!$S$37*(1+gLT)/(IF(FixInfl=1,(1+$B12+Assumptions!$D$21)*(1+InflLT)-1,$B12+Assumptions!$D$21)-gLT)/(1+IF(FixInfl=1,(1+$B12+Assumptions!$D$21)*(1+InflLT)-1,$B12+Assumptions!$D$21))^(4+1-FixTV)-IF(FixND=1,NDmult*DCF!$M$21,0) -> 202642.39
B13: 0.085 | C13: 178582.43 | D13: =NPV(($B13+0.06),DCF!$O$35:$R$35)+DCF!$R$35*(1+0.047)/(($B13+0.06)-0.047)/(1+($B13+0.06))^5-0 -> 178582.43 | E13: =D13-C13 -> 0 | G13: =NPV(IF(FixInfl=1,(1+$B13+Assumptions!$D$21)*(1+InflLT)-1,$B13+Assumptions!$D$21),DCF!$P$37:$S$37)+DCF!$S$37*(1+gLT)/(IF(FixInfl=1,(1+$B13+Assumptions!$D$21)*(1+InflLT)-1,$B13+Assumptions!$D$21)-gLT)/(1+IF(FixInfl=1,(1+$B13+Assumptions!$D$21)*(1+InflLT)-1,$B13+Assumptions!$D$21))^(4+1-FixTV)-IF(FixND=1,NDmult*DCF!$M$21,0) -> 191722.24
B14: 0.09 | C14: 169338.66 | D14: =NPV(($B14+0.06),DCF!$O$35:$R$35)+DCF!$R$35*(1+0.047)/(($B14+0.06)-0.047)/(1+($B14+0.06))^5-0 -> 169338.66 | E14: =D14-C14 -> 0 | G14: =NPV(IF(FixInfl=1,(1+$B14+Assumptions!$D$21)*(1+InflLT)-1,$B14+Assumptions!$D$21),DCF!$P$37:$S$37)+DCF!$S$37*(1+gLT)/(IF(FixInfl=1,(1+$B14+Assumptions!$D$21)*(1+InflLT)-1,$B14+Assumptions!$D$21)-gLT)/(1+IF(FixInfl=1,(1+$B14+Assumptions!$D$21)*(1+InflLT)-1,$B14+Assumptions!$D$21))^(4+1-FixTV)-IF(FixND=1,NDmult*DCF!$M$21,0) -> 181883.6
B15: House settings: ERP 6.0%, g 4.7%, no corrections, house FCFF. The house table is an Excel data table on Target!C56.
B18: End-2027 fair value (index pts), current settings
B19: Real rate \ ERP | C19: 0.04 | D19: 0.05 | E19: 0.06 | F19: 0.07 | G19: 0.08
B20: 0.05 | C20: =NPV(IF(FixInfl=1,(1+$B20+C$19)*(1+InflLT)-1,$B20+C$19),DCF!$P$37:$S$37)+DCF!$S$37*(1+gLT)/(IF(FixInfl=1,(1+$B20+C$19)*(1+InflLT)-1,$B20+C$19)-gLT)/(1+IF(FixInfl=1,(1+$B20+C$19)*(1+InflLT)-1,$B20+C$19))^(4+1-FixTV)-IF(FixND=1,NDmult*DCF!$M$21,0) -> 454824.27 | D20: =NPV(IF(FixInfl=1,(1+$B20+D$19)*(1+InflLT)-1,$B20+D$19),DCF!$P$37:$S$37)+DCF!$S$37*(1+gLT)/(IF(FixInfl=1,(1+$B20+D$19)*(1+InflLT)-1,$B20+D$19)-gLT)/(1+IF(FixInfl=1,(1+$B20+D$19)*(1+InflLT)-1,$B20+D$19))^(4+1-FixTV)-IF(FixND=1,NDmult*DCF!$M$21,0) -> 365883.78 | E20: =NPV(IF(FixInfl=1,(1+$B20+E$19)*(1+InflLT)-1,$B20+E$19),DCF!$P$37:$S$37)+DCF!$S$37*(1+gLT)/(IF(FixInfl=1,(1+$B20+E$19)*(1+InflLT)-1,$B20+E$19)-gLT)/(1+IF(FixInfl=1,(1+$B20+E$19)*(1+InflLT)-1,$B20+E$19))^(4+1-FixTV)-IF(FixND=1,NDmult*DCF!$M$21,0) -> 305377.76 | F20: =NPV(IF(FixInfl=1,(1+$B20+F$19)*(1+InflLT)-1,$B20+F$19),DCF!$P$37:$S$37)+DCF!$S$37*(1+gLT)/(IF(FixInfl=1,(1+$B20+F$19)*(1+InflLT)-1,$B20+F$19)-gLT)/(1+IF(FixInfl=1,(1+$B20+F$19)*(1+InflLT)-1,$B20+F$19))^(4+1-FixTV)-IF(FixND=1,NDmult*DCF!$M$21,0) -> 261607.54 | G20: =NPV(IF(FixInfl=1,(1+$B20+G$19)*(1+InflLT)-1,$B20+G$19),DCF!$P$37:$S$37)+DCF!$S$37*(1+gLT)/(IF(FixInfl=1,(1+$B20+G$19)*(1+InflLT)-1,$B20+G$19)-gLT)/(1+IF(FixInfl=1,(1+$B20+G$19)*(1+InflLT)-1,$B20+G$19))^(4+1-FixTV)-IF(FixND=1,NDmult*DCF!$M$21,0) -> 228513.31
B21: 0.055 | C21: =NPV(IF(FixInfl=1,(1+$B21+C$19)*(1+InflLT)-1,$B21+C$19),DCF!$P$37:$S$37)+DCF!$S$37*(1+gLT)/(IF(FixInfl=1,(1+$B21+C$19)*(1+InflLT)-1,$B21+C$19)-gLT)/(1+IF(FixInfl=1,(1+$B21+C$19)*(1+InflLT)-1,$B21+C$19))^(4+1-FixTV)-IF(FixND=1,NDmult*DCF!$M$21,0) -> 405687.66 | D21: =NPV(IF(FixInfl=1,(1+$B21+D$19)*(1+InflLT)-1,$B21+D$19),DCF!$P$37:$S$37)+DCF!$S$37*(1+gLT)/(IF(FixInfl=1,(1+$B21+D$19)*(1+InflLT)-1,$B21+D$19)-gLT)/(1+IF(FixInfl=1,(1+$B21+D$19)*(1+InflLT)-1,$B21+D$19))^(4+1-FixTV)-IF(FixND=1,NDmult*DCF!$M$21,0) -> 332996.75 | E21: =NPV(IF(FixInfl=1,(1+$B21+E$19)*(1+InflLT)-1,$B21+E$19),DCF!$P$37:$S$37)+DCF!$S$37*(1+gLT)/(IF(FixInfl=1,(1+$B21+E$19)*(1+InflLT)-1,$B21+E$19)-gLT)/(1+IF(FixInfl=1,(1+$B21+E$19)*(1+InflLT)-1,$B21+E$19))^(4+1-FixTV)-IF(FixND=1,NDmult*DCF!$M$21,0) -> 281862.98 | F21: =NPV(IF(FixInfl=1,(1+$B21+F$19)*(1+InflLT)-1,$B21+F$19),DCF!$P$37:$S$37)+DCF!$S$37*(1+gLT)/(IF(FixInfl=1,(1+$B21+F$19)*(1+InflLT)-1,$B21+F$19)-gLT)/(1+IF(FixInfl=1,(1+$B21+F$19)*(1+InflLT)-1,$B21+F$19))^(4+1-FixTV)-IF(FixND=1,NDmult*DCF!$M$21,0) -> 243983.24 | G21: =NPV(IF(FixInfl=1,(1+$B21+G$19)*(1+InflLT)-1,$B21+G$19),DCF!$P$37:$S$37)+DCF!$S$37*(1+gLT)/(IF(FixInfl=1,(1+$B21+G$19)*(1+InflLT)-1,$B21+G$19)-gLT)/(1+IF(FixInfl=1,(1+$B21+G$19)*(1+InflLT)-1,$B21+G$19))^(4+1-FixTV)-IF(FixND=1,NDmult*DCF!$M$21,0) -> 214829.39
B22: 0.06 | C22: =NPV(IF(FixInfl=1,(1+$B22+C$19)*(1+InflLT)-1,$B22+C$19),DCF!$P$37:$S$37)+DCF!$S$37*(1+gLT)/(IF(FixInfl=1,(1+$B22+C$19)*(1+InflLT)-1,$B22+C$19)-gLT)/(1+IF(FixInfl=1,(1+$B22+C$19)*(1+InflLT)-1,$B22+C$19))^(4+1-FixTV)-IF(FixND=1,NDmult*DCF!$M$21,0) -> 365883.78 | D22: =NPV(IF(FixInfl=1,(1+$B22+D$19)*(1+InflLT)-1,$B22+D$19),DCF!$P$37:$S$37)+DCF!$S$37*(1+gLT)/(IF(FixInfl=1,(1+$B22+D$19)*(1+InflLT)-1,$B22+D$19)-gLT)/(1+IF(FixInfl=1,(1+$B22+D$19)*(1+InflLT)-1,$B22+D$19))^(4+1-FixTV)-IF(FixND=1,NDmult*DCF!$M$21,0) -> 305377.76 | E22: =NPV(IF(FixInfl=1,(1+$B22+E$19)*(1+InflLT)-1,$B22+E$19),DCF!$P$37:$S$37)+DCF!$S$37*(1+gLT)/(IF(FixInfl=1,(1+$B22+E$19)*(1+InflLT)-1,$B22+E$19)-gLT)/(1+IF(FixInfl=1,(1+$B22+E$19)*(1+InflLT)-1,$B22+E$19))^(4+1-FixTV)-IF(FixND=1,NDmult*DCF!$M$21,0) -> 261607.54 | F22: =NPV(IF(FixInfl=1,(1+$B22+F$19)*(1+InflLT)-1,$B22+F$19),DCF!$P$37:$S$37)+DCF!$S$37*(1+gLT)/(IF(FixInfl=1,(1+$B22+F$19)*(1+InflLT)-1,$B22+F$19)-gLT)/(1+IF(FixInfl=1,(1+$B22+F$19)*(1+InflLT)-1,$B22+F$19))^(4+1-FixTV)-IF(FixND=1,NDmult*DCF!$M$21,0) -> 228513.31 | G22: =NPV(IF(FixInfl=1,(1+$B22+G$19)*(1+InflLT)-1,$B22+G$19),DCF!$P$37:$S$37)+DCF!$S$37*(1+gLT)/(IF(FixInfl=1,(1+$B22+G$19)*(1+InflLT)-1,$B22+G$19)-gLT)/(1+IF(FixInfl=1,(1+$B22+G$19)*(1+InflLT)-1,$B22+G$19))^(4+1-FixTV)-IF(FixND=1,NDmult*DCF!$M$21,0) -> 202642.39
B23: 0.065 | C23: =NPV(IF(FixInfl=1,(1+$B23+C$19)*(1+InflLT)-1,$B23+C$19),DCF!$P$37:$S$37)+DCF!$S$37*(1+gLT)/(IF(FixInfl=1,(1+$B23+C$19)*(1+InflLT)-1,$B23+C$19)-gLT)/(1+IF(FixInfl=1,(1+$B23+C$19)*(1+InflLT)-1,$B23+C$19))^(4+1-FixTV)-IF(FixND=1,NDmult*DCF!$M$21,0) -> 332996.75 | D23: =NPV(IF(FixInfl=1,(1+$B23+D$19)*(1+InflLT)-1,$B23+D$19),DCF!$P$37:$S$37)+DCF!$S$37*(1+gLT)/(IF(FixInfl=1,(1+$B23+D$19)*(1+InflLT)-1,$B23+D$19)-gLT)/(1+IF(FixInfl=1,(1+$B23+D$19)*(1+InflLT)-1,$B23+D$19))^(4+1-FixTV)-IF(FixND=1,NDmult*DCF!$M$21,0) -> 281862.98 | E23: =NPV(IF(FixInfl=1,(1+$B23+E$19)*(1+InflLT)-1,$B23+E$19),DCF!$P$37:$S$37)+DCF!$S$37*(1+gLT)/(IF(FixInfl=1,(1+$B23+E$19)*(1+InflLT)-1,$B23+E$19)-gLT)/(1+IF(FixInfl=1,(1+$B23+E$19)*(1+InflLT)-1,$B23+E$19))^(4+1-FixTV)-IF(FixND=1,NDmult*DCF!$M$21,0) -> 243983.24 | F23: =NPV(IF(FixInfl=1,(1+$B23+F$19)*(1+InflLT)-1,$B23+F$19),DCF!$P$37:$S$37)+DCF!$S$37*(1+gLT)/(IF(FixInfl=1,(1+$B23+F$19)*(1+InflLT)-1,$B23+F$19)-gLT)/(1+IF(FixInfl=1,(1+$B23+F$19)*(1+InflLT)-1,$B23+F$19))^(4+1-FixTV)-IF(FixND=1,NDmult*DCF!$M$21,0) -> 214829.39 | G23: =NPV(IF(FixInfl=1,(1+$B23+G$19)*(1+InflLT)-1,$B23+G$19),DCF!$P$37:$S$37)+DCF!$S$37*(1+gLT)/(IF(FixInfl=1,(1+$B23+G$19)*(1+InflLT)-1,$B23+G$19)-gLT)/(1+IF(FixInfl=1,(1+$B23+G$19)*(1+InflLT)-1,$B23+G$19))^(4+1-FixTV)-IF(FixND=1,NDmult*DCF!$M$21,0) -> 191722.24
B24: 0.0676 | C24: =NPV(IF(FixInfl=1,(1+$B24+C$19)*(1+InflLT)-1,$B24+C$19),DCF!$P$37:$S$37)+DCF!$S$37*(1+gLT)/(IF(FixInfl=1,(1+$B24+C$19)*(1+InflLT)-1,$B24+C$19)-gLT)/(1+IF(FixInfl=1,(1+$B24+C$19)*(1+InflLT)-1,$B24+C$19))^(4+1-FixTV)-IF(FixND=1,NDmult*DCF!$M$21,0) -> 318060.01 | D24: =NPV(IF(FixInfl=1,(1+$B24+D$19)*(1+InflLT)-1,$B24+D$19),DCF!$P$37:$S$37)+DCF!$S$37*(1+gLT)/(IF(FixInfl=1,(1+$B24+D$19)*(1+InflLT)-1,$B24+D$19)-gLT)/(1+IF(FixInfl=1,(1+$B24+D$19)*(1+InflLT)-1,$B24+D$19))^(4+1-FixTV)-IF(FixND=1,NDmult*DCF!$M$21,0) -> 270967.27 | E24: =NPV(IF(FixInfl=1,(1+$B24+E$19)*(1+InflLT)-1,$B24+E$19),DCF!$P$37:$S$37)+DCF!$S$37*(1+gLT)/(IF(FixInfl=1,(1+$B24+E$19)*(1+InflLT)-1,$B24+E$19)-gLT)/(1+IF(FixInfl=1,(1+$B24+E$19)*(1+InflLT)-1,$B24+E$19))^(4+1-FixTV)-IF(FixND=1,NDmult*DCF!$M$21,0) -> 235695.44 | F24: =NPV(IF(FixInfl=1,(1+$B24+F$19)*(1+InflLT)-1,$B24+F$19),DCF!$P$37:$S$37)+DCF!$S$37*(1+gLT)/(IF(FixInfl=1,(1+$B24+F$19)*(1+InflLT)-1,$B24+F$19)-gLT)/(1+IF(FixInfl=1,(1+$B24+F$19)*(1+InflLT)-1,$B24+F$19))^(4+1-FixTV)-IF(FixND=1,NDmult*DCF!$M$21,0) -> 208321.07 | G24: =NPV(IF(FixInfl=1,(1+$B24+G$19)*(1+InflLT)-1,$B24+G$19),DCF!$P$37:$S$37)+DCF!$S$37*(1+gLT)/(IF(FixInfl=1,(1+$B24+G$19)*(1+InflLT)-1,$B24+G$19)-gLT)/(1+IF(FixInfl=1,(1+$B24+G$19)*(1+InflLT)-1,$B24+G$19))^(4+1-FixTV)-IF(FixND=1,NDmult*DCF!$M$21,0) -> 186481.43
B25: 0.07 | C25: =NPV(IF(FixInfl=1,(1+$B25+C$19)*(1+InflLT)-1,$B25+C$19),DCF!$P$37:$S$37)+DCF!$S$37*(1+gLT)/(IF(FixInfl=1,(1+$B25+C$19)*(1+InflLT)-1,$B25+C$19)-gLT)/(1+IF(FixInfl=1,(1+$B25+C$19)*(1+InflLT)-1,$B25+C$19))^(4+1-FixTV)-IF(FixND=1,NDmult*DCF!$M$21,0) -> 305377.76 | D25: =NPV(IF(FixInfl=1,(1+$B25+D$19)*(1+InflLT)-1,$B25+D$19),DCF!$P$37:$S$37)+DCF!$S$37*(1+gLT)/(IF(FixInfl=1,(1+$B25+D$19)*(1+InflLT)-1,$B25+D$19)-gLT)/(1+IF(FixInfl=1,(1+$B25+D$19)*(1+InflLT)-1,$B25+D$19))^(4+1-FixTV)-IF(FixND=1,NDmult*DCF!$M$21,0) -> 261607.54 | E25: =NPV(IF(FixInfl=1,(1+$B25+E$19)*(1+InflLT)-1,$B25+E$19),DCF!$P$37:$S$37)+DCF!$S$37*(1+gLT)/(IF(FixInfl=1,(1+$B25+E$19)*(1+InflLT)-1,$B25+E$19)-gLT)/(1+IF(FixInfl=1,(1+$B25+E$19)*(1+InflLT)-1,$B25+E$19))^(4+1-FixTV)-IF(FixND=1,NDmult*DCF!$M$21,0) -> 228513.31 | F25: =NPV(IF(FixInfl=1,(1+$B25+F$19)*(1+InflLT)-1,$B25+F$19),DCF!$P$37:$S$37)+DCF!$S$37*(1+gLT)/(IF(FixInfl=1,(1+$B25+F$19)*(1+InflLT)-1,$B25+F$19)-gLT)/(1+IF(FixInfl=1,(1+$B25+F$19)*(1+InflLT)-1,$B25+F$19))^(4+1-FixTV)-IF(FixND=1,NDmult*DCF!$M$21,0) -> 202642.39 | G25: =NPV(IF(FixInfl=1,(1+$B25+G$19)*(1+InflLT)-1,$B25+G$19),DCF!$P$37:$S$37)+DCF!$S$37*(1+gLT)/(IF(FixInfl=1,(1+$B25+G$19)*(1+InflLT)-1,$B25+G$19)-gLT)/(1+IF(FixInfl=1,(1+$B25+G$19)*(1+InflLT)-1,$B25+G$19))^(4+1-FixTV)-IF(FixND=1,NDmult*DCF!$M$21,0) -> 181883.6
