Workbook
Name IdxTicker: 'Inputs'!$C$5
Name TkSuffix: 'Inputs'!$C$6
Name AsOf: 'Inputs'!$C$7
Name MomA: 'Inputs'!$C$9
Name MomB: 'Inputs'!$C$10
Name RevA: 'Inputs'!$C$11
Name RevB: 'Inputs'!$C$12
Name FldMcap: 'Inputs'!$C$14
Name FldShOut: 'Inputs'!$C$15
Name FldPx: 'Inputs'!$C$16
Name FldEps: 'Inputs'!$C$17
Name FpOvr: 'Inputs'!$C$18
Name FldTRR: 'Inputs'!$C$19
Name WgtBasis: 'Inputs'!$C$21
Name DtMomA: 'Inputs'!$C$24
Name DtMomB: 'Inputs'!$C$25
Name DtRevA: 'Inputs'!$C$26
Name DtRevB: 'Inputs'!$C$27

Sheet Read me
A1: Ibovespa factor screen — revisions, momentum and size, aggregated by sector
A2: Open with the Bloomberg add-in running. Fill one column on Sector Map; everything else calculates.
B4: WHAT YOU DO
B5: 1. Open in Bloomberg | C5: The add-in resolves one BDS call for the member list and roughly 700 BDP/BDH calls for the data. Give it a moment and press F9 if anything still reads #N/A Requesting.
B6: 2. Fill column B on Sector Map | C6: Ticker arrives on its own. Type your sector next to it. The Status column tracks what is still empty.
B7: 3. Read Sector Aggregation | C7: It discovers your sector names automatically — there is no list to maintain. Add a name, and a new row appears.
B9: ONE THING WORTH DOING ONCE
B10: Freeze the ticker column | C10: Column A of Sector Map is a formula reading the live index. That is convenient now, but the Ibovespa rebalances three times a year, and when a name enters or leaves, the formula shifts every ticker below it while your typed sectors stay put — silently misaligning them. After you have filled the sectors, select column A, copy, and Paste Special > Values. The list becomes static, your mapping is anchored to it permanently, and any future entrant simply shows "◄ not in map" on Data so you can add one row. Five seconds, and the file stops being able to lie to you.
B12: THE FIELDS, AND WHY
B13: Earnings revisions | C13: Forward EPS today divided by forward EPS as of the lookback date, minus one. The fiscal period is pinned with BEST_FPERIOD_OVERRIDE (default "BF", blended forward 12m). Without pinning it, every annual roll would compare two different fiscal years and the "revision" would be an artefact.
B14: Momentum | C14: Total return over the window via CUST_TRR_RETURN_HOLDING_PER with explicit start and end date overrides. Total return rather than price return, so a large dividend is not read as a fall. Divided by 100 because the field returns percentage points.
B15: Market cap | C15: Two are pulled. CUR_MKT_CAP is company-level, so for a name with both an ON and a PN line in the index it reports the same number twice. Shares outstanding x price gives the cap of the individual listed line. Weighting basis defaults to the latter — this is what you asked for, and it keeps PETR3+PETR4 from counting Petrobras twice.
B16: Missing data | C16: A security enters a weighted average only where both that factor and its market cap returned numbers, and only once it has a sector. The n columns on Sector Aggregation show how many names actually stood behind each figure, and the Data flag column says what is missing per ticker.
B18: WHAT I COULD NOT VERIFY
B19: No terminal here | C19: The IRR workbook I built earlier was checked cell by cell against Excel. This one could not be: there is no Bloomberg here, so no formula in it has ever returned a value. The structure, the Excel-side logic and the aggregation are sound, but treat the first open as a test run.
B20: Field names are the likely failure | C20: BDP, BDH and BDS syntax is stable, and CUR_MKT_CAP, EQY_SH_OUT, PX_LAST and BEST_EPS are long-standing mnemonics. CUST_TRR_RETURN_HOLDING_PER is the one I would check first — it is entitlement-sensitive and the override names vary. If it fails, put CHG_PCT_3M in the Total return field cell, clear the date overrides, and accept price-only momentum over a fixed window.
B21: Every mnemonic is a cell, not a formula | C21: This is why the Inputs sheet holds the field names. A wrong mnemonic is a one-cell fix that propagates to all 87 tickers, not a find-and-replace across the file.
B22: Scale conventions | C22: Check two things on the first pull: that EQY_SH_OUT is in millions on your terminal, and that the total return field returns 60 rather than 0.60 for 60%. Both are divided or multiplied accordingly and both differ between setups.
B24: COLOUR KEY
B25: Yellow | C25: You edit these.
B26: Purple | C26: Calls Bloomberg.
B27: Black | C27: Calculated in Excel.
B28: Grey, hidden | C28: Aggregation helpers on Data, columns Q to Y. Ungroup to inspect.

Sheet Inputs
A1: Inputs — the whole workbook is driven from here
A2: Edit only the YELLOW cells. Field mnemonics live here on purpose: if your terminal names a field differently, change it once here and every ticker follows.
B4: SCOPE
B5: Index ticker | C5: IBOV Index | E5: Feeds BDS(...,"INDX_MEMBERS") on the Index Members sheet. Swap for "IBX Index", "SMLL Index", etc.
B6: Ticker suffix | C6: Equity | E6: INDX_MEMBERS returns "PETR4 BZ", so " Equity" is appended to make a full BDP ticker. Keep the leading space.
B7: As-of date | C7: =TODAY() | E7: Anchor for every lookback. Leave as TODAY() for a live screen, or hardcode a date to freeze a snapshot.
B8: WINDOWS
B9: Momentum window A (months) | C9: 3 | E9: Short momentum horizon.
B10: Momentum window B (months) | C10: 6 | E10: Long momentum horizon.
B11: Revision window A (months) | C11: 3 | E11: Short earnings-revision horizon.
B12: Revision window B (months) | C12: 6 | E12: Long earnings-revision horizon.
B13: FIELDS
B14: Market cap | C14: CUR_MKT_CAP | E14: Bloomberg reports this at COMPANY level. For a Brazilian name with ON and PN lines both in the index it is the same number on both, which double-counts if you weight by it. See Weighting basis.
B15: Shares outstanding | C15: EQY_SH_OUT | E15: Shares of THIS listed line, in millions. Used to build a security-level cap.
B16: Last price | C16: PX_LAST | E16: Used with shares outstanding for the security-level cap.
B17: Forward EPS estimate | C17: BEST_EPS | E17: Consensus EPS. The revision is the change in this number, so the fiscal period must be pinned — see the override below.
B18: Fiscal period override | C18: BF | E18: BEST_FPERIOD_OVERRIDE. "BF" is blended forward 12m, which rolls continuously and is the right choice for a revision. A fixed year ("2027") also works. Leaving it unpinned would compare different fiscal years and produce a meaningless revision at every annual roll.
B19: Total return field | C19: CUST_TRR_RETURN_HOLDING_PER | E19: Total return over a custom window, driven by the two date overrides. Includes dividends, which is the correct momentum measure. If your terminal rejects it, try CHG_PCT_3M / CHG_PCT_6M instead (price only, fixed windows).
B20: WEIGHTING
B21: Weighting basis | C21: SEC_CAP | E21: SEC_CAP = shares outstanding x price, i.e. the market cap of THIS listed line. COMPANY_CAP = the CUR_MKT_CAP field. Use SEC_CAP for Brazil: it is what you asked for, and it stops PETR3+PETR4 or ITUB3+ITUB4 from counting the same company twice.
B23: DERIVED DATES (calculated)
B24: Momentum A start | C24: =EDATE(AsOf,-MomA) | E24: EDATE back from the as-of date. Bloomberg overrides receive it as YYYYMMDD.
B25: Momentum B start | C25: =EDATE(AsOf,-MomB) | E25: EDATE back from the as-of date. Bloomberg overrides receive it as YYYYMMDD.
B26: Revision A base date | C26: =EDATE(AsOf,-RevA) | E26: EDATE back from the as-of date. Bloomberg overrides receive it as YYYYMMDD.
B27: Revision B base date | C27: =EDATE(AsOf,-RevB) | E27: EDATE back from the as-of date. Bloomberg overrides receive it as YYYYMMDD.

Sheet Sector Map
A1: Sector Map — the only sheet you fill in
A2: Column A arrives from the index automatically. Type your sector in column B. Nothing else in the workbook needs touching.
A3: Ticker | B3: Sector (fill this in) | C3: Status
A4: =IFERROR(IF(INDEX('Index Members'!$A$4:$A$403,ROW()-3)=0,"",INDEX('Index Members'!$A$4:$A$403,ROW()-3)),"") | C4: =IF($A4="","",IF($B4="","EMPTY","ok"))
A5: =IFERROR(IF(INDEX('Index Members'!$A$4:$A$403,ROW()-3)=0,"",INDEX('Index Members'!$A$4:$A$403,ROW()-3)),"") | C5: =IF($A5="","",IF($B5="","EMPTY","ok"))
A6: =IFERROR(IF(INDEX('Index Members'!$A$4:$A$403,ROW()-3)=0,"",INDEX('Index Members'!$A$4:$A$403,ROW()-3)),"") | C6: =IF($A6="","",IF($B6="","EMPTY","ok"))
A7: =IFERROR(IF(INDEX('Index Members'!$A$4:$A$403,ROW()-3)=0,"",INDEX('Index Members'!$A$4:$A$403,ROW()-3)),"") | C7: =IF($A7="","",IF($B7="","EMPTY","ok"))
A8: =IFERROR(IF(INDEX('Index Members'!$A$4:$A$403,ROW()-3)=0,"",INDEX('Index Members'!$A$4:$A$403,ROW()-3)),"") | C8: =IF($A8="","",IF($B8="","EMPTY","ok"))
A9: =IFERROR(IF(INDEX('Index Members'!$A$4:$A$403,ROW()-3)=0,"",INDEX('Index Members'!$A$4:$A$403,ROW()-3)),"") | C9: =IF($A9="","",IF($B9="","EMPTY","ok"))
A10: =IFERROR(IF(INDEX('Index Members'!$A$4:$A$403,ROW()-3)=0,"",INDEX('Index Members'!$A$4:$A$403,ROW()-3)),"") | C10: =IF($A10="","",IF($B10="","EMPTY","ok"))
A11: =IFERROR(IF(INDEX('Index Members'!$A$4:$A$403,ROW()-3)=0,"",INDEX('Index Members'!$A$4:$A$403,ROW()-3)),"") | C11: =IF($A11="","",IF($B11="","EMPTY","ok"))
A12: =IFERROR(IF(INDEX('Index Members'!$A$4:$A$403,ROW()-3)=0,"",INDEX('Index Members'!$A$4:$A$403,ROW()-3)),"") | C12: =IF($A12="","",IF($B12="","EMPTY","ok"))
A13: =IFERROR(IF(INDEX('Index Members'!$A$4:$A$403,ROW()-3)=0,"",INDEX('Index Members'!$A$4:$A$403,ROW()-3)),"") | C13: =IF($A13="","",IF($B13="","EMPTY","ok"))
A14: =IFERROR(IF(INDEX('Index Members'!$A$4:$A$403,ROW()-3)=0,"",INDEX('Index Members'!$A$4:$A$403,ROW()-3)),"") | C14: =IF($A14="","",IF($B14="","EMPTY","ok"))
A15: =IFERROR(IF(INDEX('Index Members'!$A$4:$A$403,ROW()-3)=0,"",INDEX('Index Members'!$A$4:$A$403,ROW()-3)),"") | C15: =IF($A15="","",IF($B15="","EMPTY","ok"))
... A123: =IFERROR(IF(INDEX('Index Members'!$A$4:$A$403,ROW()-3)=0,"",INDEX('Index Members'!$A$4:$A$403,ROW()-3)),"") | C123: =IF($A123="","",IF($B123="","EMPTY","ok"))
A125: Filled: | B125: =COUNTIF($C$4:$C$123,"ok")&" of "&COUNTA($A$4:$A$123)&" tickers — "&COUNTIF($C$4:$C$123,"EMPTY")&" to go"

Sheet Data
A1: Security-level factor screen — every value pulled from Bloomberg
A2: Purple cells call Bloomberg. Grey columns from Q onward are aggregation helpers; they are grouped and hidden, and can be ignored.
A3: IDENTITY | D3: SIZE | I3: EARNINGS REVISIONS | N3: MOMENTUM | P3: QUALITY | Q3: AGGREGATION HELPERS
A4: Ticker | B4: Sector | C4: Bloomberg ticker | D4: Company mkt cap | E4: Shares out (mm) | F4: Price | G4: Security mkt cap | H4: Weight used | I4: Fwd EPS now | J4: Fwd EPS at A | K4: Fwd EPS at B | L4: Earnings rev. A | M4: Earnings rev. B | N4: Momentum A | O4: Momentum B | P4: Data flag | Q4: mapped | R4: w·revA | S4: w revA | T4: w·revB | U4: w revB | V4: w·momA | W4: w momA | X4: w·momB | Y4: w momB | Z4: sector #
A5: =IFERROR(IF(INDEX('Index Members'!$A$4:$A$403,ROW()-4)=0,"",INDEX('Index Members'!$A$4:$A$403,ROW()-4)),"") | B5: =IF($A5="","",IFERROR(IF(VLOOKUP($A5,'Sector Map'!$A$4:$B$123,2,FALSE)=0,"NO SECTOR",VLOOKUP($A5,'Sector Map'!$A$4:$B$123,2,FALSE)),"NOT IN MAP")) | C5: =IF($A5="","",$A5&TkSuffix) | D5: =IF($C5="","",BDP($C5,FldMcap)) | E5: =IF($C5="","",BDP($C5,FldShOut)) | F5: =IF($C5="","",BDP($C5,FldPx)) | G5: =IFERROR($E5*$F5,"") | H5: =IFERROR(IF(WgtBasis="SEC_CAP",$G5,$D5),"") | I5: =IF($C5="","",BDP($C5,FldEps,"BEST_FPERIOD_OVERRIDE="&FpOvr)) | J5: =IF($C5="","",IFERROR(INDEX(BDH($C5,FldEps,DtRevA,DtRevA,"BEST_FPERIOD_OVERRIDE="&FpOvr,"Days=A","Fill=P"),1,1),"")) | K5: =IF($C5="","",IFERROR(INDEX(BDH($C5,FldEps,DtRevB,DtRevB,"BEST_FPERIOD_OVERRIDE="&FpOvr,"Days=A","Fill=P"),1,1),"")) | L5: =IFERROR(IF($J5<=0,"",$I5/$J5-1),"") | M5: =IFERROR(IF($K5<=0,"",$I5/$K5-1),"") | N5: =IF($C5="","",IFERROR(BDP($C5,FldTRR,"CUST_TRR_START_DT="&TEXT(DtMomA,"yyyymmdd"),"CUST_TRR_END_DT="&TEXT(AsOf,"yyyymmdd"))/100,"")) | O5: =IF($C5="","",IFERROR(BDP($C5,FldTRR,"CUST_TRR_START_DT="&TEXT(DtMomB,"yyyymmdd"),"CUST_TRR_END_DT="&TEXT(AsOf,"yyyymmdd"))/100,"")) | P5: =IF($A5="","",IF($Q5=0,"sector missing",IF(NOT(ISNUMBER($H5)),"no market cap",IF(COUNT($L5:$O5)=4,"complete","missing "&(4-COUNT($L5:$O5))&" of 4 factors")))) | Q5: =IF(OR($B5="",$B5="NO SECTOR",$B5="NOT IN MAP"),0,1) | R5: =IF(AND($Q5=1,ISNUMBER($L5),ISNUMBER($H5)),$L5*$H5,0) | S5: =IF(AND($Q5=1,ISNUMBER($L5),ISNUMBER($H5)),$H5,0) | T5: =IF(AND($Q5=1,ISNUMBER($M5),ISNUMBER($H5)),$M5*$H5,0) | U5: =IF(AND($Q5=1,ISNUMBER($M5),ISNUMBER($H5)),$H5,0) | V5: =IF(AND($Q5=1,ISNUMBER($N5),ISNUMBER($H5)),$N5*$H5,0) | W5: =IF(AND($Q5=1,ISNUMBER($N5),ISNUMBER($H5)),$H5,0) | X5: =IF(AND($Q5=1,ISNUMBER($O5),ISNUMBER($H5)),$O5*$H5,0) | Y5: =IF(AND($Q5=1,ISNUMBER($O5),ISNUMBER($H5)),$H5,0) | Z5: =IF($Q5=0,"",IF(COUNTIF($B$5:$B5,$B5)>1,"",1))
A6: =IFERROR(IF(INDEX('Index Members'!$A$4:$A$403,ROW()-4)=0,"",INDEX('Index Members'!$A$4:$A$403,ROW()-4)),"") | B6: =IF($A6="","",IFERROR(IF(VLOOKUP($A6,'Sector Map'!$A$4:$B$123,2,FALSE)=0,"NO SECTOR",VLOOKUP($A6,'Sector Map'!$A$4:$B$123,2,FALSE)),"NOT IN MAP")) | C6: =IF($A6="","",$A6&TkSuffix) | D6: =IF($C6="","",BDP($C6,FldMcap)) | E6: =IF($C6="","",BDP($C6,FldShOut)) | F6: =IF($C6="","",BDP($C6,FldPx)) | G6: =IFERROR($E6*$F6,"") | H6: =IFERROR(IF(WgtBasis="SEC_CAP",$G6,$D6),"") | I6: =IF($C6="","",BDP($C6,FldEps,"BEST_FPERIOD_OVERRIDE="&FpOvr)) | J6: =IF($C6="","",IFERROR(INDEX(BDH($C6,FldEps,DtRevA,DtRevA,"BEST_FPERIOD_OVERRIDE="&FpOvr,"Days=A","Fill=P"),1,1),"")) | K6: =IF($C6="","",IFERROR(INDEX(BDH($C6,FldEps,DtRevB,DtRevB,"BEST_FPERIOD_OVERRIDE="&FpOvr,"Days=A","Fill=P"),1,1),"")) | L6: =IFERROR(IF($J6<=0,"",$I6/$J6-1),"") | M6: =IFERROR(IF($K6<=0,"",$I6/$K6-1),"") | N6: =IF($C6="","",IFERROR(BDP($C6,FldTRR,"CUST_TRR_START_DT="&TEXT(DtMomA,"yyyymmdd"),"CUST_TRR_END_DT="&TEXT(AsOf,"yyyymmdd"))/100,"")) | O6: =IF($C6="","",IFERROR(BDP($C6,FldTRR,"CUST_TRR_START_DT="&TEXT(DtMomB,"yyyymmdd"),"CUST_TRR_END_DT="&TEXT(AsOf,"yyyymmdd"))/100,"")) | P6: =IF($A6="","",IF($Q6=0,"sector missing",IF(NOT(ISNUMBER($H6)),"no market cap",IF(COUNT($L6:$O6)=4,"complete","missing "&(4-COUNT($L6:$O6))&" of 4 factors")))) | Q6: =IF(OR($B6="",$B6="NO SECTOR",$B6="NOT IN MAP"),0,1) | R6: =IF(AND($Q6=1,ISNUMBER($L6),ISNUMBER($H6)),$L6*$H6,0) | S6: =IF(AND($Q6=1,ISNUMBER($L6),ISNUMBER($H6)),$H6,0) | T6: =IF(AND($Q6=1,ISNUMBER($M6),ISNUMBER($H6)),$M6*$H6,0) | U6: =IF(AND($Q6=1,ISNUMBER($M6),ISNUMBER($H6)),$H6,0) | V6: =IF(AND($Q6=1,ISNUMBER($N6),ISNUMBER($H6)),$N6*$H6,0) | W6: =IF(AND($Q6=1,ISNUMBER($N6),ISNUMBER($H6)),$H6,0) | X6: =IF(AND($Q6=1,ISNUMBER($O6),ISNUMBER($H6)),$O6*$H6,0) | Y6: =IF(AND($Q6=1,ISNUMBER($O6),ISNUMBER($H6)),$H6,0) | Z6: =IF($Q6=0,"",IF(COUNTIF($B$5:$B6,$B6)>1,"",MAX(0,MAX($Z$5:$Z5))+1))
A7: =IFERROR(IF(INDEX('Index Members'!$A$4:$A$403,ROW()-4)=0,"",INDEX('Index Members'!$A$4:$A$403,ROW()-4)),"") | B7: =IF($A7="","",IFERROR(IF(VLOOKUP($A7,'Sector Map'!$A$4:$B$123,2,FALSE)=0,"NO SECTOR",VLOOKUP($A7,'Sector Map'!$A$4:$B$123,2,FALSE)),"NOT IN MAP")) | C7: =IF($A7="","",$A7&TkSuffix) | D7: =IF($C7="","",BDP($C7,FldMcap)) | E7: =IF($C7="","",BDP($C7,FldShOut)) | F7: =IF($C7="","",BDP($C7,FldPx)) | G7: =IFERROR($E7*$F7,"") | H7: =IFERROR(IF(WgtBasis="SEC_CAP",$G7,$D7),"") | I7: =IF($C7="","",BDP($C7,FldEps,"BEST_FPERIOD_OVERRIDE="&FpOvr)) | J7: =IF($C7="","",IFERROR(INDEX(BDH($C7,FldEps,DtRevA,DtRevA,"BEST_FPERIOD_OVERRIDE="&FpOvr,"Days=A","Fill=P"),1,1),"")) | K7: =IF($C7="","",IFERROR(INDEX(BDH($C7,FldEps,DtRevB,DtRevB,"BEST_FPERIOD_OVERRIDE="&FpOvr,"Days=A","Fill=P"),1,1),"")) | L7: =IFERROR(IF($J7<=0,"",$I7/$J7-1),"") | M7: =IFERROR(IF($K7<=0,"",$I7/$K7-1),"") | N7: =IF($C7="","",IFERROR(BDP($C7,FldTRR,"CUST_TRR_START_DT="&TEXT(DtMomA,"yyyymmdd"),"CUST_TRR_END_DT="&TEXT(AsOf,"yyyymmdd"))/100,"")) | O7: =IF($C7="","",IFERROR(BDP($C7,FldTRR,"CUST_TRR_START_DT="&TEXT(DtMomB,"yyyymmdd"),"CUST_TRR_END_DT="&TEXT(AsOf,"yyyymmdd"))/100,"")) | P7: =IF($A7="","",IF($Q7=0,"sector missing",IF(NOT(ISNUMBER($H7)),"no market cap",IF(COUNT($L7:$O7)=4,"complete","missing "&(4-COUNT($L7:$O7))&" of 4 factors")))) | Q7: =IF(OR($B7="",$B7="NO SECTOR",$B7="NOT IN MAP"),0,1) | R7: =IF(AND($Q7=1,ISNUMBER($L7),ISNUMBER($H7)),$L7*$H7,0) | S7: =IF(AND($Q7=1,ISNUMBER($L7),ISNUMBER($H7)),$H7,0) | T7: =IF(AND($Q7=1,ISNUMBER($M7),ISNUMBER($H7)),$M7*$H7,0) | U7: =IF(AND($Q7=1,ISNUMBER($M7),ISNUMBER($H7)),$H7,0) | V7: =IF(AND($Q7=1,ISNUMBER($N7),ISNUMBER($H7)),$N7*$H7,0) | W7: =IF(AND($Q7=1,ISNUMBER($N7),ISNUMBER($H7)),$H7,0) | X7: =IF(AND($Q7=1,ISNUMBER($O7),ISNUMBER($H7)),$O7*$H7,0) | Y7: =IF(AND($Q7=1,ISNUMBER($O7),ISNUMBER($H7)),$H7,0) | Z7: =IF($Q7=0,"",IF(COUNTIF($B$5:$B7,$B7)>1,"",MAX(0,MAX($Z$5:$Z6))+1))
A8: =IFERROR(IF(INDEX('Index Members'!$A$4:$A$403,ROW()-4)=0,"",INDEX('Index Members'!$A$4:$A$403,ROW()-4)),"") | B8: =IF($A8="","",IFERROR(IF(VLOOKUP($A8,'Sector Map'!$A$4:$B$123,2,FALSE)=0,"NO SECTOR",VLOOKUP($A8,'Sector Map'!$A$4:$B$123,2,FALSE)),"NOT IN MAP")) | C8: =IF($A8="","",$A8&TkSuffix) | D8: =IF($C8="","",BDP($C8,FldMcap)) | E8: =IF($C8="","",BDP($C8,FldShOut)) | F8: =IF($C8="","",BDP($C8,FldPx)) | G8: =IFERROR($E8*$F8,"") | H8: =IFERROR(IF(WgtBasis="SEC_CAP",$G8,$D8),"") | I8: =IF($C8="","",BDP($C8,FldEps,"BEST_FPERIOD_OVERRIDE="&FpOvr)) | J8: =IF($C8="","",IFERROR(INDEX(BDH($C8,FldEps,DtRevA,DtRevA,"BEST_FPERIOD_OVERRIDE="&FpOvr,"Days=A","Fill=P"),1,1),"")) | K8: =IF($C8="","",IFERROR(INDEX(BDH($C8,FldEps,DtRevB,DtRevB,"BEST_FPERIOD_OVERRIDE="&FpOvr,"Days=A","Fill=P"),1,1),"")) | L8: =IFERROR(IF($J8<=0,"",$I8/$J8-1),"") | M8: =IFERROR(IF($K8<=0,"",$I8/$K8-1),"") | N8: =IF($C8="","",IFERROR(BDP($C8,FldTRR,"CUST_TRR_START_DT="&TEXT(DtMomA,"yyyymmdd"),"CUST_TRR_END_DT="&TEXT(AsOf,"yyyymmdd"))/100,"")) | O8: =IF($C8="","",IFERROR(BDP($C8,FldTRR,"CUST_TRR_START_DT="&TEXT(DtMomB,"yyyymmdd"),"CUST_TRR_END_DT="&TEXT(AsOf,"yyyymmdd"))/100,"")) | P8: =IF($A8="","",IF($Q8=0,"sector missing",IF(NOT(ISNUMBER($H8)),"no market cap",IF(COUNT($L8:$O8)=4,"complete","missing "&(4-COUNT($L8:$O8))&" of 4 factors")))) | Q8: =IF(OR($B8="",$B8="NO SECTOR",$B8="NOT IN MAP"),0,1) | R8: =IF(AND($Q8=1,ISNUMBER($L8),ISNUMBER($H8)),$L8*$H8,0) | S8: =IF(AND($Q8=1,ISNUMBER($L8),ISNUMBER($H8)),$H8,0) | T8: =IF(AND($Q8=1,ISNUMBER($M8),ISNUMBER($H8)),$M8*$H8,0) | U8: =IF(AND($Q8=1,ISNUMBER($M8),ISNUMBER($H8)),$H8,0) | V8: =IF(AND($Q8=1,ISNUMBER($N8),ISNUMBER($H8)),$N8*$H8,0) | W8: =IF(AND($Q8=1,ISNUMBER($N8),ISNUMBER($H8)),$H8,0) | X8: =IF(AND($Q8=1,ISNUMBER($O8),ISNUMBER($H8)),$O8*$H8,0) | Y8: =IF(AND($Q8=1,ISNUMBER($O8),ISNUMBER($H8)),$H8,0) | Z8: =IF($Q8=0,"",IF(COUNTIF($B$5:$B8,$B8)>1,"",MAX(0,MAX($Z$5:$Z7))+1))
A9: =IFERROR(IF(INDEX('Index Members'!$A$4:$A$403,ROW()-4)=0,"",INDEX('Index Members'!$A$4:$A$403,ROW()-4)),"") | B9: =IF($A9="","",IFERROR(IF(VLOOKUP($A9,'Sector Map'!$A$4:$B$123,2,FALSE)=0,"NO SECTOR",VLOOKUP($A9,'Sector Map'!$A$4:$B$123,2,FALSE)),"NOT IN MAP")) | C9: =IF($A9="","",$A9&TkSuffix) | D9: =IF($C9="","",BDP($C9,FldMcap)) | E9: =IF($C9="","",BDP($C9,FldShOut)) | F9: =IF($C9="","",BDP($C9,FldPx)) | G9: =IFERROR($E9*$F9,"") | H9: =IFERROR(IF(WgtBasis="SEC_CAP",$G9,$D9),"") | I9: =IF($C9="","",BDP($C9,FldEps,"BEST_FPERIOD_OVERRIDE="&FpOvr)) | J9: =IF($C9="","",IFERROR(INDEX(BDH($C9,FldEps,DtRevA,DtRevA,"BEST_FPERIOD_OVERRIDE="&FpOvr,"Days=A","Fill=P"),1,1),"")) | K9: =IF($C9="","",IFERROR(INDEX(BDH($C9,FldEps,DtRevB,DtRevB,"BEST_FPERIOD_OVERRIDE="&FpOvr,"Days=A","Fill=P"),1,1),"")) | L9: =IFERROR(IF($J9<=0,"",$I9/$J9-1),"") | M9: =IFERROR(IF($K9<=0,"",$I9/$K9-1),"") | N9: =IF($C9="","",IFERROR(BDP($C9,FldTRR,"CUST_TRR_START_DT="&TEXT(DtMomA,"yyyymmdd"),"CUST_TRR_END_DT="&TEXT(AsOf,"yyyymmdd"))/100,"")) | O9: =IF($C9="","",IFERROR(BDP($C9,FldTRR,"CUST_TRR_START_DT="&TEXT(DtMomB,"yyyymmdd"),"CUST_TRR_END_DT="&TEXT(AsOf,"yyyymmdd"))/100,"")) | P9: =IF($A9="","",IF($Q9=0,"sector missing",IF(NOT(ISNUMBER($H9)),"no market cap",IF(COUNT($L9:$O9)=4,"complete","missing "&(4-COUNT($L9:$O9))&" of 4 factors")))) | Q9: =IF(OR($B9="",$B9="NO SECTOR",$B9="NOT IN MAP"),0,1) | R9: =IF(AND($Q9=1,ISNUMBER($L9),ISNUMBER($H9)),$L9*$H9,0) | S9: =IF(AND($Q9=1,ISNUMBER($L9),ISNUMBER($H9)),$H9,0) | T9: =IF(AND($Q9=1,ISNUMBER($M9),ISNUMBER($H9)),$M9*$H9,0) | U9: =IF(AND($Q9=1,ISNUMBER($M9),ISNUMBER($H9)),$H9,0) | V9: =IF(AND($Q9=1,ISNUMBER($N9),ISNUMBER($H9)),$N9*$H9,0) | W9: =IF(AND($Q9=1,ISNUMBER($N9),ISNUMBER($H9)),$H9,0) | X9: =IF(AND($Q9=1,ISNUMBER($O9),ISNUMBER($H9)),$O9*$H9,0) | Y9: =IF(AND($Q9=1,ISNUMBER($O9),ISNUMBER($H9)),$H9,0) | Z9: =IF($Q9=0,"",IF(COUNTIF($B$5:$B9,$B9)>1,"",MAX(0,MAX($Z$5:$Z8))+1))
A10: =IFERROR(IF(INDEX('Index Members'!$A$4:$A$403,ROW()-4)=0,"",INDEX('Index Members'!$A$4:$A$403,ROW()-4)),"") | B10: =IF($A10="","",IFERROR(IF(VLOOKUP($A10,'Sector Map'!$A$4:$B$123,2,FALSE)=0,"NO SECTOR",VLOOKUP($A10,'Sector Map'!$A$4:$B$123,2,FALSE)),"NOT IN MAP")) | C10: =IF($A10="","",$A10&TkSuffix) | D10: =IF($C10="","",BDP($C10,FldMcap)) | E10: =IF($C10="","",BDP($C10,FldShOut)) | F10: =IF($C10="","",BDP($C10,FldPx)) | G10: =IFERROR($E10*$F10,"") | H10: =IFERROR(IF(WgtBasis="SEC_CAP",$G10,$D10),"") | I10: =IF($C10="","",BDP($C10,FldEps,"BEST_FPERIOD_OVERRIDE="&FpOvr)) | J10: =IF($C10="","",IFERROR(INDEX(BDH($C10,FldEps,DtRevA,DtRevA,"BEST_FPERIOD_OVERRIDE="&FpOvr,"Days=A","Fill=P"),1,1),"")) | K10: =IF($C10="","",IFERROR(INDEX(BDH($C10,FldEps,DtRevB,DtRevB,"BEST_FPERIOD_OVERRIDE="&FpOvr,"Days=A","Fill=P"),1,1),"")) | L10: =IFERROR(IF($J10<=0,"",$I10/$J10-1),"") | M10: =IFERROR(IF($K10<=0,"",$I10/$K10-1),"") | N10: =IF($C10="","",IFERROR(BDP($C10,FldTRR,"CUST_TRR_START_DT="&TEXT(DtMomA,"yyyymmdd"),"CUST_TRR_END_DT="&TEXT(AsOf,"yyyymmdd"))/100,"")) | O10: =IF($C10="","",IFERROR(BDP($C10,FldTRR,"CUST_TRR_START_DT="&TEXT(DtMomB,"yyyymmdd"),"CUST_TRR_END_DT="&TEXT(AsOf,"yyyymmdd"))/100,"")) | P10: =IF($A10="","",IF($Q10=0,"sector missing",IF(NOT(ISNUMBER($H10)),"no market cap",IF(COUNT($L10:$O10)=4,"complete","missing "&(4-COUNT($L10:$O10))&" of 4 factors")))) | Q10: =IF(OR($B10="",$B10="NO SECTOR",$B10="NOT IN MAP"),0,1) | R10: =IF(AND($Q10=1,ISNUMBER($L10),ISNUMBER($H10)),$L10*$H10,0) | S10: =IF(AND($Q10=1,ISNUMBER($L10),ISNUMBER($H10)),$H10,0) | T10: =IF(AND($Q10=1,ISNUMBER($M10),ISNUMBER($H10)),$M10*$H10,0) | U10: =IF(AND($Q10=1,ISNUMBER($M10),ISNUMBER($H10)),$H10,0) | V10: =IF(AND($Q10=1,ISNUMBER($N10),ISNUMBER($H10)),$N10*$H10,0) | W10: =IF(AND($Q10=1,ISNUMBER($N10),ISNUMBER($H10)),$H10,0) | X10: =IF(AND($Q10=1,ISNUMBER($O10),ISNUMBER($H10)),$O10*$H10,0) | Y10: =IF(AND($Q10=1,ISNUMBER($O10),ISNUMBER($H10)),$H10,0) | Z10: =IF($Q10=0,"",IF(COUNTIF($B$5:$B10,$B10)>1,"",MAX(0,MAX($Z$5:$Z9))+1))
A11: =IFERROR(IF(INDEX('Index Members'!$A$4:$A$403,ROW()-4)=0,"",INDEX('Index Members'!$A$4:$A$403,ROW()-4)),"") | B11: =IF($A11="","",IFERROR(IF(VLOOKUP($A11,'Sector Map'!$A$4:$B$123,2,FALSE)=0,"NO SECTOR",VLOOKUP($A11,'Sector Map'!$A$4:$B$123,2,FALSE)),"NOT IN MAP")) | C11: =IF($A11="","",$A11&TkSuffix) | D11: =IF($C11="","",BDP($C11,FldMcap)) | E11: =IF($C11="","",BDP($C11,FldShOut)) | F11: =IF($C11="","",BDP($C11,FldPx)) | G11: =IFERROR($E11*$F11,"") | H11: =IFERROR(IF(WgtBasis="SEC_CAP",$G11,$D11),"") | I11: =IF($C11="","",BDP($C11,FldEps,"BEST_FPERIOD_OVERRIDE="&FpOvr)) | J11: =IF($C11="","",IFERROR(INDEX(BDH($C11,FldEps,DtRevA,DtRevA,"BEST_FPERIOD_OVERRIDE="&FpOvr,"Days=A","Fill=P"),1,1),"")) | K11: =IF($C11="","",IFERROR(INDEX(BDH($C11,FldEps,DtRevB,DtRevB,"BEST_FPERIOD_OVERRIDE="&FpOvr,"Days=A","Fill=P"),1,1),"")) | L11: =IFERROR(IF($J11<=0,"",$I11/$J11-1),"") | M11: =IFERROR(IF($K11<=0,"",$I11/$K11-1),"") | N11: =IF($C11="","",IFERROR(BDP($C11,FldTRR,"CUST_TRR_START_DT="&TEXT(DtMomA,"yyyymmdd"),"CUST_TRR_END_DT="&TEXT(AsOf,"yyyymmdd"))/100,"")) | O11: =IF($C11="","",IFERROR(BDP($C11,FldTRR,"CUST_TRR_START_DT="&TEXT(DtMomB,"yyyymmdd"),"CUST_TRR_END_DT="&TEXT(AsOf,"yyyymmdd"))/100,"")) | P11: =IF($A11="","",IF($Q11=0,"sector missing",IF(NOT(ISNUMBER($H11)),"no market cap",IF(COUNT($L11:$O11)=4,"complete","missing "&(4-COUNT($L11:$O11))&" of 4 factors")))) | Q11: =IF(OR($B11="",$B11="NO SECTOR",$B11="NOT IN MAP"),0,1) | R11: =IF(AND($Q11=1,ISNUMBER($L11),ISNUMBER($H11)),$L11*$H11,0) | S11: =IF(AND($Q11=1,ISNUMBER($L11),ISNUMBER($H11)),$H11,0) | T11: =IF(AND($Q11=1,ISNUMBER($M11),ISNUMBER($H11)),$M11*$H11,0) | U11: =IF(AND($Q11=1,ISNUMBER($M11),ISNUMBER($H11)),$H11,0) | V11: =IF(AND($Q11=1,ISNUMBER($N11),ISNUMBER($H11)),$N11*$H11,0) | W11: =IF(AND($Q11=1,ISNUMBER($N11),ISNUMBER($H11)),$H11,0) | X11: =IF(AND($Q11=1,ISNUMBER($O11),ISNUMBER($H11)),$O11*$H11,0) | Y11: =IF(AND($Q11=1,ISNUMBER($O11),ISNUMBER($H11)),$H11,0) | Z11: =IF($Q11=0,"",IF(COUNTIF($B$5:$B11,$B11)>1,"",MAX(0,MAX($Z$5:$Z10))+1))
A12: =IFERROR(IF(INDEX('Index Members'!$A$4:$A$403,ROW()-4)=0,"",INDEX('Index Members'!$A$4:$A$403,ROW()-4)),"") | B12: =IF($A12="","",IFERROR(IF(VLOOKUP($A12,'Sector Map'!$A$4:$B$123,2,FALSE)=0,"NO SECTOR",VLOOKUP($A12,'Sector Map'!$A$4:$B$123,2,FALSE)),"NOT IN MAP")) | C12: =IF($A12="","",$A12&TkSuffix) | D12: =IF($C12="","",BDP($C12,FldMcap)) | E12: =IF($C12="","",BDP($C12,FldShOut)) | F12: =IF($C12="","",BDP($C12,FldPx)) | G12: =IFERROR($E12*$F12,"") | H12: =IFERROR(IF(WgtBasis="SEC_CAP",$G12,$D12),"") | I12: =IF($C12="","",BDP($C12,FldEps,"BEST_FPERIOD_OVERRIDE="&FpOvr)) | J12: =IF($C12="","",IFERROR(INDEX(BDH($C12,FldEps,DtRevA,DtRevA,"BEST_FPERIOD_OVERRIDE="&FpOvr,"Days=A","Fill=P"),1,1),"")) | K12: =IF($C12="","",IFERROR(INDEX(BDH($C12,FldEps,DtRevB,DtRevB,"BEST_FPERIOD_OVERRIDE="&FpOvr,"Days=A","Fill=P"),1,1),"")) | L12: =IFERROR(IF($J12<=0,"",$I12/$J12-1),"") | M12: =IFERROR(IF($K12<=0,"",$I12/$K12-1),"") | N12: =IF($C12="","",IFERROR(BDP($C12,FldTRR,"CUST_TRR_START_DT="&TEXT(DtMomA,"yyyymmdd"),"CUST_TRR_END_DT="&TEXT(AsOf,"yyyymmdd"))/100,"")) | O12: =IF($C12="","",IFERROR(BDP($C12,FldTRR,"CUST_TRR_START_DT="&TEXT(DtMomB,"yyyymmdd"),"CUST_TRR_END_DT="&TEXT(AsOf,"yyyymmdd"))/100,"")) | P12: =IF($A12="","",IF($Q12=0,"sector missing",IF(NOT(ISNUMBER($H12)),"no market cap",IF(COUNT($L12:$O12)=4,"complete","missing "&(4-COUNT($L12:$O12))&" of 4 factors")))) | Q12: =IF(OR($B12="",$B12="NO SECTOR",$B12="NOT IN MAP"),0,1) | R12: =IF(AND($Q12=1,ISNUMBER($L12),ISNUMBER($H12)),$L12*$H12,0) | S12: =IF(AND($Q12=1,ISNUMBER($L12),ISNUMBER($H12)),$H12,0) | T12: =IF(AND($Q12=1,ISNUMBER($M12),ISNUMBER($H12)),$M12*$H12,0) | U12: =IF(AND($Q12=1,ISNUMBER($M12),ISNUMBER($H12)),$H12,0) | V12: =IF(AND($Q12=1,ISNUMBER($N12),ISNUMBER($H12)),$N12*$H12,0) | W12: =IF(AND($Q12=1,ISNUMBER($N12),ISNUMBER($H12)),$H12,0) | X12: =IF(AND($Q12=1,ISNUMBER($O12),ISNUMBER($H12)),$O12*$H12,0) | Y12: =IF(AND($Q12=1,ISNUMBER($O12),ISNUMBER($H12)),$H12,0) | Z12: =IF($Q12=0,"",IF(COUNTIF($B$5:$B12,$B12)>1,"",MAX(0,MAX($Z$5:$Z11))+1))
A13: =IFERROR(IF(INDEX('Index Members'!$A$4:$A$403,ROW()-4)=0,"",INDEX('Index Members'!$A$4:$A$403,ROW()-4)),"") | B13: =IF($A13="","",IFERROR(IF(VLOOKUP($A13,'Sector Map'!$A$4:$B$123,2,FALSE)=0,"NO SECTOR",VLOOKUP($A13,'Sector Map'!$A$4:$B$123,2,FALSE)),"NOT IN MAP")) | C13: =IF($A13="","",$A13&TkSuffix) | D13: =IF($C13="","",BDP($C13,FldMcap)) | E13: =IF($C13="","",BDP($C13,FldShOut)) | F13: =IF($C13="","",BDP($C13,FldPx)) | G13: =IFERROR($E13*$F13,"") | H13: =IFERROR(IF(WgtBasis="SEC_CAP",$G13,$D13),"") | I13: =IF($C13="","",BDP($C13,FldEps,"BEST_FPERIOD_OVERRIDE="&FpOvr)) | J13: =IF($C13="","",IFERROR(INDEX(BDH($C13,FldEps,DtRevA,DtRevA,"BEST_FPERIOD_OVERRIDE="&FpOvr,"Days=A","Fill=P"),1,1),"")) | K13: =IF($C13="","",IFERROR(INDEX(BDH($C13,FldEps,DtRevB,DtRevB,"BEST_FPERIOD_OVERRIDE="&FpOvr,"Days=A","Fill=P"),1,1),"")) | L13: =IFERROR(IF($J13<=0,"",$I13/$J13-1),"") | M13: =IFERROR(IF($K13<=0,"",$I13/$K13-1),"") | N13: =IF($C13="","",IFERROR(BDP($C13,FldTRR,"CUST_TRR_START_DT="&TEXT(DtMomA,"yyyymmdd"),"CUST_TRR_END_DT="&TEXT(AsOf,"yyyymmdd"))/100,"")) | O13: =IF($C13="","",IFERROR(BDP($C13,FldTRR,"CUST_TRR_START_DT="&TEXT(DtMomB,"yyyymmdd"),"CUST_TRR_END_DT="&TEXT(AsOf,"yyyymmdd"))/100,"")) | P13: =IF($A13="","",IF($Q13=0,"sector missing",IF(NOT(ISNUMBER($H13)),"no market cap",IF(COUNT($L13:$O13)=4,"complete","missing "&(4-COUNT($L13:$O13))&" of 4 factors")))) | Q13: =IF(OR($B13="",$B13="NO SECTOR",$B13="NOT IN MAP"),0,1) | R13: =IF(AND($Q13=1,ISNUMBER($L13),ISNUMBER($H13)),$L13*$H13,0) | S13: =IF(AND($Q13=1,ISNUMBER($L13),ISNUMBER($H13)),$H13,0) | T13: =IF(AND($Q13=1,ISNUMBER($M13),ISNUMBER($H13)),$M13*$H13,0) | U13: =IF(AND($Q13=1,ISNUMBER($M13),ISNUMBER($H13)),$H13,0) | V13: =IF(AND($Q13=1,ISNUMBER($N13),ISNUMBER($H13)),$N13*$H13,0) | W13: =IF(AND($Q13=1,ISNUMBER($N13),ISNUMBER($H13)),$H13,0) | X13: =IF(AND($Q13=1,ISNUMBER($O13),ISNUMBER($H13)),$O13*$H13,0) | Y13: =IF(AND($Q13=1,ISNUMBER($O13),ISNUMBER($H13)),$H13,0) | Z13: =IF($Q13=0,"",IF(COUNTIF($B$5:$B13,$B13)>1,"",MAX(0,MAX($Z$5:$Z12))+1))
A14: =IFERROR(IF(INDEX('Index Members'!$A$4:$A$403,ROW()-4)=0,"",INDEX('Index Members'!$A$4:$A$403,ROW()-4)),"") | B14: =IF($A14="","",IFERROR(IF(VLOOKUP($A14,'Sector Map'!$A$4:$B$123,2,FALSE)=0,"NO SECTOR",VLOOKUP($A14,'Sector Map'!$A$4:$B$123,2,FALSE)),"NOT IN MAP")) | C14: =IF($A14="","",$A14&TkSuffix) | D14: =IF($C14="","",BDP($C14,FldMcap)) | E14: =IF($C14="","",BDP($C14,FldShOut)) | F14: =IF($C14="","",BDP($C14,FldPx)) | G14: =IFERROR($E14*$F14,"") | H14: =IFERROR(IF(WgtBasis="SEC_CAP",$G14,$D14),"") | I14: =IF($C14="","",BDP($C14,FldEps,"BEST_FPERIOD_OVERRIDE="&FpOvr)) | J14: =IF($C14="","",IFERROR(INDEX(BDH($C14,FldEps,DtRevA,DtRevA,"BEST_FPERIOD_OVERRIDE="&FpOvr,"Days=A","Fill=P"),1,1),"")) | K14: =IF($C14="","",IFERROR(INDEX(BDH($C14,FldEps,DtRevB,DtRevB,"BEST_FPERIOD_OVERRIDE="&FpOvr,"Days=A","Fill=P"),1,1),"")) | L14: =IFERROR(IF($J14<=0,"",$I14/$J14-1),"") | M14: =IFERROR(IF($K14<=0,"",$I14/$K14-1),"") | N14: =IF($C14="","",IFERROR(BDP($C14,FldTRR,"CUST_TRR_START_DT="&TEXT(DtMomA,"yyyymmdd"),"CUST_TRR_END_DT="&TEXT(AsOf,"yyyymmdd"))/100,"")) | O14: =IF($C14="","",IFERROR(BDP($C14,FldTRR,"CUST_TRR_START_DT="&TEXT(DtMomB,"yyyymmdd"),"CUST_TRR_END_DT="&TEXT(AsOf,"yyyymmdd"))/100,"")) | P14: =IF($A14="","",IF($Q14=0,"sector missing",IF(NOT(ISNUMBER($H14)),"no market cap",IF(COUNT($L14:$O14)=4,"complete","missing "&(4-COUNT($L14:$O14))&" of 4 factors")))) | Q14: =IF(OR($B14="",$B14="NO SECTOR",$B14="NOT IN MAP"),0,1) | R14: =IF(AND($Q14=1,ISNUMBER($L14),ISNUMBER($H14)),$L14*$H14,0) | S14: =IF(AND($Q14=1,ISNUMBER($L14),ISNUMBER($H14)),$H14,0) | T14: =IF(AND($Q14=1,ISNUMBER($M14),ISNUMBER($H14)),$M14*$H14,0) | U14: =IF(AND($Q14=1,ISNUMBER($M14),ISNUMBER($H14)),$H14,0) | V14: =IF(AND($Q14=1,ISNUMBER($N14),ISNUMBER($H14)),$N14*$H14,0) | W14: =IF(AND($Q14=1,ISNUMBER($N14),ISNUMBER($H14)),$H14,0) | X14: =IF(AND($Q14=1,ISNUMBER($O14),ISNUMBER($H14)),$O14*$H14,0) | Y14: =IF(AND($Q14=1,ISNUMBER($O14),ISNUMBER($H14)),$H14,0) | Z14: =IF($Q14=0,"",IF(COUNTIF($B$5:$B14,$B14)>1,"",MAX(0,MAX($Z$5:$Z13))+1))
A15: =IFERROR(IF(INDEX('Index Members'!$A$4:$A$403,ROW()-4)=0,"",INDEX('Index Members'!$A$4:$A$403,ROW()-4)),"") | B15: =IF($A15="","",IFERROR(IF(VLOOKUP($A15,'Sector Map'!$A$4:$B$123,2,FALSE)=0,"NO SECTOR",VLOOKUP($A15,'Sector Map'!$A$4:$B$123,2,FALSE)),"NOT IN MAP")) | C15: =IF($A15="","",$A15&TkSuffix) | D15: =IF($C15="","",BDP($C15,FldMcap)) | E15: =IF($C15="","",BDP($C15,FldShOut)) | F15: =IF($C15="","",BDP($C15,FldPx)) | G15: =IFERROR($E15*$F15,"") | H15: =IFERROR(IF(WgtBasis="SEC_CAP",$G15,$D15),"") | I15: =IF($C15="","",BDP($C15,FldEps,"BEST_FPERIOD_OVERRIDE="&FpOvr)) | J15: =IF($C15="","",IFERROR(INDEX(BDH($C15,FldEps,DtRevA,DtRevA,"BEST_FPERIOD_OVERRIDE="&FpOvr,"Days=A","Fill=P"),1,1),"")) | K15: =IF($C15="","",IFERROR(INDEX(BDH($C15,FldEps,DtRevB,DtRevB,"BEST_FPERIOD_OVERRIDE="&FpOvr,"Days=A","Fill=P"),1,1),"")) | L15: =IFERROR(IF($J15<=0,"",$I15/$J15-1),"") | M15: =IFERROR(IF($K15<=0,"",$I15/$K15-1),"") | N15: =IF($C15="","",IFERROR(BDP($C15,FldTRR,"CUST_TRR_START_DT="&TEXT(DtMomA,"yyyymmdd"),"CUST_TRR_END_DT="&TEXT(AsOf,"yyyymmdd"))/100,"")) | O15: =IF($C15="","",IFERROR(BDP($C15,FldTRR,"CUST_TRR_START_DT="&TEXT(DtMomB,"yyyymmdd"),"CUST_TRR_END_DT="&TEXT(AsOf,"yyyymmdd"))/100,"")) | P15: =IF($A15="","",IF($Q15=0,"sector missing",IF(NOT(ISNUMBER($H15)),"no market cap",IF(COUNT($L15:$O15)=4,"complete","missing "&(4-COUNT($L15:$O15))&" of 4 factors")))) | Q15: =IF(OR($B15="",$B15="NO SECTOR",$B15="NOT IN MAP"),0,1) | R15: =IF(AND($Q15=1,ISNUMBER($L15),ISNUMBER($H15)),$L15*$H15,0) | S15: =IF(AND($Q15=1,ISNUMBER($L15),ISNUMBER($H15)),$H15,0) | T15: =IF(AND($Q15=1,ISNUMBER($M15),ISNUMBER($H15)),$M15*$H15,0) | U15: =IF(AND($Q15=1,ISNUMBER($M15),ISNUMBER($H15)),$H15,0) | V15: =IF(AND($Q15=1,ISNUMBER($N15),ISNUMBER($H15)),$N15*$H15,0) | W15: =IF(AND($Q15=1,ISNUMBER($N15),ISNUMBER($H15)),$H15,0) | X15: =IF(AND($Q15=1,ISNUMBER($O15),ISNUMBER($H15)),$O15*$H15,0) | Y15: =IF(AND($Q15=1,ISNUMBER($O15),ISNUMBER($H15)),$H15,0) | Z15: =IF($Q15=0,"",IF(COUNTIF($B$5:$B15,$B15)>1,"",MAX(0,MAX($Z$5:$Z14))+1))
A16: =IFERROR(IF(INDEX('Index Members'!$A$4:$A$403,ROW()-4)=0,"",INDEX('Index Members'!$A$4:$A$403,ROW()-4)),"") | B16: =IF($A16="","",IFERROR(IF(VLOOKUP($A16,'Sector Map'!$A$4:$B$123,2,FALSE)=0,"NO SECTOR",VLOOKUP($A16,'Sector Map'!$A$4:$B$123,2,FALSE)),"NOT IN MAP")) | C16: =IF($A16="","",$A16&TkSuffix) | D16: =IF($C16="","",BDP($C16,FldMcap)) | E16: =IF($C16="","",BDP($C16,FldShOut)) | F16: =IF($C16="","",BDP($C16,FldPx)) | G16: =IFERROR($E16*$F16,"") | H16: =IFERROR(IF(WgtBasis="SEC_CAP",$G16,$D16),"") | I16: =IF($C16="","",BDP($C16,FldEps,"BEST_FPERIOD_OVERRIDE="&FpOvr)) | J16: =IF($C16="","",IFERROR(INDEX(BDH($C16,FldEps,DtRevA,DtRevA,"BEST_FPERIOD_OVERRIDE="&FpOvr,"Days=A","Fill=P"),1,1),"")) | K16: =IF($C16="","",IFERROR(INDEX(BDH($C16,FldEps,DtRevB,DtRevB,"BEST_FPERIOD_OVERRIDE="&FpOvr,"Days=A","Fill=P"),1,1),"")) | L16: =IFERROR(IF($J16<=0,"",$I16/$J16-1),"") | M16: =IFERROR(IF($K16<=0,"",$I16/$K16-1),"") | N16: =IF($C16="","",IFERROR(BDP($C16,FldTRR,"CUST_TRR_START_DT="&TEXT(DtMomA,"yyyymmdd"),"CUST_TRR_END_DT="&TEXT(AsOf,"yyyymmdd"))/100,"")) | O16: =IF($C16="","",IFERROR(BDP($C16,FldTRR,"CUST_TRR_START_DT="&TEXT(DtMomB,"yyyymmdd"),"CUST_TRR_END_DT="&TEXT(AsOf,"yyyymmdd"))/100,"")) | P16: =IF($A16="","",IF($Q16=0,"sector missing",IF(NOT(ISNUMBER($H16)),"no market cap",IF(COUNT($L16:$O16)=4,"complete","missing "&(4-COUNT($L16:$O16))&" of 4 factors")))) | Q16: =IF(OR($B16="",$B16="NO SECTOR",$B16="NOT IN MAP"),0,1) | R16: =IF(AND($Q16=1,ISNUMBER($L16),ISNUMBER($H16)),$L16*$H16,0) | S16: =IF(AND($Q16=1,ISNUMBER($L16),ISNUMBER($H16)),$H16,0) | T16: =IF(AND($Q16=1,ISNUMBER($M16),ISNUMBER($H16)),$M16*$H16,0) | U16: =IF(AND($Q16=1,ISNUMBER($M16),ISNUMBER($H16)),$H16,0) | V16: =IF(AND($Q16=1,ISNUMBER($N16),ISNUMBER($H16)),$N16*$H16,0) | W16: =IF(AND($Q16=1,ISNUMBER($N16),ISNUMBER($H16)),$H16,0) | X16: =IF(AND($Q16=1,ISNUMBER($O16),ISNUMBER($H16)),$O16*$H16,0) | Y16: =IF(AND($Q16=1,ISNUMBER($O16),ISNUMBER($H16)),$H16,0) | Z16: =IF($Q16=0,"",IF(COUNTIF($B$5:$B16,$B16)>1,"",MAX(0,MAX($Z$5:$Z15))+1))
A17: =IFERROR(IF(INDEX('Index Members'!$A$4:$A$403,ROW()-4)=0,"",INDEX('Index Members'!$A$4:$A$403,ROW()-4)),"") | B17: =IF($A17="","",IFERROR(IF(VLOOKUP($A17,'Sector Map'!$A$4:$B$123,2,FALSE)=0,"NO SECTOR",VLOOKUP($A17,'Sector Map'!$A$4:$B$123,2,FALSE)),"NOT IN MAP")) | C17: =IF($A17="","",$A17&TkSuffix) | D17: =IF($C17="","",BDP($C17,FldMcap)) | E17: =IF($C17="","",BDP($C17,FldShOut)) | F17: =IF($C17="","",BDP($C17,FldPx)) | G17: =IFERROR($E17*$F17,"") | H17: =IFERROR(IF(WgtBasis="SEC_CAP",$G17,$D17),"") | I17: =IF($C17="","",BDP($C17,FldEps,"BEST_FPERIOD_OVERRIDE="&FpOvr)) | J17: =IF($C17="","",IFERROR(INDEX(BDH($C17,FldEps,DtRevA,DtRevA,"BEST_FPERIOD_OVERRIDE="&FpOvr,"Days=A","Fill=P"),1,1),"")) | K17: =IF($C17="","",IFERROR(INDEX(BDH($C17,FldEps,DtRevB,DtRevB,"BEST_FPERIOD_OVERRIDE="&FpOvr,"Days=A","Fill=P"),1,1),"")) | L17: =IFERROR(IF($J17<=0,"",$I17/$J17-1),"") | M17: =IFERROR(IF($K17<=0,"",$I17/$K17-1),"") | N17: =IF($C17="","",IFERROR(BDP($C17,FldTRR,"CUST_TRR_START_DT="&TEXT(DtMomA,"yyyymmdd"),"CUST_TRR_END_DT="&TEXT(AsOf,"yyyymmdd"))/100,"")) | O17: =IF($C17="","",IFERROR(BDP($C17,FldTRR,"CUST_TRR_START_DT="&TEXT(DtMomB,"yyyymmdd"),"CUST_TRR_END_DT="&TEXT(AsOf,"yyyymmdd"))/100,"")) | P17: =IF($A17="","",IF($Q17=0,"sector missing",IF(NOT(ISNUMBER($H17)),"no market cap",IF(COUNT($L17:$O17)=4,"complete","missing "&(4-COUNT($L17:$O17))&" of 4 factors")))) | Q17: =IF(OR($B17="",$B17="NO SECTOR",$B17="NOT IN MAP"),0,1) | R17: =IF(AND($Q17=1,ISNUMBER($L17),ISNUMBER($H17)),$L17*$H17,0) | S17: =IF(AND($Q17=1,ISNUMBER($L17),ISNUMBER($H17)),$H17,0) | T17: =IF(AND($Q17=1,ISNUMBER($M17),ISNUMBER($H17)),$M17*$H17,0) | U17: =IF(AND($Q17=1,ISNUMBER($M17),ISNUMBER($H17)),$H17,0) | V17: =IF(AND($Q17=1,ISNUMBER($N17),ISNUMBER($H17)),$N17*$H17,0) | W17: =IF(AND($Q17=1,ISNUMBER($N17),ISNUMBER($H17)),$H17,0) | X17: =IF(AND($Q17=1,ISNUMBER($O17),ISNUMBER($H17)),$O17*$H17,0) | Y17: =IF(AND($Q17=1,ISNUMBER($O17),ISNUMBER($H17)),$H17,0) | Z17: =IF($Q17=0,"",IF(COUNTIF($B$5:$B17,$B17)>1,"",MAX(0,MAX($Z$5:$Z16))+1))
... A124: =IFERROR(IF(INDEX('Index Members'!$A$4:$A$403,ROW()-4)=0,"",INDEX('Index Members'!$A$4:$A$403,ROW()-4)),"") | B124: =IF($A124="","",IFERROR(IF(VLOOKUP($A124,'Sector Map'!$A$4:$B$123,2,FALSE)=0,"NO SECTOR",VLOOKUP($A124,'Sector Map'!$A$4:$B$123,2,FALSE)),"NOT IN MAP")) | C124: =IF($A124="","",$A124&TkSuffix) | D124: =IF($C124="","",BDP($C124,FldMcap)) | E124: =IF($C124="","",BDP($C124,FldShOut)) | F124: =IF($C124="","",BDP($C124,FldPx)) | G124: =IFERROR($E124*$F124,"") | H124: =IFERROR(IF(WgtBasis="SEC_CAP",$G124,$D124),"") | I124: =IF($C124="","",BDP($C124,FldEps,"BEST_FPERIOD_OVERRIDE="&FpOvr)) | J124: =IF($C124="","",IFERROR(INDEX(BDH($C124,FldEps,DtRevA,DtRevA,"BEST_FPERIOD_OVERRIDE="&FpOvr,"Days=A","Fill=P"),1,1),"")) | K124: =IF($C124="","",IFERROR(INDEX(BDH($C124,FldEps,DtRevB,DtRevB,"BEST_FPERIOD_OVERRIDE="&FpOvr,"Days=A","Fill=P"),1,1),"")) | L124: =IFERROR(IF($J124<=0,"",$I124/$J124-1),"") | M124: =IFERROR(IF($K124<=0,"",$I124/$K124-1),"") | N124: =IF($C124="","",IFERROR(BDP($C124,FldTRR,"CUST_TRR_START_DT="&TEXT(DtMomA,"yyyymmdd"),"CUST_TRR_END_DT="&TEXT(AsOf,"yyyymmdd"))/100,"")) | O124: =IF($C124="","",IFERROR(BDP($C124,FldTRR,"CUST_TRR_START_DT="&TEXT(DtMomB,"yyyymmdd"),"CUST_TRR_END_DT="&TEXT(AsOf,"yyyymmdd"))/100,"")) | P124: =IF($A124="","",IF($Q124=0,"sector missing",IF(NOT(ISNUMBER($H124)),"no market cap",IF(COUNT($L124:$O124)=4,"complete","missing "&(4-COUNT($L124:$O124))&" of 4 factors")))) | Q124: =IF(OR($B124="",$B124="NO SECTOR",$B124="NOT IN MAP"),0,1) | R124: =IF(AND($Q124=1,ISNUMBER($L124),ISNUMBER($H124)),$L124*$H124,0) | S124: =IF(AND($Q124=1,ISNUMBER($L124),ISNUMBER($H124)),$H124,0) | T124: =IF(AND($Q124=1,ISNUMBER($M124),ISNUMBER($H124)),$M124*$H124,0) | U124: =IF(AND($Q124=1,ISNUMBER($M124),ISNUMBER($H124)),$H124,0) | V124: =IF(AND($Q124=1,ISNUMBER($N124),ISNUMBER($H124)),$N124*$H124,0) | W124: =IF(AND($Q124=1,ISNUMBER($N124),ISNUMBER($H124)),$H124,0) | X124: =IF(AND($Q124=1,ISNUMBER($O124),ISNUMBER($H124)),$O124*$H124,0) | Y124: =IF(AND($Q124=1,ISNUMBER($O124),ISNUMBER($H124)),$H124,0) | Z124: =IF($Q124=0,"",IF(COUNTIF($B$5:$B124,$B124)>1,"",MAX(0,MAX($Z$5:$Z123))+1))

Sheet Sector Aggregation
A1: Sector aggregation — market-cap weighted
A2: Sectors are discovered from what you typed on Sector Map; no list to maintain here. A security is only weighted into a factor where BOTH that factor and its market cap came back as numbers, so a single missing datapoint cannot poison a sector.
A3: Sector | B3: Names | C3: Total mkt cap | D3: Share of index | E3: Earnings rev. A | F3: Earnings rev. B | G3: Momentum A | H3: Momentum B | I3: n (rev A) | J3: n (rev B) | K3: n (mom A) | L3: n (mom B)
A4: =IFERROR(INDEX('Data'!$B$5:$B$124,MATCH(1,'Data'!$Z$5:$Z$124,0)),"") | B4: =IF($A4="","",COUNTIF('Data'!$B$5:$B$124,$A4)) | C4: =IF($A4="","",SUMIF('Data'!$B$5:$B$124,$A4,'Data'!$H$5:$H$124)) | D4: =IF(OR($A4="",$C$35=0),"",$C4/$C$35) | E4: =IF($A4="","",IF(SUMIF('Data'!$B$5:$B$124,$A4,'Data'!$S$5:$S$124)=0,"",SUMIF('Data'!$B$5:$B$124,$A4,'Data'!$R$5:$R$124)/SUMIF('Data'!$B$5:$B$124,$A4,'Data'!$S$5:$S$124))) | F4: =IF($A4="","",IF(SUMIF('Data'!$B$5:$B$124,$A4,'Data'!$U$5:$U$124)=0,"",SUMIF('Data'!$B$5:$B$124,$A4,'Data'!$T$5:$T$124)/SUMIF('Data'!$B$5:$B$124,$A4,'Data'!$U$5:$U$124))) | G4: =IF($A4="","",IF(SUMIF('Data'!$B$5:$B$124,$A4,'Data'!$W$5:$W$124)=0,"",SUMIF('Data'!$B$5:$B$124,$A4,'Data'!$V$5:$V$124)/SUMIF('Data'!$B$5:$B$124,$A4,'Data'!$W$5:$W$124))) | H4: =IF($A4="","",IF(SUMIF('Data'!$B$5:$B$124,$A4,'Data'!$Y$5:$Y$124)=0,"",SUMIF('Data'!$B$5:$B$124,$A4,'Data'!$X$5:$X$124)/SUMIF('Data'!$B$5:$B$124,$A4,'Data'!$Y$5:$Y$124))) | I4: =IF($A4="","",COUNTIF('Data'!$B$5:$B$124,$A4)-COUNTIFS('Data'!$B$5:$B$124,$A4,'Data'!$S$5:$S$124,0)) | J4: =IF($A4="","",COUNTIF('Data'!$B$5:$B$124,$A4)-COUNTIFS('Data'!$B$5:$B$124,$A4,'Data'!$U$5:$U$124,0)) | K4: =IF($A4="","",COUNTIF('Data'!$B$5:$B$124,$A4)-COUNTIFS('Data'!$B$5:$B$124,$A4,'Data'!$W$5:$W$124,0)) | L4: =IF($A4="","",COUNTIF('Data'!$B$5:$B$124,$A4)-COUNTIFS('Data'!$B$5:$B$124,$A4,'Data'!$Y$5:$Y$124,0))
A5: =IFERROR(INDEX('Data'!$B$5:$B$124,MATCH(2,'Data'!$Z$5:$Z$124,0)),"") | B5: =IF($A5="","",COUNTIF('Data'!$B$5:$B$124,$A5)) | C5: =IF($A5="","",SUMIF('Data'!$B$5:$B$124,$A5,'Data'!$H$5:$H$124)) | D5: =IF(OR($A5="",$C$35=0),"",$C5/$C$35) | E5: =IF($A5="","",IF(SUMIF('Data'!$B$5:$B$124,$A5,'Data'!$S$5:$S$124)=0,"",SUMIF('Data'!$B$5:$B$124,$A5,'Data'!$R$5:$R$124)/SUMIF('Data'!$B$5:$B$124,$A5,'Data'!$S$5:$S$124))) | F5: =IF($A5="","",IF(SUMIF('Data'!$B$5:$B$124,$A5,'Data'!$U$5:$U$124)=0,"",SUMIF('Data'!$B$5:$B$124,$A5,'Data'!$T$5:$T$124)/SUMIF('Data'!$B$5:$B$124,$A5,'Data'!$U$5:$U$124))) | G5: =IF($A5="","",IF(SUMIF('Data'!$B$5:$B$124,$A5,'Data'!$W$5:$W$124)=0,"",SUMIF('Data'!$B$5:$B$124,$A5,'Data'!$V$5:$V$124)/SUMIF('Data'!$B$5:$B$124,$A5,'Data'!$W$5:$W$124))) | H5: =IF($A5="","",IF(SUMIF('Data'!$B$5:$B$124,$A5,'Data'!$Y$5:$Y$124)=0,"",SUMIF('Data'!$B$5:$B$124,$A5,'Data'!$X$5:$X$124)/SUMIF('Data'!$B$5:$B$124,$A5,'Data'!$Y$5:$Y$124))) | I5: =IF($A5="","",COUNTIF('Data'!$B$5:$B$124,$A5)-COUNTIFS('Data'!$B$5:$B$124,$A5,'Data'!$S$5:$S$124,0)) | J5: =IF($A5="","",COUNTIF('Data'!$B$5:$B$124,$A5)-COUNTIFS('Data'!$B$5:$B$124,$A5,'Data'!$U$5:$U$124,0)) | K5: =IF($A5="","",COUNTIF('Data'!$B$5:$B$124,$A5)-COUNTIFS('Data'!$B$5:$B$124,$A5,'Data'!$W$5:$W$124,0)) | L5: =IF($A5="","",COUNTIF('Data'!$B$5:$B$124,$A5)-COUNTIFS('Data'!$B$5:$B$124,$A5,'Data'!$Y$5:$Y$124,0))
A6: =IFERROR(INDEX('Data'!$B$5:$B$124,MATCH(3,'Data'!$Z$5:$Z$124,0)),"") | B6: =IF($A6="","",COUNTIF('Data'!$B$5:$B$124,$A6)) | C6: =IF($A6="","",SUMIF('Data'!$B$5:$B$124,$A6,'Data'!$H$5:$H$124)) | D6: =IF(OR($A6="",$C$35=0),"",$C6/$C$35) | E6: =IF($A6="","",IF(SUMIF('Data'!$B$5:$B$124,$A6,'Data'!$S$5:$S$124)=0,"",SUMIF('Data'!$B$5:$B$124,$A6,'Data'!$R$5:$R$124)/SUMIF('Data'!$B$5:$B$124,$A6,'Data'!$S$5:$S$124))) | F6: =IF($A6="","",IF(SUMIF('Data'!$B$5:$B$124,$A6,'Data'!$U$5:$U$124)=0,"",SUMIF('Data'!$B$5:$B$124,$A6,'Data'!$T$5:$T$124)/SUMIF('Data'!$B$5:$B$124,$A6,'Data'!$U$5:$U$124))) | G6: =IF($A6="","",IF(SUMIF('Data'!$B$5:$B$124,$A6,'Data'!$W$5:$W$124)=0,"",SUMIF('Data'!$B$5:$B$124,$A6,'Data'!$V$5:$V$124)/SUMIF('Data'!$B$5:$B$124,$A6,'Data'!$W$5:$W$124))) | H6: =IF($A6="","",IF(SUMIF('Data'!$B$5:$B$124,$A6,'Data'!$Y$5:$Y$124)=0,"",SUMIF('Data'!$B$5:$B$124,$A6,'Data'!$X$5:$X$124)/SUMIF('Data'!$B$5:$B$124,$A6,'Data'!$Y$5:$Y$124))) | I6: =IF($A6="","",COUNTIF('Data'!$B$5:$B$124,$A6)-COUNTIFS('Data'!$B$5:$B$124,$A6,'Data'!$S$5:$S$124,0)) | J6: =IF($A6="","",COUNTIF('Data'!$B$5:$B$124,$A6)-COUNTIFS('Data'!$B$5:$B$124,$A6,'Data'!$U$5:$U$124,0)) | K6: =IF($A6="","",COUNTIF('Data'!$B$5:$B$124,$A6)-COUNTIFS('Data'!$B$5:$B$124,$A6,'Data'!$W$5:$W$124,0)) | L6: =IF($A6="","",COUNTIF('Data'!$B$5:$B$124,$A6)-COUNTIFS('Data'!$B$5:$B$124,$A6,'Data'!$Y$5:$Y$124,0))
A7: =IFERROR(INDEX('Data'!$B$5:$B$124,MATCH(4,'Data'!$Z$5:$Z$124,0)),"") | B7: =IF($A7="","",COUNTIF('Data'!$B$5:$B$124,$A7)) | C7: =IF($A7="","",SUMIF('Data'!$B$5:$B$124,$A7,'Data'!$H$5:$H$124)) | D7: =IF(OR($A7="",$C$35=0),"",$C7/$C$35) | E7: =IF($A7="","",IF(SUMIF('Data'!$B$5:$B$124,$A7,'Data'!$S$5:$S$124)=0,"",SUMIF('Data'!$B$5:$B$124,$A7,'Data'!$R$5:$R$124)/SUMIF('Data'!$B$5:$B$124,$A7,'Data'!$S$5:$S$124))) | F7: =IF($A7="","",IF(SUMIF('Data'!$B$5:$B$124,$A7,'Data'!$U$5:$U$124)=0,"",SUMIF('Data'!$B$5:$B$124,$A7,'Data'!$T$5:$T$124)/SUMIF('Data'!$B$5:$B$124,$A7,'Data'!$U$5:$U$124))) | G7: =IF($A7="","",IF(SUMIF('Data'!$B$5:$B$124,$A7,'Data'!$W$5:$W$124)=0,"",SUMIF('Data'!$B$5:$B$124,$A7,'Data'!$V$5:$V$124)/SUMIF('Data'!$B$5:$B$124,$A7,'Data'!$W$5:$W$124))) | H7: =IF($A7="","",IF(SUMIF('Data'!$B$5:$B$124,$A7,'Data'!$Y$5:$Y$124)=0,"",SUMIF('Data'!$B$5:$B$124,$A7,'Data'!$X$5:$X$124)/SUMIF('Data'!$B$5:$B$124,$A7,'Data'!$Y$5:$Y$124))) | I7: =IF($A7="","",COUNTIF('Data'!$B$5:$B$124,$A7)-COUNTIFS('Data'!$B$5:$B$124,$A7,'Data'!$S$5:$S$124,0)) | J7: =IF($A7="","",COUNTIF('Data'!$B$5:$B$124,$A7)-COUNTIFS('Data'!$B$5:$B$124,$A7,'Data'!$U$5:$U$124,0)) | K7: =IF($A7="","",COUNTIF('Data'!$B$5:$B$124,$A7)-COUNTIFS('Data'!$B$5:$B$124,$A7,'Data'!$W$5:$W$124,0)) | L7: =IF($A7="","",COUNTIF('Data'!$B$5:$B$124,$A7)-COUNTIFS('Data'!$B$5:$B$124,$A7,'Data'!$Y$5:$Y$124,0))
A8: =IFERROR(INDEX('Data'!$B$5:$B$124,MATCH(5,'Data'!$Z$5:$Z$124,0)),"") | B8: =IF($A8="","",COUNTIF('Data'!$B$5:$B$124,$A8)) | C8: =IF($A8="","",SUMIF('Data'!$B$5:$B$124,$A8,'Data'!$H$5:$H$124)) | D8: =IF(OR($A8="",$C$35=0),"",$C8/$C$35) | E8: =IF($A8="","",IF(SUMIF('Data'!$B$5:$B$124,$A8,'Data'!$S$5:$S$124)=0,"",SUMIF('Data'!$B$5:$B$124,$A8,'Data'!$R$5:$R$124)/SUMIF('Data'!$B$5:$B$124,$A8,'Data'!$S$5:$S$124))) | F8: =IF($A8="","",IF(SUMIF('Data'!$B$5:$B$124,$A8,'Data'!$U$5:$U$124)=0,"",SUMIF('Data'!$B$5:$B$124,$A8,'Data'!$T$5:$T$124)/SUMIF('Data'!$B$5:$B$124,$A8,'Data'!$U$5:$U$124))) | G8: =IF($A8="","",IF(SUMIF('Data'!$B$5:$B$124,$A8,'Data'!$W$5:$W$124)=0,"",SUMIF('Data'!$B$5:$B$124,$A8,'Data'!$V$5:$V$124)/SUMIF('Data'!$B$5:$B$124,$A8,'Data'!$W$5:$W$124))) | H8: =IF($A8="","",IF(SUMIF('Data'!$B$5:$B$124,$A8,'Data'!$Y$5:$Y$124)=0,"",SUMIF('Data'!$B$5:$B$124,$A8,'Data'!$X$5:$X$124)/SUMIF('Data'!$B$5:$B$124,$A8,'Data'!$Y$5:$Y$124))) | I8: =IF($A8="","",COUNTIF('Data'!$B$5:$B$124,$A8)-COUNTIFS('Data'!$B$5:$B$124,$A8,'Data'!$S$5:$S$124,0)) | J8: =IF($A8="","",COUNTIF('Data'!$B$5:$B$124,$A8)-COUNTIFS('Data'!$B$5:$B$124,$A8,'Data'!$U$5:$U$124,0)) | K8: =IF($A8="","",COUNTIF('Data'!$B$5:$B$124,$A8)-COUNTIFS('Data'!$B$5:$B$124,$A8,'Data'!$W$5:$W$124,0)) | L8: =IF($A8="","",COUNTIF('Data'!$B$5:$B$124,$A8)-COUNTIFS('Data'!$B$5:$B$124,$A8,'Data'!$Y$5:$Y$124,0))
A9: =IFERROR(INDEX('Data'!$B$5:$B$124,MATCH(6,'Data'!$Z$5:$Z$124,0)),"") | B9: =IF($A9="","",COUNTIF('Data'!$B$5:$B$124,$A9)) | C9: =IF($A9="","",SUMIF('Data'!$B$5:$B$124,$A9,'Data'!$H$5:$H$124)) | D9: =IF(OR($A9="",$C$35=0),"",$C9/$C$35) | E9: =IF($A9="","",IF(SUMIF('Data'!$B$5:$B$124,$A9,'Data'!$S$5:$S$124)=0,"",SUMIF('Data'!$B$5:$B$124,$A9,'Data'!$R$5:$R$124)/SUMIF('Data'!$B$5:$B$124,$A9,'Data'!$S$5:$S$124))) | F9: =IF($A9="","",IF(SUMIF('Data'!$B$5:$B$124,$A9,'Data'!$U$5:$U$124)=0,"",SUMIF('Data'!$B$5:$B$124,$A9,'Data'!$T$5:$T$124)/SUMIF('Data'!$B$5:$B$124,$A9,'Data'!$U$5:$U$124))) | G9: =IF($A9="","",IF(SUMIF('Data'!$B$5:$B$124,$A9,'Data'!$W$5:$W$124)=0,"",SUMIF('Data'!$B$5:$B$124,$A9,'Data'!$V$5:$V$124)/SUMIF('Data'!$B$5:$B$124,$A9,'Data'!$W$5:$W$124))) | H9: =IF($A9="","",IF(SUMIF('Data'!$B$5:$B$124,$A9,'Data'!$Y$5:$Y$124)=0,"",SUMIF('Data'!$B$5:$B$124,$A9,'Data'!$X$5:$X$124)/SUMIF('Data'!$B$5:$B$124,$A9,'Data'!$Y$5:$Y$124))) | I9: =IF($A9="","",COUNTIF('Data'!$B$5:$B$124,$A9)-COUNTIFS('Data'!$B$5:$B$124,$A9,'Data'!$S$5:$S$124,0)) | J9: =IF($A9="","",COUNTIF('Data'!$B$5:$B$124,$A9)-COUNTIFS('Data'!$B$5:$B$124,$A9,'Data'!$U$5:$U$124,0)) | K9: =IF($A9="","",COUNTIF('Data'!$B$5:$B$124,$A9)-COUNTIFS('Data'!$B$5:$B$124,$A9,'Data'!$W$5:$W$124,0)) | L9: =IF($A9="","",COUNTIF('Data'!$B$5:$B$124,$A9)-COUNTIFS('Data'!$B$5:$B$124,$A9,'Data'!$Y$5:$Y$124,0))
A10: =IFERROR(INDEX('Data'!$B$5:$B$124,MATCH(7,'Data'!$Z$5:$Z$124,0)),"") | B10: =IF($A10="","",COUNTIF('Data'!$B$5:$B$124,$A10)) | C10: =IF($A10="","",SUMIF('Data'!$B$5:$B$124,$A10,'Data'!$H$5:$H$124)) | D10: =IF(OR($A10="",$C$35=0),"",$C10/$C$35) | E10: =IF($A10="","",IF(SUMIF('Data'!$B$5:$B$124,$A10,'Data'!$S$5:$S$124)=0,"",SUMIF('Data'!$B$5:$B$124,$A10,'Data'!$R$5:$R$124)/SUMIF('Data'!$B$5:$B$124,$A10,'Data'!$S$5:$S$124))) | F10: =IF($A10="","",IF(SUMIF('Data'!$B$5:$B$124,$A10,'Data'!$U$5:$U$124)=0,"",SUMIF('Data'!$B$5:$B$124,$A10,'Data'!$T$5:$T$124)/SUMIF('Data'!$B$5:$B$124,$A10,'Data'!$U$5:$U$124))) | G10: =IF($A10="","",IF(SUMIF('Data'!$B$5:$B$124,$A10,'Data'!$W$5:$W$124)=0,"",SUMIF('Data'!$B$5:$B$124,$A10,'Data'!$V$5:$V$124)/SUMIF('Data'!$B$5:$B$124,$A10,'Data'!$W$5:$W$124))) | H10: =IF($A10="","",IF(SUMIF('Data'!$B$5:$B$124,$A10,'Data'!$Y$5:$Y$124)=0,"",SUMIF('Data'!$B$5:$B$124,$A10,'Data'!$X$5:$X$124)/SUMIF('Data'!$B$5:$B$124,$A10,'Data'!$Y$5:$Y$124))) | I10: =IF($A10="","",COUNTIF('Data'!$B$5:$B$124,$A10)-COUNTIFS('Data'!$B$5:$B$124,$A10,'Data'!$S$5:$S$124,0)) | J10: =IF($A10="","",COUNTIF('Data'!$B$5:$B$124,$A10)-COUNTIFS('Data'!$B$5:$B$124,$A10,'Data'!$U$5:$U$124,0)) | K10: =IF($A10="","",COUNTIF('Data'!$B$5:$B$124,$A10)-COUNTIFS('Data'!$B$5:$B$124,$A10,'Data'!$W$5:$W$124,0)) | L10: =IF($A10="","",COUNTIF('Data'!$B$5:$B$124,$A10)-COUNTIFS('Data'!$B$5:$B$124,$A10,'Data'!$Y$5:$Y$124,0))
A11: =IFERROR(INDEX('Data'!$B$5:$B$124,MATCH(8,'Data'!$Z$5:$Z$124,0)),"") | B11: =IF($A11="","",COUNTIF('Data'!$B$5:$B$124,$A11)) | C11: =IF($A11="","",SUMIF('Data'!$B$5:$B$124,$A11,'Data'!$H$5:$H$124)) | D11: =IF(OR($A11="",$C$35=0),"",$C11/$C$35) | E11: =IF($A11="","",IF(SUMIF('Data'!$B$5:$B$124,$A11,'Data'!$S$5:$S$124)=0,"",SUMIF('Data'!$B$5:$B$124,$A11,'Data'!$R$5:$R$124)/SUMIF('Data'!$B$5:$B$124,$A11,'Data'!$S$5:$S$124))) | F11: =IF($A11="","",IF(SUMIF('Data'!$B$5:$B$124,$A11,'Data'!$U$5:$U$124)=0,"",SUMIF('Data'!$B$5:$B$124,$A11,'Data'!$T$5:$T$124)/SUMIF('Data'!$B$5:$B$124,$A11,'Data'!$U$5:$U$124))) | G11: =IF($A11="","",IF(SUMIF('Data'!$B$5:$B$124,$A11,'Data'!$W$5:$W$124)=0,"",SUMIF('Data'!$B$5:$B$124,$A11,'Data'!$V$5:$V$124)/SUMIF('Data'!$B$5:$B$124,$A11,'Data'!$W$5:$W$124))) | H11: =IF($A11="","",IF(SUMIF('Data'!$B$5:$B$124,$A11,'Data'!$Y$5:$Y$124)=0,"",SUMIF('Data'!$B$5:$B$124,$A11,'Data'!$X$5:$X$124)/SUMIF('Data'!$B$5:$B$124,$A11,'Data'!$Y$5:$Y$124))) | I11: =IF($A11="","",COUNTIF('Data'!$B$5:$B$124,$A11)-COUNTIFS('Data'!$B$5:$B$124,$A11,'Data'!$S$5:$S$124,0)) | J11: =IF($A11="","",COUNTIF('Data'!$B$5:$B$124,$A11)-COUNTIFS('Data'!$B$5:$B$124,$A11,'Data'!$U$5:$U$124,0)) | K11: =IF($A11="","",COUNTIF('Data'!$B$5:$B$124,$A11)-COUNTIFS('Data'!$B$5:$B$124,$A11,'Data'!$W$5:$W$124,0)) | L11: =IF($A11="","",COUNTIF('Data'!$B$5:$B$124,$A11)-COUNTIFS('Data'!$B$5:$B$124,$A11,'Data'!$Y$5:$Y$124,0))
A12: =IFERROR(INDEX('Data'!$B$5:$B$124,MATCH(9,'Data'!$Z$5:$Z$124,0)),"") | B12: =IF($A12="","",COUNTIF('Data'!$B$5:$B$124,$A12)) | C12: =IF($A12="","",SUMIF('Data'!$B$5:$B$124,$A12,'Data'!$H$5:$H$124)) | D12: =IF(OR($A12="",$C$35=0),"",$C12/$C$35) | E12: =IF($A12="","",IF(SUMIF('Data'!$B$5:$B$124,$A12,'Data'!$S$5:$S$124)=0,"",SUMIF('Data'!$B$5:$B$124,$A12,'Data'!$R$5:$R$124)/SUMIF('Data'!$B$5:$B$124,$A12,'Data'!$S$5:$S$124))) | F12: =IF($A12="","",IF(SUMIF('Data'!$B$5:$B$124,$A12,'Data'!$U$5:$U$124)=0,"",SUMIF('Data'!$B$5:$B$124,$A12,'Data'!$T$5:$T$124)/SUMIF('Data'!$B$5:$B$124,$A12,'Data'!$U$5:$U$124))) | G12: =IF($A12="","",IF(SUMIF('Data'!$B$5:$B$124,$A12,'Data'!$W$5:$W$124)=0,"",SUMIF('Data'!$B$5:$B$124,$A12,'Data'!$V$5:$V$124)/SUMIF('Data'!$B$5:$B$124,$A12,'Data'!$W$5:$W$124))) | H12: =IF($A12="","",IF(SUMIF('Data'!$B$5:$B$124,$A12,'Data'!$Y$5:$Y$124)=0,"",SUMIF('Data'!$B$5:$B$124,$A12,'Data'!$X$5:$X$124)/SUMIF('Data'!$B$5:$B$124,$A12,'Data'!$Y$5:$Y$124))) | I12: =IF($A12="","",COUNTIF('Data'!$B$5:$B$124,$A12)-COUNTIFS('Data'!$B$5:$B$124,$A12,'Data'!$S$5:$S$124,0)) | J12: =IF($A12="","",COUNTIF('Data'!$B$5:$B$124,$A12)-COUNTIFS('Data'!$B$5:$B$124,$A12,'Data'!$U$5:$U$124,0)) | K12: =IF($A12="","",COUNTIF('Data'!$B$5:$B$124,$A12)-COUNTIFS('Data'!$B$5:$B$124,$A12,'Data'!$W$5:$W$124,0)) | L12: =IF($A12="","",COUNTIF('Data'!$B$5:$B$124,$A12)-COUNTIFS('Data'!$B$5:$B$124,$A12,'Data'!$Y$5:$Y$124,0))
A13: =IFERROR(INDEX('Data'!$B$5:$B$124,MATCH(10,'Data'!$Z$5:$Z$124,0)),"") | B13: =IF($A13="","",COUNTIF('Data'!$B$5:$B$124,$A13)) | C13: =IF($A13="","",SUMIF('Data'!$B$5:$B$124,$A13,'Data'!$H$5:$H$124)) | D13: =IF(OR($A13="",$C$35=0),"",$C13/$C$35) | E13: =IF($A13="","",IF(SUMIF('Data'!$B$5:$B$124,$A13,'Data'!$S$5:$S$124)=0,"",SUMIF('Data'!$B$5:$B$124,$A13,'Data'!$R$5:$R$124)/SUMIF('Data'!$B$5:$B$124,$A13,'Data'!$S$5:$S$124))) | F13: =IF($A13="","",IF(SUMIF('Data'!$B$5:$B$124,$A13,'Data'!$U$5:$U$124)=0,"",SUMIF('Data'!$B$5:$B$124,$A13,'Data'!$T$5:$T$124)/SUMIF('Data'!$B$5:$B$124,$A13,'Data'!$U$5:$U$124))) | G13: =IF($A13="","",IF(SUMIF('Data'!$B$5:$B$124,$A13,'Data'!$W$5:$W$124)=0,"",SUMIF('Data'!$B$5:$B$124,$A13,'Data'!$V$5:$V$124)/SUMIF('Data'!$B$5:$B$124,$A13,'Data'!$W$5:$W$124))) | H13: =IF($A13="","",IF(SUMIF('Data'!$B$5:$B$124,$A13,'Data'!$Y$5:$Y$124)=0,"",SUMIF('Data'!$B$5:$B$124,$A13,'Data'!$X$5:$X$124)/SUMIF('Data'!$B$5:$B$124,$A13,'Data'!$Y$5:$Y$124))) | I13: =IF($A13="","",COUNTIF('Data'!$B$5:$B$124,$A13)-COUNTIFS('Data'!$B$5:$B$124,$A13,'Data'!$S$5:$S$124,0)) | J13: =IF($A13="","",COUNTIF('Data'!$B$5:$B$124,$A13)-COUNTIFS('Data'!$B$5:$B$124,$A13,'Data'!$U$5:$U$124,0)) | K13: =IF($A13="","",COUNTIF('Data'!$B$5:$B$124,$A13)-COUNTIFS('Data'!$B$5:$B$124,$A13,'Data'!$W$5:$W$124,0)) | L13: =IF($A13="","",COUNTIF('Data'!$B$5:$B$124,$A13)-COUNTIFS('Data'!$B$5:$B$124,$A13,'Data'!$Y$5:$Y$124,0))
A14: =IFERROR(INDEX('Data'!$B$5:$B$124,MATCH(11,'Data'!$Z$5:$Z$124,0)),"") | B14: =IF($A14="","",COUNTIF('Data'!$B$5:$B$124,$A14)) | C14: =IF($A14="","",SUMIF('Data'!$B$5:$B$124,$A14,'Data'!$H$5:$H$124)) | D14: =IF(OR($A14="",$C$35=0),"",$C14/$C$35) | E14: =IF($A14="","",IF(SUMIF('Data'!$B$5:$B$124,$A14,'Data'!$S$5:$S$124)=0,"",SUMIF('Data'!$B$5:$B$124,$A14,'Data'!$R$5:$R$124)/SUMIF('Data'!$B$5:$B$124,$A14,'Data'!$S$5:$S$124))) | F14: =IF($A14="","",IF(SUMIF('Data'!$B$5:$B$124,$A14,'Data'!$U$5:$U$124)=0,"",SUMIF('Data'!$B$5:$B$124,$A14,'Data'!$T$5:$T$124)/SUMIF('Data'!$B$5:$B$124,$A14,'Data'!$U$5:$U$124))) | G14: =IF($A14="","",IF(SUMIF('Data'!$B$5:$B$124,$A14,'Data'!$W$5:$W$124)=0,"",SUMIF('Data'!$B$5:$B$124,$A14,'Data'!$V$5:$V$124)/SUMIF('Data'!$B$5:$B$124,$A14,'Data'!$W$5:$W$124))) | H14: =IF($A14="","",IF(SUMIF('Data'!$B$5:$B$124,$A14,'Data'!$Y$5:$Y$124)=0,"",SUMIF('Data'!$B$5:$B$124,$A14,'Data'!$X$5:$X$124)/SUMIF('Data'!$B$5:$B$124,$A14,'Data'!$Y$5:$Y$124))) | I14: =IF($A14="","",COUNTIF('Data'!$B$5:$B$124,$A14)-COUNTIFS('Data'!$B$5:$B$124,$A14,'Data'!$S$5:$S$124,0)) | J14: =IF($A14="","",COUNTIF('Data'!$B$5:$B$124,$A14)-COUNTIFS('Data'!$B$5:$B$124,$A14,'Data'!$U$5:$U$124,0)) | K14: =IF($A14="","",COUNTIF('Data'!$B$5:$B$124,$A14)-COUNTIFS('Data'!$B$5:$B$124,$A14,'Data'!$W$5:$W$124,0)) | L14: =IF($A14="","",COUNTIF('Data'!$B$5:$B$124,$A14)-COUNTIFS('Data'!$B$5:$B$124,$A14,'Data'!$Y$5:$Y$124,0))
A15: =IFERROR(INDEX('Data'!$B$5:$B$124,MATCH(12,'Data'!$Z$5:$Z$124,0)),"") | B15: =IF($A15="","",COUNTIF('Data'!$B$5:$B$124,$A15)) | C15: =IF($A15="","",SUMIF('Data'!$B$5:$B$124,$A15,'Data'!$H$5:$H$124)) | D15: =IF(OR($A15="",$C$35=0),"",$C15/$C$35) | E15: =IF($A15="","",IF(SUMIF('Data'!$B$5:$B$124,$A15,'Data'!$S$5:$S$124)=0,"",SUMIF('Data'!$B$5:$B$124,$A15,'Data'!$R$5:$R$124)/SUMIF('Data'!$B$5:$B$124,$A15,'Data'!$S$5:$S$124))) | F15: =IF($A15="","",IF(SUMIF('Data'!$B$5:$B$124,$A15,'Data'!$U$5:$U$124)=0,"",SUMIF('Data'!$B$5:$B$124,$A15,'Data'!$T$5:$T$124)/SUMIF('Data'!$B$5:$B$124,$A15,'Data'!$U$5:$U$124))) | G15: =IF($A15="","",IF(SUMIF('Data'!$B$5:$B$124,$A15,'Data'!$W$5:$W$124)=0,"",SUMIF('Data'!$B$5:$B$124,$A15,'Data'!$V$5:$V$124)/SUMIF('Data'!$B$5:$B$124,$A15,'Data'!$W$5:$W$124))) | H15: =IF($A15="","",IF(SUMIF('Data'!$B$5:$B$124,$A15,'Data'!$Y$5:$Y$124)=0,"",SUMIF('Data'!$B$5:$B$124,$A15,'Data'!$X$5:$X$124)/SUMIF('Data'!$B$5:$B$124,$A15,'Data'!$Y$5:$Y$124))) | I15: =IF($A15="","",COUNTIF('Data'!$B$5:$B$124,$A15)-COUNTIFS('Data'!$B$5:$B$124,$A15,'Data'!$S$5:$S$124,0)) | J15: =IF($A15="","",COUNTIF('Data'!$B$5:$B$124,$A15)-COUNTIFS('Data'!$B$5:$B$124,$A15,'Data'!$U$5:$U$124,0)) | K15: =IF($A15="","",COUNTIF('Data'!$B$5:$B$124,$A15)-COUNTIFS('Data'!$B$5:$B$124,$A15,'Data'!$W$5:$W$124,0)) | L15: =IF($A15="","",COUNTIF('Data'!$B$5:$B$124,$A15)-COUNTIFS('Data'!$B$5:$B$124,$A15,'Data'!$Y$5:$Y$124,0))
A16: =IFERROR(INDEX('Data'!$B$5:$B$124,MATCH(13,'Data'!$Z$5:$Z$124,0)),"") | B16: =IF($A16="","",COUNTIF('Data'!$B$5:$B$124,$A16)) | C16: =IF($A16="","",SUMIF('Data'!$B$5:$B$124,$A16,'Data'!$H$5:$H$124)) | D16: =IF(OR($A16="",$C$35=0),"",$C16/$C$35) | E16: =IF($A16="","",IF(SUMIF('Data'!$B$5:$B$124,$A16,'Data'!$S$5:$S$124)=0,"",SUMIF('Data'!$B$5:$B$124,$A16,'Data'!$R$5:$R$124)/SUMIF('Data'!$B$5:$B$124,$A16,'Data'!$S$5:$S$124))) | F16: =IF($A16="","",IF(SUMIF('Data'!$B$5:$B$124,$A16,'Data'!$U$5:$U$124)=0,"",SUMIF('Data'!$B$5:$B$124,$A16,'Data'!$T$5:$T$124)/SUMIF('Data'!$B$5:$B$124,$A16,'Data'!$U$5:$U$124))) | G16: =IF($A16="","",IF(SUMIF('Data'!$B$5:$B$124,$A16,'Data'!$W$5:$W$124)=0,"",SUMIF('Data'!$B$5:$B$124,$A16,'Data'!$V$5:$V$124)/SUMIF('Data'!$B$5:$B$124,$A16,'Data'!$W$5:$W$124))) | H16: =IF($A16="","",IF(SUMIF('Data'!$B$5:$B$124,$A16,'Data'!$Y$5:$Y$124)=0,"",SUMIF('Data'!$B$5:$B$124,$A16,'Data'!$X$5:$X$124)/SUMIF('Data'!$B$5:$B$124,$A16,'Data'!$Y$5:$Y$124))) | I16: =IF($A16="","",COUNTIF('Data'!$B$5:$B$124,$A16)-COUNTIFS('Data'!$B$5:$B$124,$A16,'Data'!$S$5:$S$124,0)) | J16: =IF($A16="","",COUNTIF('Data'!$B$5:$B$124,$A16)-COUNTIFS('Data'!$B$5:$B$124,$A16,'Data'!$U$5:$U$124,0)) | K16: =IF($A16="","",COUNTIF('Data'!$B$5:$B$124,$A16)-COUNTIFS('Data'!$B$5:$B$124,$A16,'Data'!$W$5:$W$124,0)) | L16: =IF($A16="","",COUNTIF('Data'!$B$5:$B$124,$A16)-COUNTIFS('Data'!$B$5:$B$124,$A16,'Data'!$Y$5:$Y$124,0))
A17: =IFERROR(INDEX('Data'!$B$5:$B$124,MATCH(14,'Data'!$Z$5:$Z$124,0)),"") | B17: =IF($A17="","",COUNTIF('Data'!$B$5:$B$124,$A17)) | C17: =IF($A17="","",SUMIF('Data'!$B$5:$B$124,$A17,'Data'!$H$5:$H$124)) | D17: =IF(OR($A17="",$C$35=0),"",$C17/$C$35) | E17: =IF($A17="","",IF(SUMIF('Data'!$B$5:$B$124,$A17,'Data'!$S$5:$S$124)=0,"",SUMIF('Data'!$B$5:$B$124,$A17,'Data'!$R$5:$R$124)/SUMIF('Data'!$B$5:$B$124,$A17,'Data'!$S$5:$S$124))) | F17: =IF($A17="","",IF(SUMIF('Data'!$B$5:$B$124,$A17,'Data'!$U$5:$U$124)=0,"",SUMIF('Data'!$B$5:$B$124,$A17,'Data'!$T$5:$T$124)/SUMIF('Data'!$B$5:$B$124,$A17,'Data'!$U$5:$U$124))) | G17: =IF($A17="","",IF(SUMIF('Data'!$B$5:$B$124,$A17,'Data'!$W$5:$W$124)=0,"",SUMIF('Data'!$B$5:$B$124,$A17,'Data'!$V$5:$V$124)/SUMIF('Data'!$B$5:$B$124,$A17,'Data'!$W$5:$W$124))) | H17: =IF($A17="","",IF(SUMIF('Data'!$B$5:$B$124,$A17,'Data'!$Y$5:$Y$124)=0,"",SUMIF('Data'!$B$5:$B$124,$A17,'Data'!$X$5:$X$124)/SUMIF('Data'!$B$5:$B$124,$A17,'Data'!$Y$5:$Y$124))) | I17: =IF($A17="","",COUNTIF('Data'!$B$5:$B$124,$A17)-COUNTIFS('Data'!$B$5:$B$124,$A17,'Data'!$S$5:$S$124,0)) | J17: =IF($A17="","",COUNTIF('Data'!$B$5:$B$124,$A17)-COUNTIFS('Data'!$B$5:$B$124,$A17,'Data'!$U$5:$U$124,0)) | K17: =IF($A17="","",COUNTIF('Data'!$B$5:$B$124,$A17)-COUNTIFS('Data'!$B$5:$B$124,$A17,'Data'!$W$5:$W$124,0)) | L17: =IF($A17="","",COUNTIF('Data'!$B$5:$B$124,$A17)-COUNTIFS('Data'!$B$5:$B$124,$A17,'Data'!$Y$5:$Y$124,0))
